Workbook

Sheet Read me
A1: TrustLedger analyst workbook (P07-ART-05)
A3: What it is | B3: A formula-driven recomputation of the TrustLedger quality ledger over the published synthetic snapshot tl-20261026-20261026 (dataset hash a9f7a3321b102752dd7aa95b76df14c1d9372103e685e10222959fd6438f27ff, code revision 0b5d686, as-of 2026-10-05T00:00:00Z): 40 datasets, 60 rules (55 active), 574 issues, 160 lineage edges, 30 published metrics, 400 match candidates.
A4: The decision | B4: Which data issues should be fixed first and who is accountable? The workbook shows each dataset's score under both weight versions with the critical override beside it, the issues by class (a claim is not a resolution), mean resolution by team, ownership coverage, lineage, definitions, match precision and timeliness.
A5: Synthetic data | B5: Everything is synthetic (a seeded generator). Observed = what this one draw shows; constructed = what the generator built in on purpose (its designed relationships and injected defects); hypothetical benefits are not claimed.
A6: How to use it | B6: Open the .xlsx in any spreadsheet application. Controls!B3 switches the weight version; Checks!B2 is TRUE when every figure agrees with the Python domain and the golden hand answer. Nothing needs installing to read the cached values.
A7: Recalculation status | B7: openpyxl wrote formulas only; LibreOffice (headless) recalculated the delivered file. Microsoft Excel was NOT run: nothing here was opened or recalculated by Excel (docs/workbook.md).
A8: Sheets | B8: Controls, Checks, Portfolio, Dataset scores, Golden case, Assumptions (read-this-first limits), data sheets (Rule results, Issues, Owners, Datasets, Lineage, Definitions, Matching, Timeliness, Weights), Domain reference (pasted values), SQL results (pasted).
A9: Colour | B9: Blue = typed input or pasted value; black = formula.

Sheet Controls
A1: Controls
A2: Change B3 (w1 or w2): the Selected column of `Dataset scores` follows it. Blue cells are inputs.
A3: Weight version (switch) | B3: w2
A4: As-of (UTC) | B4: 46300
A6: Weights of the selected version
A7: completeness | B7: =INDEX(Weights!$C$4:$C$5,MATCH($B$3,Weights!$A$4:$A$5,0)) -> 0.25
A8: validity | B8: =INDEX(Weights!$D$4:$D$5,MATCH($B$3,Weights!$A$4:$A$5,0)) -> 0.25
A9: uniqueness | B9: =INDEX(Weights!$E$4:$E$5,MATCH($B$3,Weights!$A$4:$A$5,0)) -> 0.25
A10: relationship | B10: =INDEX(Weights!$F$4:$F$5,MATCH($B$3,Weights!$A$4:$A$5,0)) -> 0.15
A11: timeliness | B11: =INDEX(Weights!$G$4:$G$5,MATCH($B$3,Weights!$A$4:$A$5,0)) -> 0.1
A13: Sum of the five weights (must be 1) | B13: =SUM(B7:B11) -> 1
A15: All checks pass (Checks!B2) | B15: =Checks!B2 -> TRUE

Sheet Checks
A1: Checks: TRUE when every comparison with the Python domain and the golden hand answer holds
A2: All checks pass | B2: =AND(Portfolio!E4:E38,'Dataset scores'!U4:U43,'Golden case'!E4:E24,B5,B6) -> TRUE
A4: check | B4: result
A5: Selected column equals the domain's score under the version chosen at Controls!B3 (every dataset) | B5: =SUMPRODUCT(--ISNUMBER('Dataset scores'!L4:L43))=SUMPRODUCT(--ISNUMBER(IF(Controls!B3="w1",'Dataset scores'!S4:S43,'Dataset scores'!T4:T43))) -> TRUE
A6: Every dataset-by-version row of Dataset scores agrees with the domain (rounded to 6 places) | B6: =COUNTIF('Dataset scores'!U4:U43,TRUE())=ROWS('Dataset scores'!U4:U43) -> TRUE

Sheet Portfolio
A1: Portfolio metrics, live formulas against the domain's values
A2: Column B is a formula over the data sheets; C is the domain's value pasted from `Domain reference`; D is the tolerance; E is TRUE when they agree.
A3: measure | B3: workbook (formula) | C3: domain (pasted) | D3: tolerance | E3: check
A4: datasets | B4: =COUNTA(Datasets!A4:A43) -> 40 | C4: 40 | D4: 0 | E4: =ABS(B4-C4)<=D4 -> TRUE
A5: datasets with an accountable owner | B5: =COUNTIF(Datasets!D4:D43,TRUE()) -> 35 | C5: 35 | D5: 0 | E5: =ABS(B5-C5)<=D5 -> TRUE
A6: ownership coverage | B6: =COUNTIF(Datasets!D4:D43,TRUE())/COUNTA(Datasets!A4:A43) -> 0.875 | C6: 0.875 | D6: 5e-07 | E6: =ABS(B6-C6)<=D6 -> TRUE
A7: issues resolved (a successful rerun of the same rule version) | B7: =COUNTIF(Issues!$U$4:$U$577,"resolved") -> 315 | C7: 315 | D7: 0 | E7: =ABS(B7-C7)<=D7 -> TRUE
A8: issues claimed (closed without one) | B8: =COUNTIF(Issues!$U$4:$U$577,"claimed") -> 99 | C8: 99 | D8: 0 | E8: =ABS(B8-C8)<=D8 -> TRUE
A9: issues open | B9: =COUNTIF(Issues!$U$4:$U$577,"open") -> 160 | C9: 160 | D9: 0 | E9: =ABS(B9-C9)<=D9 -> TRUE
A10: mean resolution hours (resolved only) | B10: =AVERAGEIFS(Issues!$V$4:$V$577,Issues!$U$4:$U$577,"resolved") -> 68.271587 | C10: 68.2716 | D10: 5e-05 | E10: =ABS(B10-C10)<=D10 -> TRUE
A11: mean resolution hours, Data Platform | B11: =AVERAGEIFS(Issues!$V$4:$V$577,Issues!$U$4:$U$577,"resolved",Issues!$R$4:$R$577,"Data Platform") -> 34.42018 | C11: 34.4202 | D11: 5e-05 | E11: =ABS(B11-C11)<=D11 -> TRUE
A12: mean resolution hours, all other teams | B12: =AVERAGEIFS(Issues!$V$4:$V$577,Issues!$U$4:$U$577,"resolved",Issues!$R$4:$R$577,"<>Data Platform") -> 86.183254 | C12: 86.1833 | D12: 5e-05 | E12: =ABS(B12-C12)<=D12 -> TRUE
A13: fast team ratio (Data Platform / others) | B13: =AVERAGEIFS(Issues!$V$4:$V$577,Issues!$U$4:$U$577,"resolved",Issues!$R$4:$R$577,"Data Platform")/AVERAGEIFS(Issues!$V$4:$V$577,Issues!$U$4:$U$577,"resolved",Issues!$R$4:$R$577,"<>Data Platform") -> 0.39938362 | C13: 0.399384 | D13: 5e-07 | E13: =ABS(B13-C13)<=D13 -> TRUE
A14: unresolved critical issues | B14: =COUNTIFS(Issues!$E$4:$E$577,"critical",Issues!$U$4:$U$577,"<>resolved") -> 1 | C14: 1 | D14: 0 | E14: =ABS(B14-C14)<=D14 -> TRUE
A15: unresolved high issues | B15: =COUNTIFS(Issues!$E$4:$E$577,"high",Issues!$U$4:$U$577,"<>resolved") -> 171 | C15: 171 | D15: 0 | E15: =ABS(B15-C15)<=D15 -> TRUE
A16: unresolved medium issues | B16: =COUNTIFS(Issues!$E$4:$E$577,"medium",Issues!$U$4:$U$577,"<>resolved") -> 70 | C16: 70 | D16: 0 | E16: =ABS(B16-C16)<=D16 -> TRUE
A17: unresolved low issues | B17: =COUNTIFS(Issues!$E$4:$E$577,"low",Issues!$U$4:$U$577,"<>resolved") -> 17 | C17: 17 | D17: 0 | E17: =ABS(B17-C17)<=D17 -> TRUE
A18: declared lineage edges | B18: =COUNTIF(Lineage!D4:D163,"declared") -> 80 | C18: 80 | D18: 0 | E18: =ABS(B18-C18)<=D18 -> TRUE
A19: observed edges matching a declared pair | B19: =COUNTIF(Lineage!I4:I163,TRUE()) -> 58 | C19: 58 | D19: 0 | E19: =ABS(B19-C19)<=D19 -> TRUE
A20: lineage coverage | B20: =COUNTIF(Lineage!I4:I163,TRUE())/COUNTIF(Lineage!D4:D163,"declared") -> 0.725 | C20: 0.725 | D20: 5e-07 | E20: =ABS(B20-C20)<=D20 -> TRUE
A21: undeclared observed edges | B21: =COUNTIFS(Lineage!D4:D163,"observed",Lineage!G4:G163,FALSE()) -> 12 | C21: 12 | D21: 0 | E21: =ABS(B21-C21)<=D21 -> TRUE
A22: inferred edges (never observed) | B22: =COUNTIF(Lineage!D4:D163,"inferred") -> 10 | C22: 10 | D22: 0 | E22: =ABS(B22-C22)<=D22 -> TRUE
A23: published metrics | B23: =COUNTA(Definitions!A4:A33) -> 30 | C23: 30 | D23: 0 | E23: =ABS(B23-C23)<=D23 -> TRUE
A24: metrics with a complete checklist | B24: =COUNTIF(Definitions!N4:N33,TRUE()) -> 23 | C24: 23 | D24: 0 | E24: =ABS(B24-C24)<=D24 -> TRUE
A25: definition coverage | B25: =COUNTIF(Definitions!N4:N33,TRUE())/COUNTA(Definitions!A4:A33) -> 0.76666667 | C25: 0.766667 | D25: 5e-07 | E25: =ABS(B25-C25)<=D25 -> TRUE
A26: approved merge decisions | B26: =COUNTIF(Matching!B4:B403,"approve") -> 174 | C26: 174 | D26: 0 | E26: =ABS(B26-C26)<=D26 -> TRUE
A27: approved decisions the truth confirms | B27: =COUNTIFS(Matching!B4:B403,"approve",Matching!E4:E403,TRUE()) -> 172 | C27: 172 | D27: 0 | E27: =ABS(B27-C27)<=D27 -> TRUE
A28: match precision (over approvals) | B28: =COUNTIFS(Matching!B4:B403,"approve",Matching!E4:E403,TRUE())/COUNTIF(Matching!B4:B403,"approve") -> 0.98850575 | C28: 0.988506 | D28: 5e-07 | E28: =ABS(B28-C28)<=D28 -> TRUE
A29: reviewed candidates (approved or rejected) | B29: =COUNTIF(Matching!B4:B403,"approve")+COUNTIF(Matching!B4:B403,"reject") -> 220 | C29: 220 | D29: 0 | E29: =ABS(B29-C29)<=D29 -> TRUE
A30: review-correct share (reviewed candidates that are the same entity) | B30: =(COUNTIFS(Matching!B4:B403,"approve",Matching!E4:E403,TRUE())+COUNTIFS(Matching!B4:B403,"reject",Matching!E4:E403,TRUE()))/(COUNTIF(Matching!B4:B403,"approve")+COUNTIF(Matching!B4:B403,"reject")) -> 0.84090909 | C30: 0.840909 | D30: 5e-07 | E30: =ABS(B30-C30)<=D30 -> TRUE
A31: decision-agreement share (reviews that agree with the truth; the analysis's own) | B31: =COUNTIF(Matching!F4:F403,TRUE())/COUNT(Matching!F4:F403) -> 0.93181818 | C31: (no domain value: the contract does not publish it; see the SQL investigation 07)
A32: monitored datasets | B32: =COUNTA(Timeliness!A4:A18) -> 15 | C32: 15 | D32: 0 | E32: =ABS(B32-C32)<=D32 -> TRUE
A33: on time | B33: =COUNTIF(Timeliness!H4:H18,"on_time") -> 10 | C33: 10 | D33: 0 | E33: =ABS(B33-C33)<=D33 -> TRUE
A34: pending (outside the denominator) | B34: =COUNTIF(Timeliness!H4:H18,"pending") -> 0 | C34: 0 | D34: 0 | E34: =ABS(B34-C34)<=D34 -> TRUE
A35: timeliness | B35: =COUNTIF(Timeliness!H4:H18,"on_time")/(COUNTA(Timeliness!A4:A18)-COUNTIF(Timeliness!H4:H18,"pending")) -> 0.66666667 | C35: 0.666667 | D35: 5e-07 | E35: =ABS(B35-C35)<=D35 -> TRUE
A36: critical failures (failing rows of active critical rules) | B36: ='Dataset scores'!B53 -> 2 | C36: 2 | D36: 0 | E36: =ABS(B36-C36)<=D36 -> TRUE
A37: datasets carrying the critical override | B37: ='Dataset scores'!B52 -> 1 | C37: 1 | D37: 0 | E37: =ABS(B37-C37)<=D37 -> TRUE
A38: open critical issues | B38: ='Dataset scores'!B54 -> 1 | C38: 1 | D38: 0 | E38: =ABS(B38-C38)<=D38 -> TRUE

Sheet Dataset scores
A1: Weighted score of every dataset under both weight versions, with the critical override beside it
A2: Dimension score = mean of the dataset's measured rules; weighted = sum(weight x score) / sum(weights of the MEASURED dimensions); a dataset that measures nothing is empty, never 0. Selected = the version chosen at Controls!B3.
A3: dataset_id | B3: completeness | C3: validity | D3: uniqueness | E3: relationship | F3: timeliness | G3: weight_sum_w1 | H3: weighted_w1 | I3: weight_sum_w2 | J3: weighted_w2 | K3: shift (w2 - w1) | L3: selected | M3: critical_failures | N3: open_critical_issues | O3: critical_override | P3: differs | Q3: moved_at_least_0_005 | R3: abs_shift | S3: ref_w1 (domain) | T3: ref_w2 (domain) | U3: check
A4: ds-accounts | B4: =IFERROR(AVERAGEIFS('Rule results'!$I$4:$I$58,'Rule results'!$B$4:$B$58,$A4,'Rule results'!$C$4:$C$58,B$3),"") | C4: =IFERROR(AVERAGEIFS('Rule results'!$I$4:$I$58,'Rule results'!$B$4:$B$58,$A4,'Rule results'!$C$4:$C$58,C$3),"") | D4: =IFERROR(AVERAGEIFS('Rule results'!$I$4:$I$58,'Rule results'!$B$4:$B$58,$A4,'Rule results'!$C$4:$C$58,D$3),"") -> 1 | E4: =IFERROR(AVERAGEIFS('Rule results'!$I$4:$I$58,'Rule results'!$B$4:$B$58,$A4,'Rule results'!$C$4:$C$58,E$3),"") -> 0.95 | F4: =IFERROR(AVERAGEIFS('Rule results'!$I$4:$I$58,'Rule results'!$B$4:$B$58,$A4,'Rule results'!$C$4:$C$58,F$3),"") | G4: =IF(ISNUMBER(B4),Weights!$C$4,0)+IF(ISNUMBER(C4),Weights!$D$4,0)+IF(ISNUMBER(D4),Weights!$E$4,0)+IF(ISNUMBER(E4),Weights!$F$4,0)+IF(ISNUMBER(F4),Weights!$G$4,0) -> 0.25 | H4: =IF(G4=0,"",(IF(ISNUMBER(B4),Weights!$C$4*B4,0)+IF(ISNUMBER(C4),Weights!$D$4*C4,0)+IF(ISNUMBER(D4),Weights!$E$4*D4,0)+IF(ISNUMBER(E4),Weights!$F$4*E4,0)+IF(ISNUMBER(F4),Weights!$G$4*F4,0))/G4) -> 0.99 | I4: =IF(ISNUMBER(B4),Weights!$C$5,0)+IF(ISNUMBER(C4),Weights!$D$5,0)+IF(ISNUMBER(D4),Weights!$E$5,0)+IF(ISNUMBER(E4),Weights!$F$5,0)+IF(ISNUMBER(F4),Weights!$G$5,0) -> 0.4 | J4: =IF(I4=0,"",(IF(ISNUMBER(B4),Weights!$C$5*B4,0)+IF(ISNUMBER(C4),Weights!$D$5*C4,0)+IF(ISNUMBER(D4),Weights!$E$5*D4,0)+IF(ISNUMBER(E4),Weights!$F$5*E4,0)+IF(ISNUMBER(F4),Weights!$G$5*F4,0))/I4) -> 0.98125 | K4: =IF(AND(ISNUMBER(H4),ISNUMBER(J4)),J4-H4,"") -> -0.00875 | L4: =IF(Controls!$B$3="w1",H4,J4) -> 0.98125 | M4: =SUMIFS('Rule results'!$G$4:$G$58,'Rule results'!$B$4:$B$58,$A4,'Rule results'!$D$4:$D$58,"critical") -> 0 | N4: =COUNTIFS(Issues!$B$4:$B$577,$A4,Issues!$E$4:$E$577,"critical",Issues!$U$4:$U$577,"<>resolved") -> 0 | O4: =OR(M4>0,N4>0) -> FALSE | P4: =IF(ISNUMBER(K4),IF(ABS(K4)>0.000000000001,1,0),"") -> 1 | Q4: =IF(ISNUMBER(K4),IF(ABS(K4)>=0.005,1,0),"") -> 1 | R4: =IF(ISNUMBER(K4),ABS(K4),"") -> 0.00875 | S4: ='Domain reference'!B4 -> 0.99 | T4: ='Domain reference'!C4 -> 0.98125 | U4: =AND(IF(ISNUMBER(H4),ISNUMBER(S4),NOT(ISNUMBER(S4))),IF(ISNUMBER(J4),ISNUMBER(T4),NOT(ISNUMBER(T4))),IF(ISNUMBER(H4),ABS(ROUND(H4,6)-S4)<0.0000005,TRUE()),IF(ISNUMBER(J4),ABS(ROUND(J4,6)-T4)<0.0000005,TRUE())) -> TRUE
A5: ds-billing-accounts | B5: =IFERROR(AVERAGEIFS('Rule results'!$I$4:$I$58,'Rule results'!$B$4:$B$58,$A5,'Rule results'!$C$4:$C$58,B$3),"") | C5: =IFERROR(AVERAGEIFS('Rule results'!$I$4:$I$58,'Rule results'!$B$4:$B$58,$A5,'Rule results'!$C$4:$C$58,C$3),"") | D5: =IFERROR(AVERAGEIFS('Rule results'!$I$4:$I$58,'Rule results'!$B$4:$B$58,$A5,'Rule results'!$C$4:$C$58,D$3),"") | E5: =IFERROR(AVERAGEIFS('Rule results'!$I$4:$I$58,'Rule results'!$B$4:$B$58,$A5,'Rule results'!$C$4:$C$58,E$3),"") | F5: =IFERROR(AVERAGEIFS('Rule results'!$I$4:$I$58,'Rule results'!$B$4:$B$58,$A5,'Rule results'!$C$4:$C$58,F$3),"") | G5: =IF(ISNUMBER(B5),Weights!$C$4,0)+IF(ISNUMBER(C5),Weights!$D$4,0)+IF(ISNUMBER(D5),Weights!$E$4,0)+IF(ISNUMBER(E5),Weights!$F$4,0)+IF(ISNUMBER(F5),Weights!$G$4,0) -> 0 | H5: =IF(G5=0,"",(IF(ISNUMBER(B5),Weights!$C$4*B5,0)+IF(ISNUMBER(C5),Weights!$D$4*C5,0)+IF(ISNUMBER(D5),Weights!$E$4*D5,0)+IF(ISNUMBER(E5),Weights!$F$4*E5,0)+IF(ISNUMBER(F5),Weights!$G$4*F5,0))/G5) | I5: =IF(ISNUMBER(B5),Weights!$C$5,0)+IF(ISNUMBER(C5),Weights!$D$5,0)+IF(ISNUMBER(D5),Weights!$E$5,0)+IF(ISNUMBER(E5),Weights!$F$5,0)+IF(ISNUMBER(F5),Weights!$G$5,0) -> 0 | J5: =IF(I5=0,"",(IF(ISNUMBER(B5),Weights!$C$5*B5,0)+IF(ISNUMBER(C5),Weights!$D$5*C5,0)+IF(ISNUMBER(D5),Weights!$E$5*D5,0)+IF(ISNUMBER(E5),Weights!$F$5*E5,0)+IF(ISNUMBER(F5),Weights!$G$5*F5,0))/I5) | K5: =IF(AND(ISNUMBER(H5),ISNUMBER(J5)),J5-H5,"") | L5: =IF(Controls!$B$3="w1",H5,J5) | M5: =SUMIFS('Rule results'!$G$4:$G$58,'Rule results'!$B$4:$B$58,$A5,'Rule results'!$D$4:$D$58,"critical") -> 0 | N5: =COUNTIFS(Issues!$B$4:$B$577,$A5,Issues!$E$4:$E$577,"critical",Issues!$U$4:$U$577,"<>resolved") -> 0 | O5: =OR(M5>0,N5>0) -> FALSE | P5: =IF(ISNUMBER(K5),IF(ABS(K5)>0.000000000001,1,0),"") | Q5: =IF(ISNUMBER(K5),IF(ABS(K5)>=0.005,1,0),"") | R5: =IF(ISNUMBER(K5),ABS(K5),"") | S5: ='Domain reference'!B5 -> not measured | T5: ='Domain reference'!C5 -> not measured | U5: =AND(IF(ISNUMBER(H5),ISNUMBER(S5),NOT(ISNUMBER(S5))),IF(ISNUMBER(J5),ISNUMBER(T5),NOT(ISNUMBER(T5))),IF(ISNUMBER(H5),ABS(ROUND(H5,6)-S5)<0.0000005,TRUE()),IF(ISNUMBER(J5),ABS(ROUND(J5,6)-T5)<0.0000005,TRUE())) -> TRUE
A6: ds-campaigns | B6: =IFERROR(AVERAGEIFS('Rule results'!$I$4:$I$58,'Rule results'!$B$4:$B$58,$A6,'Rule results'!$C$4:$C$58,B$3),"") | C6: =IFERROR(AVERAGEIFS('Rule results'!$I$4:$I$58,'Rule results'!$B$4:$B$58,$A6,'Rule results'!$C$4:$C$58,C$3),"") | D6: =IFERROR(AVERAGEIFS('Rule results'!$I$4:$I$58,'Rule results'!$B$4:$B$58,$A6,'Rule results'!$C$4:$C$58,D$3),"") | E6: =IFERROR(AVERAGEIFS('Rule results'!$I$4:$I$58,'Rule results'!$B$4:$B$58,$A6,'Rule results'!$C$4:$C$58,E$3),"") | F6: =IFERROR(AVERAGEIFS('Rule results'!$I$4:$I$58,'Rule results'!$B$4:$B$58,$A6,'Rule results'!$C$4:$C$58,F$3),"") | G6: =IF(ISNUMBER(B6),Weights!$C$4,0)+IF(ISNUMBER(C6),Weights!$D$4,0)+IF(ISNUMBER(D6),Weights!$E$4,0)+IF(ISNUMBER(E6),Weights!$F$4,0)+IF(ISNUMBER(F6),Weights!$G$4,0) -> 0 | H6: =IF(G6=0,"",(IF(ISNUMBER(B6),Weights!$C$4*B6,0)+IF(ISNUMBER(C6),Weights!$D$4*C6,0)+IF(ISNUMBER(D6),Weights!$E$4*D6,0)+IF(ISNUMBER(E6),Weights!$F$4*E6,0)+IF(ISNUMBER(F6),Weights!$G$4*F6,0))/G6) | I6: =IF(ISNUMBER(B6),Weights!$C$5,0)+IF(ISNUMBER(C6),Weights!$D$5,0)+IF(ISNUMBER(D6),Weights!$E$5,0)+IF(ISNUMBER(E6),Weights!$F$5,0)+IF(ISNUMBER(F6),Weights!$G$5,0) -> 0 | J6: =IF(I6=0,"",(IF(ISNUMBER(B6),Weights!$C$5*B6,0)+IF(ISNUMBER(C6),Weights!$D$5*C6,0)+IF(ISNUMBER(D6),Weights!$E$5*D6,0)+IF(ISNUMBER(E6),Weights!$F$5*E6,0)+IF(ISNUMBER(F6),Weights!$G$5*F6,0))/I6) | K6: =IF(AND(ISNUMBER(H6),ISNUMBER(J6)),J6-H6,"") | L6: =IF(Controls!$B$3="w1",H6,J6) | M6: =SUMIFS('Rule results'!$G$4:$G$58,'Rule results'!$B$4:$B$58,$A6,'Rule results'!$D$4:$D$58,"critical") -> 0 | N6: =COUNTIFS(Issues!$B$4:$B$577,$A6,Issues!$E$4:$E$577,"critical",Issues!$U$4:$U$577,"<>resolved") -> 0 | O6: =OR(M6>0,N6>0) -> FALSE | P6: =IF(ISNUMBER(K6),IF(ABS(K6)>0.000000000001,1,0),"") | Q6: =IF(ISNUMBER(K6),IF(ABS(K6)>=0.005,1,0),"") | R6: =IF(ISNUMBER(K6),ABS(K6),"") | S6: ='Domain reference'!B6 -> not measured | T6: ='Domain reference'!C6 -> not measured | U6: =AND(IF(ISNUMBER(H6),ISNUMBER(S6),NOT(ISNUMBER(S6))),IF(ISNUMBER(J6),ISNUMBER(T6),NOT(ISNUMBER(T6))),IF(ISNUMBER(H6),ABS(ROUND(H6,6)-S6)<0.0000005,TRUE()),IF(ISNUMBER(J6),ABS(ROUND(J6,6)-T6)<0.0000005,TRUE())) -> TRUE
A7: ds-carriers | B7: =IFERROR(AVERAGEIFS('Rule results'!$I$4:$I$58,'Rule results'!$B$4:$B$58,$A7,'Rule results'!$C$4:$C$58,B$3),"") | C7: =IFERROR(AVERAGEIFS('Rule results'!$I$4:$I$58,'Rule results'!$B$4:$B$58,$A7,'Rule results'!$C$4:$C$58,C$3),"") -> 0.96638655 | D7: =IFERROR(AVERAGEIFS('Rule results'!$I$4:$I$58,'Rule results'!$B$4:$B$58,$A7,'Rule results'!$C$4:$C$58,D$3),"") | E7: =IFERROR(AVERAGEIFS('Rule results'!$I$4:$I$58,'Rule results'!$B$4:$B$58,$A7,'Rule results'!$C$4:$C$58,E$3),"") | F7: =IFERROR(AVERAGEIFS('Rule results'!$I$4:$I$58,'Rule results'!$B$4:$B$58,$A7,'Rule results'!$C$4:$C$58,F$3),"") | G7: =IF(ISNUMBER(B7),Weights!$C$4,0)+IF(ISNUMBER(C7),Weights!$D$4,0)+IF(ISNUMBER(D7),Weights!$E$4,0)+IF(ISNUMBER(E7),Weights!$F$4,0)+IF(ISNUMBER(F7),Weights!$G$4,0) -> 0.3 | H7: =IF(G7=0,"",(IF(ISNUMBER(B7),Weights!$C$4*B7,0)+IF(ISNUMBER(C7),Weights!$D$4*C7,0)+IF(ISNUMBER(D7),Weights!$E$4*D7,0)+IF(ISNUMBER(E7),Weights!$F$4*E7,0)+IF(ISNUMBER(F7),Weights!$G$4*F7,0))/G7) -> 0.96638655 | I7: =IF(ISNUMBER(B7),Weights!$C$5,0)+IF(ISNUMBER(C7),Weights!$D$5,0)+IF(ISNUMBER(D7),Weights!$E$5,0)+IF(ISNUMBER(E7),Weights!$F$5,0)+IF(ISNUMBER(F7),Weights!$G$5,0) -> 0.25 | J7: =IF(I7=0,"",(IF(ISNUMBER(B7),Weights!$C$5*B7,0)+IF(ISNUMBER(C7),Weights!$D$5*C7,0)+IF(ISNUMBER(D7),Weights!$E$5*D7,0)+IF(ISNUMBER(E7),Weights!$F$5*E7,0)+IF(ISNUMBER(F7),Weights!$G$5*F7,0))/I7) -> 0.96638655 | K7: =IF(AND(ISNUMBER(H7),ISNUMBER(J7)),J7-H7,"") -> 0 | L7: =IF(Controls!$B$3="w1",H7,J7) -> 0.96638655 | M7: =SUMIFS('Rule results'!$G$4:$G$58,'Rule results'!$B$4:$B$58,$A7,'Rule results'!$D$4:$D$58,"critical") -> 0 | N7: =COUNTIFS(Issues!$B$4:$B$577,$A7,Issues!$E$4:$E$577,"critical",Issues!$U$4:$U$577,"<>resolved") -> 0 | O7: =OR(M7>0,N7>0) -> FALSE | P7: =IF(ISNUMBER(K7),IF(ABS(K7)>0.000000000001,1,0),"") -> 0 | Q7: =IF(ISNUMBER(K7),IF(ABS(K7)>=0.005,1,0),"") -> 0 | R7: =IF(ISNUMBER(K7),ABS(K7),"") -> 0 | S7: ='Domain reference'!B7 -> 0.966387 | T7: ='Domain reference'!C7 -> 0.966387 | U7: =AND(IF(ISNUMBER(H7),ISNUMBER(S7),NOT(ISNUMBER(S7))),IF(ISNUMBER(J7),ISNUMBER(T7),NOT(ISNUMBER(T7))),IF(ISNUMBER(H7),ABS(ROUND(H7,6)-S7)<0.0000005,TRUE()),IF(ISNUMBER(J7),ABS(ROUND(J7,6)-T7)<0.0000005,TRUE())) -> TRUE
A8: ds-consent-records | B8: =IFERROR(AVERAGEIFS('Rule results'!$I$4:$I$58,'Rule results'!$B$4:$B$58,$A8,'Rule results'!$C$4:$C$58,B$3),"") -> 0.90588235 | C8: =IFERROR(AVERAGEIFS('Rule results'!$I$4:$I$58,'Rule results'!$B$4:$B$58,$A8,'Rule results'!$C$4:$C$58,C$3),"") | D8: =IFERROR(AVERAGEIFS('Rule results'!$I$4:$I$58,'Rule results'!$B$4:$B$58,$A8,'Rule results'!$C$4:$C$58,D$3),"") | E8: =IFERROR(AVERAGEIFS('Rule results'!$I$4:$I$58,'Rule results'!$B$4:$B$58,$A8,'Rule results'!$C$4:$C$58,E$3),"") | F8: =IFERROR(AVERAGEIFS('Rule results'!$I$4:$I$58,'Rule results'!$B$4:$B$58,$A8,'Rule results'!$C$4:$C$58,F$3),"") -> 1 | G8: =IF(ISNUMBER(B8),Weights!$C$4,0)+IF(ISNUMBER(C8),Weights!$D$4,0)+IF(ISNUMBER(D8),Weights!$E$4,0)+IF(ISNUMBER(E8),Weights!$F$4,0)+IF(ISNUMBER(F8),Weights!$G$4,0) -> 0.45 | H8: =IF(G8=0,"",(IF(ISNUMBER(B8),Weights!$C$4*B8,0)+IF(ISNUMBER(C8),Weights!$D$4*C8,0)+IF(ISNUMBER(D8),Weights!$E$4*D8,0)+IF(ISNUMBER(E8),Weights!$F$4*E8,0)+IF(ISNUMBER(F8),Weights!$G$4*F8,0))/G8) -> 0.91633987 | I8: =IF(ISNUMBER(B8),Weights!$C$5,0)+IF(ISNUMBER(C8),Weights!$D$5,0)+IF(ISNUMBER(D8),Weights!$E$5,0)+IF(ISNUMBER(E8),Weights!$F$5,0)+IF(ISNUMBER(F8),Weights!$G$5,0) -> 0.35 | J8: =IF(I8=0,"",(IF(ISNUMBER(B8),Weights!$C$5*B8,0)+IF(ISNUMBER(C8),Weights!$D$5*C8,0)+IF(ISNUMBER(D8),Weights!$E$5*D8,0)+IF(ISNUMBER(E8),Weights!$F$5*E8,0)+IF(ISNUMBER(F8),Weights!$G$5*F8,0))/I8) -> 0.93277311 | K8: =IF(AND(ISNUMBER(H8),ISNUMBER(J8)),J8-H8,"") -> 0.01643324 | L8: =IF(Controls!$B$3="w1",H8,J8) -> 0.93277311 | M8: =SUMIFS('Rule results'!$G$4:$G$58,'Rule results'!$B$4:$B$58,$A8,'Rule results'!$D$4:$D$58,"critical") -> 0 | N8: =COUNTIFS(Issues!$B$4:$B$577,$A8,Issues!$E$4:$E$577,"critical",Issues!$U$4:$U$577,"<>resolved") -> 0 | O8: =OR(M8>0,N8>0) -> FALSE | P8: =IF(ISNUMBER(K8),IF(ABS(K8)>0.000000000001,1,0),"") -> 1 | Q8: =IF(ISNUMBER(K8),IF(ABS(K8)>=0.005,1,0),"") -> 1 | R8: =IF(ISNUMBER(K8),ABS(K8),"") -> 0.01643324 | S8: ='Domain reference'!B8 -> 0.91634 | T8: ='Domain reference'!C8 -> 0.932773 | U8: =AND(IF(ISNUMBER(H8),ISNUMBER(S8),NOT(ISNUMBER(S8))),IF(ISNUMBER(J8),ISNUMBER(T8),NOT(ISNUMBER(T8))),IF(ISNUMBER(H8),ABS(ROUND(H8,6)-S8)<0.0000005,TRUE()),IF(ISNUMBER(J8),ABS(ROUND(J8,6)-T8)<0.0000005,TRUE())) -> TRUE
A9: ds-contacts | B9: =IFERROR(AVERAGEIFS('Rule results'!$I$4:$I$58,'Rule results'!$B$4:$B$58,$A9,'Rule results'!$C$4:$C$58,B$3),"") -> 0.98214286 | C9: =IFERROR(AVERAGEIFS('Rule results'!$I$4:$I$58,'Rule results'!$B$4:$B$58,$A9,'Rule results'!$C$4:$C$58,C$3),"") | D9: =IFERROR(AVERAGEIFS('Rule results'!$I$4:$I$58,'Rule results'!$B$4:$B$58,$A9,'Rule results'!$C$4:$C$58,D$3),"") | E9: =IFERROR(AVERAGEIFS('Rule results'!$I$4:$I$58,'Rule results'!$B$4:$B$58,$A9,'Rule results'!$C$4:$C$58,E$3),"") -> 1 | F9: =IFERROR(AVERAGEIFS('Rule results'!$I$4:$I$58,'Rule results'!$B$4:$B$58,$A9,'Rule results'!$C$4:$C$58,F$3),"") | G9: =IF(ISNUMBER(B9),Weights!$C$4,0)+IF(ISNUMBER(C9),Weights!$D$4,0)+IF(ISNUMBER(D9),Weights!$E$4,0)+IF(ISNUMBER(E9),Weights!$F$4,0)+IF(ISNUMBER(F9),Weights!$G$4,0) -> 0.45 | H9: =IF(G9=0,"",(IF(ISNUMBER(B9),Weights!$C$4*B9,0)+IF(ISNUMBER(C9),Weights!$D$4*C9,0)+IF(ISNUMBER(D9),Weights!$E$4*D9,0)+IF(ISNUMBER(E9),Weights!$F$4*E9,0)+IF(ISNUMBER(F9),Weights!$G$4*F9,0))/G9) -> 0.98412698 | I9: =IF(ISNUMBER(B9),Weights!$C$5,0)+IF(ISNUMBER(C9),Weights!$D$5,0)+IF(ISNUMBER(D9),Weights!$E$5,0)+IF(ISNUMBER(E9),Weights!$F$5,0)+IF(ISNUMBER(F9),Weights!$G$5,0) -> 0.4 | J9: =IF(I9=0,"",(IF(ISNUMBER(B9),Weights!$C$5*B9,0)+IF(ISNUMBER(C9),Weights!$D$5*C9,0)+IF(ISNUMBER(D9),Weights!$E$5*D9,0)+IF(ISNUMBER(E9),Weights!$F$5*E9,0)+IF(ISNUMBER(F9),Weights!$G$5*F9,0))/I9) -> 0.98883929 | K9: =IF(AND(ISNUMBER(H9),ISNUMBER(J9)),J9-H9,"") -> 0.0047123016 | L9: =IF(Controls!$B$3="w1",H9,J9) -> 0.98883929 | M9: =SUMIFS('Rule results'!$G$4:$G$58,'Rule results'!$B$4:$B$58,$A9,'Rule results'!$D$4:$D$58,"critical") -> 0 | N9: =COUNTIFS(Issues!$B$4:$B$577,$A9,Issues!$E$4:$E$577,"critical",Issues!$U$4:$U$577,"<>resolved") -> 0 | O9: =OR(M9>0,N9>0) -> FALSE | P9: =IF(ISNUMBER(K9),IF(ABS(K9)>0.000000000001,1,0),"") -> 1 | Q9: =IF(ISNUMBER(K9),IF(ABS(K9)>=0.005,1,0),"") -> 0 | R9: =IF(ISNUMBER(K9),ABS(K9),"") -> 0.0047123016 | S9: ='Domain reference'!B9 -> 0.984127 | T9: ='Domain reference'!C9 -> 0.988839 | U9: =AND(IF(ISNUMBER(H9),ISNUMBER(S9),NOT(ISNUMBER(S9))),IF(ISNUMBER(J9),ISNUMBER(T9),NOT(ISNUMBER(T9))),IF(ISNUMBER(H9),ABS(ROUND(H9,6)-S9)<0.0000005,TRUE()),IF(ISNUMBER(J9),ABS(ROUND(J9,6)-T9)<0.0000005,TRUE())) -> TRUE
A10: ds-cost-centres | B10: =IFERROR(AVERAGEIFS('Rule results'!$I$4:$I$58,'Rule results'!$B$4:$B$58,$A10,'Rule results'!$C$4:$C$58,B$3),"") | C10: =IFERROR(AVERAGEIFS('Rule results'!$I$4:$I$58,'Rule results'!$B$4:$B$58,$A10,'Rule results'!$C$4:$C$58,C$3),"") | D10: =IFERROR(AVERAGEIFS('Rule results'!$I$4:$I$58,'Rule results'!$B$4:$B$58,$A10,'Rule results'!$C$4:$C$58,D$3),"") -> 0.97435897 | E10: =IFERROR(AVERAGEIFS('Rule results'!$I$4:$I$58,'Rule results'!$B$4:$B$58,$A10,'Rule results'!$C$4:$C$58,E$3),"") | F10: =IFERROR(AVERAGEIFS('Rule results'!$I$4:$I$58,'Rule results'!$B$4:$B$58,$A10,'Rule results'!$C$4:$C$58,F$3),"") | G10: =IF(ISNUMBER(B10),Weights!$C$4,0)+IF(ISNUMBER(C10),Weights!$D$4,0)+IF(ISNUMBER(D10),Weights!$E$4,0)+IF(ISNUMBER(E10),Weights!$F$4,0)+IF(ISNUMBER(F10),Weights!$G$4,0) -> 0.2 | H10: =IF(G10=0,"",(IF(ISNUMBER(B10),Weights!$C$4*B10,0)+IF(ISNUMBER(C10),Weights!$D$4*C10,0)+IF(ISNUMBER(D10),Weights!$E$4*D10,0)+IF(ISNUMBER(E10),Weights!$F$4*E10,0)+IF(ISNUMBER(F10),Weights!$G$4*F10,0))/G10) -> 0.97435897 | I10: =IF(ISNUMBER(B10),Weights!$C$5,0)+IF(ISNUMBER(C10),Weights!$D$5,0)+IF(ISNUMBER(D10),Weights!$E$5,0)+IF(ISNUMBER(E10),Weights!$F$5,0)+IF(ISNUMBER(F10),Weights!$G$5,0) -> 0.25 | J10: =IF(I10=0,"",(IF(ISNUMBER(B10),Weights!$C$5*B10,0)+IF(ISNUMBER(C10),Weights!$D$5*C10,0)+IF(ISNUMBER(D10),Weights!$E$5*D10,0)+IF(ISNUMBER(E10),Weights!$F$5*E10,0)+IF(ISNUMBER(F10),Weights!$G$5*F10,0))/I10) -> 0.97435897 | K10: =IF(AND(ISNUMBER(H10),ISNUMBER(J10)),J10-H10,"") -> 0 | L10: =IF(Controls!$B$3="w1",H10,J10) -> 0.97435897 | M10: =SUMIFS('Rule results'!$G$4:$G$58,'Rule results'!$B$4:$B$58,$A10,'Rule results'!$D$4:$D$58,"critical") -> 0 | N10: =COUNTIFS(Issues!$B$4:$B$577,$A10,Issues!$E$4:$E$577,"critical",Issues!$U$4:$U$577,"<>resolved") -> 0 | O10: =OR(M10>0,N10>0) -> FALSE | P10: =IF(ISNUMBER(K10),IF(ABS(K10)>0.000000000001,1,0),"") -> 0 | Q10: =IF(ISNUMBER(K10),IF(ABS(K10)>=0.005,1,0),"") -> 0 | R10: =IF(ISNUMBER(K10),ABS(K10),"") -> 0 | S10: ='Domain reference'!B10 -> 0.974359 | T10: ='Domain reference'!C10 -> 0.974359 | U10: =AND(IF(ISNUMBER(H10),ISNUMBER(S10),NOT(ISNUMBER(S10))),IF(ISNUMBER(J10),ISNUMBER(T10),NOT(ISNUMBER(T10))),IF(ISNUMBER(H10),ABS(ROUND(H10,6)-S10)<0.0000005,TRUE()),IF(ISNUMBER(J10),ABS(ROUND(J10,6)-T10)<0.0000005,TRUE())) -> TRUE
A11: ds-credit-notes | B11: =IFERROR(AVERAGEIFS('Rule results'!$I$4:$I$58,'Rule results'!$B$4:$B$58,$A11,'Rule results'!$C$4:$C$58,B$3),"") | C11: =IFERROR(AVERAGEIFS('Rule results'!$I$4:$I$58,'Rule results'!$B$4:$B$58,$A11,'Rule results'!$C$4:$C$58,C$3),"") | D11: =IFERROR(AVERAGEIFS('Rule results'!$I$4:$I$58,'Rule results'!$B$4:$B$58,$A11,'Rule results'!$C$4:$C$58,D$3),"") | E11: =IFERROR(AVERAGEIFS('Rule results'!$I$4:$I$58,'Rule results'!$B$4:$B$58,$A11,'Rule results'!$C$4:$C$58,E$3),"") | F11: =IFERROR(AVERAGEIFS('Rule results'!$I$4:$I$58,'Rule results'!$B$4:$B$58,$A11,'Rule results'!$C$4:$C$58,F$3),"") | G11: =IF(ISNUMBER(B11),Weights!$C$4,0)+IF(ISNUMBER(C11),Weights!$D$4,0)+IF(ISNUMBER(D11),Weights!$E$4,0)+IF(ISNUMBER(E11),Weights!$F$4,0)+IF(ISNUMBER(F11),Weights!$G$4,0) -> 0 | H11: =IF(G11=0,"",(IF(ISNUMBER(B11),Weights!$C$4*B11,0)+IF(ISNUMBER(C11),Weights!$D$4*C11,0)+IF(ISNUMBER(D11),Weights!$E$4*D11,0)+IF(ISNUMBER(E11),Weights!$F$4*E11,0)+IF(ISNUMBER(F11),Weights!$G$4*F11,0))/G11) | I11: =IF(ISNUMBER(B11),Weights!$C$5,0)+IF(ISNUMBER(C11),Weights!$D$5,0)+IF(ISNUMBER(D11),Weights!$E$5,0)+IF(ISNUMBER(E11),Weights!$F$5,0)+IF(ISNUMBER(F11),Weights!$G$5,0) -> 0 | J11: =IF(I11=0,"",(IF(ISNUMBER(B11),Weights!$C$5*B11,0)+IF(ISNUMBER(C11),Weights!$D$5*C11,0)+IF(ISNUMBER(D11),Weights!$E$5*D11,0)+IF(ISNUMBER(E11),Weights!$F$5*E11,0)+IF(ISNUMBER(F11),Weights!$G$5*F11,0))/I11) | K11: =IF(AND(ISNUMBER(H11),ISNUMBER(J11)),J11-H11,"") | L11: =IF(Controls!$B$3="w1",H11,J11) | M11: =SUMIFS('Rule results'!$G$4:$G$58,'Rule results'!$B$4:$B$58,$A11,'Rule results'!$D$4:$D$58,"critical") -> 0 | N11: =COUNTIFS(Issues!$B$4:$B$577,$A11,Issues!$E$4:$E$577,"critical",Issues!$U$4:$U$577,"<>resolved") -> 0 | O11: =OR(M11>0,N11>0) -> FALSE | P11: =IF(ISNUMBER(K11),IF(ABS(K11)>0.000000000001,1,0),"") | Q11: =IF(ISNUMBER(K11),IF(ABS(K11)>=0.005,1,0),"") | R11: =IF(ISNUMBER(K11),ABS(K11),"") | S11: ='Domain reference'!B11 -> not measured | T11: ='Domain reference'!C11 -> not measured | U11: =AND(IF(ISNUMBER(H11),ISNUMBER(S11),NOT(ISNUMBER(S11))),IF(ISNUMBER(J11),ISNUMBER(T11),NOT(ISNUMBER(T11))),IF(ISNUMBER(H11),ABS(ROUND(H11,6)-S11)<0.0000005,TRUE()),IF(ISNUMBER(J11),ABS(ROUND(J11,6)-T11)<0.0000005,TRUE())) -> TRUE
A12: ds-crm-activities | B12: =IFERROR(AVERAGEIFS('Rule results'!$I$4:$I$58,'Rule results'!$B$4:$B$58,$A12,'Rule results'!$C$4:$C$58,B$3),"") | C12: =IFERROR(AVERAGEIFS('Rule results'!$I$4:$I$58,'Rule results'!$B$4:$B$58,$A12,'Rule results'!$C$4:$C$58,C$3),"") | D12: =IFERROR(AVERAGEIFS('Rule results'!$I$4:$I$58,'Rule results'!$B$4:$B$58,$A12,'Rule results'!$C$4:$C$58,D$3),"") | E12: =IFERROR(AVERAGEIFS('Rule results'!$I$4:$I$58,'Rule results'!$B$4:$B$58,$A12,'Rule results'!$C$4:$C$58,E$3),"") | F12: =IFERROR(AVERAGEIFS('Rule results'!$I$4:$I$58,'Rule results'!$B$4:$B$58,$A12,'Rule results'!$C$4:$C$58,F$3),"") | G12: =IF(ISNUMBER(B12),Weights!$C$4,0)+IF(ISNUMBER(C12),Weights!$D$4,0)+IF(ISNUMBER(D12),Weights!$E$4,0)+IF(ISNUMBER(E12),Weights!$F$4,0)+IF(ISNUMBER(F12),Weights!$G$4,0) -> 0 | H12: =IF(G12=0,"",(IF(ISNUMBER(B12),Weights!$C$4*B12,0)+IF(ISNUMBER(C12),Weights!$D$4*C12,0)+IF(ISNUMBER(D12),Weights!$E$4*D12,0)+IF(ISNUMBER(E12),Weights!$F$4*E12,0)+IF(ISNUMBER(F12),Weights!$G$4*F12,0))/G12) | I12: =IF(ISNUMBER(B12),Weights!$C$5,0)+IF(ISNUMBER(C12),Weights!$D$5,0)+IF(ISNUMBER(D12),Weights!$E$5,0)+IF(ISNUMBER(E12),Weights!$F$5,0)+IF(ISNUMBER(F12),Weights!$G$5,0) -> 0 | J12: =IF(I12=0,"",(IF(ISNUMBER(B12),Weights!$C$5*B12,0)+IF(ISNUMBER(C12),Weights!$D$5*C12,0)+IF(ISNUMBER(D12),Weights!$E$5*D12,0)+IF(ISNUMBER(E12),Weights!$F$5*E12,0)+IF(ISNUMBER(F12),Weights!$G$5*F12,0))/I12) | K12: =IF(AND(ISNUMBER(H12),ISNUMBER(J12)),J12-H12,"") | L12: =IF(Controls!$B$3="w1",H12,J12) | M12: =SUMIFS('Rule results'!$G$4:$G$58,'Rule results'!$B$4:$B$58,$A12,'Rule results'!$D$4:$D$58,"critical") -> 0 | N12: =COUNTIFS(Issues!$B$4:$B$577,$A12,Issues!$E$4:$E$577,"critical",Issues!$U$4:$U$577,"<>resolved") -> 0 | O12: =OR(M12>0,N12>0) -> FALSE | P12: =IF(ISNUMBER(K12),IF(ABS(K12)>0.000000000001,1,0),"") | Q12: =IF(ISNUMBER(K12),IF(ABS(K12)>=0.005,1,0),"") | R12: =IF(ISNUMBER(K12),ABS(K12),"") | S12: ='Domain reference'!B12 -> not measured | T12: ='Domain reference'!C12 -> not measured | U12: =AND(IF(ISNUMBER(H12),ISNUMBER(S12),NOT(ISNUMBER(S12))),IF(ISNUMBER(J12),ISNUMBER(T12),NOT(ISNUMBER(T12))),IF(ISNUMBER(H12),ABS(ROUND(H12,6)-S12)<0.0000005,TRUE()),IF(ISNUMBER(J12),ABS(ROUND(J12,6)-T12)<0.0000005,TRUE())) -> TRUE
A13: ds-csat-surveys | B13: =IFERROR(AVERAGEIFS('Rule results'!$I$4:$I$58,'Rule results'!$B$4:$B$58,$A13,'Rule results'!$C$4:$C$58,B$3),"") -> 0.93548387 | C13: =IFERROR(AVERAGEIFS('Rule results'!$I$4:$I$58,'Rule results'!$B$4:$B$58,$A13,'Rule results'!$C$4:$C$58,C$3),"") | D13: =IFERROR(AVERAGEIFS('Rule results'!$I$4:$I$58,'Rule results'!$B$4:$B$58,$A13,'Rule results'!$C$4:$C$58,D$3),"") | E13: =IFERROR(AVERAGEIFS('Rule results'!$I$4:$I$58,'Rule results'!$B$4:$B$58,$A13,'Rule results'!$C$4:$C$58,E$3),"") | F13: =IFERROR(AVERAGEIFS('Rule results'!$I$4:$I$58,'Rule results'!$B$4:$B$58,$A13,'Rule results'!$C$4:$C$58,F$3),"") | G13: =IF(ISNUMBER(B13),Weights!$C$4,0)+IF(ISNUMBER(C13),Weights!$D$4,0)+IF(ISNUMBER(D13),Weights!$E$4,0)+IF(ISNUMBER(E13),Weights!$F$4,0)+IF(ISNUMBER(F13),Weights!$G$4,0) -> 0.4 | H13: =IF(G13=0,"",(IF(ISNUMBER(B13),Weights!$C$4*B13,0)+IF(ISNUMBER(C13),Weights!$D$4*C13,0)+IF(ISNUMBER(D13),Weights!$E$4*D13,0)+IF(ISNUMBER(E13),Weights!$F$4*E13,0)+IF(ISNUMBER(F13),Weights!$G$4*F13,0))/G13) -> 0.93548387 | I13: =IF(ISNUMBER(B13),Weights!$C$5,0)+IF(ISNUMBER(C13),Weights!$D$5,0)+IF(ISNUMBER(D13),Weights!$E$5,0)+IF(ISNUMBER(E13),Weights!$F$5,0)+IF(ISNUMBER(F13),Weights!$G$5,0) -> 0.25 | J13: =IF(I13=0,"",(IF(ISNUMBER(B13),Weights!$C$5*B13,0)+IF(ISNUMBER(C13),Weights!$D$5*C13,0)+IF(ISNUMBER(D13),Weights!$E$5*D13,0)+IF(ISNUMBER(E13),Weights!$F$5*E13,0)+IF(ISNUMBER(F13),Weights!$G$5*F13,0))/I13) -> 0.93548387 | K13: =IF(AND(ISNUMBER(H13),ISNUMBER(J13)),J13-H13,"") -> 0 | L13: =IF(Controls!$B$3="w1",H13,J13) -> 0.93548387 | M13: =SUMIFS('Rule results'!$G$4:$G$58,'Rule results'!$B$4:$B$58,$A13,'Rule results'!$D$4:$D$58,"critical") -> 0 | N13: =COUNTIFS(Issues!$B$4:$B$577,$A13,Issues!$E$4:$E$577,"critical",Issues!$U$4:$U$577,"<>resolved") -> 0 | O13: =OR(M13>0,N13>0) -> FALSE | P13: =IF(ISNUMBER(K13),IF(ABS(K13)>0.000000000001,1,0),"") -> 0 | Q13: =IF(ISNUMBER(K13),IF(ABS(K13)>=0.005,1,0),"") -> 0 | R13: =IF(ISNUMBER(K13),ABS(K13),"") -> 0 | S13: ='Domain reference'!B13 -> 0.935484 | T13: ='Domain reference'!C13 -> 0.935484 | U13: =AND(IF(ISNUMBER(H13),ISNUMBER(S13),NOT(ISNUMBER(S13))),IF(ISNUMBER(J13),ISNUMBER(T13),NOT(ISNUMBER(T13))),IF(ISNUMBER(H13),ABS(ROUND(H13,6)-S13)<0.0000005,TRUE()),IF(ISNUMBER(J13),ABS(ROUND(J13,6)-T13)<0.0000005,TRUE())) -> TRUE
A14: ds-customers | B14: =IFERROR(AVERAGEIFS('Rule results'!$I$4:$I$58,'Rule results'!$B$4:$B$58,$A14,'Rule results'!$C$4:$C$58,B$3),"") -> 0.99166667 | C14: =IFERROR(AVERAGEIFS('Rule results'!$I$4:$I$58,'Rule results'!$B$4:$B$58,$A14,'Rule results'!$C$4:$C$58,C$3),"") -> 0.99159664 | D14: =IFERROR(AVERAGEIFS('Rule results'!$I$4:$I$58,'Rule results'!$B$4:$B$58,$A14,'Rule results'!$C$4:$C$58,D$3),"") -> 0.98333333 | E14: =IFERROR(AVERAGEIFS('Rule results'!$I$4:$I$58,'Rule results'!$B$4:$B$58,$A14,'Rule results'!$C$4:$C$58,E$3),"") | F14: =IFERROR(AVERAGEIFS('Rule results'!$I$4:$I$58,'Rule results'!$B$4:$B$58,$A14,'Rule results'!$C$4:$C$58,F$3),"") -> 1 | G14: =IF(ISNUMBER(B14),Weights!$C$4,0)+IF(ISNUMBER(C14),Weights!$D$4,0)+IF(ISNUMBER(D14),Weights!$E$4,0)+IF(ISNUMBER(E14),Weights!$F$4,0)+IF(ISNUMBER(F14),Weights!$G$4,0) -> 0.95 | H14: =IF(G14=0,"",(IF(ISNUMBER(B14),Weights!$C$4*B14,0)+IF(ISNUMBER(C14),Weights!$D$4*C14,0)+IF(ISNUMBER(D14),Weights!$E$4*D14,0)+IF(ISNUMBER(E14),Weights!$F$4*E14,0)+IF(ISNUMBER(F14),Weights!$G$4*F14,0))/G14) -> 0.99032876 | I14: =IF(ISNUMBER(B14),Weights!$C$5,0)+IF(ISNUMBER(C14),Weights!$D$5,0)+IF(ISNUMBER(D14),Weights!$E$5,0)+IF(ISNUMBER(E14),Weights!$F$5,0)+IF(ISNUMBER(F14),Weights!$G$5,0) -> 0.85 | J14: =IF(I14=0,"",(IF(ISNUMBER(B14),Weights!$C$5*B14,0)+IF(ISNUMBER(C14),Weights!$D$5*C14,0)+IF(ISNUMBER(D14),Weights!$E$5*D14,0)+IF(ISNUMBER(E14),Weights!$F$5*E14,0)+IF(ISNUMBER(F14),Weights!$G$5*F14,0))/I14) -> 0.99017548 | K14: =IF(AND(ISNUMBER(H14),ISNUMBER(J14)),J14-H14,"") -> -0.00015328113 | L14: =IF(Controls!$B$3="w1",H14,J14) -> 0.99017548 | M14: =SUMIFS('Rule results'!$G$4:$G$58,'Rule results'!$B$4:$B$58,$A14,'Rule results'!$D$4:$D$58,"critical") -> 2 | N14: =COUNTIFS(Issues!$B$4:$B$577,$A14,Issues!$E$4:$E$577,"critical",Issues!$U$4:$U$577,"<>resolved") -> 1 | O14: =OR(M14>0,N14>0) -> TRUE | P14: =IF(ISNUMBER(K14),IF(ABS(K14)>0.000000000001,1,0),"") -> 1 | Q14: =IF(ISNUMBER(K14),IF(ABS(K14)>=0.005,1,0),"") -> 0 | R14: =IF(ISNUMBER(K14),ABS(K14),"") -> 0.00015328113 | S14: ='Domain reference'!B14 -> 0.990329 | T14: ='Domain reference'!C14 -> 0.990175 | U14: =AND(IF(ISNUMBER(H14),ISNUMBER(S14),NOT(ISNUMBER(S14))),IF(ISNUMBER(J14),ISNUMBER(T14),NOT(ISNUMBER(T14))),IF(ISNUMBER(H14),ABS(ROUND(H14,6)-S14)<0.0000005,TRUE()),IF(ISNUMBER(J14),ABS(ROUND(J14,6)-T14)<0.0000005,TRUE())) -> TRUE
A15: ds-delivery-events | B15: =IFERROR(AVERAGEIFS('Rule results'!$I$4:$I$58,'Rule results'!$B$4:$B$58,$A15,'Rule results'!$C$4:$C$58,B$3),"") | C15: =IFERROR(AVERAGEIFS('Rule results'!$I$4:$I$58,'Rule results'!$B$4:$B$58,$A15,'Rule results'!$C$4:$C$58,C$3),"") -> 0.95588235 | D15: =IFERROR(AVERAGEIFS('Rule results'!$I$4:$I$58,'Rule results'!$B$4:$B$58,$A15,'Rule results'!$C$4:$C$58,D$3),"") | E15: =IFERROR(AVERAGEIFS('Rule results'!$I$4:$I$58,'Rule results'!$B$4:$B$58,$A15,'Rule results'!$C$4:$C$58,E$3),"") | F15: =IFERROR(AVERAGEIFS('Rule results'!$I$4:$I$58,'Rule results'!$B$4:$B$58,$A15,'Rule results'!$C$4:$C$58,F$3),"") | G15: =IF(ISNUMBER(B15),Weights!$C$4,0)+IF(ISNUMBER(C15),Weights!$D$4,0)+IF(ISNUMBER(D15),Weights!$E$4,0)+IF(ISNUMBER(E15),Weights!$F$4,0)+IF(ISNUMBER(F15),Weights!$G$4,0) -> 0.3 | H15: =IF(G15=0,"",(IF(ISNUMBER(B15),Weights!$C$4*B15,0)+IF(ISNUMBER(C15),Weights!$D$4*C15,0)+IF(ISNUMBER(D15),Weights!$E$4*D15,0)+IF(ISNUMBER(E15),Weights!$F$4*E15,0)+IF(ISNUMBER(F15),Weights!$G$4*F15,0))/G15) -> 0.95588235 | I15: =IF(ISNUMBER(B15),Weights!$C$5,0)+IF(ISNUMBER(C15),Weights!$D$5,0)+IF(ISNUMBER(D15),Weights!$E$5,0)+IF(ISNUMBER(E15),Weights!$F$5,0)+IF(ISNUMBER(F15),Weights!$G$5,0) -> 0.25 | J15: =IF(I15=0,"",(IF(ISNUMBER(B15),Weights!$C$5*B15,0)+IF(ISNUMBER(C15),Weights!$D$5*C15,0)+IF(ISNUMBER(D15),Weights!$E$5*D15,0)+IF(ISNUMBER(E15),Weights!$F$5*E15,0)+IF(ISNUMBER(F15),Weights!$G$5*F15,0))/I15) -> 0.95588235 | K15: =IF(AND(ISNUMBER(H15),ISNUMBER(J15)),J15-H15,"") -> 0 | L15: =IF(Controls!$B$3="w1",H15,J15) -> 0.95588235 | M15: =SUMIFS('Rule results'!$G$4:$G$58,'Rule results'!$B$4:$B$58,$A15,'Rule results'!$D$4:$D$58,"critical") -> 0 | N15: =COUNTIFS(Issues!$B$4:$B$577,$A15,Issues!$E$4:$E$577,"critical",Issues!$U$4:$U$577,"<>resolved") -> 0 | O15: =OR(M15>0,N15>0) -> FALSE | P15: =IF(ISNUMBER(K15),IF(ABS(K15)>0.000000000001,1,0),"") -> 0 | Q15: =IF(ISNUMBER(K15),IF(ABS(K15)>=0.005,1,0),"") -> 0 | R15: =IF(ISNUMBER(K15),ABS(K15),"") -> 0 | S15: ='Domain reference'!B15 -> 0.955882 | T15: ='Domain reference'!C15 -> 0.955882 | U15: =AND(IF(ISNUMBER(H15),ISNUMBER(S15),NOT(ISNUMBER(S15))),IF(ISNUMBER(J15),ISNUMBER(T15),NOT(ISNUMBER(T15))),IF(ISNUMBER(H15),ABS(ROUND(H15,6)-S15)<0.0000005,TRUE()),IF(ISNUMBER(J15),ABS(ROUND(J15,6)-T15)<0.0000005,TRUE())) -> TRUE
... A43: ds-web-users | B43: =IFERROR(AVERAGEIFS('Rule results'!$I$4:$I$58,'Rule results'!$B$4:$B$58,$A43,'Rule results'!$C$4:$C$58,B$3),"") -> 0.98484848 | C43: =IFERROR(AVERAGEIFS('Rule results'!$I$4:$I$58,'Rule results'!$B$4:$B$58,$A43,'Rule results'!$C$4:$C$58,C$3),"") | D43: =IFERROR(AVERAGEIFS('Rule results'!$I$4:$I$58,'Rule results'!$B$4:$B$58,$A43,'Rule results'!$C$4:$C$58,D$3),"") -> 0.98484848 | E43: =IFERROR(AVERAGEIFS('Rule results'!$I$4:$I$58,'Rule results'!$B$4:$B$58,$A43,'Rule results'!$C$4:$C$58,E$3),"") | F43: =IFERROR(AVERAGEIFS('Rule results'!$I$4:$I$58,'Rule results'!$B$4:$B$58,$A43,'Rule results'!$C$4:$C$58,F$3),"") -> 1 | G43: =IF(ISNUMBER(B43),Weights!$C$4,0)+IF(ISNUMBER(C43),Weights!$D$4,0)+IF(ISNUMBER(D43),Weights!$E$4,0)+IF(ISNUMBER(E43),Weights!$F$4,0)+IF(ISNUMBER(F43),Weights!$G$4,0) -> 0.65 | H43: =IF(G43=0,"",(IF(ISNUMBER(B43),Weights!$C$4*B43,0)+IF(ISNUMBER(C43),Weights!$D$4*C43,0)+IF(ISNUMBER(D43),Weights!$E$4*D43,0)+IF(ISNUMBER(E43),Weights!$F$4*E43,0)+IF(ISNUMBER(F43),Weights!$G$4*F43,0))/G43) -> 0.98601399 | I43: =IF(ISNUMBER(B43),Weights!$C$5,0)+IF(ISNUMBER(C43),Weights!$D$5,0)+IF(ISNUMBER(D43),Weights!$E$5,0)+IF(ISNUMBER(E43),Weights!$F$5,0)+IF(ISNUMBER(F43),Weights!$G$5,0) -> 0.6 | J43: =IF(I43=0,"",(IF(ISNUMBER(B43),Weights!$C$5*B43,0)+IF(ISNUMBER(C43),Weights!$D$5*C43,0)+IF(ISNUMBER(D43),Weights!$E$5*D43,0)+IF(ISNUMBER(E43),Weights!$F$5*E43,0)+IF(ISNUMBER(F43),Weights!$G$5*F43,0))/I43) -> 0.98737374 | K43: =IF(AND(ISNUMBER(H43),ISNUMBER(J43)),J43-H43,"") -> 0.0013597514 | L43: =IF(Controls!$B$3="w1",H43,J43) -> 0.98737374 | M43: =SUMIFS('Rule results'!$G$4:$G$58,'Rule results'!$B$4:$B$58,$A43,'Rule results'!$D$4:$D$58,"critical") -> 0 | N43: =COUNTIFS(Issues!$B$4:$B$577,$A43,Issues!$E$4:$E$577,"critical",Issues!$U$4:$U$577,"<>resolved") -> 0 | O43: =OR(M43>0,N43>0) -> FALSE | P43: =IF(ISNUMBER(K43),IF(ABS(K43)>0.000000000001,1,0),"") -> 1 | Q43: =IF(ISNUMBER(K43),IF(ABS(K43)>=0.005,1,0),"") -> 0 | R43: =IF(ISNUMBER(K43),ABS(K43),"") -> 0.0013597514 | S43: ='Domain reference'!B43 -> 0.986014 | T43: ='Domain reference'!C43 -> 0.987374 | U43: =AND(IF(ISNUMBER(H43),ISNUMBER(S43),NOT(ISNUMBER(S43))),IF(ISNUMBER(J43),ISNUMBER(T43),NOT(ISNUMBER(T43))),IF(ISNUMBER(H43),ABS(ROUND(H43,6)-S43)<0.0000005,TRUE()),IF(ISNUMBER(J43),ABS(ROUND(J43,6)-T43)<0.0000005,TRUE())) -> TRUE
A45: datasets scored (w1) | B45: =COUNT(H4:H43) -> 29
A46: datasets whose score differs between w1 and w2 | B46: =SUM(P4:P43) -> 13
A47: datasets moved by at least 0.005 | B47: =SUM(Q4:Q43) -> 7
A48: mean score under w1 | B48: =AVERAGE(H4:H43) -> 0.95097983
A49: mean score under w2 | B49: =AVERAGE(J4:J43) -> 0.9431178
A50: largest absolute shift | B50: =MAX(R4:R43) -> 0.16747651
A51: largest move (signed) | B51: =INDEX(K4:K43,MATCH(MAX(R4:R43),R4:R43,0)) -> -0.16747651
A52: datasets carrying the critical override | B52: =COUNTIF(O4:O43,TRUE()) -> 1
A53: critical failures (failing rows of active critical rules) | B53: =SUM(M4:M43) -> 2
A54: open critical issues | B54: =SUM(N4:N43) -> 1

Sheet Golden case
A1: The known answer (P07-GOLD-01) by hand, with formulas, against tests/fixtures/golden/expected.json
A2: 100 eligible customer rows, 5 missing e-mails; 90 of the 95 populated pass the format rule; the critical key rule fails on 2 rows. Blue cells are typed from the fixture; every figure in column C is a formula.
A3: input or figure | B3: value (typed or formula) | C3: formula result | D3: expected.json / hand answer | E3: check
A4: eligible customer rows | B4: 100
A5: missing e-mails (null or trimmed-empty) | B5: 5
A6: passing the format rule | B6: 90
A7: completeness = (eligible - missing) / eligible | C7: =(B4-B5)/B4 -> 0.95 | D7: 0.95 | E7: =ABS(C7-D7)<0.0000005 -> TRUE
A8: populated = eligible - missing | C8: =B4-B5 -> 95 | D8: 95 | E8: =C8=D8 -> TRUE
A9: validity, populated-only = passing / populated (labelled) | C9: =B6/C8 -> 0.94736842 | D9: 0.947368 | E9: =ABS(C9-D9)<0.0000005 -> TRUE
A10: validity, all eligible = passing / eligible (labelled) | C10: =B6/B4 -> 0.9 | D10: 0.9 | E10: =ABS(C10-D10)<0.0000005 -> TRUE
A11: key rows duplicated beyond the first | B11: 2
A12: uniqueness score = (eligible - null keys - duplicate rows) / eligible | C12: =(B4-0-B11)/B4 -> 0.98 | D12: 0.98 | E12: =ABS(C12-D12)<0.0000005 -> TRUE
A13: orders: foreign keys in total | B13: 40
A14: null or empty foreign keys (counted apart, outside the denominator) | B14: 3
A15: matched | B15: 35
A16: relationship integrity = matched / (total - null or empty) | C16: =B15/(B13-B14) -> 0.94594595 | D16: 0.945946 | E16: =ABS(C16-D16)<0.0000005 -> TRUE
A17: timeliness score of ds-customers (refreshed in its window) | B17: 1
A18: (weights come from the Weights sheet; relationship is unmeasured on ds-customers)
A19: weighted score under w1 = sum(w x score) / sum(w of the measured dimensions) | C19: =(Weights!$C$4*C7+Weights!$D$4*C9+Weights!$E$4*C12+Weights!$G$4*B17)/(Weights!$C$4+Weights!$D$4+Weights!$E$4+Weights!$G$4) -> 0.95811634 | D19: 0.958116 | E19: =ABS(C19-D19)<0.0000005 -> TRUE
A20: weighted score under w2 | C20: =(Weights!$C$5*C7+Weights!$D$5*C9+Weights!$E$5*C12+Weights!$G$5*B17)/(Weights!$C$5+Weights!$D$5+Weights!$E$5+Weights!$G$5) -> 0.96393189 | D20: 0.963932 | E20: =ABS(C20-D20)<0.0000005 -> TRUE
A21: critical failures of active critical rules (the key rule) | C21: =B11 -> 2 | D21: 2 | E21: =C21=D21 -> TRUE
A22: critical override (a failing critical rule or an open critical issue) | C22: =OR(C21>0,B24>0) -> TRUE | D22: =TRUE() -> TRUE | E22: =C22=D22 -> TRUE
A23: both scores above 0.95 although the override is set | C23: =AND(C19>0.95,C20>0.95,C22) -> TRUE | D23: =TRUE() -> TRUE | E23: =C23=D23 -> TRUE
A24: open critical issues (typed from the fixture) | B24: 1

Sheet Assumptions
A1: Assumptions and limits
A3: id | B3: statement
A4: A-01 | B4: Weights and checklists are append-only versions (D-07 assumption 4): the weighted score is sum(weight x score) / sum(weights of the measured dimensions) under the version named; unmeasured dimensions leave both sums; null if none is measured. Validity enters as populated-only (D-06).
A5: A-02 | B5: A dimension's score on a dataset is the plain mean of its measured rules' scores (D-07 assumption 5). Critical failures are the failing rows of active critical rules; open critical issues (open, reopened or claimed) are counted apart; either sets the override whatever the score is (D-01, D-06).
A6: A-03 | B6: An issue is resolved only after a successful rerun of the same rule version (D-03); claimed issues are listed apart and never counted as resolved; hours = verifying rerun - first detected_at, 4 places.
A7: A-04 | B7: Ownership coverage counts datasets whose owner is active at the as-of (D-02). Lineage coverage counts distinct observed pairs that match a declared pair over declared pairs; the workbook counts edge rows, which equal distinct pairs per kind on this snapshot (80, 70 and 10; asserted by build_workbook.py). Inferred edges never count as observed.
A8: A-05 | B8: Timeliness: the latest daily occurrence started by the as-of, on time in [occurrence, occurrence + grace), pending while open (outside the denominator), else late (D-10 R7-01).
A9: A-06 | B9: Match precision = approved decisions confirmed by the synthetic truth / approved decisions; the review-correct share = reviewed candidates that are the same true entity / reviewed candidates (D-06). The truth is the verification layer's and is typed only for these two formulas.
A10: W-01 | B10: Observed, constructed and hypothetical results are kept apart: every figure is observed in one draw of a generated world; the designed relationships (DR-01..DR-06) and the twelve injected defects are constructed; no benefit to a real organisation is claimed.
A11: W-02 | B11: TYPED from the independent Python side, not replayed by formulas: the per-rule counts (eligible, populated, failing: pattern matching, duplicate keys and parent lookups over 2,554 rows) and the timeliness occurrence and deadline instants (a daily local time in an IANA zone). Every result is compared with the Python domain after recalculation.
A12: W-03 | B12: Recalculation: openpyxl writes formulas only; the delivered file was recalculated by LibreOffice headless and carries its cached values; Excel was NOT run. fullCalcOnLoad is set so Excel recalculates on open. Functions used: AVERAGEIFS, COUNTIFS, SUMIFS, SUMPRODUCT, INDEX, MATCH, IF, IFERROR, ISNUMBER, AND, OR, ROUND, ABS (no _xlfn functions).
A13: W-04 | B13: The switch changes which weight version the Selected column shows; both versions are always computed and checked, so the check cell does not depend on the switch.
A14: W-05 | B14: The workbook has no macros, no external links and no credentials.

Sheet Rule results
A1: The 55 rules active at the as-of: measured counts (typed) and the score each contributes (formula)
A2: eligible, populated and failing are TYPED from the independent Python side (W-02); score_den = populated for validity else eligible; score = (eligible - failing) / score_den, empty when it measures nothing.
A3: rule_id | B3: dataset_id | C3: dimension | D3: severity | E3: eligible | F3: populated | G3: failing | H3: score_den | I3: score
A4: r-accounts-fk-customer_key | B4: ds-accounts | C4: relationship | D4: high | E4: 100 | G4: 5 | H4: =IF(C4="validity",F4,E4) -> 100 | I4: =IF(H4>0,(E4-G4)/H4,"") -> 0.95
A5: r-accounts-unique-account_key | B5: ds-accounts | C5: uniqueness | D5: medium | E5: 101 | G5: 0 | H5: =IF(C5="validity",F5,E5) -> 101 | I5: =IF(H5>0,(E5-G5)/H5,"") -> 1
A6: r-carriers-valid-carrier_code | B6: ds-carriers | C6: validity | D6: medium | E6: 119 | F6: 119 | G6: 4 | H6: =IF(C6="validity",F6,E6) -> 119 | I6: =IF(H6>0,(E6-G6)/H6,"") -> 0.96638655
A7: r-consent-records-complete-consent_flag | B7: ds-consent-records | C7: completeness | D7: high | E7: 85 | F7: 77 | G7: 8 | H7: =IF(C7="validity",F7,E7) -> 85 | I7: =IF(H7>0,(E7-G7)/H7,"") -> 0.90588235
A8: r-consent-records-fresh | B8: ds-consent-records | C8: timeliness | D8: medium | E8: 1 | G8: 0 | H8: =IF(C8="validity",F8,E8) -> 1 | I8: =IF(H8>0,(E8-G8)/H8,"") -> 1
A9: r-contacts-complete-email | B9: ds-contacts | C9: completeness | D9: high | E9: 56 | F9: 55 | G9: 1 | H9: =IF(C9="validity",F9,E9) -> 56 | I9: =IF(H9>0,(E9-G9)/H9,"") -> 0.98214286
A10: r-contacts-fk-customer_key | B10: ds-contacts | C10: relationship | D10: low | E10: 54 | G10: 0 | H10: =IF(C10="validity",F10,E10) -> 54 | I10: =IF(H10>0,(E10-G10)/H10,"") -> 1
A11: r-cost-centres-unique-cost_centre_code | B11: ds-cost-centres | C11: uniqueness | D11: medium | E11: 78 | G11: 2 | H11: =IF(C11="validity",F11,E11) -> 78 | I11: =IF(H11>0,(E11-G11)/H11,"") -> 0.97435897
A12: r-csat-surveys-complete-score | B12: ds-csat-surveys | C12: completeness | D12: low | E12: 124 | F12: 116 | G12: 8 | H12: =IF(C12="validity",F12,E12) -> 124 | I12: =IF(H12>0,(E12-G12)/H12,"") -> 0.93548387
A13: r-customers-complete-email | B13: ds-customers | C13: completeness | D13: high | E13: 120 | F13: 119 | G13: 1 | H13: =IF(C13="validity",F13,E13) -> 120 | I13: =IF(H13>0,(E13-G13)/H13,"") -> 0.99166667
A14: r-customers-fresh | B14: ds-customers | C14: timeliness | D14: medium | E14: 1 | G14: 0 | H14: =IF(C14="validity",F14,E14) -> 1 | I14: =IF(H14>0,(E14-G14)/H14,"") -> 1
A15: r-customers-unique-customer_key | B15: ds-customers | C15: uniqueness | D15: critical | E15: 120 | G15: 2 | H15: =IF(C15="validity",F15,E15) -> 120 | I15: =IF(H15>0,(E15-G15)/H15,"") -> 0.98333333
A16: r-customers-valid-email | B16: ds-customers | C16: validity | D16: medium | E16: 120 | F16: 119 | G16: 2 | H16: =IF(C16="validity",F16,E16) -> 119 | I16: =IF(H16>0,(E16-G16)/H16,"") -> 0.99159664
A17: r-delivery-events-valid-event_ref | B17: ds-delivery-events | C17: validity | D17: high | E17: 68 | F17: 68 | G17: 3 | H17: =IF(C17="validity",F17,E17) -> 68 | I17: =IF(H17>0,(E17-G17)/H17,"") -> 0.95588235
A18: r-employees-valid-work_email | B18: ds-employees | C18: validity | D18: high | E18: 39 | F18: 39 | G18: 0 | H18: =IF(C18="validity",F18,E18) -> 39 | I18: =IF(H18>0,(E18-G18)/H18,"") -> 1
A19: r-inventory-complete-warehouse_code | B19: ds-inventory | C19: completeness | D19: medium | E19: 71 | F19: 71 | G19: 0 | H19: =IF(C19="validity",F19,E19) -> 71 | I19: =IF(H19>0,(E19-G19)/H19,"") -> 1
A20: r-inventory-fresh | B20: ds-inventory | C20: timeliness | D20: high | E20: 1 | G20: 0 | H20: =IF(C20="validity",F20,E20) -> 1 | I20: =IF(H20>0,(E20-G20)/H20,"") -> 1
A21: r-invoices-fk-customer_key | B21: ds-invoices | C21: relationship | D21: low | E21: 81 | G21: 2 | H21: =IF(C21="validity",F21,E21) -> 81 | I21: =IF(H21>0,(E21-G21)/H21,"") -> 0.97530864
A22: r-invoices-fresh | B22: ds-invoices | C22: timeliness | D22: medium | E22: 1 | G22: 0 | H22: =IF(C22="validity",F22,E22) -> 1 | I22: =IF(H22>0,(E22-G22)/H22,"") -> 1
A23: r-invoices-valid-currency | B23: ds-invoices | C23: validity | D23: high | E23: 82 | F23: 82 | G23: 1 | H23: =IF(C23="validity",F23,E23) -> 82 | I23: =IF(H23>0,(E23-G23)/H23,"") -> 0.98780488
A24: r-kb-articles-unique-article_key | B24: ds-kb-articles | C24: uniqueness | D24: medium | E24: 66 | G24: 1 | H24: =IF(C24="validity",F24,E24) -> 66 | I24: =IF(H24>0,(E24-G24)/H24,"") -> 0.98484848
A25: r-ledger-entries-complete-amount | B25: ds-ledger-entries | C25: completeness | D25: high | E25: 54 | F25: 50 | G25: 4 | H25: =IF(C25="validity",F25,E25) -> 54 | I25: =IF(H25>0,(E25-G25)/H25,"") -> 0.92592593
A26: r-ledger-entries-unique-entry_key | B26: ds-ledger-entries | C26: uniqueness | D26: critical | E26: 62 | G26: 0 | H26: =IF(C26="validity",F26,E26) -> 62 | I26: =IF(H26>0,(E26-G26)/H26,"") -> 1
A27: r-ledger-entries-valid-currency | B27: ds-ledger-entries | C27: validity | D27: high | E27: 54 | F27: 54 | G27: 4 | H27: =IF(C27="validity",F27,E27) -> 54 | I27: =IF(H27>0,(E27-G27)/H27,"") -> 0.92592593
A28: r-opportunities-fk-account_key | B28: ds-opportunities | C28: relationship | D28: high | E28: 79 | G28: 9 | H28: =IF(C28="validity",F28,E28) -> 79 | I28: =IF(H28>0,(E28-G28)/H28,"") -> 0.88607595
A29: r-order-lines-fk-order_key | B29: ds-order-lines | C29: relationship | D29: critical | E29: 108 | G29: 0 | H29: =IF(C29="validity",F29,E29) -> 108 | I29: =IF(H29>0,(E29-G29)/H29,"") -> 1
A30: r-order-lines-fk-product_code | B30: ds-order-lines | C30: relationship | D30: low | E30: 106 | G30: 7 | H30: =IF(C30="validity",F30,E30) -> 106 | I30: =IF(H30>0,(E30-G30)/H30,"") -> 0.93396226
A31: r-orders-complete-order_date | B31: ds-orders | C31: completeness | D31: high | E31: 58 | F31: 56 | G31: 2 | H31: =IF(C31="validity",F31,E31) -> 58 | I31: =IF(H31>0,(E31-G31)/H31,"") -> 0.96551724
A32: r-orders-fk-customer_key | B32: ds-orders | C32: relationship | D32: high | E32: 61 | G32: 0 | H32: =IF(C32="validity",F32,E32) -> 61 | I32: =IF(H32>0,(E32-G32)/H32,"") -> 1
A33: r-orders-fresh | B33: ds-orders | C33: timeliness | D33: medium | E33: 1 | G33: 1 | H33: =IF(C33="validity",F33,E33) -> 1 | I33: =IF(H33>0,(E33-G33)/H33,"") -> 0
A34: r-orders-unique-order_key | B34: ds-orders | C34: uniqueness | D34: critical | E34: 66 | G34: 0 | H34: =IF(C34="validity",F34,E34) -> 66 | I34: =IF(H34>0,(E34-G34)/H34,"") -> 1
A35: r-orders-valid-currency | B35: ds-orders | C35: validity | D35: medium | E35: 66 | F35: 66 | G35: 0 | H35: =IF(C35="validity",F35,E35) -> 66 | I35: =IF(H35>0,(E35-G35)/H35,"") -> 1
A36: r-payments-fk-invoice_key | B36: ds-payments | C36: relationship | D36: low | E36: 82 | G36: 1 | H36: =IF(C36="validity",F36,E36) -> 82 | I36: =IF(H36>0,(E36-G36)/H36,"") -> 0.98780488
A37: r-payments-fresh | B37: ds-payments | C37: timeliness | D37: high | E37: 1 | G37: 1 | H37: =IF(C37="validity",F37,E37) -> 1 | I37: =IF(H37>0,(E37-G37)/H37,"") -> 0
A38: r-payments-unique-payment_key | B38: ds-payments | C38: uniqueness | D38: critical | E38: 84 | G38: 0 | H38: =IF(C38="validity",F38,E38) -> 84 | I38: =IF(H38>0,(E38-G38)/H38,"") -> 1
A39: r-products-complete-category | B39: ds-products | C39: completeness | D39: medium | E39: 116 | F39: 114 | G39: 2 | H39: =IF(C39="validity",F39,E39) -> 116 | I39: =IF(H39>0,(E39-G39)/H39,"") -> 0.98275862
A40: r-products-unique-product_code | B40: ds-products | C40: uniqueness | D40: high | E40: 116 | G40: 2 | H40: =IF(C40="validity",F40,E40) -> 116 | I40: =IF(H40>0,(E40-G40)/H40,"") -> 0.98275862
...

Sheet Issues
A1: 574 issues: the facts of each issue and its verifying run (typed), the class and the hours (formulas)
A2: resolved = closed by the as-of AND the verification run is a rerun, for this issue, of the same rule at the same version, with 0 failures, not before the detection or the latest reopen; claimed = closed otherwise; open = the rest.
A3: issue_id | B3: dataset_id | C3: rule_id | D3: owner_id | E3: severity | F3: status | G3: detected_at | H3: closed_at | I3: verified_at | J3: ver_kind | K3: ver_for_issue | L3: ver_rule_id | M3: ver_rule_version | N3: base_rule_version | O3: ver_failure_count | P3: last_reopen_at | Q3: reopen_cycles | R3: owner_team | S3: closed | T3: verified | U3: class | V3: hours | W3: owner_accountable
A4: iss-0001 | B4: ds-carriers | C4: r-carriers-valid-carrier_code | D4: own-05 | E4: medium | F4: closed | G4: 46216.107 | H4: 46220.114 | I4: 46220.145 | J4: rerun | K4: iss-0001 | L4: r-carriers-valid-carrier_code | M4: 1 | N4: 1 | O4: 0 | Q4: 0 | R4: =INDEX(Owners!$B$4:$B$21,MATCH(D4,Owners!$A$4:$A$21,0)) -> Data Platform | S4: =AND(F4="closed",ISNUMBER(H4),H4<=Controls!$B$4) -> TRUE | T4: =AND(ISNUMBER(I4),I4<=Controls!$B$4,J4="rerun",K4=A4,L4=C4,M4=N4,O4=0,I4>=G4,IF(ISNUMBER(P4),I4>=P4,TRUE())) -> TRUE | U4: =IF(AND(S4,T4),"resolved",IF(S4,"claimed","open")) -> resolved | V4: =ROUND((IF(U4="resolved",I4,IF(U4="claimed",H4,Controls!$B$4))-G4)*24,4) -> 96.9167 | W4: =INDEX(Owners!$E$4:$E$21,MATCH(D4,Owners!$A$4:$A$21,0)) -> TRUE
A5: iss-0002 | B5: ds-contacts | C5: r-contacts-complete-email | D5: own-12 | E5: high | F5: closed | G5: 46216.119 | H5: 46218.958 | I5: 46219.518 | J5: rerun | K5: iss-0002 | L5: r-contacts-complete-email | M5: 1 | N5: 1 | O5: 0 | Q5: 0 | R5: =INDEX(Owners!$B$4:$B$21,MATCH(D5,Owners!$A$4:$A$21,0)) -> Finance Systems | S5: =AND(F5="closed",ISNUMBER(H5),H5<=Controls!$B$4) -> TRUE | T5: =AND(ISNUMBER(I5),I5<=Controls!$B$4,J5="rerun",K5=A5,L5=C5,M5=N5,O5=0,I5>=G5,IF(ISNUMBER(P5),I5>=P5,TRUE())) -> TRUE | U5: =IF(AND(S5,T5),"resolved",IF(S5,"claimed","open")) -> resolved | V5: =ROUND((IF(U5="resolved",I5,IF(U5="claimed",H5,Controls!$B$4))-G5)*24,4) -> 81.5667 | W5: =INDEX(Owners!$E$4:$E$21,MATCH(D5,Owners!$A$4:$A$21,0)) -> FALSE
A6: iss-0003 | B6: ds-products | C6: r-products-complete-category | D6: own-17 | E6: medium | F6: closed | G6: 46216.246 | H6: 46218.61 | I6: 46218.776 | J6: rerun | K6: iss-0003 | L6: r-products-complete-category | M6: 1 | N6: 1 | O6: 0 | Q6: 0 | R6: =INDEX(Owners!$B$4:$B$21,MATCH(D6,Owners!$A$4:$A$21,0)) -> Support Operations | S6: =AND(F6="closed",ISNUMBER(H6),H6<=Controls!$B$4) -> TRUE | T6: =AND(ISNUMBER(I6),I6<=Controls!$B$4,J6="rerun",K6=A6,L6=C6,M6=N6,O6=0,I6>=G6,IF(ISNUMBER(P6),I6>=P6,TRUE())) -> TRUE | U6: =IF(AND(S6,T6),"resolved",IF(S6,"claimed","open")) -> resolved | V6: =ROUND((IF(U6="resolved",I6,IF(U6="claimed",H6,Controls!$B$4))-G6)*24,4) -> 60.7167 | W6: =INDEX(Owners!$E$4:$E$21,MATCH(D6,Owners!$A$4:$A$21,0)) -> TRUE
A7: iss-0004 | B7: ds-customers | C7: r-customers-valid-email | D7: own-07 | E7: medium | F7: closed | G7: 46217.092 | H7: 46217.723 | N7: 1 | Q7: 0 | R7: =INDEX(Owners!$B$4:$B$21,MATCH(D7,Owners!$A$4:$A$21,0)) -> Customer Data | S7: =AND(F7="closed",ISNUMBER(H7),H7<=Controls!$B$4) -> TRUE | T7: =AND(ISNUMBER(I7),I7<=Controls!$B$4,J7="rerun",K7=A7,L7=C7,M7=N7,O7=0,I7>=G7,IF(ISNUMBER(P7),I7>=P7,TRUE())) -> FALSE | U7: =IF(AND(S7,T7),"resolved",IF(S7,"claimed","open")) -> claimed | V7: =ROUND((IF(U7="resolved",I7,IF(U7="claimed",H7,Controls!$B$4))-G7)*24,4) -> 15.1333 | W7: =INDEX(Owners!$E$4:$E$21,MATCH(D7,Owners!$A$4:$A$21,0)) -> TRUE
A8: iss-0005 | B8: ds-refunds | C8: r-refunds-fk-payment_key | D8: own-18 | E8: high | F8: closed | G8: 46217.16 | H8: 46219.298 | I8: 46219.386 | J8: rerun | K8: iss-0005 | L8: r-refunds-fk-payment_key | M8: 1 | N8: 1 | O8: 0 | Q8: 0 | R8: =INDEX(Owners!$B$4:$B$21,MATCH(D8,Owners!$A$4:$A$21,0)) -> Support Operations | S8: =AND(F8="closed",ISNUMBER(H8),H8<=Controls!$B$4) -> TRUE | T8: =AND(ISNUMBER(I8),I8<=Controls!$B$4,J8="rerun",K8=A8,L8=C8,M8=N8,O8=0,I8>=G8,IF(ISNUMBER(P8),I8>=P8,TRUE())) -> TRUE | U8: =IF(AND(S8,T8),"resolved",IF(S8,"claimed","open")) -> resolved | V8: =ROUND((IF(U8="resolved",I8,IF(U8="claimed",H8,Controls!$B$4))-G8)*24,4) -> 53.4167 | W8: =INDEX(Owners!$E$4:$E$21,MATCH(D8,Owners!$A$4:$A$21,0)) -> TRUE
A9: iss-0006 | B9: ds-ledger-entries | C9: r-ledger-entries-valid-currency | D9: own-12 | E9: high | F9: closed | G9: 46217.215 | H9: 46218.948 | I9: 46219.487 | J9: rerun | K9: iss-0006 | L9: r-ledger-entries-valid-currency | M9: 1 | N9: 1 | O9: 0 | Q9: 0 | R9: =INDEX(Owners!$B$4:$B$21,MATCH(D9,Owners!$A$4:$A$21,0)) -> Finance Systems | S9: =AND(F9="closed",ISNUMBER(H9),H9<=Controls!$B$4) -> TRUE | T9: =AND(ISNUMBER(I9),I9<=Controls!$B$4,J9="rerun",K9=A9,L9=C9,M9=N9,O9=0,I9>=G9,IF(ISNUMBER(P9),I9>=P9,TRUE())) -> TRUE | U9: =IF(AND(S9,T9),"resolved",IF(S9,"claimed","open")) -> resolved | V9: =ROUND((IF(U9="resolved",I9,IF(U9="claimed",H9,Controls!$B$4))-G9)*24,4) -> 54.5333 | W9: =INDEX(Owners!$E$4:$E$21,MATCH(D9,Owners!$A$4:$A$21,0)) -> FALSE
A10: iss-0007 | B10: ds-contacts | C10: r-contacts-complete-email | D10: own-12 | E10: high | F10: closed | G10: 46218.119 | H10: 46220.198 | I10: 46220.253 | J10: rerun | K10: iss-0007 | L10: r-contacts-complete-email | M10: 1 | N10: 1 | O10: 0 | Q10: 0 | R10: =INDEX(Owners!$B$4:$B$21,MATCH(D10,Owners!$A$4:$A$21,0)) -> Finance Systems | S10: =AND(F10="closed",ISNUMBER(H10),H10<=Controls!$B$4) -> TRUE | T10: =AND(ISNUMBER(I10),I10<=Controls!$B$4,J10="rerun",K10=A10,L10=C10,M10=N10,O10=0,I10>=G10,IF(ISNUMBER(P10),I10>=P10,TRUE())) -> TRUE | U10: =IF(AND(S10,T10),"resolved",IF(S10,"claimed","open")) -> resolved | V10: =ROUND((IF(U10="resolved",I10,IF(U10="claimed",H10,Controls!$B$4))-G10)*24,4) -> 51.2 | W10: =INDEX(Owners!$E$4:$E$21,MATCH(D10,Owners!$A$4:$A$21,0)) -> FALSE
