Workbook

Sheet Read me
A1: ServiceFlow analyst workbook (P04-ART-05)
A2: SYNTHETIC DATA: every ticket, agent and figure is generated (seed 20261026); nothing describes a real support team.
A4: What it is | B4: A formula-driven workbook over the published synthetic snapshot of ServiceFlow (3,817 accepted tickets, 12 weeks from 2026-07-06). It recomputes the headline metrics of the contract with live formulas so an analyst can follow a number cell by cell, and it can be switched between the whole twelve weeks, the training weeks (1-8) and the holdout weeks (9-12).
A5: How to read it without installing anything | B5: Open the .xlsx in any spreadsheet application, or read docs/workbook.md (it lists every sheet and the checked values). The delivered file already carries values calculated by LibreOffice.
A6: How to use the switch | B6: Scenario!B3 takes full, training or holdout. Every figure on Metrics, Hour of week and Queue by priority follows it; the check column of Metrics compares each figure with the Python domain's value for the same window (pasted on 'Domain reference').
A7: Observed, simulated, hypothetical | B7: Everything on the data sheets and on Metrics is OBSERVED in a synthetic history. Nothing here is a simulation result: the three simulated scenarios and their replications are in docs/executive-memo.md and artifacts/bi/. No staffing benefit is claimed.
A8: Inputs (blue) and formulas (black) | B8: Blue cells are typed inputs: the per-ticket instants (epoch seconds, UTC), shifts, intervals, surveys, SLA targets, the window table and the expected values of the check columns. Black cells are formulas.
A9: Where the per-ticket instants come from | B9: The event log (21,893 accepted events) was replayed ONCE in Python (the domain's replay) to the first human reply, first service start, final resolution, abandonment and the service intervals; the workbook starts from those instants. The replay itself is not a spreadsheet formula (limit W-02).
A10: Dataset and code | B10: Dataset hash 944ef91b3dc17c04c6bb601e0faac94f956d121877de2b9864988cf7c5d5cba4 (web/public/data/manifest.json, dataset_version sf-20261026-20261026); code revision 43de7f8; contract v1 (docs/contracts.md D-01..D-09).
A11: Recalculation status | B11: openpyxl wrote formulas only; LibreOffice (headless) recalculated the delivered file. Microsoft Excel was NOT run: nothing here was opened or recalculated by Excel (docs/workbook.md).
A12: Sheets | B12: Scenario, Metrics, Domain reference, Hour of week, Queue by priority, Golden case, Assumptions, Tickets, Intervals, Shifts, Surveys, SQL results (pasted).

Sheet Scenario
A1: Scenario switch, windows and SLA targets
A2: Change B3 to full, training or holdout. All windows are half-open [start, end) in UTC epoch seconds (D-08).
A3: scenario | B3: full
A6: window | B6: start (epoch s) | C6: end (epoch s) | D6: start UTC | E6: end UTC
A7: full | B7: 1783296000 | C7: 1790553600 | D7: 2026-07-06T00:00:00Z | E7: 2026-09-28T00:00:00Z
A8: training | B8: 1783296000 | C8: 1788134400 | D8: 2026-07-06T00:00:00Z | E8: 2026-08-31T00:00:00Z
A9: holdout | B9: 1788134400 | C9: 1790553600 | D9: 2026-08-31T00:00:00Z | E9: 2026-09-28T00:00:00Z
A11: window start (epoch s) | B11: =INDEX($B$7:$B$9,MATCH($B$3,$A$7:$A$9,0)) -> 1783296000
A12: window end (epoch s) | B12: =INDEX($C$7:$C$9,MATCH($B$3,$A$7:$A$9,0)) -> 1790553600
A13: window length (hours) | B13: =(B12-B11)/3600 -> 2016
A14: backlog / open-overdue cutoff (epoch s) | B14: =B12 -> 1790553600 | C14: the window end (the domain's default cutoff)
A17: priority | B17: first response target (min) | C17: resolution target (min)
A18: P1 | B18: 15 | C18: 240
A19: P2 | B19: 60 | C19: 1440
A20: P3 | B20: 240 | C20: 4320
A22: channels that can abandon | B22: chat | C22: phone
A24: positive CSAT score >= | B24: 4

Sheet Metrics
A1: Headline metrics for the selected window (live formulas)
A2: Window: Scenario!B3. 'check' is TRUE when the formula equals the Python domain's figure for the same window within the tolerance (half a unit in the last place).
A3: selected scenario | B3: =Scenario!B3 -> full | D3: all checks TRUE | E3: =AND(G6:G31) -> TRUE
A5: metric | B5: value (formula) | C5: unit | D5: definition | E5: Python domain (pasted) | F5: tolerance | G5: check
A6: Arrivals | B6: =SUM(Tickets!$L$2:$L$3818) -> 3817 | C6: tickets | D6: tickets created in the window [start, end) | E6: =INDEX('Domain reference'!$B$5:$D$5,MATCH(Scenario!$B$3,'Domain reference'!$B$4:$D$4,0)) -> 3817 | F6: 0 | G6: =ABS(B6-E6)<=F6+0.0000000001 -> TRUE
A7: Completions | B7: =SUM(Tickets!$O$2:$O$3818) -> 3608 | C7: tickets | D7: tickets whose FINAL resolution is in the window (a reopened ticket is one completion) | E7: =INDEX('Domain reference'!$B$6:$D$6,MATCH(Scenario!$B$3,'Domain reference'!$B$4:$D$4,0)) -> 3608 | F7: 0 | G7: =ABS(B7-E7)<=F7+0.0000000001 -> TRUE
A8: Arrival rate | B8: =ROUND(B6/Scenario!$B$13,6) -> 1.893353 | C8: tickets / hour | D8: arrivals / window hours | E8: =INDEX('Domain reference'!$B$7:$D$7,MATCH(Scenario!$B$3,'Domain reference'!$B$4:$D$4,0)) -> 1.893353 | F8: 5e-07 | G8: =ABS(B8-E8)<=F8+0.0000000001 -> TRUE
A9: Completion rate | B9: =ROUND(B7/Scenario!$B$13,6) -> 1.789683 | C9: tickets / hour | D9: completions / window hours | E9: =INDEX('Domain reference'!$B$8:$D$8,MATCH(Scenario!$B$3,'Domain reference'!$B$4:$D$4,0)) -> 1.789683 | F9: 5e-07 | G9: =ABS(B9-E9)<=F9+0.0000000001 -> TRUE
A10: Mean first response | B10: =ROUND(AVERAGE(Tickets!$M$2:$M$3818),4) -> 28.0046 | C10: minutes | D10: first human reply minus arrival, tickets with a human reply (a bot never counts) | E10: =INDEX('Domain reference'!$B$9:$D$9,MATCH(Scenario!$B$3,'Domain reference'!$B$4:$D$4,0)) -> 28.0046 | F10: 5e-05 | G10: =ABS(B10-E10)<=F10+0.0000000001 -> TRUE
A11: P90 first response | B11: =ROUND(SMALL(Tickets!$M$2:$M$3818,INT((9*COUNT(Tickets!$M$2:$M$3818)+9)/10)),4) -> 44.15 | C11: minutes | D11: nearest rank: the value at index ceil(0.9 n) | E11: =INDEX('Domain reference'!$B$10:$D$10,MATCH(Scenario!$B$3,'Domain reference'!$B$4:$D$4,0)) -> 44.15 | F11: 5e-05 | G11: =ABS(B11-E11)<=F11+0.0000000001 -> TRUE
A12: Mean wait to first service | B12: =ROUND(AVERAGE(Tickets!$N$2:$N$3818),4) -> 25.5073 | C12: minutes | D12: first service_started minus the original arrival, tickets that were served | E12: =INDEX('Domain reference'!$B$11:$D$11,MATCH(Scenario!$B$3,'Domain reference'!$B$4:$D$4,0)) -> 25.5073 | F12: 5e-05 | G12: =ABS(B12-E12)<=F12+0.0000000001 -> TRUE
A13: P90 wait to first service | B13: =ROUND(SMALL(Tickets!$N$2:$N$3818,INT((9*COUNT(Tickets!$N$2:$N$3818)+9)/10)),4) -> 41.5167 | C13: minutes | D13: an addition beyond the 28 published keys; nearest rank | E13: =INDEX('Domain reference'!$B$29:$D$29,MATCH(Scenario!$B$3,'Domain reference'!$B$4:$D$4,0)) -> 41.5167 | F13: 5e-05 | G13: =ABS(B13-E13)<=F13+0.0000000001 -> TRUE
A14: Mean resolution | B14: =ROUND(AVERAGE(Tickets!$P$2:$P$3818),4) -> 164.5909 | C14: minutes | D14: final resolution minus the ORIGINAL arrival (a reopened ticket is charged its dormant gap) | E14: =INDEX('Domain reference'!$B$12:$D$12,MATCH(Scenario!$B$3,'Domain reference'!$B$4:$D$4,0)) -> 164.5909 | F14: 5e-05 | G14: =ABS(B14-E14)<=F14+0.0000000001 -> TRUE
A15: P90 resolution | B15: =ROUND(SMALL(Tickets!$P$2:$P$3818,INT((9*COUNT(Tickets!$P$2:$P$3818)+9)/10)),4) -> 294.5833 | C15: minutes | D15: an addition beyond the 28 published keys; nearest rank | E15: =INDEX('Domain reference'!$B$30:$D$30,MATCH(Scenario!$B$3,'Domain reference'!$B$4:$D$4,0)) -> 294.5833 | F15: 5e-05 | G15: =ABS(B15-E15)<=F15+0.0000000001 -> TRUE
A16: Handling | B16: =ROUND(SUM(Intervals!$E$2:$E$4977),4) -> 189836.27 | C16: minutes | D16: service intervals clipped to the window; waiting_customer and idle time excluded | E16: =INDEX('Domain reference'!$B$13:$D$13,MATCH(Scenario!$B$3,'Domain reference'!$B$4:$D$4,0)) -> 189836.27 | F16: 5e-05 | G16: =ABS(B16-E16)<=F16+0.0000000001 -> TRUE
A17: First response within target | B17: =SUM(Tickets!$S$2:$S$3818) -> 3437 | C17: tickets | D17: first response <= the priority's target | E17: =INDEX('Domain reference'!$B$15:$D$15,MATCH(Scenario!$B$3,'Domain reference'!$B$4:$D$4,0)) -> 3437 | F17: 0 | G17: =ABS(B17-E17)<=F17+0.0000000001 -> TRUE
A18: First response eligible | B18: =COUNT(Tickets!$S$2:$S$3818) -> 3616 | C18: tickets | D18: arrivals with a human reply (open overdue tickets are never in a denominator) | E18: =INDEX('Domain reference'!$B$16:$D$16,MATCH(Scenario!$B$3,'Domain reference'!$B$4:$D$4,0)) -> 3616 | F18: 0 | G18: =ABS(B18-E18)<=F18+0.0000000001 -> TRUE
A19: SLA first response compliance | B19: =ROUND(B17/B18,6) -> 0.950498 | C19: ratio | D19: within / eligible | E19: =INDEX('Domain reference'!$B$14:$D$14,MATCH(Scenario!$B$3,'Domain reference'!$B$4:$D$4,0)) -> 0.950498 | F19: 5e-07 | G19: =ABS(B19-E19)<=F19+0.0000000001 -> TRUE
A20: Resolution within target | B20: =SUM(Tickets!$T$2:$T$3818) -> 3529 | C20: tickets | D20: resolution <= the priority's target | E20: =INDEX('Domain reference'!$B$18:$D$18,MATCH(Scenario!$B$3,'Domain reference'!$B$4:$D$4,0)) -> 3529 | F20: 0 | G20: =ABS(B20-E20)<=F20+0.0000000001 -> TRUE
A21: Resolution eligible | B21: =COUNT(Tickets!$T$2:$T$3818) -> 3608 | C21: tickets | D21: completions in the window | E21: =INDEX('Domain reference'!$B$19:$D$19,MATCH(Scenario!$B$3,'Domain reference'!$B$4:$D$4,0)) -> 3608 | F21: 0 | G21: =ABS(B21-E21)<=F21+0.0000000001 -> TRUE
A22: SLA resolution compliance | B22: =ROUND(B20/B21,6) -> 0.978104 | C22: ratio | D22: within / eligible | E22: =INDEX('Domain reference'!$B$17:$D$17,MATCH(Scenario!$B$3,'Domain reference'!$B$4:$D$4,0)) -> 0.978104 | F22: 5e-07 | G22: =ABS(B22-E22)<=F22+0.0000000001 -> TRUE
A23: Backlog at the window end | B23: =SUM(Tickets!$U$2:$U$3818) -> 0 | C23: tickets | D23: arrived by the end and not resolved or abandoned by it (a reopened ticket is read by its final resolution: exact for these three windows, W-03) | E23: =INDEX('Domain reference'!$B$28:$D$28,MATCH(Scenario!$B$3,'Domain reference'!$B$4:$D$4,0)) -> 0 | F23: 0 | G23: =ABS(B23-E23)<=F23+0.0000000001 -> TRUE
A24: Open overdue at the window end | B24: =SUM(Tickets!$V$2:$V$3818) -> 0 | C24: tickets | D24: open and older than its resolution target; kept apart, never dropped (P04-TEST-06) | E24: =INDEX('Domain reference'!$B$20:$D$20,MATCH(Scenario!$B$3,'Domain reference'!$B$4:$D$4,0)) -> 0 | F24: 0 | G24: =ABS(B24-E24)<=F24+0.0000000001 -> TRUE
A25: Staffed available time | B25: =ROUND(SUM(Shifts!$G$2:$G$1021),4) -> 447450 | C25: minutes | D25: shift overlap with the window; the declared break is deducted only for a shift the window covers whole (D-05) | E25: =INDEX('Domain reference'!$B$21:$D$21,MATCH(Scenario!$B$3,'Domain reference'!$B$4:$D$4,0)) -> 447450 | F25: 5e-05 | G25: =ABS(B25-E25)<=F25+0.0000000001 -> TRUE
A26: Staffed time, whole shifts | B26: =ROUND(SUM(Shifts!$H$2:$H$1021),4) -> 447990 | C26: minutes | D26: every shift net of its declared break, clipped by nothing | E26: =INDEX('Domain reference'!$B$22:$D$22,MATCH(Scenario!$B$3,'Domain reference'!$B$4:$D$4,0)) -> 447990 | F26: 5e-05 | G26: =ABS(B26-E26)<=F26+0.0000000001 -> TRUE
A27: Agent occupancy | B27: =ROUND(B16/B25,6) -> 0.424263 | C27: ratio | D27: handling / staffed available time | E27: =INDEX('Domain reference'!$B$23:$D$23,MATCH(Scenario!$B$3,'Domain reference'!$B$4:$D$4,0)) -> 0.424263 | F27: 5e-07 | G27: =ABS(B27-E27)<=F27+0.0000000001 -> TRUE
A28: Abandonment rate | B28: =ROUND(COUNTIFS(Tickets!$L$2:$L$3818,1,Tickets!$W$2:$W$3818,1,Tickets!$X$2:$X$3818,1)/COUNTIFS(Tickets!$L$2:$L$3818,1,Tickets!$W$2:$W$3818,1),6) -> 0.118213 | C28: ratio | D28: abandoned / arrivals, only on channels that can abandon (chat, phone) | E28: =INDEX('Domain reference'!$B$24:$D$24,MATCH(Scenario!$B$3,'Domain reference'!$B$4:$D$4,0)) -> 0.118213 | F28: 5e-07 | G28: =ABS(B28-E28)<=F28+0.0000000001 -> TRUE
A29: Survey invitation rate | B29: =ROUND(SUM(Surveys!$F$2:$F$2148)/B7,6) -> 0.595067 | C29: ratio | D29: invited / completions | E29: =INDEX('Domain reference'!$B$26:$D$26,MATCH(Scenario!$B$3,'Domain reference'!$B$4:$D$4,0)) -> 0.595067 | F29: 5e-07 | G29: =ABS(B29-E29)<=F29+0.0000000001 -> TRUE
A30: Survey response rate | B30: =ROUND(SUM(Surveys!$G$2:$G$2148)/SUM(Surveys!$F$2:$F$2148),6) -> 0.349325 | C30: ratio | D30: valid responses / invited | E30: =INDEX('Domain reference'!$B$27:$D$27,MATCH(Scenario!$B$3,'Domain reference'!$B$4:$D$4,0)) -> 0.349325 | F30: 5e-07 | G30: =ABS(B30-E30)<=F30+0.0000000001 -> TRUE
A31: CSAT | B31: =ROUND(SUM(Surveys!$H$2:$H$2148)/SUM(Surveys!$G$2:$G$2148),6) -> 0.864 | C31: ratio | D31: positive (score >= 4) / valid responses; nonresponse is not random (docs/sql-analysis.md section 07) | E31: =INDEX('Domain reference'!$B$25:$D$25,MATCH(Scenario!$B$3,'Domain reference'!$B$4:$D$4,0)) -> 0.864 | F31: 5e-07 | G31: =ABS(B31-E31)<=F31+0.0000000001 -> TRUE

Sheet Domain reference
A1: PASTED VALUES from the Python domain (compute_metrics), not formulas
A2: One column per window: the domain's figure computed over web/public/data with exact rationals. Metrics reads these only for its check column.
A4: metric | B4: full | C4: training | D4: holdout
A5: arrival_count | B5: 3817 | C5: 2386 | D5: 1431
A6: completion_count | B6: 3608 | C6: 2260 | D6: 1348
A7: arrival_rate_per_hour | B7: 1.893353 | C7: 1.775298 | D7: 2.129464
A8: completion_rate_per_hour | B8: 1.789683 | C8: 1.681548 | D8: 2.005952
A9: mean_first_response_minutes | B9: 28.0046 | C9: 23.4036 | D9: 35.7365
A10: p90_first_response_minutes | B10: 44.15 | C10: 37.55 | D10: 59.3833
A11: mean_wait_minutes | B11: 25.5073 | C11: 20.8904 | D11: 33.2661
A12: mean_resolution_minutes | B12: 164.5909 | C12: 155.2115 | D12: 180.3161
A13: handling_minutes_total | B13: 189836.27 | C13: 118965.38 | D13: 70870.883
A14: sla_first_response_compliance | B14: 0.950498 | C14: 0.95633 | D14: 0.940697
A15: sla_first_response_within | B15: 3437 | C15: 2168 | D15: 1269
A16: sla_first_response_eligible | B16: 3616 | C16: 2267 | D16: 1349
... A30: p90_resolution_minutes | B30: 294.5833 | C30: 242.35 | D30: 385.8333

Sheet Hour of week
A1: Arrivals by weekday and UTC hour for the selected window (COUNTIFS over Tickets)
A2: Weekday 0 = Monday. The Monday 09-11 UTC block is the capacity bind of the generator's design (docs/sql-analysis.md section 01).
A4: weekday \ hour (UTC) | B4: 0 | C4: 1 | D4: 2 | E4: 3 | F4: 4 | G4: 5 | H4: 6 | I4: 7 | J4: 8 | K4: 9 | L4: 10 | M4: 11 | N4: 12 | O4: 13 | P4: 14 | Q4: 15 | R4: 16 | S4: 17 | T4: 18 | U4: 19 | V4: 20 | W4: 21 | X4: 22 | Y4: 23 | Z4: total
A5: 0 | B5: =COUNTIFS(Tickets!$L$2:$L$3818,1,Tickets!$Y$2:$Y$3818,$A5,Tickets!$Z$2:$Z$3818,0) -> 1 | C5: =COUNTIFS(Tickets!$L$2:$L$3818,1,Tickets!$Y$2:$Y$3818,$A5,Tickets!$Z$2:$Z$3818,1) -> 3 | D5: =COUNTIFS(Tickets!$L$2:$L$3818,1,Tickets!$Y$2:$Y$3818,$A5,Tickets!$Z$2:$Z$3818,2) -> 2 | E5: =COUNTIFS(Tickets!$L$2:$L$3818,1,Tickets!$Y$2:$Y$3818,$A5,Tickets!$Z$2:$Z$3818,3) -> 4 | F5: =COUNTIFS(Tickets!$L$2:$L$3818,1,Tickets!$Y$2:$Y$3818,$A5,Tickets!$Z$2:$Z$3818,4) -> 2 | G5: =COUNTIFS(Tickets!$L$2:$L$3818,1,Tickets!$Y$2:$Y$3818,$A5,Tickets!$Z$2:$Z$3818,5) -> 4 | H5: =COUNTIFS(Tickets!$L$2:$L$3818,1,Tickets!$Y$2:$Y$3818,$A5,Tickets!$Z$2:$Z$3818,6) -> 18 | I5: =COUNTIFS(Tickets!$L$2:$L$3818,1,Tickets!$Y$2:$Y$3818,$A5,Tickets!$Z$2:$Z$3818,7) -> 23 | J5: =COUNTIFS(Tickets!$L$2:$L$3818,1,Tickets!$Y$2:$Y$3818,$A5,Tickets!$Z$2:$Z$3818,8) -> 42 | K5: =COUNTIFS(Tickets!$L$2:$L$3818,1,Tickets!$Y$2:$Y$3818,$A5,Tickets!$Z$2:$Z$3818,9) -> 109 | L5: =COUNTIFS(Tickets!$L$2:$L$3818,1,Tickets!$Y$2:$Y$3818,$A5,Tickets!$Z$2:$Z$3818,10) -> 129 | M5: =COUNTIFS(Tickets!$L$2:$L$3818,1,Tickets!$Y$2:$Y$3818,$A5,Tickets!$Z$2:$Z$3818,11) -> 54 | N5: =COUNTIFS(Tickets!$L$2:$L$3818,1,Tickets!$Y$2:$Y$3818,$A5,Tickets!$Z$2:$Z$3818,12) -> 59 | O5: =COUNTIFS(Tickets!$L$2:$L$3818,1,Tickets!$Y$2:$Y$3818,$A5,Tickets!$Z$2:$Z$3818,13) -> 75 | P5: =COUNTIFS(Tickets!$L$2:$L$3818,1,Tickets!$Y$2:$Y$3818,$A5,Tickets!$Z$2:$Z$3818,14) -> 67 | Q5: =COUNTIFS(Tickets!$L$2:$L$3818,1,Tickets!$Y$2:$Y$3818,$A5,Tickets!$Z$2:$Z$3818,15) -> 54 | R5: =COUNTIFS(Tickets!$L$2:$L$3818,1,Tickets!$Y$2:$Y$3818,$A5,Tickets!$Z$2:$Z$3818,16) -> 49 | S5: =COUNTIFS(Tickets!$L$2:$L$3818,1,Tickets!$Y$2:$Y$3818,$A5,Tickets!$Z$2:$Z$3818,17) -> 41 | T5: =COUNTIFS(Tickets!$L$2:$L$3818,1,Tickets!$Y$2:$Y$3818,$A5,Tickets!$Z$2:$Z$3818,18) -> 37 | U5: =COUNTIFS(Tickets!$L$2:$L$3818,1,Tickets!$Y$2:$Y$3818,$A5,Tickets!$Z$2:$Z$3818,19) -> 22 | V5: =COUNTIFS(Tickets!$L$2:$L$3818,1,Tickets!$Y$2:$Y$3818,$A5,Tickets!$Z$2:$Z$3818,20) -> 27 | W5: =COUNTIFS(Tickets!$L$2:$L$3818,1,Tickets!$Y$2:$Y$3818,$A5,Tickets!$Z$2:$Z$3818,21) -> 19 | X5: =COUNTIFS(Tickets!$L$2:$L$3818,1,Tickets!$Y$2:$Y$3818,$A5,Tickets!$Z$2:$Z$3818,22) -> 7 | Y5: =COUNTIFS(Tickets!$L$2:$L$3818,1,Tickets!$Y$2:$Y$3818,$A5,Tickets!$Z$2:$Z$3818,23) -> 2 | Z5: =SUM(B5:Y5) -> 850 | AA5: Mon
A6: 1 | B6: =COUNTIFS(Tickets!$L$2:$L$3818,1,Tickets!$Y$2:$Y$3818,$A6,Tickets!$Z$2:$Z$3818,0) -> 1 | C6: =COUNTIFS(Tickets!$L$2:$L$3818,1,Tickets!$Y$2:$Y$3818,$A6,Tickets!$Z$2:$Z$3818,1) -> 1 | D6: =COUNTIFS(Tickets!$L$2:$L$3818,1,Tickets!$Y$2:$Y$3818,$A6,Tickets!$Z$2:$Z$3818,2) -> 0 | E6: =COUNTIFS(Tickets!$L$2:$L$3818,1,Tickets!$Y$2:$Y$3818,$A6,Tickets!$Z$2:$Z$3818,3) -> 2 | F6: =COUNTIFS(Tickets!$L$2:$L$3818,1,Tickets!$Y$2:$Y$3818,$A6,Tickets!$Z$2:$Z$3818,4) -> 3 | G6: =COUNTIFS(Tickets!$L$2:$L$3818,1,Tickets!$Y$2:$Y$3818,$A6,Tickets!$Z$2:$Z$3818,5) -> 6 | H6: =COUNTIFS(Tickets!$L$2:$L$3818,1,Tickets!$Y$2:$Y$3818,$A6,Tickets!$Z$2:$Z$3818,6) -> 17 | I6: =COUNTIFS(Tickets!$L$2:$L$3818,1,Tickets!$Y$2:$Y$3818,$A6,Tickets!$Z$2:$Z$3818,7) -> 38 | J6: =COUNTIFS(Tickets!$L$2:$L$3818,1,Tickets!$Y$2:$Y$3818,$A6,Tickets!$Z$2:$Z$3818,8) -> 37 | K6: =COUNTIFS(Tickets!$L$2:$L$3818,1,Tickets!$Y$2:$Y$3818,$A6,Tickets!$Z$2:$Z$3818,9) -> 44 | L6: =COUNTIFS(Tickets!$L$2:$L$3818,1,Tickets!$Y$2:$Y$3818,$A6,Tickets!$Z$2:$Z$3818,10) -> 70 | M6: =COUNTIFS(Tickets!$L$2:$L$3818,1,Tickets!$Y$2:$Y$3818,$A6,Tickets!$Z$2:$Z$3818,11) -> 66 | N6: =COUNTIFS(Tickets!$L$2:$L$3818,1,Tickets!$Y$2:$Y$3818,$A6,Tickets!$Z$2:$Z$3818,12) -> 62 | O6: =COUNTIFS(Tickets!$L$2:$L$3818,1,Tickets!$Y$2:$Y$3818,$A6,Tickets!$Z$2:$Z$3818,13) -> 62 | P6: =COUNTIFS(Tickets!$L$2:$L$3818,1,Tickets!$Y$2:$Y$3818,$A6,Tickets!$Z$2:$Z$3818,14) -> 68 | Q6: =COUNTIFS(Tickets!$L$2:$L$3818,1,Tickets!$Y$2:$Y$3818,$A6,Tickets!$Z$2:$Z$3818,15) -> 71 | R6: =COUNTIFS(Tickets!$L$2:$L$3818,1,Tickets!$Y$2:$Y$3818,$A6,Tickets!$Z$2:$Z$3818,16) -> 53 | S6: =COUNTIFS(Tickets!$L$2:$L$3818,1,Tickets!$Y$2:$Y$3818,$A6,Tickets!$Z$2:$Z$3818,17) -> 43 | T6: =COUNTIFS(Tickets!$L$2:$L$3818,1,Tickets!$Y$2:$Y$3818,$A6,Tickets!$Z$2:$Z$3818,18) -> 35 | U6: =COUNTIFS(Tickets!$L$2:$L$3818,1,Tickets!$Y$2:$Y$3818,$A6,Tickets!$Z$2:$Z$3818,19) -> 24 | V6: =COUNTIFS(Tickets!$L$2:$L$3818,1,Tickets!$Y$2:$Y$3818,$A6,Tickets!$Z$2:$Z$3818,20) -> 14 | W6: =COUNTIFS(Tickets!$L$2:$L$3818,1,Tickets!$Y$2:$Y$3818,$A6,Tickets!$Z$2:$Z$3818,21) -> 14 | X6: =COUNTIFS(Tickets!$L$2:$L$3818,1,Tickets!$Y$2:$Y$3818,$A6,Tickets!$Z$2:$Z$3818,22) -> 6 | Y6: =COUNTIFS(Tickets!$L$2:$L$3818,1,Tickets!$Y$2:$Y$3818,$A6,Tickets!$Z$2:$Z$3818,23) -> 7 | Z6: =SUM(B6:Y6) -> 744 | AA6: Tue
A7: 2 | B7: =COUNTIFS(Tickets!$L$2:$L$3818,1,Tickets!$Y$2:$Y$3818,$A7,Tickets!$Z$2:$Z$3818,0) -> 1 | C7: =COUNTIFS(Tickets!$L$2:$L$3818,1,Tickets!$Y$2:$Y$3818,$A7,Tickets!$Z$2:$Z$3818,1) -> 1 | D7: =COUNTIFS(Tickets!$L$2:$L$3818,1,Tickets!$Y$2:$Y$3818,$A7,Tickets!$Z$2:$Z$3818,2) -> 2 | E7: =COUNTIFS(Tickets!$L$2:$L$3818,1,Tickets!$Y$2:$Y$3818,$A7,Tickets!$Z$2:$Z$3818,3) -> 8 | F7: =COUNTIFS(Tickets!$L$2:$L$3818,1,Tickets!$Y$2:$Y$3818,$A7,Tickets!$Z$2:$Z$3818,4) -> 2 | G7: =COUNTIFS(Tickets!$L$2:$L$3818,1,Tickets!$Y$2:$Y$3818,$A7,Tickets!$Z$2:$Z$3818,5) -> 4 | H7: =COUNTIFS(Tickets!$L$2:$L$3818,1,Tickets!$Y$2:$Y$3818,$A7,Tickets!$Z$2:$Z$3818,6) -> 18 | I7: =COUNTIFS(Tickets!$L$2:$L$3818,1,Tickets!$Y$2:$Y$3818,$A7,Tickets!$Z$2:$Z$3818,7) -> 35 | J7: =COUNTIFS(Tickets!$L$2:$L$3818,1,Tickets!$Y$2:$Y$3818,$A7,Tickets!$Z$2:$Z$3818,8) -> 44 | K7: =COUNTIFS(Tickets!$L$2:$L$3818,1,Tickets!$Y$2:$Y$3818,$A7,Tickets!$Z$2:$Z$3818,9) -> 43 | L7: =COUNTIFS(Tickets!$L$2:$L$3818,1,Tickets!$Y$2:$Y$3818,$A7,Tickets!$Z$2:$Z$3818,10) -> 59 | M7: =COUNTIFS(Tickets!$L$2:$L$3818,1,Tickets!$Y$2:$Y$3818,$A7,Tickets!$Z$2:$Z$3818,11) -> 60 | N7: =COUNTIFS(Tickets!$L$2:$L$3818,1,Tickets!$Y$2:$Y$3818,$A7,Tickets!$Z$2:$Z$3818,12) -> 41 | O7: =COUNTIFS(Tickets!$L$2:$L$3818,1,Tickets!$Y$2:$Y$3818,$A7,Tickets!$Z$2:$Z$3818,13) -> 57 | P7: =COUNTIFS(Tickets!$L$2:$L$3818,1,Tickets!$Y$2:$Y$3818,$A7,Tickets!$Z$2:$Z$3818,14) -> 56 | Q7: =COUNTIFS(Tickets!$L$2:$L$3818,1,Tickets!$Y$2:$Y$3818,$A7,Tickets!$Z$2:$Z$3818,15) -> 67 | R7: =COUNTIFS(Tickets!$L$2:$L$3818,1,Tickets!$Y$2:$Y$3818,$A7,Tickets!$Z$2:$Z$3818,16) -> 65 | S7: =COUNTIFS(Tickets!$L$2:$L$3818,1,Tickets!$Y$2:$Y$3818,$A7,Tickets!$Z$2:$Z$3818,17) -> 48 | T7: =COUNTIFS(Tickets!$L$2:$L$3818,1,Tickets!$Y$2:$Y$3818,$A7,Tickets!$Z$2:$Z$3818,18) -> 45 | U7: =COUNTIFS(Tickets!$L$2:$L$3818,1,Tickets!$Y$2:$Y$3818,$A7,Tickets!$Z$2:$Z$3818,19) -> 28 | V7: =COUNTIFS(Tickets!$L$2:$L$3818,1,Tickets!$Y$2:$Y$3818,$A7,Tickets!$Z$2:$Z$3818,20) -> 18 | W7: =COUNTIFS(Tickets!$L$2:$L$3818,1,Tickets!$Y$2:$Y$3818,$A7,Tickets!$Z$2:$Z$3818,21) -> 21 | X7: =COUNTIFS(Tickets!$L$2:$L$3818,1,Tickets!$Y$2:$Y$3818,$A7,Tickets!$Z$2:$Z$3818,22) -> 3 | Y7: =COUNTIFS(Tickets!$L$2:$L$3818,1,Tickets!$Y$2:$Y$3818,$A7,Tickets!$Z$2:$Z$3818,23) -> 2 | Z7: =SUM(B7:Y7) -> 728 | AA7: Wed
A8: 3 | B8: =COUNTIFS(Tickets!$L$2:$L$3818,1,Tickets!$Y$2:$Y$3818,$A8,Tickets!$Z$2:$Z$3818,0) -> 2 | C8: =COUNTIFS(Tickets!$L$2:$L$3818,1,Tickets!$Y$2:$Y$3818,$A8,Tickets!$Z$2:$Z$3818,1) -> 0 | D8: =COUNTIFS(Tickets!$L$2:$L$3818,1,Tickets!$Y$2:$Y$3818,$A8,Tickets!$Z$2:$Z$3818,2) -> 1 | E8: =COUNTIFS(Tickets!$L$2:$L$3818,1,Tickets!$Y$2:$Y$3818,$A8,Tickets!$Z$2:$Z$3818,3) -> 4 | F8: =COUNTIFS(Tickets!$L$2:$L$3818,1,Tickets!$Y$2:$Y$3818,$A8,Tickets!$Z$2:$Z$3818,4) -> 8 | G8: =COUNTIFS(Tickets!$L$2:$L$3818,1,Tickets!$Y$2:$Y$3818,$A8,Tickets!$Z$2:$Z$3818,5) -> 5 | H8: =COUNTIFS(Tickets!$L$2:$L$3818,1,Tickets!$Y$2:$Y$3818,$A8,Tickets!$Z$2:$Z$3818,6) -> 17 | I8: =COUNTIFS(Tickets!$L$2:$L$3818,1,Tickets!$Y$2:$Y$3818,$A8,Tickets!$Z$2:$Z$3818,7) -> 18 | J8: =COUNTIFS(Tickets!$L$2:$L$3818,1,Tickets!$Y$2:$Y$3818,$A8,Tickets!$Z$2:$Z$3818,8) -> 35 | K8: =COUNTIFS(Tickets!$L$2:$L$3818,1,Tickets!$Y$2:$Y$3818,$A8,Tickets!$Z$2:$Z$3818,9) -> 55 | L8: =COUNTIFS(Tickets!$L$2:$L$3818,1,Tickets!$Y$2:$Y$3818,$A8,Tickets!$Z$2:$Z$3818,10) -> 59 | M8: =COUNTIFS(Tickets!$L$2:$L$3818,1,Tickets!$Y$2:$Y$3818,$A8,Tickets!$Z$2:$Z$3818,11) -> 54 | N8: =COUNTIFS(Tickets!$L$2:$L$3818,1,Tickets!$Y$2:$Y$3818,$A8,Tickets!$Z$2:$Z$3818,12) -> 60 | O8: =COUNTIFS(Tickets!$L$2:$L$3818,1,Tickets!$Y$2:$Y$3818,$A8,Tickets!$Z$2:$Z$3818,13) -> 56 | P8: =COUNTIFS(Tickets!$L$2:$L$3818,1,Tickets!$Y$2:$Y$3818,$A8,Tickets!$Z$2:$Z$3818,14) -> 65 | Q8: =COUNTIFS(Tickets!$L$2:$L$3818,1,Tickets!$Y$2:$Y$3818,$A8,Tickets!$Z$2:$Z$3818,15) -> 64 | R8: =COUNTIFS(Tickets!$L$2:$L$3818,1,Tickets!$Y$2:$Y$3818,$A8,Tickets!$Z$2:$Z$3818,16) -> 49 | S8: =COUNTIFS(Tickets!$L$2:$L$3818,1,Tickets!$Y$2:$Y$3818,$A8,Tickets!$Z$2:$Z$3818,17) -> 49 | T8: =COUNTIFS(Tickets!$L$2:$L$3818,1,Tickets!$Y$2:$Y$3818,$A8,Tickets!$Z$2:$Z$3818,18) -> 43 | U8: =COUNTIFS(Tickets!$L$2:$L$3818,1,Tickets!$Y$2:$Y$3818,$A8,Tickets!$Z$2:$Z$3818,19) -> 25 | V8: =COUNTIFS(Tickets!$L$2:$L$3818,1,Tickets!$Y$2:$Y$3818,$A8,Tickets!$Z$2:$Z$3818,20) -> 26 | W8: =COUNTIFS(Tickets!$L$2:$L$3818,1,Tickets!$Y$2:$Y$3818,$A8,Tickets!$Z$2:$Z$3818,21) -> 10 | X8: =COUNTIFS(Tickets!$L$2:$L$3818,1,Tickets!$Y$2:$Y$3818,$A8,Tickets!$Z$2:$Z$3818,22) -> 9 | Y8: =COUNTIFS(Tickets!$L$2:$L$3818,1,Tickets!$Y$2:$Y$3818,$A8,Tickets!$Z$2:$Z$3818,23) -> 4 | Z8: =SUM(B8:Y8) -> 718 | AA8: Thu
A9: 4 | B9: =COUNTIFS(Tickets!$L$2:$L$3818,1,Tickets!$Y$2:$Y$3818,$A9,Tickets!$Z$2:$Z$3818,0) -> 2 | C9: =COUNTIFS(Tickets!$L$2:$L$3818,1,Tickets!$Y$2:$Y$3818,$A9,Tickets!$Z$2:$Z$3818,1) -> 2 | D9: =COUNTIFS(Tickets!$L$2:$L$3818,1,Tickets!$Y$2:$Y$3818,$A9,Tickets!$Z$2:$Z$3818,2) -> 2 | E9: =COUNTIFS(Tickets!$L$2:$L$3818,1,Tickets!$Y$2:$Y$3818,$A9,Tickets!$Z$2:$Z$3818,3) -> 1 | F9: =COUNTIFS(Tickets!$L$2:$L$3818,1,Tickets!$Y$2:$Y$3818,$A9,Tickets!$Z$2:$Z$3818,4) -> 5 | G9: =COUNTIFS(Tickets!$L$2:$L$3818,1,Tickets!$Y$2:$Y$3818,$A9,Tickets!$Z$2:$Z$3818,5) -> 5 | H9: =COUNTIFS(Tickets!$L$2:$L$3818,1,Tickets!$Y$2:$Y$3818,$A9,Tickets!$Z$2:$Z$3818,6) -> 9 | I9: =COUNTIFS(Tickets!$L$2:$L$3818,1,Tickets!$Y$2:$Y$3818,$A9,Tickets!$Z$2:$Z$3818,7) -> 22 | J9: =COUNTIFS(Tickets!$L$2:$L$3818,1,Tickets!$Y$2:$Y$3818,$A9,Tickets!$Z$2:$Z$3818,8) -> 40 | K9: =COUNTIFS(Tickets!$L$2:$L$3818,1,Tickets!$Y$2:$Y$3818,$A9,Tickets!$Z$2:$Z$3818,9) -> 58 | L9: =COUNTIFS(Tickets!$L$2:$L$3818,1,Tickets!$Y$2:$Y$3818,$A9,Tickets!$Z$2:$Z$3818,10) -> 45 | M9: =COUNTIFS(Tickets!$L$2:$L$3818,1,Tickets!$Y$2:$Y$3818,$A9,Tickets!$Z$2:$Z$3818,11) -> 52 | N9: =COUNTIFS(Tickets!$L$2:$L$3818,1,Tickets!$Y$2:$Y$3818,$A9,Tickets!$Z$2:$Z$3818,12) -> 57 | O9: =COUNTIFS(Tickets!$L$2:$L$3818,1,Tickets!$Y$2:$Y$3818,$A9,Tickets!$Z$2:$Z$3818,13) -> 65 | P9: =COUNTIFS(Tickets!$L$2:$L$3818,1,Tickets!$Y$2:$Y$3818,$A9,Tickets!$Z$2:$Z$3818,14) -> 52 | Q9: =COUNTIFS(Tickets!$L$2:$L$3818,1,Tickets!$Y$2:$Y$3818,$A9,Tickets!$Z$2:$Z$3818,15) -> 45 | R9: =COUNTIFS(Tickets!$L$2:$L$3818,1,Tickets!$Y$2:$Y$3818,$A9,Tickets!$Z$2:$Z$3818,16) -> 44 | S9: =COUNTIFS(Tickets!$L$2:$L$3818,1,Tickets!$Y$2:$Y$3818,$A9,Tickets!$Z$2:$Z$3818,17) -> 38 | T9: =COUNTIFS(Tickets!$L$2:$L$3818,1,Tickets!$Y$2:$Y$3818,$A9,Tickets!$Z$2:$Z$3818,18) -> 24 | U9: =COUNTIFS(Tickets!$L$2:$L$3818,1,Tickets!$Y$2:$Y$3818,$A9,Tickets!$Z$2:$Z$3818,19) -> 20 | V9: =COUNTIFS(Tickets!$L$2:$L$3818,1,Tickets!$Y$2:$Y$3818,$A9,Tickets!$Z$2:$Z$3818,20) -> 16 | W9: =COUNTIFS(Tickets!$L$2:$L$3818,1,Tickets!$Y$2:$Y$3818,$A9,Tickets!$Z$2:$Z$3818,21) -> 12 | X9: =COUNTIFS(Tickets!$L$2:$L$3818,1,Tickets!$Y$2:$Y$3818,$A9,Tickets!$Z$2:$Z$3818,22) -> 6 | Y9: =COUNTIFS(Tickets!$L$2:$L$3818,1,Tickets!$Y$2:$Y$3818,$A9,Tickets!$Z$2:$Z$3818,23) -> 4 | Z9: =SUM(B9:Y9) -> 626 | AA9: Fri
A10: 5 | B10: =COUNTIFS(Tickets!$L$2:$L$3818,1,Tickets!$Y$2:$Y$3818,$A10,Tickets!$Z$2:$Z$3818,0) -> 1 | C10: =COUNTIFS(Tickets!$L$2:$L$3818,1,Tickets!$Y$2:$Y$3818,$A10,Tickets!$Z$2:$Z$3818,1) -> 0 | D10: =COUNTIFS(Tickets!$L$2:$L$3818,1,Tickets!$Y$2:$Y$3818,$A10,Tickets!$Z$2:$Z$3818,2) -> 1 | E10: =COUNTIFS(Tickets!$L$2:$L$3818,1,Tickets!$Y$2:$Y$3818,$A10,Tickets!$Z$2:$Z$3818,3) -> 0 | F10: =COUNTIFS(Tickets!$L$2:$L$3818,1,Tickets!$Y$2:$Y$3818,$A10,Tickets!$Z$2:$Z$3818,4) -> 0 | G10: =COUNTIFS(Tickets!$L$2:$L$3818,1,Tickets!$Y$2:$Y$3818,$A10,Tickets!$Z$2:$Z$3818,5) -> 1 | H10: =COUNTIFS(Tickets!$L$2:$L$3818,1,Tickets!$Y$2:$Y$3818,$A10,Tickets!$Z$2:$Z$3818,6) -> 2 | I10: =COUNTIFS(Tickets!$L$2:$L$3818,1,Tickets!$Y$2:$Y$3818,$A10,Tickets!$Z$2:$Z$3818,7) -> 1 | J10: =COUNTIFS(Tickets!$L$2:$L$3818,1,Tickets!$Y$2:$Y$3818,$A10,Tickets!$Z$2:$Z$3818,8) -> 2 | K10: =COUNTIFS(Tickets!$L$2:$L$3818,1,Tickets!$Y$2:$Y$3818,$A10,Tickets!$Z$2:$Z$3818,9) -> 10 | L10: =COUNTIFS(Tickets!$L$2:$L$3818,1,Tickets!$Y$2:$Y$3818,$A10,Tickets!$Z$2:$Z$3818,10) -> 9 | M10: =COUNTIFS(Tickets!$L$2:$L$3818,1,Tickets!$Y$2:$Y$3818,$A10,Tickets!$Z$2:$Z$3818,11) -> 6 | N10: =COUNTIFS(Tickets!$L$2:$L$3818,1,Tickets!$Y$2:$Y$3818,$A10,Tickets!$Z$2:$Z$3818,12) -> 6 | O10: =COUNTIFS(Tickets!$L$2:$L$3818,1,Tickets!$Y$2:$Y$3818,$A10,Tickets!$Z$2:$Z$3818,13) -> 4 | P10: =COUNTIFS(Tickets!$L$2:$L$3818,1,Tickets!$Y$2:$Y$3818,$A10,Tickets!$Z$2:$Z$3818,14) -> 8 | Q10: =COUNTIFS(Tickets!$L$2:$L$3818,1,Tickets!$Y$2:$Y$3818,$A10,Tickets!$Z$2:$Z$3818,15) -> 7 | R10: =COUNTIFS(Tickets!$L$2:$L$3818,1,Tickets!$Y$2:$Y$3818,$A10,Tickets!$Z$2:$Z$3818,16) -> 4 | S10: =COUNTIFS(Tickets!$L$2:$L$3818,1,Tickets!$Y$2:$Y$3818,$A10,Tickets!$Z$2:$Z$3818,17) -> 4 | T10: =COUNTIFS(Tickets!$L$2:$L$3818,1,Tickets!$Y$2:$Y$3818,$A10,Tickets!$Z$2:$Z$3818,18) -> 8 | U10: =COUNTIFS(Tickets!$L$2:$L$3818,1,Tickets!$Y$2:$Y$3818,$A10,Tickets!$Z$2:$Z$3818,19) -> 2 | V10: =COUNTIFS(Tickets!$L$2:$L$3818,1,Tickets!$Y$2:$Y$3818,$A10,Tickets!$Z$2:$Z$3818,20) -> 4 | W10: =COUNTIFS(Tickets!$L$2:$L$3818,1,Tickets!$Y$2:$Y$3818,$A10,Tickets!$Z$2:$Z$3818,21) -> 2 | X10: =COUNTIFS(Tickets!$L$2:$L$3818,1,Tickets!$Y$2:$Y$3818,$A10,Tickets!$Z$2:$Z$3818,22) -> 0 | Y10: =COUNTIFS(Tickets!$L$2:$L$3818,1,Tickets!$Y$2:$Y$3818,$A10,Tickets!$Z$2:$Z$3818,23) -> 1 | Z10: =SUM(B10:Y10) -> 83 | AA10: Sat
A11: 6 | B11: =COUNTIFS(Tickets!$L$2:$L$3818,1,Tickets!$Y$2:$Y$3818,$A11,Tickets!$Z$2:$Z$3818,0) -> 0 | C11: =COUNTIFS(Tickets!$L$2:$L$3818,1,Tickets!$Y$2:$Y$3818,$A11,Tickets!$Z$2:$Z$3818,1) -> 0 | D11: =COUNTIFS(Tickets!$L$2:$L$3818,1,Tickets!$Y$2:$Y$3818,$A11,Tickets!$Z$2:$Z$3818,2) -> 0 | E11: =COUNTIFS(Tickets!$L$2:$L$3818,1,Tickets!$Y$2:$Y$3818,$A11,Tickets!$Z$2:$Z$3818,3) -> 0 | F11: =COUNTIFS(Tickets!$L$2:$L$3818,1,Tickets!$Y$2:$Y$3818,$A11,Tickets!$Z$2:$Z$3818,4) -> 1 | G11: =COUNTIFS(Tickets!$L$2:$L$3818,1,Tickets!$Y$2:$Y$3818,$A11,Tickets!$Z$2:$Z$3818,5) -> 2 | H11: =COUNTIFS(Tickets!$L$2:$L$3818,1,Tickets!$Y$2:$Y$3818,$A11,Tickets!$Z$2:$Z$3818,6) -> 0 | I11: =COUNTIFS(Tickets!$L$2:$L$3818,1,Tickets!$Y$2:$Y$3818,$A11,Tickets!$Z$2:$Z$3818,7) -> 2 | J11: =COUNTIFS(Tickets!$L$2:$L$3818,1,Tickets!$Y$2:$Y$3818,$A11,Tickets!$Z$2:$Z$3818,8) -> 2 | K11: =COUNTIFS(Tickets!$L$2:$L$3818,1,Tickets!$Y$2:$Y$3818,$A11,Tickets!$Z$2:$Z$3818,9) -> 5 | L11: =COUNTIFS(Tickets!$L$2:$L$3818,1,Tickets!$Y$2:$Y$3818,$A11,Tickets!$Z$2:$Z$3818,10) -> 8 | M11: =COUNTIFS(Tickets!$L$2:$L$3818,1,Tickets!$Y$2:$Y$3818,$A11,Tickets!$Z$2:$Z$3818,11) -> 6 | N11: =COUNTIFS(Tickets!$L$2:$L$3818,1,Tickets!$Y$2:$Y$3818,$A11,Tickets!$Z$2:$Z$3818,12) -> 11 | O11: =COUNTIFS(Tickets!$L$2:$L$3818,1,Tickets!$Y$2:$Y$3818,$A11,Tickets!$Z$2:$Z$3818,13) -> 5 | P11: =COUNTIFS(Tickets!$L$2:$L$3818,1,Tickets!$Y$2:$Y$3818,$A11,Tickets!$Z$2:$Z$3818,14) -> 9 | Q11: =COUNTIFS(Tickets!$L$2:$L$3818,1,Tickets!$Y$2:$Y$3818,$A11,Tickets!$Z$2:$Z$3818,15) -> 4 | R11: =COUNTIFS(Tickets!$L$2:$L$3818,1,Tickets!$Y$2:$Y$3818,$A11,Tickets!$Z$2:$Z$3818,16) -> 5 | S11: =COUNTIFS(Tickets!$L$2:$L$3818,1,Tickets!$Y$2:$Y$3818,$A11,Tickets!$Z$2:$Z$3818,17) -> 2 | T11: =COUNTIFS(Tickets!$L$2:$L$3818,1,Tickets!$Y$2:$Y$3818,$A11,Tickets!$Z$2:$Z$3818,18) -> 2 | U11: =COUNTIFS(Tickets!$L$2:$L$3818,1,Tickets!$Y$2:$Y$3818,$A11,Tickets!$Z$2:$Z$3818,19) -> 1 | V11: =COUNTIFS(Tickets!$L$2:$L$3818,1,Tickets!$Y$2:$Y$3818,$A11,Tickets!$Z$2:$Z$3818,20) -> 2 | W11: =COUNTIFS(Tickets!$L$2:$L$3818,1,Tickets!$Y$2:$Y$3818,$A11,Tickets!$Z$2:$Z$3818,21) -> 0 | X11: =COUNTIFS(Tickets!$L$2:$L$3818,1,Tickets!$Y$2:$Y$3818,$A11,Tickets!$Z$2:$Z$3818,22) -> 1 | Y11: =COUNTIFS(Tickets!$L$2:$L$3818,1,Tickets!$Y$2:$Y$3818,$A11,Tickets!$Z$2:$Z$3818,23) -> 0 | Z11: =SUM(B11:Y11) -> 68 | AA11: Sun
A13: all | B13: =SUM(B5:B11) -> 8 | C13: =SUM(C5:C11) -> 7 | D13: =SUM(D5:D11) -> 8 | E13: =SUM(E5:E11) -> 19 | F13: =SUM(F5:F11) -> 21 | G13: =SUM(G5:G11) -> 27 | H13: =SUM(H5:H11) -> 81 | I13: =SUM(I5:I11) -> 139 | ... Z13: =SUM(Z5:Z11) -> 3817
A15: Monday 09:00-11:00 UTC arrivals | B15: =K5+L5 -> 238
A16: grid total equals Metrics arrivals | B16: =Z13=Metrics!B6 -> TRUE
A17: expected Monday 09-11 arrivals (query 01, typed) | C17: 238 | D17: 144 | E17: 94 | F17: full / training / holdout
A18: check (matches the selected window) | B18: =B15=INDEX(C17:E17,MATCH(Scenario!B3,{"full","training","holdout"},0)) -> TRUE

Sheet Queue by priority
A1: Queue x priority for the selected window (final queue; COUNTIFS / AVERAGEIFS over Tickets)
A2: Expected columns are typed from query 02 and apply to the FULL window only; the check reads n/a for another scenario.
A4: queue | B4: priority | C4: arrivals | D4: mean first response (min) | E4: mean wait to first service (min) | F4: first response compliance | G4: query 02 arrivals (full) | H4: query 02 mean first response (full) | I4: query 02 mean wait (full) | J4: check (full only)
A5: q-001 | B5: P1 | C5: =COUNTIFS(Tickets!$L$2:$L$3818,1,Tickets!$D$2:$D$3818,$A5,Tickets!$B$2:$B$3818,$B5) -> 45 | D5: =IFERROR(ROUND(AVERAGEIFS(Tickets!$M$2:$M$3818,Tickets!$D$2:$D$3818,$A5,Tickets!$B$2:$B$3818,$B5),4),"") -> 9.1602 | E5: =IFERROR(ROUND(AVERAGEIFS(Tickets!$N$2:$N$3818,Tickets!$D$2:$D$3818,$A5,Tickets!$B$2:$B$3818,$B5),4),"") -> 6.8803 | F5: =IFERROR(ROUND(SUMIFS(Tickets!$S$2:$S$3818,Tickets!$D$2:$D$3818,$A5,Tickets!$B$2:$B$3818,$B5)/COUNTIFS(Tickets!$D$2:$D$3818,$A5,Tickets!$B$2:$B$3818,$B5,Tickets!$S$2:$S$3818,">=0"),6),"") -> 0.840909 | G5: 45 | H5: 9.1602 | I5: 6.8803 | J5: =IF(Scenario!$B$3="full",AND(C5=G5,ABS(D5-H5)<0.00005001,ABS(E5-I5)<0.00005001),"n/a") -> TRUE
A6: q-001 | B6: P2 | C6: =COUNTIFS(Tickets!$L$2:$L$3818,1,Tickets!$D$2:$D$3818,$A6,Tickets!$B$2:$B$3818,$B6) -> 431 | D6: =IFERROR(ROUND(AVERAGEIFS(Tickets!$M$2:$M$3818,Tickets!$D$2:$D$3818,$A6,Tickets!$B$2:$B$3818,$B6),4),"") -> 21.724 | E6: =IFERROR(ROUND(AVERAGEIFS(Tickets!$N$2:$N$3818,Tickets!$D$2:$D$3818,$A6,Tickets!$B$2:$B$3818,$B6),4),"") -> 19.2497 | F6: =IFERROR(ROUND(SUMIFS(Tickets!$S$2:$S$3818,Tickets!$D$2:$D$3818,$A6,Tickets!$B$2:$B$3818,$B6)/COUNTIFS(Tickets!$D$2:$D$3818,$A6,Tickets!$B$2:$B$3818,$B6,Tickets!$S$2:$S$3818,">=0"),6),"") -> 0.947494 | G6: 431 | H6: 21.724 | I6: 19.2497 | J6: =IF(Scenario!$B$3="full",AND(C6=G6,ABS(D6-H6)<0.00005001,ABS(E6-I6)<0.00005001),"n/a") -> TRUE
A7: q-001 | B7: P3 | C7: =COUNTIFS(Tickets!$L$2:$L$3818,1,Tickets!$D$2:$D$3818,$A7,Tickets!$B$2:$B$3818,$B7) -> 846 | D7: =IFERROR(ROUND(AVERAGEIFS(Tickets!$M$2:$M$3818,Tickets!$D$2:$D$3818,$A7,Tickets!$B$2:$B$3818,$B7),4),"") -> 18.0483 | E7: =IFERROR(ROUND(AVERAGEIFS(Tickets!$N$2:$N$3818,Tickets!$D$2:$D$3818,$A7,Tickets!$B$2:$B$3818,$B7),4),"") -> 15.5235 | F7: =IFERROR(ROUND(SUMIFS(Tickets!$S$2:$S$3818,Tickets!$D$2:$D$3818,$A7,Tickets!$B$2:$B$3818,$B7)/COUNTIFS(Tickets!$D$2:$D$3818,$A7,Tickets!$B$2:$B$3818,$B7,Tickets!$S$2:$S$3818,">=0"),6),"") -> 0.991261 | G7: 846 | H7: 18.0483 | I7: 15.5235 | J7: =IF(Scenario!$B$3="full",AND(C7=G7,ABS(D7-H7)<0.00005001,ABS(E7-I7)<0.00005001),"n/a") -> TRUE
A8: q-002 | B8: P1 | C8: =COUNTIFS(Tickets!$L$2:$L$3818,1,Tickets!$D$2:$D$3818,$A8,Tickets!$B$2:$B$3818,$B8) -> 148 | D8: =IFERROR(ROUND(AVERAGEIFS(Tickets!$M$2:$M$3818,Tickets!$D$2:$D$3818,$A8,Tickets!$B$2:$B$3818,$B8),4),"") -> 22.8731 | E8: =IFERROR(ROUND(AVERAGEIFS(Tickets!$N$2:$N$3818,Tickets!$D$2:$D$3818,$A8,Tickets!$B$2:$B$3818,$B8),4),"") -> 20.4291 | F8: =IFERROR(ROUND(SUMIFS(Tickets!$S$2:$S$3818,Tickets!$D$2:$D$3818,$A8,Tickets!$B$2:$B$3818,$B8)/COUNTIFS(Tickets!$D$2:$D$3818,$A8,Tickets!$B$2:$B$3818,$B8,Tickets!$S$2:$S$3818,">=0"),6),"") -> 0.823944 | G8: 148 | H8: 22.8731 | I8: 20.4291 | J8: =IF(Scenario!$B$3="full",AND(C8=G8,ABS(D8-H8)<0.00005001,ABS(E8-I8)<0.00005001),"n/a") -> TRUE
A9: q-002 | B9: P2 | C9: =COUNTIFS(Tickets!$L$2:$L$3818,1,Tickets!$D$2:$D$3818,$A9,Tickets!$B$2:$B$3818,$B9) -> 586 | D9: =IFERROR(ROUND(AVERAGEIFS(Tickets!$M$2:$M$3818,Tickets!$D$2:$D$3818,$A9,Tickets!$B$2:$B$3818,$B9),4),"") -> 38.2414 | E9: =IFERROR(ROUND(AVERAGEIFS(Tickets!$N$2:$N$3818,Tickets!$D$2:$D$3818,$A9,Tickets!$B$2:$B$3818,$B9),4),"") -> 35.7298 | F9: =IFERROR(ROUND(SUMIFS(Tickets!$S$2:$S$3818,Tickets!$D$2:$D$3818,$A9,Tickets!$B$2:$B$3818,$B9)/COUNTIFS(Tickets!$D$2:$D$3818,$A9,Tickets!$B$2:$B$3818,$B9,Tickets!$S$2:$S$3818,">=0"),6),"") -> 0.906422 | G9: 586 | H9: 38.2414 | I9: 35.7298 | J9: =IF(Scenario!$B$3="full",AND(C9=G9,ABS(D9-H9)<0.00005001,ABS(E9-I9)<0.00005001),"n/a") -> TRUE
A10: q-002 | B10: P3 | C10: =COUNTIFS(Tickets!$L$2:$L$3818,1,Tickets!$D$2:$D$3818,$A10,Tickets!$B$2:$B$3818,$B10) -> 809 | D10: =IFERROR(ROUND(AVERAGEIFS(Tickets!$M$2:$M$3818,Tickets!$D$2:$D$3818,$A10,Tickets!$B$2:$B$3818,$B10),4),"") -> 51.9017 | E10: =IFERROR(ROUND(AVERAGEIFS(Tickets!$N$2:$N$3818,Tickets!$D$2:$D$3818,$A10,Tickets!$B$2:$B$3818,$B10),4),"") -> 49.4389 | F10: =IFERROR(ROUND(SUMIFS(Tickets!$S$2:$S$3818,Tickets!$D$2:$D$3818,$A10,Tickets!$B$2:$B$3818,$B10)/COUNTIFS(Tickets!$D$2:$D$3818,$A10,Tickets!$B$2:$B$3818,$B10,Tickets!$S$2:$S$3818,">=0"),6),"") -> 0.954485 | G10: 809 | H10: 51.9017 | I10: 49.4389 | J10: =IF(Scenario!$B$3="full",AND(C10=G10,ABS(D10-H10)<0.00005001,ABS(E10-I10)<0.00005001),"n/a") -> TRUE
A11: q-003 | B11: P1 | C11: =COUNTIFS(Tickets!$L$2:$L$3818,1,Tickets!$D$2:$D$3818,$A11,Tickets!$B$2:$B$3818,$B11) -> 43 | D11: =IFERROR(ROUND(AVERAGEIFS(Tickets!$M$2:$M$3818,Tickets!$D$2:$D$3818,$A11,Tickets!$B$2:$B$3818,$B11),4),"") -> 12.426 | E11: =IFERROR(ROUND(AVERAGEIFS(Tickets!$N$2:$N$3818,Tickets!$D$2:$D$3818,$A11,Tickets!$B$2:$B$3818,$B11),4),"") -> 9.9244 | F11: =IFERROR(ROUND(SUMIFS(Tickets!$S$2:$S$3818,Tickets!$D$2:$D$3818,$A11,Tickets!$B$2:$B$3818,$B11)/COUNTIFS(Tickets!$D$2:$D$3818,$A11,Tickets!$B$2:$B$3818,$B11,Tickets!$S$2:$S$3818,">=0"),6),"") -> 0.804878 | G11: 43 | H11: 12.426 | I11: 9.9244 | J11: =IF(Scenario!$B$3="full",AND(C11=G11,ABS(D11-H11)<0.00005001,ABS(E11-I11)<0.00005001),"n/a") -> TRUE
A12: q-003 | B12: P2 | C12: =COUNTIFS(Tickets!$L$2:$L$3818,1,Tickets!$D$2:$D$3818,$A12,Tickets!$B$2:$B$3818,$B12) -> 370 | D12: =IFERROR(ROUND(AVERAGEIFS(Tickets!$M$2:$M$3818,Tickets!$D$2:$D$3818,$A12,Tickets!$B$2:$B$3818,$B12),4),"") -> 14.6941 | E12: =IFERROR(ROUND(AVERAGEIFS(Tickets!$N$2:$N$3818,Tickets!$D$2:$D$3818,$A12,Tickets!$B$2:$B$3818,$B12),4),"") -> 12.1977 | F12: =IFERROR(ROUND(SUMIFS(Tickets!$S$2:$S$3818,Tickets!$D$2:$D$3818,$A12,Tickets!$B$2:$B$3818,$B12)/COUNTIFS(Tickets!$D$2:$D$3818,$A12,Tickets!$B$2:$B$3818,$B12,Tickets!$S$2:$S$3818,">=0"),6),"") -> 0.955056 | G12: 370 | H12: 14.6941 | I12: 12.1977 | J12: =IF(Scenario!$B$3="full",AND(C12=G12,ABS(D12-H12)<0.00005001,ABS(E12-I12)<0.00005001),"n/a") -> TRUE
A13: q-003 | B13: P3 | C13: =COUNTIFS(Tickets!$L$2:$L$3818,1,Tickets!$D$2:$D$3818,$A13,Tickets!$B$2:$B$3818,$B13) -> 539 | D13: =IFERROR(ROUND(AVERAGEIFS(Tickets!$M$2:$M$3818,Tickets!$D$2:$D$3818,$A13,Tickets!$B$2:$B$3818,$B13),4),"") -> 16.7022 | E13: =IFERROR(ROUND(AVERAGEIFS(Tickets!$N$2:$N$3818,Tickets!$D$2:$D$3818,$A13,Tickets!$B$2:$B$3818,$B13),4),"") -> 14.1611 | F13: =IFERROR(ROUND(SUMIFS(Tickets!$S$2:$S$3818,Tickets!$D$2:$D$3818,$A13,Tickets!$B$2:$B$3818,$B13)/COUNTIFS(Tickets!$D$2:$D$3818,$A13,Tickets!$B$2:$B$3818,$B13,Tickets!$S$2:$S$3818,">=0"),6),"") -> 0.982726 | G13: 539 | H13: 16.7022 | I13: 14.1611 | J13: =IF(Scenario!$B$3="full",AND(C13=G13,ABS(D13-H13)<0.00005001,ABS(E13-I13)<0.00005001),"n/a") -> TRUE

Sheet Golden case
A1: The known answer (P04-GOLD-01) as spreadsheet formulas
A2: One agent, three tickets at minute 0, deterministic 10-minute service, FIFO. Independent of every other sheet.
A4: ticket | B4: arrival (min) | C4: service (min) | D4: service start (min) | E4: wait (min) | F4: completion (min) | G4: first response (min) | I4: service minutes | J4: 10
A5: t-001 | B5: 0 | C5: =$J$4 -> 10 | D5: =MAX(B5,0) -> 0 | E5: =D5-B5 -> 0 | F5: =D5+C5 -> 10 | G5: =D5-B5 -> 0
A6: t-002 | B6: 0 | C6: =$J$4 -> 10 | D6: =MAX(B6,F5) -> 10 | E6: =D6-B6 -> 10 | F6: =D6+C6 -> 20 | G6: =D6-B6 -> 10
A7: t-003 | B7: 0 | C7: =$J$4 -> 10 | D7: =MAX(B7,F6) -> 20 | E7: =D7-B7 -> 20 | F7: =D7+C7 -> 30 | G7: =D7-B7 -> 20
A9: mean wait (min) | B9: =AVERAGE(E5:E7) -> 10 | D9: expected (expected.json) | E9: 10 | F9: =ABS(B9-E9)<0.00005 -> TRUE
A10: last completion (min) | B10: =MAX(F5:F7) -> 30 | D10: expected | E10: 30 | F10: =ABS(B10-E10)<0.00005 -> TRUE
A11: handling total (min) | B11: =SUM(C5:C7) -> 30 | D11: expected | E11: 30 | F11: =ABS(B11-E11)<0.00005 -> TRUE
A12: mean first response (min) | B12: =AVERAGE(G5:G7) -> 10 | D12: expected | E12: 10 | F12: =ABS(B12-E12)<0.00005 -> TRUE
A14: starts 0 / 10 / 20 and waits 0 / 10 / 20 | B14: =AND(D5=0,D6=10,D7=20,E5=0,E6=10,E7=20) -> TRUE
A15: all golden checks TRUE | B15: =AND(F9:F12,B14) -> TRUE

Sheet Assumptions
A1: Assumptions and limits
A2: D-nn are contract decisions (docs/contracts.md); W-nn are this workbook's own limits.
A4: id | B4: statement
A5: D-01 | B5: Events are an ordered log (occurred_at, event_id); FIFO within priority; a transfer keeps the arrival instant; a reopen is one customer contact.
A6: D-02 | B6: UTC instants; first response = first HUMAN reply (a bot never counts); resolution = final resolution minus the ORIGINAL arrival; P90 is nearest rank (index ceil(0.9 n)); handling = service intervals only.
A7: D-03 | B7: Staffed available time = shift minutes minus the declared break; occupancy = handling / staffed; abandonment only on channels that can abandon; CSAT = positive / valid responses.
A8: D-05 | B8: The break is deducted only when the window covers the whole shift; the backlog counts arrived tickets not resolved or abandoned; the survey invitation rate is over resolved tickets.
A9: D-08 | B9: The site window is [2026-07-06, as_of + 1 s); training = weeks 1-8, holdout = weeks 9-12; timestamps are integer epoch seconds.
A10: D-09 | B10: Wait means wait to first service; a reopened ticket is charged its dormant gap; calendars are ignored (every SLA policy uses the 24x7 cal-001).
A11: W-01 | B11: Synthetic data only. The holdout's +20 % arrival intensity is a chosen realisation of a seeded series (docs/contracts.md D-09 R4-13).
A12: W-02 | B12: The per-ticket instants and the service intervals were derived from the event log ONCE in Python (the domain's replay); the replay is not a spreadsheet formula. Everything after those instants is.
A13: W-03 | B13: Backlog and open overdue at the window end read a reopened ticket by its final resolution; checked equal to the domain for all three windows (1 open ticket at the end of the training window, none otherwise). It is not a general as-of reconstruction.
A14: W-04 | B14: Recalculation: openpyxl writes formulas only. The delivered file was recalculated by LibreOffice headless and carries its cached values; Excel was NOT run (docs/workbook.md). fullCalcOnLoad is set so Excel recalculates on open.
A15: W-05 | B15: Instants are integer epoch seconds (UTC), so a minute is exact to the second; the check tolerance is half a unit in the last place of the stated precision.
... A17: W-07 | B17: Simulation results (docs/executive-memo.md) are estimates and are not part of this workbook.

Sheet Tickets
A1: ticket_id | B1: priority | C1: channel | D1: final queue | E1: created (epoch s) | F1: first human reply (epoch s) | G1: first service (epoch s) | H1: final resolution (epoch s) | I1: abandoned (epoch s) | J1: reopens | K1: transfers | L1: in arrivals | M1: first response (min) | N1: wait to first service (min) | O1: in completions | P1: resolution (min) | Q1: first response target (min) | R1: resolution target (min) | S1: first response within | T1: resolution within | U1: open at window end | V1: overdue at window end | W1: can abandon | X1: abandoned | Y1: weekday (0=Mon) | Z1: hour (UTC) | AA1: created (UTC text)
A2: t-0001 | B2: P2 | C2: chat | D2: q-003 | E2: 1783302666 | I2: 1783304164 | J2: 0 | K2: 0 | L2: =IF(AND(E2>=Scenario!$B$11,E2<Scenario!$B$12),1,0) -> 1 | M2: =IF(AND(L2=1,ISNUMBER(F2)),MAX(0,F2-E2)/60,"") | N2: =IF(AND(L2=1,ISNUMBER(G2)),MAX(0,G2-E2)/60,"") | O2: =IF(ISNUMBER(H2),IF(AND(H2>=Scenario!$B$11,H2<Scenario!$B$12),1,0),0) -> 0 | P2: =IF(O2=1,MAX(0,H2-E2)/60,"") | Q2: =INDEX(Scenario!$B$18:$B$20,MATCH(B2,Scenario!$A$18:$A$20,0)) -> 60 | R2: =INDEX(Scenario!$C$18:$C$20,MATCH(B2,Scenario!$A$18:$A$20,0)) -> 1440 | S2: =IF(ISNUMBER(M2),IF(M2<=Q2,1,0),"") | T2: =IF(ISNUMBER(P2),IF(P2<=R2,1,0),"") | U2: =IF(E2>Scenario!$B$14,0,IF(OR(AND(ISNUMBER(H2),H2<=Scenario!$B$14),AND(ISNUMBER(I2),I2<=Scenario!$B$14)),0,1)) -> 0 | V2: =IF(AND(U2=1,(Scenario!$B$14-E2)/60>R2),1,0) -> 0 | W2: =IF(OR(C2=Scenario!$B$22,C2=Scenario!$C$22),1,0) -> 1 | X2: =IF(ISNUMBER(I2),1,0) -> 1 | Y2: =MOD(INT(E2/86400)+3,7) -> 0 | Z2: =MOD(INT(E2/3600),24) -> 1 | AA2: 2026-07-06T01:51:06Z
A3: t-0002 | B3: P3 | C3: email | D3: q-001 | E3: 1783307173 | F3: 1783314209 | G3: 1783314047 | H3: 1783315005 | J3: 0 | K3: 0 | L3: =IF(AND(E3>=Scenario!$B$11,E3<Scenario!$B$12),1,0) -> 1 | M3: =IF(AND(L3=1,ISNUMBER(F3)),MAX(0,F3-E3)/60,"") -> 117.26667 | N3: =IF(AND(L3=1,ISNUMBER(G3)),MAX(0,G3-E3)/60,"") -> 114.56667 | O3: =IF(ISNUMBER(H3),IF(AND(H3>=Scenario!$B$11,H3<Scenario!$B$12),1,0),0) -> 1 | P3: =IF(O3=1,MAX(0,H3-E3)/60,"") -> 130.53333 | Q3: =INDEX(Scenario!$B$18:$B$20,MATCH(B3,Scenario!$A$18:$A$20,0)) -> 240 | R3: =INDEX(Scenario!$C$18:$C$20,MATCH(B3,Scenario!$A$18:$A$20,0)) -> 4320 | S3: =IF(ISNUMBER(M3),IF(M3<=Q3,1,0),"") -> 1 | T3: =IF(ISNUMBER(P3),IF(P3<=R3,1,0),"") -> 1 | U3: =IF(E3>Scenario!$B$14,0,IF(OR(AND(ISNUMBER(H3),H3<=Scenario!$B$14),AND(ISNUMBER(I3),I3<=Scenario!$B$14)),0,1)) -> 0 | V3: =IF(AND(U3=1,(Scenario!$B$14-E3)/60>R3),1,0) -> 0 | W3: =IF(OR(C3=Scenario!$B$22,C3=Scenario!$C$22),1,0) -> 0 | X3: =IF(ISNUMBER(I3),1,0) -> 0 | Y3: =MOD(INT(E3/86400)+3,7) -> 0 | Z3: =MOD(INT(E3/3600),24) -> 3 | AA3: 2026-07-06T03:06:13Z
A4: t-0003 | B4: P3 | C4: email | D4: q-001 | E4: 1783310288 | F4: 1783314188 | G4: 1783314016 | H4: 1783315952 | J4: 0 | K4: 1 | L4: =IF(AND(E4>=Scenario!$B$11,E4<Scenario!$B$12),1,0) -> 1 | M4: =IF(AND(L4=1,ISNUMBER(F4)),MAX(0,F4-E4)/60,"") -> 65 | N4: =IF(AND(L4=1,ISNUMBER(G4)),MAX(0,G4-E4)/60,"") -> 62.133333 | O4: =IF(ISNUMBER(H4),IF(AND(H4>=Scenario!$B$11,H4<Scenario!$B$12),1,0),0) -> 1 | P4: =IF(O4=1,MAX(0,H4-E4)/60,"") -> 94.4 | Q4: =INDEX(Scenario!$B$18:$B$20,MATCH(B4,Scenario!$A$18:$A$20,0)) -> 240 | R4: =INDEX(Scenario!$C$18:$C$20,MATCH(B4,Scenario!$A$18:$A$20,0)) -> 4320 | S4: =IF(ISNUMBER(M4),IF(M4<=Q4,1,0),"") -> 1 | T4: =IF(ISNUMBER(P4),IF(P4<=R4,1,0),"") -> 1 | U4: =IF(E4>Scenario!$B$14,0,IF(OR(AND(ISNUMBER(H4),H4<=Scenario!$B$14),AND(ISNUMBER(I4),I4<=Scenario!$B$14)),0,1)) -> 0 | V4: =IF(AND(U4=1,(Scenario!$B$14-E4)/60>R4),1,0) -> 0 | W4: =IF(OR(C4=Scenario!$B$22,C4=Scenario!$C$22),1,0) -> 0 | X4: =IF(ISNUMBER(I4),1,0) -> 0 | Y4: =MOD(INT(E4/86400)+3,7) -> 0 | Z4: =MOD(INT(E4/3600),24) -> 3 | AA4: 2026-07-06T03:58:08Z
A5: t-0004 | B5: P3 | C5: chat | D5: q-002 | E5: 1783311821 | F5: 1783314270 | G5: 1783314053 | H5: 1783315477 | J5: 0 | K5: 0 | L5: =IF(AND(E5>=Scenario!$B$11,E5<Scenario!$B$12),1,0) -> 1 | M5: =IF(AND(L5=1,ISNUMBER(F5)),MAX(0,F5-E5)/60,"") -> 40.816667 | N5: =IF(AND(L5=1,ISNUMBER(G5)),MAX(0,G5-E5)/60,"") -> 37.2 | O5: =IF(ISNUMBER(H5),IF(AND(H5>=Scenario!$B$11,H5<Scenario!$B$12),1,0),0) -> 1 | P5: =IF(O5=1,MAX(0,H5-E5)/60,"") -> 60.933333 | Q5: =INDEX(Scenario!$B$18:$B$20,MATCH(B5,Scenario!$A$18:$A$20,0)) -> 240 | R5: =INDEX(Scenario!$C$18:$C$20,MATCH(B5,Scenario!$A$18:$A$20,0)) -> 4320 | S5: =IF(ISNUMBER(M5),IF(M5<=Q5,1,0),"") -> 1 | T5: =IF(ISNUMBER(P5),IF(P5<=R5,1,0),"") -> 1 | U5: =IF(E5>Scenario!$B$14,0,IF(OR(AND(ISNUMBER(H5),H5<=Scenario!$B$14),AND(ISNUMBER(I5),I5<=Scenario!$B$14)),0,1)) -> 0 | V5: =IF(AND(U5=1,(Scenario!$B$14-E5)/60>R5),1,0) -> 0 | W5: =IF(OR(C5=Scenario!$B$22,C5=Scenario!$C$22),1,0) -> 1 | X5: =IF(ISNUMBER(I5),1,0) -> 0 | Y5: =MOD(INT(E5/86400)+3,7) -> 0 | Z5: =MOD(INT(E5/3600),24) -> 4 | AA5: 2026-07-06T04:23:41Z
A6: t-0005 | B6: P3 | C6: chat | D6: q-002 | E6: 1783312860 | I6: 1783314516 | J6: 0 | K6: 0 | L6: =IF(AND(E6>=Scenario!$B$11,E6<Scenario!$B$12),1,0) -> 1 | M6: =IF(AND(L6=1,ISNUMBER(F6)),MAX(0,F6-E6)/60,"") | N6: =IF(AND(L6=1,ISNUMBER(G6)),MAX(0,G6-E6)/60,"") | O6: =IF(ISNUMBER(H6),IF(AND(H6>=Scenario!$B$11,H6<Scenario!$B$12),1,0),0) -> 0 | P6: =IF(O6=1,MAX(0,H6-E6)/60,"") | Q6: =INDEX(Scenario!$B$18:$B$20,MATCH(B6,Scenario!$A$18:$A$20,0)) -> 240 | R6: =INDEX(Scenario!$C$18:$C$20,MATCH(B6,Scenario!$A$18:$A$20,0)) -> 4320 | S6: =IF(ISNUMBER(M6),IF(M6<=Q6,1,0),"") | T6: =IF(ISNUMBER(P6),IF(P6<=R6,1,0),"") | U6: =IF(E6>Scenario!$B$14,0,IF(OR(AND(ISNUMBER(H6),H6<=Scenario!$B$14),AND(ISNUMBER(I6),I6<=Scenario!$B$14)),0,1)) -> 0 | V6: =IF(AND(U6=1,(Scenario!$B$14-E6)/60>R6),1,0) -> 0 | W6: =IF(OR(C6=Scenario!$B$22,C6=Scenario!$C$22),1,0) -> 1 | X6: =IF(ISNUMBER(I6),1,0) -> 1 | Y6: =MOD(INT(E6/86400)+3,7) -> 0 | Z6: =MOD(INT(E6/3600),24) -> 4 | AA6: 2026-07-06T04:41:00Z
A7: t-0006 | B7: P3 | C7: phone | D7: q-003 | E7: 1783314204 | I7: 1783314324 | J7: 0 | K7: 0 | L7: =IF(AND(E7>=Scenario!$B$11,E7<Scenario!$B$12),1,0) -> 1 | M7: =IF(AND(L7=1,ISNUMBER(F7)),MAX(0,F7-E7)/60,"") | N7: =IF(AND(L7=1,ISNUMBER(G7)),MAX(0,G7-E7)/60,"") | O7: =IF(ISNUMBER(H7),IF(AND(H7>=Scenario!$B$11,H7<Scenario!$B$12),1,0),0) -> 0 | P7: =IF(O7=1,MAX(0,H7-E7)/60,"") | Q7: =INDEX(Scenario!$B$18:$B$20,MATCH(B7,Scenario!$A$18:$A$20,0)) -> 240 | R7: =INDEX(Scenario!$C$18:$C$20,MATCH(B7,Scenario!$A$18:$A$20,0)) -> 4320 | S7: =IF(ISNUMBER(M7),IF(M7<=Q7,1,0),"") | T7: =IF(ISNUMBER(P7),IF(P7<=R7,1,0),"") | U7: =IF(E7>Scenario!$B$14,0,IF(OR(AND(ISNUMBER(H7),H7<=Scenario!$B$14),AND(ISNUMBER(I7),I7<=Scenario!$B$14)),0,1)) -> 0 | V7: =IF(AND(U7=1,(Scenario!$B$14-E7)/60>R7),1,0) -> 0 | W7: =IF(OR(C7=Scenario!$B$22,C7=Scenario!$C$22),1,0) -> 1 | X7: =IF(ISNUMBER(I7),1,0) -> 1 | Y7: =MOD(INT(E7/86400)+3,7) -> 0 | Z7: =MOD(INT(E7/3600),24) -> 5 | AA7: 2026-07-06T05:03:24Z
A8: t-0007 | B8: P3 | C8: phone | D8: q-003 | E8: 1783317827 | F8: 1783317936 | G8: 1783317848 | H8: 1783321141 | J8: 0 | K8: 0 | L8: =IF(AND(E8>=Scenario!$B$11,E8<Scenario!$B$12),1,0) -> 1 | M8: =IF(AND(L8=1,ISNUMBER(F8)),MAX(0,F8-E8)/60,"") -> 1.8166667 | N8: =IF(AND(L8=1,ISNUMBER(G8)),MAX(0,G8-E8)/60,"") -> 0.35 | O8: =IF(ISNUMBER(H8),IF(AND(H8>=Scenario!$B$11,H8<Scenario!$B$12),1,0),0) -> 1 | P8: =IF(O8=1,MAX(0,H8-E8)/60,"") -> 55.233333 | Q8: =INDEX(Scenario!$B$18:$B$20,MATCH(B8,Scenario!$A$18:$A$20,0)) -> 240 | R8: =INDEX(Scenario!$C$18:$C$20,MATCH(B8,Scenario!$A$18:$A$20,0)) -> 4320 | S8: =IF(ISNUMBER(M8),IF(M8<=Q8,1,0),"") -> 1 | T8: =IF(ISNUMBER(P8),IF(P8<=R8,1,0),"") -> 1 | U8: =IF(E8>Scenario!$B$14,0,IF(OR(AND(ISNUMBER(H8),H8<=Scenario!$B$14),AND(ISNUMBER(I8),I8<=Scenario!$B$14)),0,1)) -> 0 | V8: =IF(AND(U8=1,(Scenario!$B$14-E8)/60>R8),1,0) -> 0 | W8: =IF(OR(C8=Scenario!$B$22,C8=Scenario!$C$22),1,0) -> 1 | X8: =IF(ISNUMBER(I8),1,0) -> 0 | Y8: =MOD(INT(E8/86400)+3,7) -> 0 | Z8: =MOD(INT(E8/3600),24) -> 6 | AA8: 2026-07-06T06:03:47Z
A9: t-0008 | B9: P3 | C9: phone | D9: q-003 | E9: 1783320295 | F9: 1783321366 | G9: 1783321183 | H9: 1783325212 | J9: 0 | K9: 0 | L9: =IF(AND(E9>=Scenario!$B$11,E9<Scenario!$B$12),1,0) -> 1 | M9: =IF(AND(L9=1,ISNUMBER(F9)),MAX(0,F9-E9)/60,"") -> 17.85 | N9: =IF(AND(L9=1,ISNUMBER(G9)),MAX(0,G9-E9)/60,"") -> 14.8 | O9: =IF(ISNUMBER(H9),IF(AND(H9>=Scenario!$B$11,H9<Scenario!$B$12),1,0),0) -> 1 | P9: =IF(O9=1,MAX(0,H9-E9)/60,"") -> 81.95 | Q9: =INDEX(Scenario!$B$18:$B$20,MATCH(B9,Scenario!$A$18:$A$20,0)) -> 240 | R9: =INDEX(Scenario!$C$18:$C$20,MATCH(B9,Scenario!$A$18:$A$20,0)) -> 4320 | S9: =IF(ISNUMBER(M9),IF(M9<=Q9,1,0),"") -> 1 | T9: =IF(ISNUMBER(P9),IF(P9<=R9,1,0),"") -> 1 | U9: =IF(E9>Scenario!$B$14,0,IF(OR(AND(ISNUMBER(H9),H9<=Scenario!$B$14),AND(ISNUMBER(I9),I9<=Scenario!$B$14)),0,1)) -> 0 | V9: =IF(AND(U9=1,(Scenario!$B$14-E9)/60>R9),1,0) -> 0 | W9: =IF(OR(C9=Scenario!$B$22,C9=Scenario!$C$22),1,0) -> 1 | X9: =IF(ISNUMBER(I9),1,0) -> 0 | Y9: =MOD(INT(E9/86400)+3,7) -> 0 | Z9: =MOD(INT(E9/3600),24) -> 6 | AA9: 2026-07-06T06:44:55Z
A10: t-0009 | B10: P3 | C10: email | D10: q-002 | E10: 1783323034 | F10: 1783323249 | G10: 1783323077 | H10: 1783328005 | J10: 0 | K10: 0 | L10: =IF(AND(E10>=Scenario!$B$11,E10<Scenario!$B$12),1,0) -> 1 | M10: =IF(AND(L10=1,ISNUMBER(F10)),MAX(0,F10-E10)/60,"") -> 3.5833333 | N10: =IF(AND(L10=1,ISNUMBER(G10)),MAX(0,G10-E10)/60,"") -> 0.71666667 | O10: =IF(ISNUMBER(H10),IF(AND(H10>=Scenario!$B$11,H10<Scenario!$B$12),1,0),0) -> 1 | P10: =IF(O10=1,MAX(0,H10-E10)/60,"") -> 82.85 | Q10: =INDEX(Scenario!$B$18:$B$20,MATCH(B10,Scenario!$A$18:$A$20,0)) -> 240 | R10: =INDEX(Scenario!$C$18:$C$20,MATCH(B10,Scenario!$A$18:$A$20,0)) -> 4320 | S10: =IF(ISNUMBER(M10),IF(M10<=Q10,1,0),"") -> 1 | T10: =IF(ISNUMBER(P10),IF(P10<=R10,1,0),"") -> 1 | U10: =IF(E10>Scenario!$B$14,0,IF(OR(AND(ISNUMBER(H10),H10<=Scenario!$B$14),AND(ISNUMBER(I10),I10<=Scenario!$B$14)),0,1)) -> 0 | V10: =IF(AND(U10=1,(Scenario!$B$14-E10)/60>R10),1,0) -> 0 | W10: =IF(OR(C10=Scenario!$B$22,C10=Scenario!$C$22),1,0) -> 0 | X10: =IF(ISNUMBER(I10),1,0) -> 0 | Y10: =MOD(INT(E10/86400)+3,7) -> 0 | Z10: =MOD(INT(E10/3600),24) -> 7 | AA10: 2026-07-06T07:30:34Z
A11: t-0010 | B11: P3 | C11: chat | D11: q-002 | E11: 1783325078 | F11: 1783325239 | G11: 1783325088 | H11: 1783326596 | J11: 0 | K11: 0 | L11: =IF(AND(E11>=Scenario!$B$11,E11<Scenario!$B$12),1,0) -> 1 | M11: =IF(AND(L11=1,ISNUMBER(F11)),MAX(0,F11-E11)/60,"") -> 2.6833333 | N11: =IF(AND(L11=1,ISNUMBER(G11)),MAX(0,G11-E11)/60,"") -> 0.16666667 | O11: =IF(ISNUMBER(H11),IF(AND(H11>=Scenario!$B$11,H11<Scenario!$B$12),1,0),0) -> 1 | P11: =IF(O11=1,MAX(0,H11-E11)/60,"") -> 25.3 | Q11: =INDEX(Scenario!$B$18:$B$20,MATCH(B11,Scenario!$A$18:$A$20,0)) -> 240 | R11: =INDEX(Scenario!$C$18:$C$20,MATCH(B11,Scenario!$A$18:$A$20,0)) -> 4320 | S11: =IF(ISNUMBER(M11),IF(M11<=Q11,1,0),"") -> 1 | T11: =IF(ISNUMBER(P11),IF(P11<=R11,1,0),"") -> 1 | U11: =IF(E11>Scenario!$B$14,0,IF(OR(AND(ISNUMBER(H11),H11<=Scenario!$B$14),AND(ISNUMBER(I11),I11<=Scenario!$B$14)),0,1)) -> 0 | V11: =IF(AND(U11=1,(Scenario!$B$14-E11)/60>R11),1,0) -> 0 | W11: =IF(OR(C11=Scenario!$B$22,C11=Scenario!$C$22),1,0) -> 1 | X11: =IF(ISNUMBER(I11),1,0) -> 0 | Y11: =MOD(INT(E11/86400)+3,7) -> 0 | Z11: =MOD(INT(E11/3600),24) -> 8 | AA11: 2026-07-06T08:04:38Z
A12: t-0011 | B12: P3 | C12: email | D12: q-002 | E12: 1783325484 | F12: 1783325605 | G12: 1783325540 | H12: 1783329989 | J12: 0 | K12: 0 | L12: =IF(AND(E12>=Scenario!$B$11,E12<Scenario!$B$12),1,0) -> 1 | M12: =IF(AND(L12=1,ISNUMBER(F12)),MAX(0,F12-E12)/60,"") -> 2.0166667 | N12: =IF(AND(L12=1,ISNUMBER(G12)),MAX(0,G12-E12)/60,"") -> 0.93333333 | O12: =IF(ISNUMBER(H12),IF(AND(H12>=Scenario!$B$11,H12<Scenario!$B$12),1,0),0) -> 1 | P12: =IF(O12=1,MAX(0,H12-E12)/60,"") -> 75.083333 | Q12: =INDEX(Scenario!$B$18:$B$20,MATCH(B12,Scenario!$A$18:$A$20,0)) -> 240 | R12: =INDEX(Scenario!$C$18:$C$20,MATCH(B12,Scenario!$A$18:$A$20,0)) -> 4320 | S12: =IF(ISNUMBER(M12),IF(M12<=Q12,1,0),"") -> 1 | T12: =IF(ISNUMBER(P12),IF(P12<=R12,1,0),"") -> 1 | U12: =IF(E12>Scenario!$B$14,0,IF(OR(AND(ISNUMBER(H12),H12<=Scenario!$B$14),AND(ISNUMBER(I12),I12<=Scenario!$B$14)),0,1)) -> 0 | V12: =IF(AND(U12=1,(Scenario!$B$14-E12)/60>R12),1,0) -> 0 | W12: =IF(OR(C12=Scenario!$B$22,C12=Scenario!$C$22),1,0) -> 0 | X12: =IF(ISNUMBER(I12),1,0) -> 0 | Y12: =MOD(INT(E12/86400)+3,7) -> 0 | Z12: =MOD(INT(E12/3600),24) -> 8 | AA12: 2026-07-06T08:11:24Z
A13: t-0012 | B13: P3 | C13: email | D13: q-002 | E13: 1783327596 | F13: 1783327717 | G13: 1783327613 | H13: 1783329512 | J13: 0 | K13: 0 | L13: =IF(AND(E13>=Scenario!$B$11,E13<Scenario!$B$12),1,0) -> 1 | M13: =IF(AND(L13=1,ISNUMBER(F13)),MAX(0,F13-E13)/60,"") -> 2.0166667 | N13: =IF(AND(L13=1,ISNUMBER(G13)),MAX(0,G13-E13)/60,"") -> 0.28333333 | O13: =IF(ISNUMBER(H13),IF(AND(H13>=Scenario!$B$11,H13<Scenario!$B$12),1,0),0) -> 1 | P13: =IF(O13=1,MAX(0,H13-E13)/60,"") -> 31.933333 | Q13: =INDEX(Scenario!$B$18:$B$20,MATCH(B13,Scenario!$A$18:$A$20,0)) -> 240 | R13: =INDEX(Scenario!$C$18:$C$20,MATCH(B13,Scenario!$A$18:$A$20,0)) -> 4320 | S13: =IF(ISNUMBER(M13),IF(M13<=Q13,1,0),"") -> 1 | T13: =IF(ISNUMBER(P13),IF(P13<=R13,1,0),"") -> 1 | U13: =IF(E13>Scenario!$B$14,0,IF(OR(AND(ISNUMBER(H13),H13<=Scenario!$B$14),AND(ISNUMBER(I13),I13<=Scenario!$B$14)),0,1)) -> 0 | V13: =IF(AND(U13=1,(Scenario!$B$14-E13)/60>R13),1,0) -> 0 | W13: =IF(OR(C13=Scenario!$B$22,C13=Scenario!$C$22),1,0) -> 0 | X13: =IF(ISNUMBER(I13),1,0) -> 0 | Y13: =MOD(INT(E13/86400)+3,7) -> 0 | Z13: =MOD(INT(E13/3600),24) -> 8 | AA13: 2026-07-06T08:46:36Z
A14: t-0013 | B14: P1 | C14: email | D14: q-002 | E14: 1783328650 | F14: 1783328755 | G14: 1783328666 | H14: 1783333443 | J14: 0 | K14: 0 | L14: =IF(AND(E14>=Scenario!$B$11,E14<Scenario!$B$12),1,0) -> 1 | M14: =IF(AND(L14=1,ISNUMBER(F14)),MAX(0,F14-E14)/60,"") -> 1.75 | N14: =IF(AND(L14=1,ISNUMBER(G14)),MAX(0,G14-E14)/60,"") -> 0.26666667 | O14: =IF(ISNUMBER(H14),IF(AND(H14>=Scenario!$B$11,H14<Scenario!$B$12),1,0),0) -> 1 | P14: =IF(O14=1,MAX(0,H14-E14)/60,"") -> 79.883333 | Q14: =INDEX(Scenario!$B$18:$B$20,MATCH(B14,Scenario!$A$18:$A$20,0)) -> 15 | R14: =INDEX(Scenario!$C$18:$C$20,MATCH(B14,Scenario!$A$18:$A$20,0)) -> 240 | S14: =IF(ISNUMBER(M14),IF(M14<=Q14,1,0),"") -> 1 | T14: =IF(ISNUMBER(P14),IF(P14<=R14,1,0),"") -> 1 | U14: =IF(E14>Scenario!$B$14,0,IF(OR(AND(ISNUMBER(H14),H14<=Scenario!$B$14),AND(ISNUMBER(I14),I14<=Scenario!$B$14)),0,1)) -> 0 | V14: =IF(AND(U14=1,(Scenario!$B$14-E14)/60>R14),1,0) -> 0 | W14: =IF(OR(C14=Scenario!$B$22,C14=Scenario!$C$22),1,0) -> 0 | X14: =IF(ISNUMBER(I14),1,0) -> 0 | Y14: =MOD(INT(E14/86400)+3,7) -> 0 | Z14: =MOD(INT(E14/3600),24) -> 9 | AA14: 2026-07-06T09:04:10Z
A15: t-0014 | B15: P3 | C15: email | D15: q-002 | E15: 1783328881 | F15: 1783329048 | G15: 1783328892 | H15: 1783333972 | J15: 0 | K15: 0 | L15: =IF(AND(E15>=Scenario!$B$11,E15<Scenario!$B$12),1,0) -> 1 | M15: =IF(AND(L15=1,ISNUMBER(F15)),MAX(0,F15-E15)/60,"") -> 2.7833333 | N15: =IF(AND(L15=1,ISNUMBER(G15)),MAX(0,G15-E15)/60,"") -> 0.18333333 | O15: =IF(ISNUMBER(H15),IF(AND(H15>=Scenario!$B$11,H15<Scenario!$B$12),1,0),0) -> 1 | P15: =IF(O15=1,MAX(0,H15-E15)/60,"") -> 84.85 | Q15: =INDEX(Scenario!$B$18:$B$20,MATCH(B15,Scenario!$A$18:$A$20,0)) -> 240 | R15: =INDEX(Scenario!$C$18:$C$20,MATCH(B15,Scenario!$A$18:$A$20,0)) -> 4320 | S15: =IF(ISNUMBER(M15),IF(M15<=Q15,1,0),"") -> 1 | T15: =IF(ISNUMBER(P15),IF(P15<=R15,1,0),"") -> 1 | U15: =IF(E15>Scenario!$B$14,0,IF(OR(AND(ISNUMBER(H15),H15<=Scenario!$B$14),AND(ISNUMBER(I15),I15<=Scenario!$B$14)),0,1)) -> 0 | V15: =IF(AND(U15=1,(Scenario!$B$14-E15)/60>R15),1,0) -> 0 | W15: =IF(OR(C15=Scenario!$B$22,C15=Scenario!$C$22),1,0) -> 0 | X15: =IF(ISNUMBER(I15),1,0) -> 0 | Y15: =MOD(INT(E15/86400)+3,7) -> 0 | Z15: =MOD(INT(E15/3600),24) -> 9 | AA15: 2026-07-06T09:08:01Z
A16: t-0015 | B16: P3 | C16: email | D16: q-001 | E16: 1783328892 | F16: 1783329570 | G16: 1783329360 | H16: 1783402736 | J16: 1 | K16: 0 | L16: =IF(AND(E16>=Scenario!$B$11,E16<Scenario!$B$12),1,0) -> 1 | M16: =IF(AND(L16=1,ISNUMBER(F16)),MAX(0,F16-E16)/60,"") -> 11.3 | N16: =IF(AND(L16=1,ISNUMBER(G16)),MAX(0,G16-E16)/60,"") -> 7.8 | O16: =IF(ISNUMBER(H16),IF(AND(H16>=Scenario!$B$11,H16<Scenario!$B$12),1,0),0) -> 1 | P16: =IF(O16=1,MAX(0,H16-E16)/60,"") -> 1230.7333 | Q16: =INDEX(Scenario!$B$18:$B$20,MATCH(B16,Scenario!$A$18:$A$20,0)) -> 240 | R16: =INDEX(Scenario!$C$18:$C$20,MATCH(B16,Scenario!$A$18:$A$20,0)) -> 4320 | S16: =IF(ISNUMBER(M16),IF(M16<=Q16,1,0),"") -> 1 | T16: =IF(ISNUMBER(P16),IF(P16<=R16,1,0),"") -> 1 | U16: =IF(E16>Scenario!$B$14,0,IF(OR(AND(ISNUMBER(H16),H16<=Scenario!$B$14),AND(ISNUMBER(I16),I16<=Scenario!$B$14)),0,1)) -> 0 | V16: =IF(AND(U16=1,(Scenario!$B$14-E16)/60>R16),1,0) -> 0 | W16: =IF(OR(C16=Scenario!$B$22,C16=Scenario!$C$22),1,0) -> 0 | X16: =IF(ISNUMBER(I16),1,0) -> 0 | Y16: =MOD(INT(E16/86400)+3,7) -> 0 | Z16: =MOD(INT(E16/3600),24) -> 9 | AA16: 2026-07-06T09:08:12Z
A17: t-0016 | B17: P3 | C17: phone | D17: q-002 | E17: 1783329064 | I17: 1783329184 | J17: 0 | K17: 0 | L17: =IF(AND(E17>=Scenario!$B$11,E17<Scenario!$B$12),1,0) -> 1 | M17: =IF(AND(L17=1,ISNUMBER(F17)),MAX(0,F17-E17)/60,"") | N17: =IF(AND(L17=1,ISNUMBER(G17)),MAX(0,G17-E17)/60,"") | O17: =IF(ISNUMBER(H17),IF(AND(H17>=Scenario!$B$11,H17<Scenario!$B$12),1,0),0) -> 0 | P17: =IF(O17=1,MAX(0,H17-E17)/60,"") | Q17: =INDEX(Scenario!$B$18:$B$20,MATCH(B17,Scenario!$A$18:$A$20,0)) -> 240 | R17: =INDEX(Scenario!$C$18:$C$20,MATCH(B17,Scenario!$A$18:$A$20,0)) -> 4320 | S17: =IF(ISNUMBER(M17),IF(M17<=Q17,1,0),"") | T17: =IF(ISNUMBER(P17),IF(P17<=R17,1,0),"") | U17: =IF(E17>Scenario!$B$14,0,IF(OR(AND(ISNUMBER(H17),H17<=Scenario!$B$14),AND(ISNUMBER(I17),I17<=Scenario!$B$14)),0,1)) -> 0 | V17: =IF(AND(U17=1,(Scenario!$B$14-E17)/60>R17),1,0) -> 0 | W17: =IF(OR(C17=Scenario!$B$22,C17=Scenario!$C$22),1,0) -> 1 | X17: =IF(ISNUMBER(I17),1,0) -> 1 | Y17: =MOD(INT(E17/86400)+3,7) -> 0 | Z17: =MOD(INT(E17/3600),24) -> 9 | AA17: 2026-07-06T09:11:04Z
