Workbook

Sheet Inputs
A1: Inputs: the golden fixture (tests/fixtures/golden/inputs.json, fixture supplyscope-golden-v1)
A2: SYNTHETIC. Every cell below is a typed input copied from the fixture (blue). Instants are UTC (yyyy-mm-dd hh:mm:ss). Contract v1, docs/contracts.md.
A4: parameters
A5: name | B5: value | C5: source
A6: as_of | B6: 46113 | C6: inputs.json as_of (editable: the as-of filter of the Ledger follows it)
A7: window_start | B7: 46082 | C7: inputs.json window_start
A8: reorder_point | B8: 70 | C8: replenishment_params.reorder_point
A9: target_position | B9: 120 | C9: replenishment_params.target_position
A10: minimum_order_quantity | B10: 50 | C10: products.minimum_order_quantity
A11: pack_size | B11: 24 | C11: products.pack_size
A12: unit_cost | B12: 12.5 | C12: products.unit_cost (no cost_versions in the fixture)
A13: reserved | B13: 0 | C13: fixture_declaration: no-reservation fixture, reservations is empty
A15: inventory_movements
A16: movement_id | B16: product_id | C16: location_id | D16: quantity_delta | E16: event_at | F16: movement_type
A17: mv-001 | B17: prod-001 | C17: loc-001 | D17: 60 | E17: 46082.333 | F17: receipt
A18: mv-002 | B18: prod-001 | C18: loc-001 | D18: -25 | E18: 46086.417 | F18: sale
A19: mv-003 | B19: prod-001 | C19: loc-001 | D19: -35 | E19: 46092.458 | F19: sale
A20: mv-004 | B20: prod-001 | C20: loc-001 | D20: -35 | E20: 46093.375 | F20: sale
A21: mv-005 | B21: prod-001 | C21: loc-001 | D21: 35 | E21: 46093.625 | F21: receipt
A22: mv-006 | B22: prod-001 | C22: loc-001 | D22: 40 | E22: 46097.333 | F22: receipt
A23: mv-007 | B23: prod-001 | C23: loc-001 | D23: -10 | E23: 46114.417 | F23: sale
A25: purchase_orders
A26: purchase_order_id | B26: supplier_id | C26: ordered_at | D26: status | E26: currency
A27: po-001 | B27: sup-001 | C27: 46101.375 | D27: confirmed | E27: USD
A29: purchase_order_lines | D29: state_added is not a fixture field: it names the fixture state (inputs.json states) that adds the line; blank = in every state
A30: po_line_id | B30: purchase_order_id | C30: product_id | D30: ordered_quantity | E30: unit_cost | F30: state_added
A31: pol-001 | B31: po-001 | C31: prod-001 | D31: 30 | E31: 12.5
A32: pol-002 | B32: po-001 | C32: prod-001 | D32: 20 | E32: 12.5 | F32: position_80
A34: receipts | D34: the fixture has no receipt rows: on order is ordered - 0
A35: receipt_id | B35: po_line_id | C35: location_id | D35: received_quantity | E35: received_at
A36: (none in the golden fixture)
A38: backorders | D38: closed_at blank = still open
A39: backorder_id | B39: product_id | C39: location_id | D39: quantity | E39: opened_at | F39: closed_at
A40: bo-001 | B40: prod-001 | C40: loc-001 | D40: 5 | E40: 46093.375 | F40: 46094.417
A41: bo-002 | B41: prod-001 | C41: loc-001 | D41: 10 | E41: 46080.5

Sheet Ledger
A1: Ledger: running stock with the day order and the as-of filter (contract D-01)
A2: Live formulas over Inputs. Sort key = date x 10 + type rank (receipt 0, sale 1, other 2) + time-of-day / 10, so inside a date receipts come first, then sales, then the rest. A movement counts only when event_at <= as_of (Inputs).
A4: movement_id | B4: event_at | C4: movement_type | D4: quantity_delta | E4: date | F4: type_rank | G4: sort_key | H4: in_scope (<= as_of) | I4: day_order_rank | J4: running stock, day order | K4: running stock, timestamp order
A5: =Inputs!$A$17 -> mv-001 | B5: =Inputs!$E$17 -> 46082.333 | C5: =Inputs!$F$17 -> receipt | D5: =Inputs!$D$17 -> 60 | E5: =INT(B5) -> 46082 | F5: =IF(C5="receipt",0,IF(C5="sale",1,2)) -> 0 | G5: =E5*10+F5+MOD(B5,1)/10 -> 460820.03 | H5: =IF(B5<=Inputs!$B$6,1,0) -> 1 | I5: =IF(H5=1,SUMPRODUCT(($H$5:$H$11=1)*($G$5:$G$11<=G5)),"") -> 1 | J5: =IF(H5=1,SUMPRODUCT(($H$5:$H$11=1)*($G$5:$G$11<=G5)*$D$5:$D$11),"") -> 60 | K5: =IF(H5=1,SUMPRODUCT(($H$5:$H$11=1)*($B$5:$B$11<=B5)*$D$5:$D$11),"") -> 60
A6: =Inputs!$A$18 -> mv-002 | B6: =Inputs!$E$18 -> 46086.417 | C6: =Inputs!$F$18 -> sale | D6: =Inputs!$D$18 -> -25 | E6: =INT(B6) -> 46086 | F6: =IF(C6="receipt",0,IF(C6="sale",1,2)) -> 1 | G6: =E6*10+F6+MOD(B6,1)/10 -> 460861.04 | H6: =IF(B6<=Inputs!$B$6,1,0) -> 1 | I6: =IF(H6=1,SUMPRODUCT(($H$5:$H$11=1)*($G$5:$G$11<=G6)),"") -> 2 | J6: =IF(H6=1,SUMPRODUCT(($H$5:$H$11=1)*($G$5:$G$11<=G6)*$D$5:$D$11),"") -> 35 | K6: =IF(H6=1,SUMPRODUCT(($H$5:$H$11=1)*($B$5:$B$11<=B6)*$D$5:$D$11),"") -> 35
A7: =Inputs!$A$19 -> mv-003 | B7: =Inputs!$E$19 -> 46092.458 | C7: =Inputs!$F$19 -> sale | D7: =Inputs!$D$19 -> -35 | E7: =INT(B7) -> 46092 | F7: =IF(C7="receipt",0,IF(C7="sale",1,2)) -> 1 | G7: =E7*10+F7+MOD(B7,1)/10 -> 460921.05 | H7: =IF(B7<=Inputs!$B$6,1,0) -> 1 | I7: =IF(H7=1,SUMPRODUCT(($H$5:$H$11=1)*($G$5:$G$11<=G7)),"") -> 3 | J7: =IF(H7=1,SUMPRODUCT(($H$5:$H$11=1)*($G$5:$G$11<=G7)*$D$5:$D$11),"") -> 0 | K7: =IF(H7=1,SUMPRODUCT(($H$5:$H$11=1)*($B$5:$B$11<=B7)*$D$5:$D$11),"") -> 0
A8: =Inputs!$A$20 -> mv-004 | B8: =Inputs!$E$20 -> 46093.375 | C8: =Inputs!$F$20 -> sale | D8: =Inputs!$D$20 -> -35 | E8: =INT(B8) -> 46093 | F8: =IF(C8="receipt",0,IF(C8="sale",1,2)) -> 1 | G8: =E8*10+F8+MOD(B8,1)/10 -> 460931.04 | H8: =IF(B8<=Inputs!$B$6,1,0) -> 1 | I8: =IF(H8=1,SUMPRODUCT(($H$5:$H$11=1)*($G$5:$G$11<=G8)),"") -> 5 | J8: =IF(H8=1,SUMPRODUCT(($H$5:$H$11=1)*($G$5:$G$11<=G8)*$D$5:$D$11),"") -> 0 | K8: =IF(H8=1,SUMPRODUCT(($H$5:$H$11=1)*($B$5:$B$11<=B8)*$D$5:$D$11),"") -> -35
A9: =Inputs!$A$21 -> mv-005 | B9: =Inputs!$E$21 -> 46093.625 | C9: =Inputs!$F$21 -> receipt | D9: =Inputs!$D$21 -> 35 | E9: =INT(B9) -> 46093 | F9: =IF(C9="receipt",0,IF(C9="sale",1,2)) -> 0 | G9: =E9*10+F9+MOD(B9,1)/10 -> 460930.06 | H9: =IF(B9<=Inputs!$B$6,1,0) -> 1 | I9: =IF(H9=1,SUMPRODUCT(($H$5:$H$11=1)*($G$5:$G$11<=G9)),"") -> 4 | J9: =IF(H9=1,SUMPRODUCT(($H$5:$H$11=1)*($G$5:$G$11<=G9)*$D$5:$D$11),"") -> 35 | K9: =IF(H9=1,SUMPRODUCT(($H$5:$H$11=1)*($B$5:$B$11<=B9)*$D$5:$D$11),"") -> 0
A10: =Inputs!$A$22 -> mv-006 | B10: =Inputs!$E$22 -> 46097.333 | C10: =Inputs!$F$22 -> receipt | D10: =Inputs!$D$22 -> 40 | E10: =INT(B10) -> 46097 | F10: =IF(C10="receipt",0,IF(C10="sale",1,2)) -> 0 | G10: =E10*10+F10+MOD(B10,1)/10 -> 460970.03 | H10: =IF(B10<=Inputs!$B$6,1,0) -> 1 | I10: =IF(H10=1,SUMPRODUCT(($H$5:$H$11=1)*($G$5:$G$11<=G10)),"") -> 6 | J10: =IF(H10=1,SUMPRODUCT(($H$5:$H$11=1)*($G$5:$G$11<=G10)*$D$5:$D$11),"") -> 40 | K10: =IF(H10=1,SUMPRODUCT(($H$5:$H$11=1)*($B$5:$B$11<=B10)*$D$5:$D$11),"") -> 40
A11: =Inputs!$A$23 -> mv-007 | B11: =Inputs!$E$23 -> 46114.417 | C11: =Inputs!$F$23 -> sale | D11: =Inputs!$D$23 -> -10 | E11: =INT(B11) -> 46114 | F11: =IF(C11="receipt",0,IF(C11="sale",1,2)) -> 1 | G11: =E11*10+F11+MOD(B11,1)/10 -> 461141.04 | H11: =IF(B11<=Inputs!$B$6,1,0) -> 0 | I11: =IF(H11=1,SUMPRODUCT(($H$5:$H$11=1)*($G$5:$G$11<=G11)),"") | J11: =IF(H11=1,SUMPRODUCT(($H$5:$H$11=1)*($G$5:$G$11<=G11)*$D$5:$D$11),"") | K11: =IF(H11=1,SUMPRODUCT(($H$5:$H$11=1)*($B$5:$B$11<=B11)*$D$5:$D$11),"")
A13: on hand, raw (sum of in-scope deltas) | B13: =SUMPRODUCT($H$5:$H$11*$D$5:$D$11) -> 40
A14: on hand (a negative reconstruction counts as 0) | B14: =MAX(0,B13) -> 40
A15: lowest running stock, day order (incl. the opening 0) | B15: =MIN(0,MIN($J$5:$J$11)) -> 0
A16: lowest running stock, timestamp order | B16: =MIN(0,MIN($K$5:$K$11)) -> -35
A17: flag | B17: =IF(OR(B13<0,B15<0),"NEGATIVE_STOCK","ok") -> ok
A18: movements counted / excluded by the as-of filter | B18: =SUM($H$5:$H$11)&" / "&(7-SUM($H$5:$H$11)) -> 6 / 1

Sheet Position
A1: Position: on hand + on order - backorders (contract D-01, P03-TEST-10)
A2: Live formulas. Reserved is NOT subtracted from the position (declared no-reservation fixture: reserved = 0). Column C is the golden state, column D the position_80 state (adds the fixture's second line); column B follows the switch Figures!B3.
A4: purchase order lines (open quantity = ordered - received by as_of, confirmed orders placed by as_of)
A5: po_line_id | B5: ordered_quantity | C5: received by as_of | D5: open quantity | E5: order confirmed and placed (1/0) | F5: in state golden (1/0) | G5: in state position_80 (1/0)
A6: =Inputs!$A$31 -> pol-001 | B6: =Inputs!$D$31 -> 30 | C6: =SUMPRODUCT((Inputs!$B$36:$B$36=A6)*(Inputs!$E$36:$E$36<=Inputs!$B$6)*Inputs!$D$36:$D$36) -> 0 | D6: =MAX(B6-C6,0) -> 30 | E6: =IF(AND(INDEX(Inputs!$D$27:$D$27,MATCH(Inputs!$B$31,Inputs!$A$27:$A$27,0))="confirmed",INDEX(Inputs!$C$27:$C$27,MATCH(Inputs!$B$31,Inputs!$A$27:$A$27,0))<=Inputs!$B$6),1,0) -> 1 | F6: =IF(Inputs!$F$31="",1,0) -> 1 | G6: =IF(OR(Inputs!$F$31="",Inputs!$F$31="position_80"),1,0) -> 1
A7: =Inputs!$A$32 -> pol-002 | B7: =Inputs!$D$32 -> 20 | C7: =SUMPRODUCT((Inputs!$B$36:$B$36=A7)*(Inputs!$E$36:$E$36<=Inputs!$B$6)*Inputs!$D$36:$D$36) -> 0 | D7: =MAX(B7-C7,0) -> 20 | E7: =IF(AND(INDEX(Inputs!$D$27:$D$27,MATCH(Inputs!$B$32,Inputs!$A$27:$A$27,0))="confirmed",INDEX(Inputs!$C$27:$C$27,MATCH(Inputs!$B$32,Inputs!$A$27:$A$27,0))<=Inputs!$B$6),1,0) -> 1 | F7: =IF(Inputs!$F$32="",1,0) -> 0 | G7: =IF(OR(Inputs!$F$32="",Inputs!$F$32="position_80"),1,0) -> 1
A9: quantity | B9: selected (Figures!B3) | C9: state golden | D9: state position_80 | E9: rule
A10: on hand | B10: =IF(Figures!$B$3=1,D10,C10) -> 40 | C10: =Ledger!$B$14 -> 40 | D10: =Ledger!$B$14 -> 40 | E10: Ledger: sum of in-scope posted deltas, floored at 0 (D-01)
A11: on order | B11: =IF(Figures!$B$3=1,D11,C11) -> 30 | C11: =SUMPRODUCT($D$6:$D$7*$E$6:$E$7*$F$6:$F$7) -> 30 | D11: =SUMPRODUCT($D$6:$D$7*$E$6:$E$7*$G$6:$G$7) -> 50 | E11: open quantity of confirmed lines (D-01, D-04)
A12: backorders open at as_of | B12: =IF(Figures!$B$3=1,D12,C12) -> 10 | C12: =SUMPRODUCT((Inputs!$E$40:$E$41<=Inputs!$B$6)*(((Inputs!$F$40:$F$41="")+(Inputs!$F$40:$F$41>Inputs!$B$6))>0)*Inputs!$D$40:$D$41) -> 10 | D12: =SUMPRODUCT((Inputs!$E$40:$E$41<=Inputs!$B$6)*(((Inputs!$F$40:$F$41="")+(Inputs!$F$40:$F$41>Inputs!$B$6))>0)*Inputs!$D$40:$D$41) -> 10 | E12: opened by as_of and not closed by as_of
A13: reserved | B13: =IF(Figures!$B$3=1,D13,C13) -> 0 | C13: =Inputs!$B$13 -> 0 | D13: =Inputs!$B$13 -> 0 | E13: declared 0 for the golden fixture
A14: available = on hand - reserved | B14: =IF(Figures!$B$3=1,D14,C14) -> 40 | C14: =C10-C13 -> 40 | D14: =D10-D13 -> 40 | E14: not the position
A15: inventory position | B15: =IF(Figures!$B$3=1,D15,C15) -> 60 | C15: =C10+C11-C12 -> 60 | D15: =D10+D11-D12 -> 80 | E15: on hand + on order - backorders; reserved not subtracted

Sheet Replenishment
A1: Replenishment: ROP, target, MOQ and pack rounding (contract D-02, D-06)
A2: Live formulas. raw = target - position; after MOQ = MAX(raw, MOQ); order = CEILING(after MOQ to the pack size); all three are 0 when the reorder is not triggered (position >= ROP).
A4: quantity | B4: selected (Figures!B3) | C4: state golden | D4: state position_80 | E4: rule
A5: inventory position | B5: =IF(Figures!$B$3=1,D5,C5) -> 60 | C5: =Position!C15 -> 60 | D5: =Position!D15 -> 80 | E5: from Position
A6: reorder point | B6: =IF(Figures!$B$3=1,D6,C6) -> 70 | C6: =Inputs!$B$8 -> 70 | D6: =Inputs!$B$8 -> 70 | E6: Inputs replenishment_params
A7: target position | B7: =IF(Figures!$B$3=1,D7,C7) -> 120 | C7: =Inputs!$B$9 -> 120 | D7: =Inputs!$B$9 -> 120 | E7: Inputs replenishment_params
A8: triggered (1 = position < reorder point) | B8: =IF(Figures!$B$3=1,D8,C8) -> 1 | C8: =IF(C5<C6,1,0) -> 1 | D8: =IF(D5<D6,1,0) -> 0 | E8: D-02, D-06
A9: raw order = target - position | B9: =IF(Figures!$B$3=1,D9,C9) -> 60 | C9: =IF(C8=1,MAX(C7-C5,0),0) -> 60 | D9: =IF(D8=1,MAX(D7-D5,0),0) -> 0 | E9: 0 when not triggered
A10: minimum order quantity (MOQ) | B10: =IF(Figures!$B$3=1,D10,C10) -> 50 | C10: =Inputs!$B$10 -> 50 | D10: =Inputs!$B$10 -> 50 | E10: Inputs products
A11: after MOQ = MAX(raw, MOQ) | B11: =IF(Figures!$B$3=1,D11,C11) -> 60 | C11: =IF(C8=1,MAX(C9,C10),0) -> 60 | D11: =IF(D8=1,MAX(D9,D10),0) -> 0 | E11: MOQ is applied before pack rounding
A12: pack size | B12: =IF(Figures!$B$3=1,D12,C12) -> 24 | C12: =Inputs!$B$11 -> 24 | D12: =Inputs!$B$11 -> 24 | E12: Inputs products
A13: order quantity = CEILING(after MOQ, pack size) | B13: =IF(Figures!$B$3=1,D13,C13) -> 72 | C13: =IF(C8=1,CEILING(C11,C12),0) -> 72 | D13: =IF(D8=1,CEILING(D11,D12),0) -> 0 | E13: whole packs
A14: order quantity as packs | B14: =IF(Figures!$B$3=1,D14,C14) -> 3 | C14: =C13/C12 -> 3 | D14: =D13/D12 -> 0 | E14: check: a whole number

Sheet Figures
A1: Figures: the golden position and order (P03-GOLD-01) and the position-80 switch
A2: SYNTHETIC. B3 is the state switch: 0 = golden (on order 30, position 60 -> order 72), 1 = position_80 (on order 50, position 80 -> no order). Column B follows the switch, C is always golden, D always position_80. E and F are the hand-derived expectations typed from expected.json; G and H compare.
A3: state switch (0 = golden, 1 = position_80) | B3: 0
A4: inputs read | B4: =IF(ISNUMBER(SEARCH("supplyscope-golden",Inputs!$A$1)),"golden fixture supplyscope-golden-v1","unexpected inputs") -> golden fixture supplyscope-golden-v1
A7: figure | B7: selected | C7: golden | D7: position_80 | E7: expected golden (expected.json) | F7: expected position_80 (expected.json) | G7: golden matches | H7: position_80 matches
A8: On hand | B8: =Position!B10 -> 40 | C8: =Position!C10 -> 40 | D8: =Position!D10 -> 40 | E8: 40 | F8: 40 | G8: =ROUND(C8-E8,6)=0 -> TRUE | H8: =ROUND(D8-F8,6)=0 -> TRUE
A9: On order | B9: =Position!B11 -> 30 | C9: =Position!C11 -> 30 | D9: =Position!D11 -> 50 | E9: 30 | F9: 50 | G9: =ROUND(C9-E9,6)=0 -> TRUE | H9: =ROUND(D9-F9,6)=0 -> TRUE
A10: Backorders open | B10: =Position!B12 -> 10 | C10: =Position!C12 -> 10 | D10: =Position!D12 -> 10 | E10: 10 | F10: 10 | G10: =ROUND(C10-E10,6)=0 -> TRUE | H10: =ROUND(D10-F10,6)=0 -> TRUE
A11: Inventory position | B11: =Position!B15 -> 60 | C11: =Position!C15 -> 60 | D11: =Position!D15 -> 80 | E11: 60 | F11: 80 | G11: =ROUND(C11-E11,6)=0 -> TRUE | H11: =ROUND(D11-F11,6)=0 -> TRUE
A12: Reorder point | B12: =Replenishment!B6 -> 70 | C12: =Replenishment!C6 -> 70 | D12: =Replenishment!D6 -> 70 | E12: 70 | F12: 70 | G12: =ROUND(C12-E12,6)=0 -> TRUE | H12: =ROUND(D12-F12,6)=0 -> TRUE
A13: Target position | B13: =Replenishment!B7 -> 120 | C13: =Replenishment!C7 -> 120 | D13: =Replenishment!D7 -> 120 | E13: 120 | F13: 120 | G13: =ROUND(C13-E13,6)=0 -> TRUE | H13: =ROUND(D13-F13,6)=0 -> TRUE
A14: Raw order (target - position) | B14: =Replenishment!B9 -> 60 | C14: =Replenishment!C9 -> 60 | D14: =Replenishment!D9 -> 0 | E14: 60 | F14: 0 | G14: =ROUND(C14-E14,6)=0 -> TRUE | H14: =ROUND(D14-F14,6)=0 -> TRUE
A15: Order after MOQ | B15: =Replenishment!B11 -> 60 | C15: =Replenishment!C11 -> 60 | D15: =Replenishment!D11 -> 0 | E15: 60 | F15: 0 | G15: =ROUND(C15-E15,6)=0 -> TRUE | H15: =ROUND(D15-F15,6)=0 -> TRUE
A16: Order quantity (pack rounded) | B16: =Replenishment!B13 -> 72 | C16: =Replenishment!C13 -> 72 | D16: =Replenishment!D13 -> 0 | E16: 72 | F16: 0 | G16: =ROUND(C16-E16,6)=0 -> TRUE | H16: =ROUND(D16-F16,6)=0 -> TRUE
A17: Working capital (on hand x unit cost) | B17: =Position!B10*Inputs!$B$12 -> 500 | C17: =Position!C10*Inputs!$B$12 -> 500 | D17: =Position!D10*Inputs!$B$12 -> 500 | E17: 500 | F17: 500 | G17: =ROUND(C17-E17,6)=0 -> TRUE | H17: =ROUND(D17-F17,6)=0 -> TRUE
A18: Reorder triggered (1/0) | B18: =Replenishment!B8 -> 1 | C18: =Replenishment!C8 -> 1 | D18: =Replenishment!D8 -> 0 | E18: 1 | F18: 0 | G18: =C18=E18 -> TRUE | H18: =D18=F18 -> TRUE
A20: every golden and position_80 figure matches | B20: =AND(G8:G18,H8:H18) -> TRUE
A21: chain 40 / 30 / 10 / 60 / 60 / 60 / 72 (golden) read off column C | B21: =C8&" / "&C9&" / "&C10&" / "&C11&" / "&C14&" / "&C15&" / "&C16 -> 40 / 30 / 10 / 60 / 60 / 60 / 72

Sheet Assumptions
A1: Assumptions: contract decisions D-01..D-06 and the workbook's own limits
A3: ID | B3: Statement
A4: D-01 | B4: Ledger, day order and as-of stock: stock = sum of posted deltas up to the cutoff; inside a date receipts, then demand, then review; negative reconstruction flagged NEGATIVE_STOCK and valued at 0; position = on hand + confirmed on order - backorders, reserved not subtracted (docs/contracts.md).
A5: D-02 | B5: Replenishment: order = pack_round_up(max(target - position, MOQ)) when position < reorder point, else 0. Golden: 40 / 30 / 10 -> 60; ROP 70, target 120 -> raw 60; MOQ 50, pack 24 -> 72; position 80 -> 0.
A6: D-03 | B6: Demand and forecasts: observed sales are censored during stockouts, latent demand is published separately; baselines first; a forecast may use only information known at its cutoff. Not computed in this workbook (queries 05 and 07).
A7: D-04 | B7: Receipts, suppliers, unmet demand: a receipt before its order is rejected; a partial receipt leaves the line open; on-time rate uses receipts dated up to the cutoff; a backorder or a lost sale, never both.
A8: D-05 | B8: Simulation and valuation: working capital = sum on hand x unit cost at the cost in force. The golden fixture has one cost and no cost_versions, so on hand x 12.50 = 500.00.
A9: D-06 | B9: Fixture-driven clarifications: requested = fulfilled + backorders opened in the window; a stockout day is a date on which a backorder opened; raw, MOQ and pack quantities are 0 when not triggered.
A10: W-01 | B10: Scope: one SKU, one location, one supplier, the golden fixture. Fill rate, stockout days, supplier reliability and forecast accuracy are done by the SQL and Python implementations (docs/sql-analysis.md), not by these formulas.
A11: W-02 | B11: Instants are Excel date serials (UTC, no zone). Sort keys use SUMPRODUCT over serials, not string-built criteria, so a time such as 08:00 compares exactly.
A12: W-03 | B12: State switch: Figures!B3 = 1 selects the position_80 state (adds the fixture's second line pol-002, 20 units). The column 'state_added' on Inputs is not a fixture field, it records which state adds the line.
A13: W-04 | B13: Recalculation: openpyxl writes formulas only. The delivered file was recalculated by LibreOffice headless and carries its cached values; Excel was NOT run (docs/workbook.md). fullCalcOnLoad is set so Excel recalculates on open.
A14: W-05 | B14: Snapshot summary is a paste of the stored results of data/sql/analysis/run_all.py and goes stale if the data or the queries change; its dataset hash is in the header. The synthetic snapshot is not evidence about a real business.

Sheet Snapshot summary
A1: PASTED VALUES (not formulas) from data/sql/analysis/run_all.py; each section is titled with its query file
A2: SYNTHETIC. Dataset ss-20261026-20261026, generator dataset_hash 5bdabb50eea4b192e3b17e1e5b1a79dc6b26feb4a2b8b78ad094acde9f8bcc8c, contract v1; database seeded through the domain's validate_batch (4 rows rejected and kept in rejected_records).
A4: 01_stock_position_month_end_by_location.sql
A5: month | B5: location_id | C5: on_hand | D5: on_order | E5: backorders | F5: position | G5: on_order_confirmed_only | H5: pct_of_capacity | I5: negative_pairs
A6: 2025-04 | B6: loc-01 | C6: 378 | D6: 420 | E6: 0 | F6: 798 | G6: 0 | H6: 41 | I6: 0
A7: 2025-04 | B7: loc-02 | C7: 228 | D7: 314 | E7: 0 | F7: 542 | G7: 0 | H7: 96.6 | I7: 0
A8: 2025-04 | B8: loc-03 | C8: 214 | D8: 140 | E8: 0 | F8: 354 | G8: 0 | H8: 38.5 | I8: 0
A9: 2025-05 | B9: loc-01 | C9: 426 | D9: 340 | E9: 0 | F9: 766 | G9: 0 | H9: 39.4 | I9: 0
A10: 2025-05 | B10: loc-02 | C10: 173 | D10: 348 | E10: 0 | F10: 521 | G10: 0 | H10: 92.9 | I10: 0
A11: 2025-05 | B11: loc-03 | C11: 212 | D11: 120 | E11: 0 | F11: 332 | G11: 0 | H11: 36.1 | I11: 0
A12: 2025-06 | B12: loc-01 | C12: 347 | D12: 498 | E12: 0 | F12: 845 | G12: 0 | H12: 43.5 | I12: 0
A13: 2025-06 | B13: loc-02 | C13: 200 | D13: 342 | E13: 0 | F13: 542 | G13: 0 | H13: 96.6 | I13: 0
A14: 2025-06 | B14: loc-03 | C14: 233 | D14: 108 | E14: 0 | F14: 341 | G14: 0 | H14: 37.1 | I14: 0
A15: 2025-07 | B15: loc-01 | C15: 484 | D15: 288 | E15: 0 | F15: 772 | G15: 0 | H15: 39.7 | I15: 0
A16: 2025-07 | B16: loc-02 | C16: 228 | D16: 296 | E16: 0 | F16: 524 | G16: 0 | H16: 93.4 | I16: 0
A17: 2025-07 | B17: loc-03 | C17: 135 | D17: 232 | E17: 1 | F17: 366 | G17: 0 | H17: 39.9 | I17: 0
... A59: 2026-09 | B59: loc-03 | C59: 270 | D59: 60 | E59: 0 | F59: 330 | G59: 24 | H59: 35.9 | I59: 0
A62: 02_draft_orders_arithmetic.sql
A63: product_id | B63: location_id | C63: abc_class | D63: supplier_id | E63: on_hand | F63: on_order | G63: backorders | H63: position | I63: reorder_point | J63: target_position | K63: raw_order | L63: moq | M63: after_moq | N63: pack_size | O63: order_qty | P63: unit_cost | Q63: order_value
A64: prod-002 | B64: loc-02 | C64: A | D64: sup-02 | E64: 70 | F64: 48 | G64: 0 | H64: 118 | I64: 128 | J64: 252 | K64: 134 | L64: 24 | M64: 134 | N64: 12 | O64: 144 | P64: 41.74 | Q64: 6010.56
A65: prod-005 | B65: loc-02 | C65: A | D65: sup-01 | E65: 0 | F65: 48 | G65: 0 | H65: 48 | I65: 51 | J65: 144 | K65: 96 | L65: 24 | M65: 96 | N65: 12 | O65: 96 | P65: 53.17 | Q65: 5104.32
A66: TOTAL (2 of 60 triggered) | E66: 1020 | F66: 608 | G66: 0 | H66: 1628 | I66: 1198 | J66: 2336 | K66: 230 | M66: 230 | O66: 240 | Q66: 11114.88
A69: 03_fill_rate_stockout_by_location_abc.sql
A70: location_id | B70: abc_class | C70: pairs | D70: fulfilled_units | E70: unmet_units | F70: requested_units | G70: fill_rate | H70: stockout_pair_days | I70: stockout_pair_day_share
A71: loc-01 | B71: A | C71: 3 | D71: 10983 | E71: 425 | F71: 11408 | G71: 0.962745 | H71: 42 | I71: 0.025547
A72: loc-01 | B72: B | C72: 10 | D72: 2353 | E72: 69 | F72: 2422 | G72: 0.971511 | H72: 54 | I72: 0.009854
A73: loc-01 | B73: C | C73: 16 | D73: 1402 | E73: 46 | F73: 1448 | G73: 0.968232 | H73: 32 | I73: 0.00365
A74: loc-01 | B74: ALL | C74: 29 | D74: 14738 | E74: 540 | F74: 15278 | G74: 0.964655 | H74: 128 | I74: 0.008054
A75: loc-02 | B75: A | C75: 3 | D75: 12087 | E75: 1682 | F75: 13769 | G75: 0.877842 | H75: 205 | I75: 0.124696
A76: loc-02 | B76: B | C76: 3 | D76: 679 | E76: 18 | F76: 697 | G76: 0.974175 | H76: 15 | I76: 0.009124
A77: loc-02 | B77: C | C77: 11 | D77: 862 | E77: 14 | F77: 876 | G77: 0.984018 | H77: 13 | I77: 0.002157
A78: loc-02 | B78: ALL | C78: 17 | D78: 13628 | E78: 1714 | F78: 15342 | G78: 0.888281 | H78: 233 | I78: 0.025011
A79: loc-03 | B79: A | C79: 2 | D79: 6120 | E79: 316 | F79: 6436 | G79: 0.950901 | H79: 47 | I79: 0.042883
A80: loc-03 | B80: B | C80: 3 | D80: 771 | E80: 28 | F80: 799 | G80: 0.964956 | H80: 13 | I80: 0.007908
A81: loc-03 | B81: C | C81: 9 | D81: 819 | E81: 14 | F81: 833 | G81: 0.983193 | H81: 10 | I81: 0.002028
A82: loc-03 | B82: ALL | C82: 14 | D82: 7710 | E82: 358 | F82: 8068 | G82: 0.955627 | H82: 70 | I82: 0.009124
A83: ALL | B83: ALL | C83: 60 | D83: 36076 | E83: 2612 | F83: 38688 | G83: 0.932486 | H83: 431 | I83: 0.013108
A86: 04_supplier_on_time_by_month.sql
A87: supplier_id | B87: month | C87: eligible_receipts | D87: on_time_receipts | E87: on_time_rate | F87: cum_eligible | G87: cum_on_time_rate | H87: overdue_open_lines
A88: sup-01 | B88: 2025-04 | C88: 23 | D88: 20 | E88: 0.869565 | F88: 23 | G88: 0.869565 | H88: 0
...
