Workbook

Sheet Inputs
A1: Inputs: the golden fixture rows (tests/fixtures/golden/inputs.json, fixture onboard-studio-golden-v1)
A2: SYNTHETIC. Every cell below is a typed input copied from the fixture (blue). Instants are UTC, shown as yyyy-mm-dd hh:mm. Contract v1, docs/contracts.md.
A4: organizations
A5: organization_id | B5: organization_name | C5: segment | D5: region | E5: created_at
A6: org-001 | B6: Synthetic Holdings Ltd | C6: smb | D6: emea | E6: 46054
A8: workflow_versions
A9: workflow_version_id | B9: template_id | C9: version_number | D9: published_at | E9: definition_hash
A10: wfv-001 | B10: tpl-001 | C10: 1 | D10: 46082 | E10: 3a4701f5d9e983fc4fa4643cd871ea03b5dd0d4bbaef4390a50545cfe4443bec
A12: step_definitions
A13: step_definition_id | B13: workflow_version_id | C13: step_name | D13: required | E13: role_key | F13: sequence
A14: sd-001 | B14: wfv-001 | C14: collect_documents | D14: true | E14: ops | F14: 1
A15: sd-002 | B15: wfv-001 | C15: approve_account | D15: true | E15: reviewer | F15: 2
A17: dependencies
A18: dependency_id | B18: step_definition_id | C18: prerequisite_id | D18: dependency_type | E18: created_at
A19: dep-001 | B19: sd-002 | C19: sd-001 | D19: mandatory | E19: 46082
A21: sla_rules
A22: sla_rule_id | B22: workflow_version_id | C22: business_minutes | D22: pause_policy | E22: calendar_id
A23: sla-001 | B23: wfv-001 | C23: 480 | D23: customer_info_requested | E23: cal-001
A25: calendar_intervals
A26: calendar_interval_id | B26: calendar_id | C26: starts_at | D26: ends_at | E26: timezone
A27: ci-001 | B27: cal-001 | C27: 46083.375 | D27: 46083.708 | E27: UTC
A28: ci-002 | B28: cal-001 | C28: 46084.375 | D28: 46084.708 | E28: UTC
A29: ci-003 | B29: cal-001 | C29: 46085.375 | D29: 46085.708 | E29: UTC
A30: ci-004 | B30: cal-001 | C30: 46086.375 | D30: 46086.708 | E30: UTC
A31: ci-005 | B31: cal-001 | C31: 46087.375 | D31: 46087.708 | E31: UTC
A32: ci-006 | B32: cal-001 | C32: 46090.375 | D32: 46090.708 | E32: UTC
A33: ci-007 | B33: cal-001 | C33: 46091.375 | D33: 46091.708 | E33: UTC
A34: ci-008 | B34: cal-001 | C34: 46092.375 | D34: 46092.708 | E34: UTC
A35: ci-009 | B35: cal-001 | C35: 46093.375 | D35: 46093.708 | E35: UTC
A36: ci-010 | B36: cal-001 | C36: 46094.375 | D36: 46094.708 | E36: UTC
A38: cases
A39: case_id | B39: organization_id | C39: workflow_version_id | D39: status | E39: opened_at | F39: completed_at
A40: case-001 | B40: org-001 | C40: wfv-001 | D40: completed | E40: 46087.667 | F40: 46090.417
A42: step_instances
A43: step_instance_id | B43: case_id | C43: step_definition_id | D43: status | E43: version_number | F43: ready_at | G43: started_at | H43: approved_at
A44: si-001 | B44: case-001 | C44: sd-001 | D44: approved | E44: 1 | F44: 46087.667 | G44: 46087.67 | H44: 46090.403
A45: si-002 | B45: case-001 | C45: sd-002 | D45: approved | E45: 1 | F45: 46090.403 | G45: 46090.406 | H45: 46090.417
A47: assignments
A48: assignment_id | B48: step_instance_id | C48: assignee_id | D48: assigned_at | E48: ended_at
A49: asg-001 | B49: si-001 | C49: ops-001 | D49: 46087.667 | E49: 46090.403
...

Sheet Calendar
A1: Calendar: working intervals of cal-001 (half-open [starts_at, ends_at); contract D-01)
A2: Live links to Inputs (calendar_intervals). `kind` is typed: the fixture rows carry none and D-06 defaults it to 'working'. No holidays in the fixture.
A4: calendar_interval_id | B4: calendar_id | C4: starts_at (UTC) | D4: ends_at (UTC) | E4: kind | F4: hours (formula)
A5: =Inputs!$A$27 -> ci-001 | B5: =Inputs!$B$27 -> cal-001 | C5: =Inputs!$C$27 -> 46083.375 | D5: =Inputs!$D$27 -> 46083.708 | E5: working | F5: =ROUND((D5-C5)*24,6) -> 8
A6: =Inputs!$A$28 -> ci-002 | B6: =Inputs!$B$28 -> cal-001 | C6: =Inputs!$C$28 -> 46084.375 | D6: =Inputs!$D$28 -> 46084.708 | E6: working | F6: =ROUND((D6-C6)*24,6) -> 8
A7: =Inputs!$A$29 -> ci-003 | B7: =Inputs!$B$29 -> cal-001 | C7: =Inputs!$C$29 -> 46085.375 | D7: =Inputs!$D$29 -> 46085.708 | E7: working | F7: =ROUND((D7-C7)*24,6) -> 8
A8: =Inputs!$A$30 -> ci-004 | B8: =Inputs!$B$30 -> cal-001 | C8: =Inputs!$C$30 -> 46086.375 | D8: =Inputs!$D$30 -> 46086.708 | E8: working | F8: =ROUND((D8-C8)*24,6) -> 8
A9: =Inputs!$A$31 -> ci-005 | B9: =Inputs!$B$31 -> cal-001 | C9: =Inputs!$C$31 -> 46087.375 | D9: =Inputs!$D$31 -> 46087.708 | E9: working | F9: =ROUND((D9-C9)*24,6) -> 8
A10: =Inputs!$A$32 -> ci-006 | B10: =Inputs!$B$32 -> cal-001 | C10: =Inputs!$C$32 -> 46090.375 | D10: =Inputs!$D$32 -> 46090.708 | E10: working | F10: =ROUND((D10-C10)*24,6) -> 8
A11: =Inputs!$A$33 -> ci-007 | B11: =Inputs!$B$33 -> cal-001 | C11: =Inputs!$C$33 -> 46091.375 | D11: =Inputs!$D$33 -> 46091.708 | E11: working | F11: =ROUND((D11-C11)*24,6) -> 8
A12: =Inputs!$A$34 -> ci-008 | B12: =Inputs!$B$34 -> cal-001 | C12: =Inputs!$C$34 -> 46092.375 | D12: =Inputs!$D$34 -> 46092.708 | E12: working | F12: =ROUND((D12-C12)*24,6) -> 8
A13: =Inputs!$A$35 -> ci-009 | B13: =Inputs!$B$35 -> cal-001 | C13: =Inputs!$C$35 -> 46093.375 | D13: =Inputs!$D$35 -> 46093.708 | E13: working | F13: =ROUND((D13-C13)*24,6) -> 8
A14: =Inputs!$A$36 -> ci-010 | B14: =Inputs!$B$36 -> cal-001 | C14: =Inputs!$C$36 -> 46094.375 | D14: =Inputs!$D$36 -> 46094.708 | E14: working | F14: =ROUND((D14-C14)*24,6) -> 8
E15: working hours in the calendar | F15: =ROUND(SUMIF(E5:E14,"working",F5:F14),4) -> 80

Sheet Overlap
A1: Overlap: the interval-overlap arithmetic as live formulas (docs/contracts.md D-01; golden P02-GOLD-01)
A2: overlap(range, working interval) = MAX(0, MIN(range_end, interval_end) - MAX(range_start, interval_start)) in hours. Intervals that are not 'working' contribute 0.
A4: Case span | D4: Waiting interval clipped to the case span (D-06)
A5: case_id | B5: =Inputs!$A$40 -> case-001 | D5: waiting_interval_id | E5: =Inputs!$A$63 -> wi-001
A6: opened_at | B6: =Inputs!$E$40 -> 46087.667 | D6: reason_code | E6: =Inputs!$C$63 -> customer_info_requested
A7: completed_at | B7: =Inputs!$F$40 -> 46090.417 | D7: clipped start | E7: =MAX(Inputs!$D$63,B6) -> 46087.688
D8: clipped end | E8: =MIN(Inputs!$E$63,B7) -> 46090.396
A10: calendar_interval_id | B10: kind | C10: starts_at (UTC) | D10: ends_at (UTC) | E10: case overlap (h) | F10: waiting overlap (h)
A11: =Calendar!A5 -> ci-001 | B11: =Calendar!E5 -> working | C11: =Calendar!C5 -> 46083.375 | D11: =Calendar!D5 -> 46083.708 | E11: =IF(B11="working",ROUND(MAX(0,MIN($B$7,D11)-MAX($B$6,C11))*24,6),0) -> 0 | F11: =IF(B11="working",ROUND(MAX(0,MIN($E$8,D11)-MAX($E$7,C11))*24,6),0) -> 0
A12: =Calendar!A6 -> ci-002 | B12: =Calendar!E6 -> working | C12: =Calendar!C6 -> 46084.375 | D12: =Calendar!D6 -> 46084.708 | E12: =IF(B12="working",ROUND(MAX(0,MIN($B$7,D12)-MAX($B$6,C12))*24,6),0) -> 0 | F12: =IF(B12="working",ROUND(MAX(0,MIN($E$8,D12)-MAX($E$7,C12))*24,6),0) -> 0
A13: =Calendar!A7 -> ci-003 | B13: =Calendar!E7 -> working | C13: =Calendar!C7 -> 46085.375 | D13: =Calendar!D7 -> 46085.708 | E13: =IF(B13="working",ROUND(MAX(0,MIN($B$7,D13)-MAX($B$6,C13))*24,6),0) -> 0 | F13: =IF(B13="working",ROUND(MAX(0,MIN($E$8,D13)-MAX($E$7,C13))*24,6),0) -> 0
A14: =Calendar!A8 -> ci-004 | B14: =Calendar!E8 -> working | C14: =Calendar!C8 -> 46086.375 | D14: =Calendar!D8 -> 46086.708 | E14: =IF(B14="working",ROUND(MAX(0,MIN($B$7,D14)-MAX($B$6,C14))*24,6),0) -> 0 | F14: =IF(B14="working",ROUND(MAX(0,MIN($E$8,D14)-MAX($E$7,C14))*24,6),0) -> 0
A15: =Calendar!A9 -> ci-005 | B15: =Calendar!E9 -> working | C15: =Calendar!C9 -> 46087.375 | D15: =Calendar!D9 -> 46087.708 | E15: =IF(B15="working",ROUND(MAX(0,MIN($B$7,D15)-MAX($B$6,C15))*24,6),0) -> 1 | F15: =IF(B15="working",ROUND(MAX(0,MIN($E$8,D15)-MAX($E$7,C15))*24,6),0) -> 0.5
A16: =Calendar!A10 -> ci-006 | B16: =Calendar!E10 -> working | C16: =Calendar!C10 -> 46090.375 | D16: =Calendar!D10 -> 46090.708 | E16: =IF(B16="working",ROUND(MAX(0,MIN($B$7,D16)-MAX($B$6,C16))*24,6),0) -> 1 | F16: =IF(B16="working",ROUND(MAX(0,MIN($E$8,D16)-MAX($E$7,C16))*24,6),0) -> 0.5
A17: =Calendar!A11 -> ci-007 | B17: =Calendar!E11 -> working | C17: =Calendar!C11 -> 46091.375 | D17: =Calendar!D11 -> 46091.708 | E17: =IF(B17="working",ROUND(MAX(0,MIN($B$7,D17)-MAX($B$6,C17))*24,6),0) -> 0 | F17: =IF(B17="working",ROUND(MAX(0,MIN($E$8,D17)-MAX($E$7,C17))*24,6),0) -> 0
A18: =Calendar!A12 -> ci-008 | B18: =Calendar!E12 -> working | C18: =Calendar!C12 -> 46092.375 | D18: =Calendar!D12 -> 46092.708 | E18: =IF(B18="working",ROUND(MAX(0,MIN($B$7,D18)-MAX($B$6,C18))*24,6),0) -> 0 | F18: =IF(B18="working",ROUND(MAX(0,MIN($E$8,D18)-MAX($E$7,C18))*24,6),0) -> 0
A19: =Calendar!A13 -> ci-009 | B19: =Calendar!E13 -> working | C19: =Calendar!C13 -> 46093.375 | D19: =Calendar!D13 -> 46093.708 | E19: =IF(B19="working",ROUND(MAX(0,MIN($B$7,D19)-MAX($B$6,C19))*24,6),0) -> 0 | F19: =IF(B19="working",ROUND(MAX(0,MIN($E$8,D19)-MAX($E$7,C19))*24,6),0) -> 0
A20: =Calendar!A14 -> ci-010 | B20: =Calendar!E14 -> working | C20: =Calendar!C14 -> 46094.375 | D20: =Calendar!D14 -> 46094.708 | E20: =IF(B20="working",ROUND(MAX(0,MIN($B$7,D20)-MAX($B$6,C20))*24,6),0) -> 0 | F20: =IF(B20="working",ROUND(MAX(0,MIN($E$8,D20)-MAX($E$7,C20))*24,6),0) -> 0
A21: TOTAL business hours | E21: =ROUND(SUM(E11:E20),4) -> 2 | F21: =ROUND(SUM(F11:F20),4) -> 1
A22: working intervals touched | E22: =COUNTIF(E11:E20,">0") -> 2 | F22: =COUNTIF(F11:F20,">0") -> 2
A24: Reading: E = business cycle time (expected 2.0000: Fri 16:00-17:00 + Mon 09:00-10:00). F = business overlap of the waiting interval (expected 1.0000: Fri 16:30-17:00 + Mon 09:00-09:30).

Sheet Figures
A1: Figures: the golden case's durations from the Overlap formulas (contract D-01, D-04, D-05)
A2: Change B3 to see the effect of the pause policy: 1 = the waiting reason is pause-eligible, 0 = it is not. Columns C and D evaluate both states at once.
A3: Pause-eligible switch (1 / 0) | B3: 1
A4: Policy check (formula) | B4: =IF(ISNUMBER(SEARCH(Inputs!$C$63,Inputs!$D$23)),1,0) -> 1 | C4: <- 1 when the SLA rule's pause_policy in Inputs lists the waiting reason
A6: Quantity (hours unless stated) | B6: Selected state (switch B3) | C6: State A: pause-eligible | D6: State B: not eligible | E6: Expected A (expected.json) | F6: Expected B (expected.json) | G6: A matches | H6: B matches
A7: switch used in the column | B7: =$B$3 -> 1 | C7: 1 | D7: 0
A8: Calendar cycle time | B8: =ROUND((Inputs!$F$40-Inputs!$E$40)*24,4) -> 66 | C8: =ROUND((Inputs!$F$40-Inputs!$E$40)*24,4) -> 66 | D8: =ROUND((Inputs!$F$40-Inputs!$E$40)*24,4) -> 66 | E8: 66 | F8: 66 | G8: =ABS(C8-E8)<0.00005 -> TRUE | H8: =ABS(D8-F8)<0.00005 -> TRUE
A9: Business cycle time | B9: =Overlap!$E$21 -> 2 | C9: =Overlap!$E$21 -> 2 | D9: =Overlap!$E$21 -> 2 | E9: 2 | F9: 2 | G9: =ABS(C9-E9)<0.00005 -> TRUE | H9: =ABS(D9-F9)<0.00005 -> TRUE
A10: Paused time (calendar) | B10: =IF(B$7=1,ROUND(MAX(0,Overlap!$E$8-Overlap!$E$7)*24,4),0) -> 65 | C10: =IF(C$7=1,ROUND(MAX(0,Overlap!$E$8-Overlap!$E$7)*24,4),0) -> 65 | D10: =IF(D$7=1,ROUND(MAX(0,Overlap!$E$8-Overlap!$E$7)*24,4),0) -> 0 | E10: 65 | F10: 0 | G10: =ABS(C10-E10)<0.00005 -> TRUE | H10: =ABS(D10-F10)<0.00005 -> TRUE
A11: Paused business overlap | B11: =IF(B$7=1,Overlap!$F$21,0) -> 1 | C11: =IF(C$7=1,Overlap!$F$21,0) -> 1 | D11: =IF(D$7=1,Overlap!$F$21,0) -> 0 | E11: 1 | F11: 0 | G11: =ABS(C11-E11)<0.00005 -> TRUE | H11: =ABS(D11-F11)<0.00005 -> TRUE
A12: Active elapsed time | B12: =ROUND(MAX(0,B9-B11),4) -> 1 | C12: =ROUND(MAX(0,C9-C11),4) -> 1 | D12: =ROUND(MAX(0,D9-D11),4) -> 2 | E12: 1 | F12: 2 | G12: =ABS(C12-E12)<0.00005 -> TRUE | H12: =ABS(D12-F12)<0.00005 -> TRUE
A13: SLA business minutes (sla_rules) | B13: =Inputs!$C$23 -> 480 | C13: =Inputs!$C$23 -> 480 | D13: =Inputs!$C$23 -> 480
A14: Active minutes (active hours x 60) | B14: =ROUND(B12*60,2) -> 60 | C14: =ROUND(C12*60,2) -> 60 | D14: =ROUND(D12*60,2) -> 120
A15: SLA met (active minutes <= SLA minutes) | B15: =IF(B14<=B13,"met","missed") -> met | C15: =IF(C14<=C13,"met","missed") -> met | D15: =IF(D14<=D13,"met","missed") -> met
A16: SLA attainment (met / completed eligible, 1 case) | B16: =IF(B15="met",1,0)/1 -> 1 | C16: =IF(C15="met",1,0)/1 -> 1 | D16: =IF(D15="met",1,0)/1 -> 1 | E16: 1 | F16: 1 | G16: =ABS(C16-E16)<0.0000005 -> TRUE | H16: =ABS(D16-F16)<0.0000005 -> TRUE
A18: All checks (A and B) pass | B18: =AND(G8:H12,G16:H16) -> TRUE
A20: Why 66 / 2 / 65 / 1: calendar = Fri 16:00 -> Mon 10:00 on the wall clock; business keeps only the working intervals (Fri 16:00-17:00, Mon 09:00-10:00); the waiting interval Fri 16:30 -> Mon 09:30 is 65 h of wall clock and 1 h of working time, so active = 2 - 1 = 1 when its reason is pause-eligible and 2 when not.

Sheet Assumptions
A1: Assumptions: contract decisions D-01..D-06 and the workbook's own limits
A3: ID | B3: Statement
A4: D-01 | B4: Time, calendars and intervals. UTC instants; calendar = Monday-Friday 09:00-17:00 UTC with no holidays in the fixture; durations in hours at 4 decimals; calendar cycle = completed - opened; business cycle = sum of overlap with working intervals; paused = waiting intervals whose reason is in the SLA rule's pause_policy; active = business - business overlap of eligible pauses; customer waiting is never counted as employee processing.
A5: D-02 | B5: Workflow versions and cases. A published version is immutable and a case keeps the version it was created with. The workbook uses the single version wfv-001 of the golden fixture.
A6: D-03 | B6: Steps, documents, approvals. Documents are append-only; approval needs an independent reviewer of the step's role; completion needs every required step approved and every required document accepted. Not modelled in the workbook (the fixture satisfies them).
A7: D-04 | B7: Rates and backlog. SLA attainment = completed eligible cases within SLA / completed eligible cases; open cases are shown beside it. The workbook has one completed case, so attainment is 0 or 1.
A8: D-05 | B8: Fixture-driven clarifications. SLA test: active hours x 60 <= business minutes; step waiting = started_at - ready_at in business hours; population durations are means over accepted completed cases.
A9: D-06 | B9: Schema clarifications. calendar_intervals.kind in {working, holiday} (default working); waiting intervals are clipped to the case span and merged before deduction; active hours floor at 0. The Overlap sheet clips the waiting interval but has one interval, so no merge is needed.
A10: W-01 | B10: Workbook limit: one case, one waiting interval, no holidays. Holiday subtraction and merging of overlapping waits are done by the SQL and Python implementations (docs/sql-analysis.md), not by these formulas.
A11: W-02 | B11: Workbook limit: instants are stored as Excel date serials (UTC, no zone). Each overlap row is ROUND(...,6) hours to remove binary floating-point noise (1 s = 0.000278 h, so 6 decimals cannot hide a real second); totals are ROUND(...,4).
A12: W-03 | B12: Recalculation: openpyxl writes formulas only. The delivered file was recalculated by LibreOffice headless and carries its cached values; Excel was NOT run (see docs/workbook.md). fullCalcOnLoad is set so Excel recalculates on open.
A13: W-04 | B13: Snapshot summary is a paste of the output of data/sql/analysis/run_all.py (artifacts/analysis-results.json) and goes stale if the data changes.

Sheet Snapshot summary
A1: PASTED VALUES (not formulas) from data/sql/analysis/run_all.py; each section is titled with its query file
A2: SYNTHETIC. Dataset os-20261026-20261026, generator dataset_hash 3c20d296bcf178065e9178cae04f763994b4d7197026af2c021ab55b4cc2bc6a, contract v1; database seeded through the domain's validate_batch (733 of 740 cases accepted; 269 rejected rows kept).
A4: 01_cycle_time_by_opening_month.sql
A5: period | B5: completed_cases | C5: calendar_h | D5: business_h | E5: cal_to_bus | F5: active_h
A6: 2025-04 | B6: 48 | C6: 79.3858 | D6: 19.5469 | E6: 4.06 | F6: 9.133
A7: 2025-05 | B7: 43 | C7: 100.6601 | D7: 22.2647 | E7: 4.52 | F7: 9.4512
A8: 2025-06 | B8: 42 | C8: 82.3552 | D8: 18.8683 | E8: 4.36 | F8: 8.923
A9: 2025-07 | B9: 43 | C9: 89.8244 | D9: 22.1333 | E9: 4.06 | F9: 9.674
A10: 2025-08 | B10: 36 | C10: 78.3065 | D10: 17.3954 | E10: 4.5 | F10: 8.8218
A11: 2025-09 | B11: 40 | C11: 88.0121 | D11: 20.2433 | E11: 4.35 | F11: 9.2867
A12: 2025-10 | B12: 34 | C12: 79.4838 | D12: 18.3074 | E12: 4.34 | F12: 6.5716
A13: 2025-11 | B13: 35 | C13: 76.8433 | D13: 17.2624 | E13: 4.45 | F13: 7.0233
A14: 2025-12 | B14: 40 | C14: 74.5975 | D14: 17.1975 | E14: 4.34 | F14: 6.56
A15: 2026-01 | B15: 43 | C15: 85.3535 | D15: 18.4484 | E15: 4.63 | F15: 7.2535
A16: 2026-02 | B16: 32 | C16: 66.876 | D16: 16.3729 | E16: 4.08 | F16: 6.9604
A17: 2026-03 | B17: 40 | C17: 73.6108 | D17: 17.0958 | E17: 4.31 | F17: 7.3067
... A24: TOTAL | B24: 712 | C24: 79.9529 | D24: 18.5028 | E24: 4.32 | F24: 7.902
A27: 02_version_comparison_comparable_window.sql
A28: window | B28: version | C28: completed_cases | D28: open_cases | E28: business_h | F28: paused_business_h | G28: active_h | H28: active_sd_h | I28: handoffs_per_case | J28: sla_attainment | K28: sla_if_no_pause | L28: rework_rate | M28: first_pass_rate | N28: pct_enterprise | O28: pct_reg_north
A29: all (2025-04..2026-09) | B29: wfv-001 | C29: 430 | D29: 13 | E29: 19.5686 | F29: 10.3334 | G29: 9.2352 | H29: 1.7442 | I29: 1.1093 | J29: 0.260465 | K29: 0.074419 | L29: 0.180995 | M29: 0.920849 | N29: 24.7 | O29: 22.1
A30: all (2025-04..2026-09) | B30: wfv-002 | C30: 282 | D30: 8 | E30: 16.8776 | F30: 11.0086 | G30: 5.869 | H30: 1.2797 | I30: 0.8865 | J30: 0.950355 | K30: 0.29078 | L30: 0.193772 | M30: 0.941718 | N30: 18.4 | O30: 21.6
A31: overlap (2025-10..2026-09) | B31: wfv-001 | C31: 178 | D31: 10 | E31: 18.7568 | F31: 9.5066 | G31: 9.2503 | H31: 1.7311 | I31: 1.2135 | J31: 0.258427 | K31: 0.05618 | L31: 0.160428 | M31: 0.933036 | N31: 20.2 | O31: 22.5
A32: overlap (2025-10..2026-09) | B32: wfv-002 | C32: 282 | D32: 8 | E32: 16.8776 | F32: 11.0086 | G32: 5.869 | H32: 1.2797 | I32: 0.8865 | J32: 0.950355 | K32: 0.29078 | L32: 0.193772 | M32: 0.941718 | N32: 18.4 | O32: 21.6
A35: 03_sla_by_segment_region.sql
A36: segment | B36: region | C36: completed_cases | D36: within_sla | E36: sla_attainment | F36: open_cases_not_in_rate | G36: active_h | H36: pct_v2
A37: enterprise | B37: reg-east | C37: 50 | D37: 25 | E37: 0.5 | F37: 2 | G37: 8.028 | H37: 34
A38: enterprise | B38: reg-north | C38: 29 | D38: 15 | E38: 0.517241 | F38: 1 | G38: 8.1408 | H38: 37.9
A39: enterprise | B39: reg-south | C39: 43 | D39: 20 | E39: 0.465116 | F39: 1 | G39: 8.3554 | H39: 30.2
A40: enterprise | B40: reg-west | C40: 36 | D40: 19 | E40: 0.527778 | F40: 0 | G40: 7.9074 | H40: 30.6
A41: enterprise | B41: ALL | C41: 158 | D41: 79 | E41: 0.5 | F41: 4 | G41: 8.1103 | H41: 32.9
A42: mid_market | B42: reg-east | C42: 64 | D42: 38 | E42: 0.59375 | F42: 1 | G42: 7.6661 | H42: 46.9
A43: mid_market | B43: reg-north | C43: 61 | D43: 25 | E43: 0.409836 | F43: 1 | G43: 8.15 | H43: 31.1
A44: mid_market | B44: reg-south | C44: 66 | D44: 32 | E44: 0.484848 | F44: 3 | G44: 8.3442 | H44: 37.9
A45: mid_market | B45: reg-west | C45: 71 | D45: 40 | E45: 0.56338 | F45: 0 | G45: 7.6885 | H45: 45.1
A46: mid_market | B46: ALL | C46: 262 | D46: 135 | E46: 0.515267 | F46: 5 | G46: 7.9557 | H46: 40.5
A47: smb | B47: reg-east | C47: 81 | D47: 48 | E47: 0.592593 | F47: 5 | G47: 7.6617 | H47: 45.7
A48: smb | B48: reg-north | C48: 66 | D48: 45 | E48: 0.681818 | F48: 3 | G48: 7.2793 | H48: 47
... A56: ALL | B56: ALL | C56: 712 | D56: 380 | E56: 0.533708 | F56: 21 | G56: 7.902 | H56: 39.6
A59: 04_step_waiting_by_step_assignee.sql
A60: lens | B60: step_name | C60: who | D60: step_instances | E60: wait_bh | F60: started_to_decision_bh | G60: started_to_decision_cal_h
...
