Workbook

Sheet Read me
A1: RetentionLab analyst workbook (P10-ART-05)
A3: What it is | B3: A formula-driven recomputation of the RetentionLab evaluation over the published synthetic snapshot rl-20261026-20261026 (dataset hash 9ebaaadab8a2f70e5f25820616391ee0aec55fbf0b121dee25460de469821b1c, code revision ce96e65, as-of 2026-10-05T00:00:00Z): the 1,513-row held-out test table of the full 2,400-account world, the 200-account cohort and its 97-account 2026-09-01 queue.
A4: The decision | B4: Which accounts deserve limited retention attention under uncertain intervention value? The workbook shows how well four models rank and score the held-out rows (the margin of the logistic model over its baselines is met by construction), how well calibrated the probabilities are, what a capacity of 5, 10 or 20 gets, what the censored tail hides, where the population drifts, and what a HYPOTHETICAL contact programme would be worth under stated assumptions.
A5: Synthetic data | B5: Everything is synthetic (a seeded generator). Simulated = what this one draw shows; hypothetical = an assumption-based value (the expected intervention value); no retention improvement is claimed and the ranking by risk is not a treatment effect.
A6: How to use it | B6: Open the .xlsx in any spreadsheet application. Controls!B3 selects the model, B5 a scenario, B11:B14 a what-if; Checks!B2 is TRUE when every figure agrees with the SQL/Python results and the golden hand answer. Nothing needs installing to read the cached values.
A7: Recalculation status | B7: openpyxl wrote formulas only; LibreOffice (headless) recalculated the delivered file. Microsoft Excel was NOT run: nothing here was opened or recalculated by Excel (docs/workbook.md).
A8: Sheets | B8: Controls, Checks, Models, Calibration, Capacity, Economics, Censored tail, Drift, Purge, Golden case, Assumptions, Scenarios, Test table (the 1,513 rows with the live per-row columns), SQL results (pasted).
A9: Colour | B9: Blue = typed input or pasted value; black = formula.

Sheet Controls
A1: Controls
A2: Change B3 (the model whose block Capacity shows), B5 (a scenario) and the what-if inputs B11:B14. Blue cells are inputs.
A3: Selected model | B3: logistic_regression
A4: Model index (1..4) | B4: =MATCH(B3,Models!A5:A8,0) -> 3
A5: Selected scenario | B5: sc-001
A6: Scenario capacity K | B6: =INDEX(Scenarios!B5:B7,MATCH(B5,Scenarios!A5:A7,0)) -> 5
A7: Scenario contact cost (USD) | B7: =INDEX(Scenarios!C5:C7,MATCH(B5,Scenarios!A5:A7,0)) -> 8
A8: Scenario assumed effect | B8: =INDEX(Scenarios!D5:D7,MATCH(B5,Scenarios!A5:A7,0)) -> 0.3
A9: Scenario margin (USD per retained account) | B9: =INDEX(Scenarios!E5:E7,MATCH(B5,Scenarios!A5:A7,0)) -> 200
A10: What-if (hypothetical, on the 97 cohort accounts)
A11: What-if capacity K | B11: 5
A12: What-if contact cost (USD) | B12: 8
A13: What-if assumed effect (share of risk removed, 0 to 1) | B13: 0.3
A14: What-if margin (USD per retained account) | B14: 200
A16: As-of (UTC) | B16: 46300
A18: All checks pass (Checks!B2) | B18: =Checks!B2 -> TRUE

Sheet Checks
A1: Checks: TRUE when every comparison with the SQL/Python results and the golden hand answer holds
A2: All checks pass | B2: =AND(F5:F74) -> TRUE
A4: # | B4: check | C4: workbook | D4: reference | E4: tolerance | F4: ok | G4: reference source
A5: 1 | B5: Average precision of random_baseline = the SQL/Python figure | C5: =Models!F5 -> 0.1267928 | D5: 0.126793 | E5: 5.0000001e-07 | F5: =ABS(C5-D5)<=E5 -> TRUE | G5: analysis-results.json 01_model_comparison__models
A6: 2 | B6: Brier score of random_baseline = the SQL/Python figure | C6: =Models!H5 -> 0.32654299 | D6: 0.326543 | E6: 5.0000001e-07 | F6: =ABS(C6-D6)<=E6 -> TRUE | G6: analysis-results.json 01_model_comparison__models
A7: 3 | B7: Average precision of business_rule = the SQL/Python figure | C7: =Models!F6 -> 0.13665283 | D7: 0.136653 | E7: 5.0000001e-07 | F7: =ABS(C7-D7)<=E7 -> TRUE | G7: analysis-results.json 01_model_comparison__models
A8: 4 | B8: Brier score of business_rule = the SQL/Python figure | C8: =Models!H6 -> 0.1092548 | D8: 0.109255 | E8: 5.0000001e-07 | F8: =ABS(C8-D8)<=E8 -> TRUE | G8: analysis-results.json 01_model_comparison__models
A9: 5 | B9: Average precision of logistic_regression = the SQL/Python figure | C9: =Models!F7 -> 0.23855217 | D9: 0.238552 | E9: 5.0000001e-07 | F9: =ABS(C9-D9)<=E9 -> TRUE | G9: analysis-results.json 01_model_comparison__models
A10: 6 | B10: Brier score of logistic_regression = the SQL/Python figure | C10: =Models!H7 -> 0.10501911 | D10: 0.105019 | E10: 5.0000001e-07 | F10: =ABS(C10-D10)<=E10 -> TRUE | G10: analysis-results.json 01_model_comparison__models
A11: 7 | B11: Average precision of prevalence_baseline = the SQL/Python figure | C11: =Models!F8 -> 0.12491738 | D11: 0.124917 | E11: 5.0000001e-07 | F11: =ABS(C11-D11)<=E11 -> TRUE | G11: analysis-results.json 01_model_comparison__models
A12: 8 | B12: Brier score of prevalence_baseline = the SQL/Python figure | C12: =Models!H8 -> 0.10966401 | D12: 0.109664 | E12: 5.0000001e-07 | F12: =ABS(C12-D12)<=E12 -> TRUE | G12: analysis-results.json 01_model_comparison__models
A13: 9 | B13: Average precision of logistic_uncalibrated = the SQL/Python figure | C13: =Models!F9 -> 0.23855217 | D13: 0.238552 | E13: 5.0000001e-07 | F13: =ABS(C13-D13)<=E13 -> TRUE | G13: analysis-results.json 01_model_comparison__models
A14: 10 | B14: Brier score of logistic_uncalibrated = the SQL/Python figure | C14: =Models!H9 -> 0.10451485 | D14: 0.104515 | E14: 5.0000001e-07 | F14: =ABS(C14-D14)<=E14 -> TRUE | G14: analysis-results.json 01_model_comparison__models
A15: 11 | B15: Margin ap_over_rule = the SQL figure | C15: =Models!C13 -> 0.101899 | D15: 0.101899 | E15: 5.0000001e-07 | F15: =ABS(C15-D15)<=E15 -> TRUE | G15: analysis-results.json 08_rows_and_margins__margins
A16: 12 | B16: Margin ap_over_random = the SQL figure | C16: =Models!C14 -> 0.111759 | D16: 0.111759 | E16: 5.0000001e-07 | F16: =ABS(C16-D16)<=E16 -> TRUE | G16: analysis-results.json 08_rows_and_margins__margins
A17: 13 | B17: Margin brier_under_rule = the SQL figure | C17: =Models!C15 -> 0.004236 | D17: 0.004236 | E17: 5.0000001e-07 | F17: =ABS(C17-D17)<=E17 -> TRUE | G17: analysis-results.json 08_rows_and_margins__margins
A18: 14 | B18: Margin brier_under_random = the SQL figure | C18: =Models!C16 -> 0.221524 | D18: 0.221524 | E18: 5.0000001e-07 | F18: =ABS(C18-D18)<=E18 -> TRUE | G18: analysis-results.json 08_rows_and_margins__margins
A19: 15 | B19: Margin ap_over_prevalence_constant (reference) = the SQL figure | C19: =Models!C17 -> 0.113635 | D19: 0.113635 | E19: 5.0000001e-07 | F19: =ABS(C19-D19)<=E19 -> TRUE | G19: analysis-results.json 08_rows_and_margins__margins
A20: 16 | B20: Margin brier_under_prevalence_constant (reference) = the SQL figure | C20: =Models!C18 -> 0.004645 | D20: 0.004645 | E20: 5.0000001e-07 | F20: =ABS(C20-D20)<=E20 -> TRUE | G20: analysis-results.json 08_rows_and_margins__margins
A21: 17 | B21: Models: rows = 1,513 for every model | C21: =SUMPRODUCT(--(Models!C5:C9=1513)) -> 5 | D21: 5 | E21: 0 | F21: =ABS(C21-D21)<=E21 -> TRUE | G21: manifest row_counts.test_cohort
A22: 18 | B22: Models: churning rows = 189 for every model | C22: =SUMPRODUCT(--(Models!D5:D9=189)) -> 5 | D22: 5 | E22: 0 | F22: =ABS(C22-D22)<=E22 -> TRUE | G22: manifest DR-01 realised
A23: 19 | B23: Calibration bins of logistic_regression (Platt): row counts = the SQL counts (sum of differences) | C23: =SUM(Calibration!K5:K14) -> 0 | D23: 0 | E23: 0 | F23: =ABS(C23-D23)<=E23 -> TRUE | G23: analysis-results.json 02_calibration_platt__bins
A24: 20 | B24: Calibration bins of logistic_regression (Platt): gaps of the occupied bins = the SQL gaps (each within the 2-place rounding) | C24: =MAX(Calibration!L5:L14) -> 0.0042633129 | D24: 0 | E24: 0.0050001 | F24: =ABS(C24-D24)<=E24 -> TRUE | G24: same
A25: 21 | B25: Calibration bins of logistic_regression (Platt): all 1,513 rows fall in a bin | C25: =SUM(Calibration!D5:D14) -> 1513 | D25: 1513 | E25: 0 | F25: =ABS(C25-D25)<=E25 -> TRUE | G25: test table
A26: 22 | B26: Calibration bins of logistic_regression (before Platt): row counts = the SQL counts (sum of differences) | C26: =SUM(Calibration!K19:K28) -> 0 | D26: 0 | E26: 0 | F26: =ABS(C26-D26)<=E26 -> TRUE | G26: analysis-results.json 02_calibration_platt__bins
A27: 23 | B27: Calibration bins of logistic_regression (before Platt): gaps of the occupied bins = the SQL gaps (each within the 2-place rounding) | C27: =MAX(Calibration!L19:L28) -> 0.0049285714 | D27: 0 | E27: 0.0050001 | F27: =ABS(C27-D27)<=E27 -> TRUE | G27: same
A28: 24 | B28: Calibration bins of logistic_regression (before Platt): all 1,513 rows fall in a bin | C28: =SUM(Calibration!D19:D28) -> 1513 | D28: 1513 | E28: 0 | F28: =ABS(C28-D28)<=E28 -> TRUE | G28: test table
A29: 25 | B29: Calibration: six of the ten bins of the Platt-calibrated model hold no rows | C29: =COUNTIF(Calibration!D5:D14,0) -> 6 | D29: 6 | E29: 0 | F29: =ABS(C29-D29)<=E29 -> TRUE | G29: analysis-results.json 02_calibration_platt__bins
A30: 26 | B30: Platt effect: Brier before Platt | C30: =Calibration!B36 -> 0.10451485 | D30: 0.104515 | E30: 5.0000001e-07 | F30: =ABS(C30-D30)<=E30 -> TRUE | G30: analysis-results.json 02_calibration_platt__platt_effect
A31: 27 | B31: Platt effect: Brier after Platt | C31: =Calibration!B37 -> 0.10501911 | D31: 0.105019 | E31: 5.0000001e-07 | F31: =ABS(C31-D31)<=E31 -> TRUE | G31: analysis-results.json 02_calibration_platt__platt_effect
A32: 28 | B32: Platt effect: Brier change | C32: =Calibration!B38 -> 0.000504 | D32: 0.000504 | E32: 5.0000001e-07 | F32: =ABS(C32-D32)<=E32 -> TRUE | G32: analysis-results.json 02_calibration_platt__platt_effect
A33: 29 | B33: Platt effect: Overall gap before (pp) | C33: =Calibration!B39 -> -2.2559106 | D33: -2.26 | E33: 0.0050001 | F33: =ABS(C33-D33)<=E33 -> TRUE | G33: analysis-results.json 02_calibration_platt__platt_effect
A34: 30 | B34: Platt effect: Overall gap after (pp) | C34: =Calibration!B40 -> -2.8603321 | D34: -2.86 | E34: 0.0050001 | F34: =ABS(C34-D34)<=E34 -> TRUE | G34: analysis-results.json 02_calibration_platt__platt_effect
A35: 31 | B35: Platt effect: Platt made the Brier worse on test (TRUE/FALSE) | C35: =Calibration!B41 -> TRUE | D35: =TRUE() -> TRUE | E35: 0 | F35: =C35=D35 -> TRUE | G35: analysis-results.json 02_calibration_platt__platt_effect
A36: 32 | B36: Calibration gaps by segment and region = the SQL gaps (largest difference, within the 2-place rounding) | C36: =MAX(Calibration!I48:I56) -> 0.0036540161 | D36: 0 | E36: 0.0050001 | F36: =ABS(C36-D36)<=E36 -> TRUE | G36: analysis-results.json 10_segment_region_calibration
A37: 33 | B37: Capacity: precision@K of every model and capacity = the SQL figures (largest absolute difference) | C37: =SUMPRODUCT(MAX(ABS(Capacity!E5:E16-Capacity!H5:H16))) -> 0 | D37: 0 | E37: 5.0000001e-07 | F37: =ABS(C37-D37)<=E37 -> TRUE | G37: analysis-results.json 03_capacity_economics__test_population_at_k
A38: 34 | B38: Capacity: recall@K of every model and capacity = the SQL figures | C38: =SUMPRODUCT(MAX(ABS(Capacity!F5:F16-Capacity!I5:I16))) -> 2.6455026e-08 | D38: 0 | E38: 5.0000001e-07 | F38: =ABS(C38-D38)<=E38 -> TRUE | G38: same
A39: 35 | B39: Capacity: risk lift@K of every model and capacity = the SQL figures | C39: =SUMPRODUCT(MAX(ABS(Capacity!G5:G16-Capacity!J5:J16))) -> 4.4973545e-07 | D39: 0 | E39: 5.0000001e-07 | F39: =ABS(C39-D39)<=E39 -> TRUE | G39: same
A40: 36 | B40: Capacity: the selected-model block equals the grid row of the selected model (precision@K, K = 5, 10, 20) | C40: =ABS(Capacity!D21-INDEX(Capacity!H5:H16,(Controls!B4-1)*3+1))+ABS(Capacity!D22-INDEX(Capacity!H5:H16,(Controls!B4-1)*3+2))+ABS(Capacity!D23-INDEX(Capacity!H5:H16,(Controls!B4-1)*3+3)) -> 0 | D40: 0 | E40: 1.5000001e-06 | F40: =ABS(C40-D40)<=E40 -> TRUE | G40: analysis-results.json 03_capacity_economics__test_population_at_k
A41: 37 | B41: Economics sc-001: the cohort expected value (97 scored accounts) = the published cohort figure | C41: =Economics!H5 -> 21.38 | D41: 21.38 | E41: 1e-07 | F41: =ABS(C41-D41)<=E41 -> TRUE | G41: manifest published_cohort.economics; analysis-results.json 03_capacity_economics__cohort_economics
...

Sheet Models
A1: Model comparison on the test population (D-03, D-07 DR-01)
A2: Average precision = mean over churning rows of the precision at that row's tied threshold (scikit-learn step form). Brier = mean((p - y)^2). The margins are met BY CONSTRUCTION (D-G02).
A4: model | B4: test-table column | C4: rows | D4: churning rows | E4: prevalence | F4: average precision | G4: top-25 probability threshold (rank only inside it) | H4: Brier score | I4: mean probability | J4: reference AP (SQL 01) | K4: reference Brier (SQL 01)
A5: random_baseline | B5: L | C5: =COUNT('Test table'!$L$5:$L$1517) -> 1513 | D5: =SUM('Test table'!$K$5:$K$1517) -> 189 | E5: =D5/C5 -> 0.12491738 | F5: =SUM('Test table'!$U$5:$U$1517)/D5 -> 0.1267928 | G5: =LARGE('Test table'!$L$5:$L$1517,25) -> 0.981331 | H5: =SUM('Test table'!$Z$5:$Z$1517)/C5 -> 0.32654299 | I5: =AVERAGE('Test table'!$L$5:$L$1517) -> 0.49180276 | J5: 0.126793 | K5: 0.326543
A6: business_rule | B6: M | C6: =COUNT('Test table'!$M$5:$M$1517) -> 1513 | D6: =SUM('Test table'!$K$5:$K$1517) -> 189 | E6: =D6/C6 -> 0.12491738 | F6: =SUM('Test table'!$V$5:$V$1517)/D6 -> 0.13665283 | G6: =LARGE('Test table'!$M$5:$M$1517,25) -> 0.184211 | H6: =SUM('Test table'!$AA$5:$AA$1517)/C6 -> 0.1092548 | I6: =AVERAGE('Test table'!$M$5:$M$1517) -> 0.1038175 | J6: 0.136653 | K6: 0.109255
A7: logistic_regression | B7: N | C7: =COUNT('Test table'!$N$5:$N$1517) -> 1513 | D7: =SUM('Test table'!$K$5:$K$1517) -> 189 | E7: =D7/C7 -> 0.12491738 | F7: =SUM('Test table'!$W$5:$W$1517)/D7 -> 0.23855217 | G7: =LARGE('Test table'!$N$5:$N$1517,25) -> 0.238419 | H7: =SUM('Test table'!$AB$5:$AB$1517)/C7 -> 0.10501911 | I7: =AVERAGE('Test table'!$N$5:$N$1517) -> 0.096314061 | J7: 0.238552 | K7: 0.105019
A8: prevalence_baseline | B8: O | C8: =COUNT('Test table'!$O$5:$O$1517) -> 1513 | D8: =SUM('Test table'!$K$5:$K$1517) -> 189 | E8: =D8/C8 -> 0.12491738 | F8: =SUM('Test table'!$X$5:$X$1517)/D8 -> 0.12491738 | G8: =LARGE('Test table'!$O$5:$O$1517,25) -> 0.106183 | H8: =SUM('Test table'!$AC$5:$AC$1517)/C8 -> 0.10966401 | I8: =AVERAGE('Test table'!$O$5:$O$1517) -> 0.106183 | J8: 0.124917 | K8: 0.109664
A9: logistic_uncalibrated | B9: P | C9: =COUNT('Test table'!$P$5:$P$1517) -> 1513 | D9: =SUM('Test table'!$K$5:$K$1517) -> 189 | E9: =D9/C9 -> 0.12491738 | F9: =SUM('Test table'!$Y$5:$Y$1517)/D9 -> 0.23855217 | G9: =LARGE('Test table'!$P$5:$P$1517,25) -> 0.259675 | H9: =SUM('Test table'!$AD$5:$AD$1517)/C9 -> 0.10451485 | I9: =AVERAGE('Test table'!$P$5:$P$1517) -> 0.10235828 | J9: 0.238552 | K9: 0.104515
A11: Margins of the Platt-calibrated logistic regression
A12: margin | B12: declared before the first run (D-G01) | C12: realised (6-place figures) | D12: status | E12: reference (SQL 08)
A13: ap_over_rule | B13: 0.03 | C13: =ROUND(F7,6)-ROUND(F6,6) -> 0.101899 | D13: =IF(ISNUMBER(B13),IF(C13>=B13,"met, by construction (D-G02)","not met"),"reference, not a target") -> met, by construction (D-G02) | E13: 0.101899
A14: ap_over_random | B14: 0.05 | C14: =ROUND(F7,6)-ROUND(F5,6) -> 0.111759 | D14: =IF(ISNUMBER(B14),IF(C14>=B14,"met, by construction (D-G02)","not met"),"reference, not a target") -> met, by construction (D-G02) | E14: 0.111759
A15: brier_under_rule | B15: 0.002 | C15: =ROUND(H6,6)-ROUND(H7,6) -> 0.004236 | D15: =IF(ISNUMBER(B15),IF(C15>=B15,"met, by construction (D-G02)","not met"),"reference, not a target") -> met, by construction (D-G02) | E15: 0.004236
A16: brier_under_random | B16: 0.05 | C16: =ROUND(H5,6)-ROUND(H7,6) -> 0.221524 | D16: =IF(ISNUMBER(B16),IF(C16>=B16,"met, by construction (D-G02)","not met"),"reference, not a target") -> met, by construction (D-G02) | E16: 0.221524
A17: ap_over_prevalence_constant (reference) | C17: =ROUND(F7,6)-ROUND(F8,6) -> 0.113635 | D17: =IF(ISNUMBER(B17),IF(C17>=B17,"met, by construction (D-G02)","not met"),"reference, not a target") -> reference, not a target | E17: 0.113635
A18: brier_under_prevalence_constant (reference) | C18: =ROUND(H8,6)-ROUND(H7,6) -> 0.004645 | D18: =IF(ISNUMBER(B18),IF(C18>=B18,"met, by construction (D-G02)","not met"),"reference, not a target") -> reference, not a target | E18: 0.004645
A20: A met margin is a property of the synthetic world: the generator's engagement signal was strengthened until the margins were met (manifest D-G02). The Brier margin over the random baseline is uninformative (a uniform random score cannot beat about 0.33); the honest reference is the prevalence constant.

Sheet Calibration
A1: Calibration bins with their counts, and the effect of the Platt mapping (D-03, D-09 R10-08)
A2: bin = floor(10 p), the last closed; gap = (mean predicted - observed) x 100 pp. An empty bin has no mean, rate or gap (blank, never 0).
A3: logistic_regression (Platt)
A4: bin | B4: lower | C4: upper | D4: rows | E4: churning rows | F4: mean predicted | G4: observed rate | H4: gap (pp) | I4: reference rows (SQL 02) | J4: reference gap (pp) | K4: row diff | L4: gap diff
A5: 0 | B5: 0 | C5: 0.1 | D5: =COUNTIF('Test table'!$AE$5:$AE$1517,A5) -> 815 | E5: =COUNTIFS('Test table'!$AE$5:$AE$1517,A5,'Test table'!$K$5:$K$1517,1) -> 56 | F5: =IF(D5=0,"",AVERAGEIFS('Test table'!$N$5:$N$1517,'Test table'!$AE$5:$AE$1517,A5)) -> 0.05665429 | G5: =IF(D5=0,"",E5/D5) -> 0.068711656 | H5: =IF(D5=0,"",(F5-G5)*100) -> -1.2057367 | I5: 815 | J5: -1.21 | K5: =ABS(D5-I5) -> 0 | L5: =IF(D5=0,0,ABS(H5-J5)) -> 0.0042633129
A6: 1 | B6: 0.1 | C6: 0.2 | D6: =COUNTIF('Test table'!$AE$5:$AE$1517,A6) -> 640 | E6: =COUNTIFS('Test table'!$AE$5:$AE$1517,A6,'Test table'!$K$5:$K$1517,1) -> 117 | F6: =IF(D6=0,"",AVERAGEIFS('Test table'!$N$5:$N$1517,'Test table'!$AE$5:$AE$1517,A6)) -> 0.13324477 | G6: =IF(D6=0,"",E6/D6) -> 0.1828125 | H6: =IF(D6=0,"",(F6-G6)*100) -> -4.9567734 | I6: 640 | J6: -4.96 | K6: =ABS(D6-I6) -> 0 | L6: =IF(D6=0,0,ABS(H6-J6)) -> 0.0032265625
A7: 2 | B7: 0.2 | C7: 0.3 | D7: =COUNTIF('Test table'!$AE$5:$AE$1517,A7) -> 50 | E7: =COUNTIFS('Test table'!$AE$5:$AE$1517,A7,'Test table'!$K$5:$K$1517,1) -> 15 | F7: =IF(D7=0,"",AVERAGEIFS('Test table'!$N$5:$N$1517,'Test table'!$AE$5:$AE$1517,A7)) -> 0.23010702 | G7: =IF(D7=0,"",E7/D7) -> 0.3 | H7: =IF(D7=0,"",(F7-G7)*100) -> -6.989298 | I7: 50 | J7: -6.99 | K7: =ABS(D7-I7) -> 0 | L7: =IF(D7=0,0,ABS(H7-J7)) -> 0.000702
A8: 3 | B8: 0.3 | C8: 0.4 | D8: =COUNTIF('Test table'!$AE$5:$AE$1517,A8) -> 8 | E8: =COUNTIFS('Test table'!$AE$5:$AE$1517,A8,'Test table'!$K$5:$K$1517,1) -> 1 | F8: =IF(D8=0,"",AVERAGEIFS('Test table'!$N$5:$N$1517,'Test table'!$AE$5:$AE$1517,A8)) -> 0.345991 | G8: =IF(D8=0,"",E8/D8) -> 0.125 | H8: =IF(D8=0,"",(F8-G8)*100) -> 22.0991 | I8: 8 | J8: 22.1 | K8: =ABS(D8-I8) -> 0 | L8: =IF(D8=0,0,ABS(H8-J8)) -> 0.0009
A9: 4 | B9: 0.4 | C9: 0.5 | D9: =COUNTIF('Test table'!$AE$5:$AE$1517,A9) -> 0 | E9: =COUNTIFS('Test table'!$AE$5:$AE$1517,A9,'Test table'!$K$5:$K$1517,1) -> 0 | F9: =IF(D9=0,"",AVERAGEIFS('Test table'!$N$5:$N$1517,'Test table'!$AE$5:$AE$1517,A9)) | G9: =IF(D9=0,"",E9/D9) | H9: =IF(D9=0,"",(F9-G9)*100) | I9: 0 | K9: =ABS(D9-I9) -> 0 | L9: =IF(D9=0,0,ABS(H9-J9)) -> 0
A10: 5 | B10: 0.5 | C10: 0.6 | D10: =COUNTIF('Test table'!$AE$5:$AE$1517,A10) -> 0 | E10: =COUNTIFS('Test table'!$AE$5:$AE$1517,A10,'Test table'!$K$5:$K$1517,1) -> 0 | F10: =IF(D10=0,"",AVERAGEIFS('Test table'!$N$5:$N$1517,'Test table'!$AE$5:$AE$1517,A10)) | G10: =IF(D10=0,"",E10/D10) | H10: =IF(D10=0,"",(F10-G10)*100) | I10: 0 | K10: =ABS(D10-I10) -> 0 | L10: =IF(D10=0,0,ABS(H10-J10)) -> 0
A11: 6 | B11: 0.6 | C11: 0.7 | D11: =COUNTIF('Test table'!$AE$5:$AE$1517,A11) -> 0 | E11: =COUNTIFS('Test table'!$AE$5:$AE$1517,A11,'Test table'!$K$5:$K$1517,1) -> 0 | F11: =IF(D11=0,"",AVERAGEIFS('Test table'!$N$5:$N$1517,'Test table'!$AE$5:$AE$1517,A11)) | G11: =IF(D11=0,"",E11/D11) | H11: =IF(D11=0,"",(F11-G11)*100) | I11: 0 | K11: =ABS(D11-I11) -> 0 | L11: =IF(D11=0,0,ABS(H11-J11)) -> 0
A12: 7 | B12: 0.7 | C12: 0.8 | D12: =COUNTIF('Test table'!$AE$5:$AE$1517,A12) -> 0 | E12: =COUNTIFS('Test table'!$AE$5:$AE$1517,A12,'Test table'!$K$5:$K$1517,1) -> 0 | F12: =IF(D12=0,"",AVERAGEIFS('Test table'!$N$5:$N$1517,'Test table'!$AE$5:$AE$1517,A12)) | G12: =IF(D12=0,"",E12/D12) | H12: =IF(D12=0,"",(F12-G12)*100) | I12: 0 | K12: =ABS(D12-I12) -> 0 | L12: =IF(D12=0,0,ABS(H12-J12)) -> 0
A13: 8 | B13: 0.8 | C13: 0.9 | D13: =COUNTIF('Test table'!$AE$5:$AE$1517,A13) -> 0 | E13: =COUNTIFS('Test table'!$AE$5:$AE$1517,A13,'Test table'!$K$5:$K$1517,1) -> 0 | F13: =IF(D13=0,"",AVERAGEIFS('Test table'!$N$5:$N$1517,'Test table'!$AE$5:$AE$1517,A13)) | G13: =IF(D13=0,"",E13/D13) | H13: =IF(D13=0,"",(F13-G13)*100) | I13: 0 | K13: =ABS(D13-I13) -> 0 | L13: =IF(D13=0,0,ABS(H13-J13)) -> 0
A14: 9 | B14: 0.9 | C14: 1 | D14: =COUNTIF('Test table'!$AE$5:$AE$1517,A14) -> 0 | E14: =COUNTIFS('Test table'!$AE$5:$AE$1517,A14,'Test table'!$K$5:$K$1517,1) -> 0 | F14: =IF(D14=0,"",AVERAGEIFS('Test table'!$N$5:$N$1517,'Test table'!$AE$5:$AE$1517,A14)) | G14: =IF(D14=0,"",E14/D14) | H14: =IF(D14=0,"",(F14-G14)*100) | I14: 0 | K14: =ABS(D14-I14) -> 0 | L14: =IF(D14=0,0,ABS(H14-J14)) -> 0
A17: logistic_regression (before Platt)
A18: bin | B18: lower | C18: upper | D18: rows | E18: churning rows | F18: mean predicted | G18: observed rate | H18: gap (pp) | I18: reference rows (SQL 02) | J18: reference gap (pp) | K18: row diff | L18: gap diff
A19: 0 | B19: 0 | C19: 0.1 | D19: =COUNTIF('Test table'!$AF$5:$AF$1517,A19) -> 778 | E19: =COUNTIFS('Test table'!$AF$5:$AF$1517,A19,'Test table'!$K$5:$K$1517,1) -> 51 | F19: =IF(D19=0,"",AVERAGEIFS('Test table'!$P$5:$P$1517,'Test table'!$AF$5:$AF$1517,A19)) -> 0.056720095 | G19: =IF(D19=0,"",E19/D19) -> 0.065552699 | H19: =IF(D19=0,"",(F19-G19)*100) -> -0.88326041 | I19: 778 | J19: -0.88 | K19: =ABS(D19-I19) -> 0 | L19: =IF(D19=0,0,ABS(H19-J19)) -> 0.0032604113
A20: 1 | B20: 0.1 | C20: 0.2 | D20: =COUNTIF('Test table'!$AF$5:$AF$1517,A20) -> 653 | E20: =COUNTIFS('Test table'!$AF$5:$AF$1517,A20,'Test table'!$K$5:$K$1517,1) -> 113 | F20: =IF(D20=0,"",AVERAGEIFS('Test table'!$P$5:$P$1517,'Test table'!$AF$5:$AF$1517,A20)) -> 0.13802141 | G20: =IF(D20=0,"",E20/D20) -> 0.17304747 | H20: =IF(D20=0,"",(F20-G20)*100) -> -3.5026064 | I20: 653 | J20: -3.5 | K20: =ABS(D20-I20) -> 0 | L20: =IF(D20=0,0,ABS(H20-J20)) -> 0.0026064319
A21: 2 | B21: 0.2 | C21: 0.3 | D21: =COUNTIF('Test table'!$AF$5:$AF$1517,A21) -> 72 | E21: =COUNTIFS('Test table'!$AF$5:$AF$1517,A21,'Test table'!$K$5:$K$1517,1) -> 23 | F21: =IF(D21=0,"",AVERAGEIFS('Test table'!$P$5:$P$1517,'Test table'!$AF$5:$AF$1517,A21)) -> 0.23570743 | G21: =IF(D21=0,"",E21/D21) -> 0.31944444 | H21: =IF(D21=0,"",(F21-G21)*100) -> -8.3737014 | I21: 72 | J21: -8.37 | K21: =ABS(D21-I21) -> 0 | L21: =IF(D21=0,0,ABS(H21-J21)) -> 0.0037013889
A22: 3 | B22: 0.3 | C22: 0.4 | D22: =COUNTIF('Test table'!$AF$5:$AF$1517,A22) -> 7 | E22: =COUNTIFS('Test table'!$AF$5:$AF$1517,A22,'Test table'!$K$5:$K$1517,1) -> 2 | F22: =IF(D22=0,"",AVERAGEIFS('Test table'!$P$5:$P$1517,'Test table'!$AF$5:$AF$1517,A22)) -> 0.340665 | G22: =IF(D22=0,"",E22/D22) -> 0.28571429 | H22: =IF(D22=0,"",(F22-G22)*100) -> 5.4950714 | I22: 7 | J22: 5.5 | K22: =ABS(D22-I22) -> 0 | L22: =IF(D22=0,0,ABS(H22-J22)) -> 0.0049285714
A23: 4 | B23: 0.4 | C23: 0.5 | D23: =COUNTIF('Test table'!$AF$5:$AF$1517,A23) -> 3 | E23: =COUNTIFS('Test table'!$AF$5:$AF$1517,A23,'Test table'!$K$5:$K$1517,1) -> 0 | F23: =IF(D23=0,"",AVERAGEIFS('Test table'!$P$5:$P$1517,'Test table'!$AF$5:$AF$1517,A23)) -> 0.41875633 | G23: =IF(D23=0,"",E23/D23) -> 0 | H23: =IF(D23=0,"",(F23-G23)*100) -> 41.875633 | I23: 3 | J23: 41.88 | K23: =ABS(D23-I23) -> 0 | L23: =IF(D23=0,0,ABS(H23-J23)) -> 0.0043666667
A24: 5 | B24: 0.5 | C24: 0.6 | D24: =COUNTIF('Test table'!$AF$5:$AF$1517,A24) -> 0 | E24: =COUNTIFS('Test table'!$AF$5:$AF$1517,A24,'Test table'!$K$5:$K$1517,1) -> 0 | F24: =IF(D24=0,"",AVERAGEIFS('Test table'!$P$5:$P$1517,'Test table'!$AF$5:$AF$1517,A24)) | G24: =IF(D24=0,"",E24/D24) | H24: =IF(D24=0,"",(F24-G24)*100) | I24: 0 | K24: =ABS(D24-I24) -> 0 | L24: =IF(D24=0,0,ABS(H24-J24)) -> 0
A25: 6 | B25: 0.6 | C25: 0.7 | D25: =COUNTIF('Test table'!$AF$5:$AF$1517,A25) -> 0 | E25: =COUNTIFS('Test table'!$AF$5:$AF$1517,A25,'Test table'!$K$5:$K$1517,1) -> 0 | F25: =IF(D25=0,"",AVERAGEIFS('Test table'!$P$5:$P$1517,'Test table'!$AF$5:$AF$1517,A25)) | G25: =IF(D25=0,"",E25/D25) | H25: =IF(D25=0,"",(F25-G25)*100) | I25: 0 | K25: =ABS(D25-I25) -> 0 | L25: =IF(D25=0,0,ABS(H25-J25)) -> 0
A26: 7 | B26: 0.7 | C26: 0.8 | D26: =COUNTIF('Test table'!$AF$5:$AF$1517,A26) -> 0 | E26: =COUNTIFS('Test table'!$AF$5:$AF$1517,A26,'Test table'!$K$5:$K$1517,1) -> 0 | F26: =IF(D26=0,"",AVERAGEIFS('Test table'!$P$5:$P$1517,'Test table'!$AF$5:$AF$1517,A26)) | G26: =IF(D26=0,"",E26/D26) | H26: =IF(D26=0,"",(F26-G26)*100) | I26: 0 | K26: =ABS(D26-I26) -> 0 | L26: =IF(D26=0,0,ABS(H26-J26)) -> 0
A27: 8 | B27: 0.8 | C27: 0.9 | D27: =COUNTIF('Test table'!$AF$5:$AF$1517,A27) -> 0 | E27: =COUNTIFS('Test table'!$AF$5:$AF$1517,A27,'Test table'!$K$5:$K$1517,1) -> 0 | F27: =IF(D27=0,"",AVERAGEIFS('Test table'!$P$5:$P$1517,'Test table'!$AF$5:$AF$1517,A27)) | G27: =IF(D27=0,"",E27/D27) | H27: =IF(D27=0,"",(F27-G27)*100) | I27: 0 | K27: =ABS(D27-I27) -> 0 | L27: =IF(D27=0,0,ABS(H27-J27)) -> 0
A28: 9 | B28: 0.9 | C28: 1 | D28: =COUNTIF('Test table'!$AF$5:$AF$1517,A28) -> 0 | E28: =COUNTIFS('Test table'!$AF$5:$AF$1517,A28,'Test table'!$K$5:$K$1517,1) -> 0 | F28: =IF(D28=0,"",AVERAGEIFS('Test table'!$P$5:$P$1517,'Test table'!$AF$5:$AF$1517,A28)) | G28: =IF(D28=0,"",E28/D28) | H28: =IF(D28=0,"",(F28-G28)*100) | I28: 0 | K28: =ABS(D28-I28) -> 0 | L28: =IF(D28=0,0,ABS(H28-J28)) -> 0
A34: Platt effect on the test rows
A35: figure | B35: workbook | C35: reference (SQL 02 / calibration.json)
A36: Brier before Platt | B36: =Models!H9 -> 0.10451485 | C36: 0.104515
A37: Brier after Platt | B37: =Models!H7 -> 0.10501911 | C37: 0.105019
A38: Brier change | B38: =ROUND(Models!H7,6)-ROUND(Models!H9,6) -> 0.000504 | C38: 0.000504
A39: Overall gap before (pp) | B39: =(Models!I9-Models!E7)*100 -> -2.2559106 | C39: -2.26
A40: Overall gap after (pp) | B40: =(Models!I7-Models!E7)*100 -> -2.8603321 | C40: -2.86
A41: Platt made the Brier worse on test (TRUE/FALSE) | B41: =ROUND(Models!H7,6)>ROUND(Models!H9,6) -> TRUE | C41: =TRUE() -> TRUE
A43: The mapping was fitted on 289 retained validation rows, all from one cutoff (2025-10-01), because the label-window purge removes the later validation cutoffs; it made the model slightly worse on the four test cutoffs.
A46: Calibration gap by segment and region (Platt-calibrated model)
A47: dimension | B47: group | C47: rows | D47: churning rows | E47: mean predicted | F47: observed rate | G47: gap (pp) | H47: reference gap (pp) | I47: diff
A48: segment | B48: enterprise | C48: =COUNTIF('Test table'!$E$5:$E$1517,B48) -> 213 | D48: =COUNTIFS('Test table'!$E$5:$E$1517,B48,'Test table'!$K$5:$K$1517,1) -> 11 | E48: =AVERAGEIFS('Test table'!$N$5:$N$1517,'Test table'!$E$5:$E$1517,B48) -> 0.038806662 | F48: =D48/C48 -> 0.051643192 | G48: =(E48-F48)*100 -> -1.2836531 | H48: -1.28 | I48: =ABS(G48-H48) -> 0.0036530516
A49: segment | B49: mid | C49: =COUNTIF('Test table'!$E$5:$E$1517,B49) -> 380 | D49: =COUNTIFS('Test table'!$E$5:$E$1517,B49,'Test table'!$K$5:$K$1517,1) -> 34 | E49: =AVERAGEIFS('Test table'!$N$5:$N$1517,'Test table'!$E$5:$E$1517,B49) -> 0.069537224 | F49: =D49/C49 -> 0.089473684 | G49: =(E49-F49)*100 -> -1.9936461 | H49: -1.99 | I49: =ABS(G49-H49) -> 0.0036460526
A50: segment | B50: smb | C50: =COUNTIF('Test table'!$E$5:$E$1517,B50) -> 498 | D50: =COUNTIFS('Test table'!$E$5:$E$1517,B50,'Test table'!$K$5:$K$1517,1) -> 52 | E50: =AVERAGEIFS('Test table'!$N$5:$N$1517,'Test table'!$E$5:$E$1517,B50) -> 0.10658113 | F50: =D50/C50 -> 0.10441767 | G50: =(E50-F50)*100 -> 0.21634598 | H50: 0.22 | I50: =ABS(G50-H50) -> 0.0036540161
...

Sheet Capacity
A1: Precision, recall and risk lift at the three capacities, test population (outcomes known)
A2: Rank: probability descending, then account id, then the earlier cutoff. Risk lift is a ranking statistic, NOT treatment uplift. The 2026-09-01 queue has no known outcomes (Economics).
A4: model | B4: scenario | C4: K | D4: churners in top K | E4: precision@K | F4: recall@K | G4: risk lift@K | H4: reference precision (SQL 03) | I4: reference recall | J4: reference lift | K4: tie across the cut (reference)
A5: random_baseline | B5: =Scenarios!A5 -> sc-001 | C5: =Scenarios!B5 -> 5 | D5: =COUNTIFS('Test table'!$Q$5:$Q$1517,"<="&C5,'Test table'!$K$5:$K$1517,1) -> 0 | E5: =D5/C5 -> 0 | F5: =D5/Models!$D$5 -> 0 | G5: =E5/Models!$E$5 -> 0 | H5: 0 | I5: 0 | J5: 0 | K5: =FALSE() -> FALSE
A6: random_baseline | B6: =Scenarios!A6 -> sc-002 | C6: =Scenarios!B6 -> 10 | D6: =COUNTIFS('Test table'!$Q$5:$Q$1517,"<="&C6,'Test table'!$K$5:$K$1517,1) -> 1 | E6: =D6/C6 -> 0.1 | F6: =D6/Models!$D$5 -> 0.0052910053 | G6: =E6/Models!$E$5 -> 0.8005291 | H6: 0.1 | I6: 0.005291 | J6: 0.800529 | K6: =FALSE() -> FALSE
A7: random_baseline | B7: =Scenarios!A7 -> sc-003 | C7: =Scenarios!B7 -> 20 | D7: =COUNTIFS('Test table'!$Q$5:$Q$1517,"<="&C7,'Test table'!$K$5:$K$1517,1) -> 1 | E7: =D7/C7 -> 0.05 | F7: =D7/Models!$D$5 -> 0.0052910053 | G7: =E7/Models!$E$5 -> 0.40026455 | H7: 0.05 | I7: 0.005291 | J7: 0.400265 | K7: =FALSE() -> FALSE
A8: business_rule | B8: =Scenarios!A5 -> sc-001 | C8: =Scenarios!B5 -> 5 | D8: =COUNTIFS('Test table'!$R$5:$R$1517,"<="&C8,'Test table'!$K$5:$K$1517,1) -> 2 | E8: =D8/C8 -> 0.4 | F8: =D8/Models!$D$6 -> 0.010582011 | G8: =E8/Models!$E$6 -> 3.2021164 | H8: 0.4 | I8: 0.010582 | J8: 3.202116 | K8: =TRUE() -> TRUE
A9: business_rule | B9: =Scenarios!A6 -> sc-002 | C9: =Scenarios!B6 -> 10 | D9: =COUNTIFS('Test table'!$R$5:$R$1517,"<="&C9,'Test table'!$K$5:$K$1517,1) -> 3 | E9: =D9/C9 -> 0.3 | F9: =D9/Models!$D$6 -> 0.015873016 | G9: =E9/Models!$E$6 -> 2.4015873 | H9: 0.3 | I9: 0.015873 | J9: 2.401587 | K9: =TRUE() -> TRUE
A10: business_rule | B10: =Scenarios!A7 -> sc-003 | C10: =Scenarios!B7 -> 20 | D10: =COUNTIFS('Test table'!$R$5:$R$1517,"<="&C10,'Test table'!$K$5:$K$1517,1) -> 3 | E10: =D10/C10 -> 0.15 | F10: =D10/Models!$D$6 -> 0.015873016 | G10: =E10/Models!$E$6 -> 1.2007937 | H10: 0.15 | I10: 0.015873 | J10: 1.200794 | K10: =TRUE() -> TRUE
A11: logistic_regression | B11: =Scenarios!A5 -> sc-001 | C11: =Scenarios!B5 -> 5 | D11: =COUNTIFS('Test table'!$S$5:$S$1517,"<="&C11,'Test table'!$K$5:$K$1517,1) -> 0 | E11: =D11/C11 -> 0 | F11: =D11/Models!$D$7 -> 0 | G11: =E11/Models!$E$7 -> 0 | H11: 0 | I11: 0 | J11: 0 | K11: =FALSE() -> FALSE
A12: logistic_regression | B12: =Scenarios!A6 -> sc-002 | C12: =Scenarios!B6 -> 10 | D12: =COUNTIFS('Test table'!$S$5:$S$1517,"<="&C12,'Test table'!$K$5:$K$1517,1) -> 2 | E12: =D12/C12 -> 0.2 | F12: =D12/Models!$D$7 -> 0.010582011 | G12: =E12/Models!$E$7 -> 1.6010582 | H12: 0.2 | I12: 0.010582 | J12: 1.601058 | K12: =FALSE() -> FALSE
A13: logistic_regression | B13: =Scenarios!A7 -> sc-003 | C13: =Scenarios!B7 -> 20 | D13: =COUNTIFS('Test table'!$S$5:$S$1517,"<="&C13,'Test table'!$K$5:$K$1517,1) -> 5 | E13: =D13/C13 -> 0.25 | F13: =D13/Models!$D$7 -> 0.026455026 | G13: =E13/Models!$E$7 -> 2.0013228 | H13: 0.25 | I13: 0.026455 | J13: 2.001323 | K13: =FALSE() -> FALSE
A14: prevalence_baseline | B14: =Scenarios!A5 -> sc-001 | C14: =Scenarios!B5 -> 5 | D14: =COUNTIFS('Test table'!$T$5:$T$1517,"<="&C14,'Test table'!$K$5:$K$1517,1) -> 0 | E14: =D14/C14 -> 0 | F14: =D14/Models!$D$8 -> 0 | G14: =E14/Models!$E$8 -> 0 | H14: 0 | I14: 0 | J14: 0 | K14: =TRUE() -> TRUE
A15: prevalence_baseline | B15: =Scenarios!A6 -> sc-002 | C15: =Scenarios!B6 -> 10 | D15: =COUNTIFS('Test table'!$T$5:$T$1517,"<="&C15,'Test table'!$K$5:$K$1517,1) -> 0 | E15: =D15/C15 -> 0 | F15: =D15/Models!$D$8 -> 0 | G15: =E15/Models!$E$8 -> 0 | H15: 0 | I15: 0 | J15: 0 | K15: =TRUE() -> TRUE
A16: prevalence_baseline | B16: =Scenarios!A7 -> sc-003 | C16: =Scenarios!B7 -> 20 | D16: =COUNTIFS('Test table'!$T$5:$T$1517,"<="&C16,'Test table'!$K$5:$K$1517,1) -> 0 | E16: =D16/C16 -> 0 | F16: =D16/Models!$D$8 -> 0 | G16: =E16/Models!$E$8 -> 0 | H16: 0 | I16: 0 | J16: 0 | K16: =TRUE() -> TRUE
A19: Selected model (Controls!B3)
A20: scenario | B20: K | C20: churners in top K | D20: precision@K | E20: recall@K | F20: risk lift@K
A21: =Scenarios!A5 -> sc-001 | B21: =Scenarios!B5 -> 5 | C21: =INDEX(D$5:D$16,(Controls!$B$4-1)*3+1) -> 0 | D21: =INDEX(E$5:E$16,(Controls!$B$4-1)*3+1) -> 0 | E21: =INDEX(F$5:F$16,(Controls!$B$4-1)*3+1) -> 0 | F21: =INDEX(G$5:G$16,(Controls!$B$4-1)*3+1) -> 0
A22: =Scenarios!A6 -> sc-002 | B22: =Scenarios!B6 -> 10 | C22: =INDEX(D$5:D$16,(Controls!$B$4-1)*3+2) -> 2 | D22: =INDEX(E$5:E$16,(Controls!$B$4-1)*3+2) -> 0.2 | E22: =INDEX(F$5:F$16,(Controls!$B$4-1)*3+2) -> 0.010582011 | F22: =INDEX(G$5:G$16,(Controls!$B$4-1)*3+2) -> 1.6010582
A23: =Scenarios!A7 -> sc-003 | B23: =Scenarios!B7 -> 20 | C23: =INDEX(D$5:D$16,(Controls!$B$4-1)*3+3) -> 5 | D23: =INDEX(E$5:E$16,(Controls!$B$4-1)*3+3) -> 0.25 | E23: =INDEX(F$5:F$16,(Controls!$B$4-1)*3+3) -> 0.026455026 | F23: =INDEX(G$5:G$16,(Controls!$B$4-1)*3+3) -> 2.0013228

Sheet Economics
A1: Hypothetical expected intervention value (D-03, D-09 R10-04): assumption-based, by population
A2: Expected value = sum over the top-K accounts of (probability x assumed effect x margin - contact cost), rounded ONCE at the end. A ranking by risk is not a treatment effect; no randomised experiment supports the assumed effect.
A4: account_id | B4: probability (logistic, Platt) | C4: rank (p desc, account id asc) | E4: scenario | F4: capacity K | G4: contact budget (K x cost) | H4: COHORT expected value (97 scored accounts) | I4: published cohort value (manifest) | J4: WORLD expected value (1,241 scored accounts, published) | K4: world scored accounts | L4: label | M4: population note
A5: 11 | B5: 0.127847 | C5: =1+COUNTIF($B$5:$B$101,">"&B5)+COUNTIFS($B$5:$B$101,B5,$A$5:$A$101,"<"&A5) -> 27 | E5: =Scenarios!A5 -> sc-001 | F5: =Scenarios!B5 -> 5 | G5: =ROUND(F5*Scenarios!C5,2) -> 40 | H5: =ROUND(SUMPRODUCT(($C$5:$C$101<=F5)*($B$5:$B$101*Scenarios!D5*Scenarios!E5-Scenarios!C5)),2) -> 21.38 | I5: 21.38 | J5: 81.13 | K5: 1241 | L5: hypothetical | M5: cohort: computed here; world: TYPED from cutoff_aggregates.json (not recomputable from the cohort)
A6: 20 | B6: 0.09385 | C6: =1+COUNTIF($B$5:$B$101,">"&B6)+COUNTIFS($B$5:$B$101,B6,$A$5:$A$101,"<"&A6) -> 45 | E6: =Scenarios!A6 -> sc-002 | F6: =Scenarios!B6 -> 10 | G6: =ROUND(F6*Scenarios!C6,2) -> 80 | H6: =ROUND(SUMPRODUCT(($C$5:$C$101<=F6)*($B$5:$B$101*Scenarios!D6*Scenarios!E6-Scenarios!C6)),2) -> -6.87 | I6: -6.87 | J6: 71.04 | K6: 1241 | L6: hypothetical | M6: cohort: computed here; world: TYPED from cutoff_aggregates.json (not recomputable from the cohort)
A7: 43 | B7: 0.131947 | C7: =1+COUNTIF($B$5:$B$101,">"&B7)+COUNTIFS($B$5:$B$101,B7,$A$5:$A$101,"<"&A7) -> 20 | E7: =Scenarios!A7 -> sc-003 | F7: =Scenarios!B7 -> 20 | G7: =ROUND(F7*Scenarios!C7,2) -> 160 | H7: =ROUND(SUMPRODUCT(($C$5:$C$101<=F7)*($B$5:$B$101*Scenarios!D7*Scenarios!E7-Scenarios!C7)),2) -> -95.46 | I7: -95.46 | J7: -29.12 | K7: 1241 | L7: hypothetical | M7: cohort: computed here; world: TYPED from cutoff_aggregates.json (not recomputable from the cohort)
A8: 159 | B8: 0.054025 | C8: =1+COUNTIF($B$5:$B$101,">"&B8)+COUNTIFS($B$5:$B$101,B8,$A$5:$A$101,"<"&A8) -> 73
A9: 176 | B9: 0.026838 | C9: =1+COUNTIF($B$5:$B$101,">"&B9)+COUNTIFS($B$5:$B$101,B9,$A$5:$A$101,"<"&A9) -> 92
A10: 183 | B10: 0.050814 | C10: =1+COUNTIF($B$5:$B$101,">"&B10)+COUNTIFS($B$5:$B$101,B10,$A$5:$A$101,"<"&A10) -> 76 | E10: What-if (Controls!B11:B14)
A11: 185 | B11: 0.045482 | C11: =1+COUNTIF($B$5:$B$101,">"&B11)+COUNTIFS($B$5:$B$101,B11,$A$5:$A$101,"<"&A11) -> 83 | E11: capacity K | F11: =Controls!B11 -> 5
A12: 243 | B12: 0.124832 | C12: =1+COUNTIF($B$5:$B$101,">"&B12)+COUNTIFS($B$5:$B$101,B12,$A$5:$A$101,"<"&A12) -> 30 | E12: contact budget | F12: =ROUND(Controls!B11*Controls!B12,2) -> 40
A13: 247 | B13: 0.091857 | C13: =1+COUNTIF($B$5:$B$101,">"&B13)+COUNTIFS($B$5:$B$101,B13,$A$5:$A$101,"<"&A13) -> 49 | E13: HYPOTHETICAL expected value, 97 cohort accounts | F13: =ROUND(SUMPRODUCT(($C$5:$C$101<=Controls!B11)*($B$5:$B$101*Controls!B13*Controls!B14-Controls!B12)),2) -> 21.38
A14: 265 | B14: 0.161134 | C14: =1+COUNTIF($B$5:$B$101,">"&B14)+COUNTIFS($B$5:$B$101,B14,$A$5:$A$101,"<"&A14) -> 7 | E14: A what-if is an assumption, not an estimate. The same K and economics on the whole world cannot be recomputed here.
A15: 268 | B15: 0.12865 | C15: =1+COUNTIF($B$5:$B$101,">"&B15)+COUNTIFS($B$5:$B$101,B15,$A$5:$A$101,"<"&A15) -> 25
A16: 272 | B16: 0.159722 | C16: =1+COUNTIF($B$5:$B$101,">"&B16)+COUNTIFS($B$5:$B$101,B16,$A$5:$A$101,"<"&A16) -> 8 | E16: Outcomes: every row of the 2026-09-01 cutoff is censored at the as-of (label window closes 2026-12-14), so precision and recall of these queues are unknown, not zero.
A17: 291 | B17: 0.077542 | C17: =1+COUNTIF($B$5:$B$101,">"&B17)+COUNTIFS($B$5:$B$101,B17,$A$5:$A$101,"<"&A17) -> 56
A18: 317 | B18: 0.129433 | C18: =1+COUNTIF($B$5:$B$101,">"&B18)+COUNTIFS($B$5:$B$101,B18,$A$5:$A$101,"<"&A18) -> 23
A19: 383 | B19: 0.124025 | C19: =1+COUNTIF($B$5:$B$101,">"&B19)+COUNTIFS($B$5:$B$101,B19,$A$5:$A$101,"<"&A19) -> 32
A20: 421 | B20: 0.10545 | C20: =1+COUNTIF($B$5:$B$101,">"&B20)+COUNTIFS($B$5:$B$101,B20,$A$5:$A$101,"<"&A20) -> 43
A21: 445 | B21: 0.134482 | C21: =1+COUNTIF($B$5:$B$101,">"&B21)+COUNTIFS($B$5:$B$101,B21,$A$5:$A$101,"<"&A21) -> 18
A22: 449 | B22: 0.070662 | C22: =1+COUNTIF($B$5:$B$101,">"&B22)+COUNTIFS($B$5:$B$101,B22,$A$5:$A$101,"<"&A22) -> 58
A23: 468 | B23: 0.10052 | C23: =1+COUNTIF($B$5:$B$101,">"&B23)+COUNTIFS($B$5:$B$101,B23,$A$5:$A$101,"<"&A23) -> 44
A24: 680 | B24: 0.046693 | C24: =1+COUNTIF($B$5:$B$101,">"&B24)+COUNTIFS($B$5:$B$101,B24,$A$5:$A$101,"<"&A24) -> 81
A25: 700 | B25: 0.062069 | C25: =1+COUNTIF($B$5:$B$101,">"&B25)+COUNTIFS($B$5:$B$101,B25,$A$5:$A$101,"<"&A25) -> 64
A26: 703 | B26: 0.050384 | C26: =1+COUNTIF($B$5:$B$101,">"&B26)+COUNTIFS($B$5:$B$101,B26,$A$5:$A$101,"<"&A26) -> 77
A27: 712 | B27: 0.050384 | C27: =1+COUNTIF($B$5:$B$101,">"&B27)+COUNTIFS($B$5:$B$101,B27,$A$5:$A$101,"<"&A27) -> 78
A28: 754 | B28: 0.004575 | C28: =1+COUNTIF($B$5:$B$101,">"&B28)+COUNTIFS($B$5:$B$101,B28,$A$5:$A$101,"<"&A28) -> 97
... A101: 2296 | B101: 0.067519 | C101: =1+COUNTIF($B$5:$B$101,">"&B101)+COUNTIFS($B$5:$B$101,B101,$A$5:$A$101,"<"&A101) -> 60

Sheet Censored tail
A1: The censored tail by cutoff (D-01, D-07 DR-05): rows whose label window has not closed are excluded, never counted as retained
A2: World columns are TYPED from cutoff_aggregates.json (2,400 accounts); the cohort columns are TYPED from the loaded 200-account cohort (SQL 04). Shares and rates are formulas.
A4: cutoff | B4: range | C4: WORLD eligible | D4: world mature | E4: world censored | F4: world mature churned | G4: world censored share | H4: world mature churn rate | I4: published rate if censored rows were counted as non-churn | J4: implied cancellations seen so far | K4: COHORT eligible | L4: cohort censored | M4: cohort cancellations seen so far | N4: cohort censored share | O4: distance of the implied count from a whole number
A5: 45658 | B5: train | C5: 113 | D5: 113 | E5: 0 | F5: 12 | G5: =E5/C5 -> 0 | H5: =IF(D5=0,"",F5/D5) -> 0.10619469 | J5: =IF(ISNUMBER(I5),ROUND(I5*C5,0),"") | K5: 14 | L5: 0 | M5: 0 | N5: =L5/K5 -> 0 | O5: =IF(ISNUMBER(I5),ABS(J5-I5*C5),0) -> 0
A6: 45689 | B6: train | C6: 126 | D6: 126 | E6: 0 | F6: 13 | G6: =E6/C6 -> 0 | H6: =IF(D6=0,"",F6/D6) -> 0.1031746 | J6: =IF(ISNUMBER(I6),ROUND(I6*C6,0),"") | K6: 14 | L6: 0 | M6: 0 | N6: =L6/K6 -> 0 | O6: =IF(ISNUMBER(I6),ABS(J6-I6*C6),0) -> 0
A7: 45717 | B7: train | C7: 131 | D7: 131 | E7: 0 | F7: 12 | G7: =E7/C7 -> 0 | H7: =IF(D7=0,"",F7/D7) -> 0.091603053 | J7: =IF(ISNUMBER(I7),ROUND(I7*C7,0),"") | K7: 14 | L7: 0 | M7: 0 | N7: =L7/K7 -> 0 | O7: =IF(ISNUMBER(I7),ABS(J7-I7*C7),0) -> 0
A8: 45748 | B8: train | C8: 150 | D8: 150 | E8: 0 | F8: 12 | G8: =E8/C8 -> 0 | H8: =IF(D8=0,"",F8/D8) -> 0.08 | J8: =IF(ISNUMBER(I8),ROUND(I8*C8,0),"") | K8: 13 | L8: 0 | M8: 0 | N8: =L8/K8 -> 0 | O8: =IF(ISNUMBER(I8),ABS(J8-I8*C8),0) -> 0
A9: 45778 | B9: train | C9: 165 | D9: 165 | E9: 0 | F9: 13 | G9: =E9/C9 -> 0 | H9: =IF(D9=0,"",F9/D9) -> 0.078787879 | J9: =IF(ISNUMBER(I9),ROUND(I9*C9,0),"") | K9: 15 | L9: 0 | M9: 0 | N9: =L9/K9 -> 0 | O9: =IF(ISNUMBER(I9),ABS(J9-I9*C9),0) -> 0
A10: 45809 | B10: train | C10: 183 | D10: 183 | E10: 0 | F10: 17 | G10: =E10/C10 -> 0 | H10: =IF(D10=0,"",F10/D10) -> 0.092896175 | J10: =IF(ISNUMBER(I10),ROUND(I10*C10,0),"") | K10: 16 | L10: 0 | M10: 0 | N10: =L10/K10 -> 0 | O10: =IF(ISNUMBER(I10),ABS(J10-I10*C10),0) -> 0
A11: 45839 | B11: train | C11: 198 | D11: 198 | E11: 0 | F11: 20 | G11: =E11/C11 -> 0 | H11: =IF(D11=0,"",F11/D11) -> 0.1010101 | J11: =IF(ISNUMBER(I11),ROUND(I11*C11,0),"") | K11: 20 | L11: 0 | M11: 0 | N11: =L11/K11 -> 0 | O11: =IF(ISNUMBER(I11),ABS(J11-I11*C11),0) -> 0
A12: 45870 | B12: train | C12: 214 | D12: 214 | E12: 0 | F12: 27 | G12: =E12/C12 -> 0 | H12: =IF(D12=0,"",F12/D12) -> 0.12616822 | J12: =IF(ISNUMBER(I12),ROUND(I12*C12,0),"") | K12: 22 | L12: 0 | M12: 0 | N12: =L12/K12 -> 0 | O12: =IF(ISNUMBER(I12),ABS(J12-I12*C12),0) -> 0
A13: 45901 | B13: train | C13: 228 | D13: 228 | E13: 0 | F13: 23 | G13: =E13/C13 -> 0 | H13: =IF(D13=0,"",F13/D13) -> 0.10087719 | J13: =IF(ISNUMBER(I13),ROUND(I13*C13,0),"") | K13: 23 | L13: 0 | M13: 0 | N13: =L13/K13 -> 0 | O13: =IF(ISNUMBER(I13),ABS(J13-I13*C13),0) -> 0
A14: 45931 | B14: validation | C14: 300 | D14: 300 | E14: 0 | F14: 27 | G14: =E14/C14 -> 0 | H14: =IF(D14=0,"",F14/D14) -> 0.09 | J14: =IF(ISNUMBER(I14),ROUND(I14*C14,0),"") | K14: 24 | L14: 0 | M14: 0 | N14: =L14/K14 -> 0 | O14: =IF(ISNUMBER(I14),ABS(J14-I14*C14),0) -> 0
A15: 45962 | B15: validation | C15: 318 | D15: 318 | E15: 0 | F15: 25 | G15: =E15/C15 -> 0 | H15: =IF(D15=0,"",F15/D15) -> 0.078616352 | J15: =IF(ISNUMBER(I15),ROUND(I15*C15,0),"") | K15: 25 | L15: 0 | M15: 0 | N15: =L15/K15 -> 0 | O15: =IF(ISNUMBER(I15),ABS(J15-I15*C15),0) -> 0
A16: 45992 | B16: validation | C16: 329 | D16: 329 | E16: 0 | F16: 26 | G16: =E16/C16 -> 0 | H16: =IF(D16=0,"",F16/D16) -> 0.079027356 | J16: =IF(ISNUMBER(I16),ROUND(I16*C16,0),"") | K16: 28 | L16: 0 | M16: 0 | N16: =L16/K16 -> 0 | O16: =IF(ISNUMBER(I16),ABS(J16-I16*C16),0) -> 0
... A22: 46174 | B22: outside | C22: 1124 | D22: 1124 | E22: 0 | F22: 117 | G22: =E22/C22 -> 0 | H22: =IF(D22=0,"",F22/D22) -> 0.10409253 | J22: =IF(ISNUMBER(I22),ROUND(I22*C22,0),"") | K22: 90 | L22: 0 | M22: 0 | N22: =L22/K22 -> 0 | O22: =IF(ISNUMBER(I22),ABS(J22-I22*C22),0) -> 0
A23: 46204 | B23: outside | C23: 1154 | D23: 0 | E23: 1154 | F23: 0 | G23: =E23/C23 -> 1 | H23: =IF(D23=0,"",F23/D23) | I23: 0.094454 | J23: =IF(ISNUMBER(I23),ROUND(I23*C23,0),"") -> 109 | K23: 94 | L23: 94 | M23: 11 | N23: =L23/K23 -> 1 | O23: =IF(ISNUMBER(I23),ABS(J23-I23*C23),0) -> 8.4e-05
A24: 46235 | B24: outside | C24: 1199 | D24: 0 | E24: 1199 | F24: 0 | G24: =E24/C24 -> 1 | H24: =IF(D24=0,"",F24/D24) | I24: 0.069224 | J24: =IF(ISNUMBER(I24),ROUND(I24*C24,0),"") -> 83 | K24: 95 | L24: 95 | M24: 9 | N24: =L24/K24 -> 1 | O24: =IF(ISNUMBER(I24),ABS(J24-I24*C24),0) -> 0.000424
A25: 46266 | B25: outside | C25: 1241 | D25: 0 | E25: 1241 | F25: 0 | G25: =E25/C25 -> 1 | H25: =IF(D25=0,"",F25/D25) | I25: 0.038678 | J25: =IF(ISNUMBER(I25),ROUND(I25*C25,0),"") -> 48 | K25: 97 | L25: 97 | M25: 4 | N25: =L25/K25 -> 1 | O25: =IF(ISNUMBER(I25),ABS(J25-I25*C25),0) -> 0.000602
A26: Total | C26: =SUM(C5:C25) -> 9039 | D26: =SUM(D5:D25) -> 5445 | E26: =SUM(E5:E25) -> 3594 | F26: =SUM(F5:F25) -> 569 | G26: =E26/C26 -> 0.39761036 | H26: =F26/D26 -> 0.10449954 | K26: =SUM(K5:K25) -> 765 | L26: =SUM(L5:L25) -> 286 | M26: =SUM(M5:M25) -> 24 | N26: =L26/K26 -> 0.37385621
A28: If censored rows were counted as retained, the last three cutoffs would show 9.4 %, 6.9 % and 3.9 % churn (world) instead of an unknown: the rate collapses towards zero the nearer the cutoff is to the as-of.

Sheet Drift
A1: Population drift of usage_events_30d by region (D-03 P10-MET-11, D-P10-10)
A2: PSI = sum (actual - expected) x LN(actual / expected) over bins [0,1), [1,3), [3,inf); a zero proportion is replaced by 0.0001 (floored, counted). The 0.2 threshold is a diagnostic, not proof. Reference = the 2026-02-01 cohort.
A4: group | B4: cutoff index | C4: cur 0 | D4: cur 1-2 | E4: cur 3+ | F4: ref 0 | G4: ref 1-2 | H4: ref 3+ | I4: current rows | J4: reference rows | K4: floored bins | L4: PSI (workbook) | M4: exceeds 0.2 | N4: PSI published (full world) | O4: diff
A5: apac | B5: 0 | C5: =COUNTIFS('Test table'!$C$5:$C$1517,$B5,'Test table'!$F$5:$F$1517,"apac",'Test table'!$G$5:$G$1517,">=0",'Test table'!$G$5:$G$1517,"<1") -> 5 | D5: =COUNTIFS('Test table'!$C$5:$C$1517,$B5,'Test table'!$F$5:$F$1517,"apac",'Test table'!$G$5:$G$1517,">=1",'Test table'!$G$5:$G$1517,"<3") -> 7 | E5: =COUNTIFS('Test table'!$C$5:$C$1517,$B5,'Test table'!$F$5:$F$1517,"apac",'Test table'!$G$5:$G$1517,">=3") -> 45 | F5: =COUNTIFS('Test table'!$C$5:$C$1517,0,'Test table'!$F$5:$F$1517,"apac",'Test table'!$G$5:$G$1517,">=0",'Test table'!$G$5:$G$1517,"<1") -> 5 | G5: =COUNTIFS('Test table'!$C$5:$C$1517,0,'Test table'!$F$5:$F$1517,"apac",'Test table'!$G$5:$G$1517,">=1",'Test table'!$G$5:$G$1517,"<3") -> 7 | H5: =COUNTIFS('Test table'!$C$5:$C$1517,0,'Test table'!$F$5:$F$1517,"apac",'Test table'!$G$5:$G$1517,">=3") -> 45 | I5: =SUM(C5:E5) -> 57 | J5: =SUM(F5:H5) -> 57 | K5: =SUMPRODUCT(--((C5:E5=0)+(F5:H5=0)>0)) -> 0 | L5: =((IF(C5=0,0.0001,C5/$I5)-IF(F5=0,0.0001,F5/$J5))*LN(IF(C5=0,0.0001,C5/$I5)/IF(F5=0,0.0001,F5/$J5)))+((IF(D5=0,0.0001,D5/$I5)-IF(G5=0,0.0001,G5/$J5))*LN(IF(D5=0,0.0001,D5/$I5)/IF(G5=0,0.0001,G5/$J5)))+((IF(E5=0,0.0001,E5/$I5)-IF(H5=0,0.0001,H5/$J5))*LN(IF(E5=0,0.0001,E5/$I5)/IF(H5=0,0.0001,H5/$J5))) -> 0 | M5: =L5>0.2 -> FALSE | N5: 0 | O5: =ABS(L5-N5) -> 0
A6: apac | B6: 1 | C6: =COUNTIFS('Test table'!$C$5:$C$1517,$B6,'Test table'!$F$5:$F$1517,"apac",'Test table'!$G$5:$G$1517,">=0",'Test table'!$G$5:$G$1517,"<1") -> 1 | D6: =COUNTIFS('Test table'!$C$5:$C$1517,$B6,'Test table'!$F$5:$F$1517,"apac",'Test table'!$G$5:$G$1517,">=1",'Test table'!$G$5:$G$1517,"<3") -> 11 | E6: =COUNTIFS('Test table'!$C$5:$C$1517,$B6,'Test table'!$F$5:$F$1517,"apac",'Test table'!$G$5:$G$1517,">=3") -> 47 | F6: =COUNTIFS('Test table'!$C$5:$C$1517,0,'Test table'!$F$5:$F$1517,"apac",'Test table'!$G$5:$G$1517,">=0",'Test table'!$G$5:$G$1517,"<1") -> 5 | G6: =COUNTIFS('Test table'!$C$5:$C$1517,0,'Test table'!$F$5:$F$1517,"apac",'Test table'!$G$5:$G$1517,">=1",'Test table'!$G$5:$G$1517,"<3") -> 7 | H6: =COUNTIFS('Test table'!$C$5:$C$1517,0,'Test table'!$F$5:$F$1517,"apac",'Test table'!$G$5:$G$1517,">=3") -> 45 | I6: =SUM(C6:E6) -> 59 | J6: =SUM(F6:H6) -> 57 | K6: =SUMPRODUCT(--((C6:E6=0)+(F6:H6=0)>0)) -> 0 | L6: =((IF(C6=0,0.0001,C6/$I6)-IF(F6=0,0.0001,F6/$J6))*LN(IF(C6=0,0.0001,C6/$I6)/IF(F6=0,0.0001,F6/$J6)))+((IF(D6=0,0.0001,D6/$I6)-IF(G6=0,0.0001,G6/$J6))*LN(IF(D6=0,0.0001,D6/$I6)/IF(G6=0,0.0001,G6/$J6)))+((IF(E6=0,0.0001,E6/$I6)-IF(H6=0,0.0001,H6/$J6))*LN(IF(E6=0,0.0001,E6/$I6)/IF(H6=0,0.0001,H6/$J6))) -> 0.14297195 | M6: =L6>0.2 -> FALSE | N6: 0.142972 | O6: =ABS(L6-N6) -> 4.5695247e-08
A7: apac | B7: 2 | C7: =COUNTIFS('Test table'!$C$5:$C$1517,$B7,'Test table'!$F$5:$F$1517,"apac",'Test table'!$G$5:$G$1517,">=0",'Test table'!$G$5:$G$1517,"<1") -> 3 | D7: =COUNTIFS('Test table'!$C$5:$C$1517,$B7,'Test table'!$F$5:$F$1517,"apac",'Test table'!$G$5:$G$1517,">=1",'Test table'!$G$5:$G$1517,"<3") -> 12 | E7: =COUNTIFS('Test table'!$C$5:$C$1517,$B7,'Test table'!$F$5:$F$1517,"apac",'Test table'!$G$5:$G$1517,">=3") -> 46 | F7: =COUNTIFS('Test table'!$C$5:$C$1517,0,'Test table'!$F$5:$F$1517,"apac",'Test table'!$G$5:$G$1517,">=0",'Test table'!$G$5:$G$1517,"<1") -> 5 | G7: =COUNTIFS('Test table'!$C$5:$C$1517,0,'Test table'!$F$5:$F$1517,"apac",'Test table'!$G$5:$G$1517,">=1",'Test table'!$G$5:$G$1517,"<3") -> 7 | H7: =COUNTIFS('Test table'!$C$5:$C$1517,0,'Test table'!$F$5:$F$1517,"apac",'Test table'!$G$5:$G$1517,">=3") -> 45 | I7: =SUM(C7:E7) -> 61 | J7: =SUM(F7:H7) -> 57 | K7: =SUMPRODUCT(--((C7:E7=0)+(F7:H7=0)>0)) -> 0 | L7: =((IF(C7=0,0.0001,C7/$I7)-IF(F7=0,0.0001,F7/$J7))*LN(IF(C7=0,0.0001,C7/$I7)/IF(F7=0,0.0001,F7/$J7)))+((IF(D7=0,0.0001,D7/$I7)-IF(G7=0,0.0001,G7/$J7))*LN(IF(D7=0,0.0001,D7/$I7)/IF(G7=0,0.0001,G7/$J7)))+((IF(E7=0,0.0001,E7/$I7)-IF(H7=0,0.0001,H7/$J7))*LN(IF(E7=0,0.0001,E7/$I7)/IF(H7=0,0.0001,H7/$J7))) -> 0.058748728 | M7: =L7>0.2 -> FALSE | N7: 0.058749 | O7: =ABS(L7-N7) -> 2.7157132e-07
A8: apac | B8: 3 | C8: =COUNTIFS('Test table'!$C$5:$C$1517,$B8,'Test table'!$F$5:$F$1517,"apac",'Test table'!$G$5:$G$1517,">=0",'Test table'!$G$5:$G$1517,"<1") -> 8 | D8: =COUNTIFS('Test table'!$C$5:$C$1517,$B8,'Test table'!$F$5:$F$1517,"apac",'Test table'!$G$5:$G$1517,">=1",'Test table'!$G$5:$G$1517,"<3") -> 22 | E8: =COUNTIFS('Test table'!$C$5:$C$1517,$B8,'Test table'!$F$5:$F$1517,"apac",'Test table'!$G$5:$G$1517,">=3") -> 26 | F8: =COUNTIFS('Test table'!$C$5:$C$1517,0,'Test table'!$F$5:$F$1517,"apac",'Test table'!$G$5:$G$1517,">=0",'Test table'!$G$5:$G$1517,"<1") -> 5 | G8: =COUNTIFS('Test table'!$C$5:$C$1517,0,'Test table'!$F$5:$F$1517,"apac",'Test table'!$G$5:$G$1517,">=1",'Test table'!$G$5:$G$1517,"<3") -> 7 | H8: =COUNTIFS('Test table'!$C$5:$C$1517,0,'Test table'!$F$5:$F$1517,"apac",'Test table'!$G$5:$G$1517,">=3") -> 45 | I8: =SUM(C8:E8) -> 56 | J8: =SUM(F8:H8) -> 57 | K8: =SUMPRODUCT(--((C8:E8=0)+(F8:H8=0)>0)) -> 0 | L8: =((IF(C8=0,0.0001,C8/$I8)-IF(F8=0,0.0001,F8/$J8))*LN(IF(C8=0,0.0001,C8/$I8)/IF(F8=0,0.0001,F8/$J8)))+((IF(D8=0,0.0001,D8/$I8)-IF(G8=0,0.0001,G8/$J8))*LN(IF(D8=0,0.0001,D8/$I8)/IF(G8=0,0.0001,G8/$J8)))+((IF(E8=0,0.0001,E8/$I8)-IF(H8=0,0.0001,H8/$J8))*LN(IF(E8=0,0.0001,E8/$I8)/IF(H8=0,0.0001,H8/$J8))) -> 0.51354516 | M8: =L8>0.2 -> TRUE | N8: 0.513545 | O8: =ABS(L8-N8) -> 1.575726e-07
A9: other_regions | B9: 0 | C9: =COUNTIFS('Test table'!$C$5:$C$1517,$B9,'Test table'!$F$5:$F$1517,"<>apac",'Test table'!$G$5:$G$1517,">=0",'Test table'!$G$5:$G$1517,"<1") -> 9 | D9: =COUNTIFS('Test table'!$C$5:$C$1517,$B9,'Test table'!$F$5:$F$1517,"<>apac",'Test table'!$G$5:$G$1517,">=1",'Test table'!$G$5:$G$1517,"<3") -> 61 | E9: =COUNTIFS('Test table'!$C$5:$C$1517,$B9,'Test table'!$F$5:$F$1517,"<>apac",'Test table'!$G$5:$G$1517,">=3") -> 237 | F9: =COUNTIFS('Test table'!$C$5:$C$1517,0,'Test table'!$F$5:$F$1517,"<>apac",'Test table'!$G$5:$G$1517,">=0",'Test table'!$G$5:$G$1517,"<1") -> 9 | G9: =COUNTIFS('Test table'!$C$5:$C$1517,0,'Test table'!$F$5:$F$1517,"<>apac",'Test table'!$G$5:$G$1517,">=1",'Test table'!$G$5:$G$1517,"<3") -> 61 | H9: =COUNTIFS('Test table'!$C$5:$C$1517,0,'Test table'!$F$5:$F$1517,"<>apac",'Test table'!$G$5:$G$1517,">=3") -> 237 | I9: =SUM(C9:E9) -> 307 | J9: =SUM(F9:H9) -> 307 | K9: =SUMPRODUCT(--((C9:E9=0)+(F9:H9=0)>0)) -> 0 | L9: =((IF(C9=0,0.0001,C9/$I9)-IF(F9=0,0.0001,F9/$J9))*LN(IF(C9=0,0.0001,C9/$I9)/IF(F9=0,0.0001,F9/$J9)))+((IF(D9=0,0.0001,D9/$I9)-IF(G9=0,0.0001,G9/$J9))*LN(IF(D9=0,0.0001,D9/$I9)/IF(G9=0,0.0001,G9/$J9)))+((IF(E9=0,0.0001,E9/$I9)-IF(H9=0,0.0001,H9/$J9))*LN(IF(E9=0,0.0001,E9/$I9)/IF(H9=0,0.0001,H9/$J9))) -> 0 | M9: =L9>0.2 -> FALSE | N9: 0 | O9: =ABS(L9-N9) -> 0
A10: other_regions | B10: 1 | C10: =COUNTIFS('Test table'!$C$5:$C$1517,$B10,'Test table'!$F$5:$F$1517,"<>apac",'Test table'!$G$5:$G$1517,">=0",'Test table'!$G$5:$G$1517,"<1") -> 4 | D10: =COUNTIFS('Test table'!$C$5:$C$1517,$B10,'Test table'!$F$5:$F$1517,"<>apac",'Test table'!$G$5:$G$1517,">=1",'Test table'!$G$5:$G$1517,"<3") -> 55 | E10: =COUNTIFS('Test table'!$C$5:$C$1517,$B10,'Test table'!$F$5:$F$1517,"<>apac",'Test table'!$G$5:$G$1517,">=3") -> 254 | F10: =COUNTIFS('Test table'!$C$5:$C$1517,0,'Test table'!$F$5:$F$1517,"<>apac",'Test table'!$G$5:$G$1517,">=0",'Test table'!$G$5:$G$1517,"<1") -> 9 | G10: =COUNTIFS('Test table'!$C$5:$C$1517,0,'Test table'!$F$5:$F$1517,"<>apac",'Test table'!$G$5:$G$1517,">=1",'Test table'!$G$5:$G$1517,"<3") -> 61 | H10: =COUNTIFS('Test table'!$C$5:$C$1517,0,'Test table'!$F$5:$F$1517,"<>apac",'Test table'!$G$5:$G$1517,">=3") -> 237 | I10: =SUM(C10:E10) -> 313 | J10: =SUM(F10:H10) -> 307 | K10: =SUMPRODUCT(--((C10:E10=0)+(F10:H10=0)>0)) -> 0 | L10: =((IF(C10=0,0.0001,C10/$I10)-IF(F10=0,0.0001,F10/$J10))*LN(IF(C10=0,0.0001,C10/$I10)/IF(F10=0,0.0001,F10/$J10)))+((IF(D10=0,0.0001,D10/$I10)-IF(G10=0,0.0001,G10/$J10))*LN(IF(D10=0,0.0001,D10/$I10)/IF(G10=0,0.0001,G10/$J10)))+((IF(E10=0,0.0001,E10/$I10)-IF(H10=0,0.0001,H10/$J10))*LN(IF(E10=0,0.0001,E10/$I10)/IF(H10=0,0.0001,H10/$J10))) -> 0.018526395 | M10: =L10>0.2 -> FALSE | N10: 0.018526 | O10: =ABS(L10-N10) -> 3.9465349e-07
A11: other_regions | B11: 2 | C11: =COUNTIFS('Test table'!$C$5:$C$1517,$B11,'Test table'!$F$5:$F$1517,"<>apac",'Test table'!$G$5:$G$1517,">=0",'Test table'!$G$5:$G$1517,"<1") -> 8 | D11: =COUNTIFS('Test table'!$C$5:$C$1517,$B11,'Test table'!$F$5:$F$1517,"<>apac",'Test table'!$G$5:$G$1517,">=1",'Test table'!$G$5:$G$1517,"<3") -> 49 | E11: =COUNTIFS('Test table'!$C$5:$C$1517,$B11,'Test table'!$F$5:$F$1517,"<>apac",'Test table'!$G$5:$G$1517,">=3") -> 267 | F11: =COUNTIFS('Test table'!$C$5:$C$1517,0,'Test table'!$F$5:$F$1517,"<>apac",'Test table'!$G$5:$G$1517,">=0",'Test table'!$G$5:$G$1517,"<1") -> 9 | G11: =COUNTIFS('Test table'!$C$5:$C$1517,0,'Test table'!$F$5:$F$1517,"<>apac",'Test table'!$G$5:$G$1517,">=1",'Test table'!$G$5:$G$1517,"<3") -> 61 | H11: =COUNTIFS('Test table'!$C$5:$C$1517,0,'Test table'!$F$5:$F$1517,"<>apac",'Test table'!$G$5:$G$1517,">=3") -> 237 | I11: =SUM(C11:E11) -> 324 | J11: =SUM(F11:H11) -> 307 | K11: =SUMPRODUCT(--((C11:E11=0)+(F11:H11=0)>0)) -> 0 | L11: =((IF(C11=0,0.0001,C11/$I11)-IF(F11=0,0.0001,F11/$J11))*LN(IF(C11=0,0.0001,C11/$I11)/IF(F11=0,0.0001,F11/$J11)))+((IF(D11=0,0.0001,D11/$I11)-IF(G11=0,0.0001,G11/$J11))*LN(IF(D11=0,0.0001,D11/$I11)/IF(G11=0,0.0001,G11/$J11)))+((IF(E11=0,0.0001,E11/$I11)-IF(H11=0,0.0001,H11/$J11))*LN(IF(E11=0,0.0001,E11/$I11)/IF(H11=0,0.0001,H11/$J11))) -> 0.017149714 | M11: =L11>0.2 -> FALSE | N11: 0.01715 | O11: =ABS(L11-N11) -> 2.8562217e-07
A12: other_regions | B12: 3 | C12: =COUNTIFS('Test table'!$C$5:$C$1517,$B12,'Test table'!$F$5:$F$1517,"<>apac",'Test table'!$G$5:$G$1517,">=0",'Test table'!$G$5:$G$1517,"<1") -> 5 | D12: =COUNTIFS('Test table'!$C$5:$C$1517,$B12,'Test table'!$F$5:$F$1517,"<>apac",'Test table'!$G$5:$G$1517,">=1",'Test table'!$G$5:$G$1517,"<3") -> 72 | E12: =COUNTIFS('Test table'!$C$5:$C$1517,$B12,'Test table'!$F$5:$F$1517,"<>apac",'Test table'!$G$5:$G$1517,">=3") -> 259 | F12: =COUNTIFS('Test table'!$C$5:$C$1517,0,'Test table'!$F$5:$F$1517,"<>apac",'Test table'!$G$5:$G$1517,">=0",'Test table'!$G$5:$G$1517,"<1") -> 9 | G12: =COUNTIFS('Test table'!$C$5:$C$1517,0,'Test table'!$F$5:$F$1517,"<>apac",'Test table'!$G$5:$G$1517,">=1",'Test table'!$G$5:$G$1517,"<3") -> 61 | H12: =COUNTIFS('Test table'!$C$5:$C$1517,0,'Test table'!$F$5:$F$1517,"<>apac",'Test table'!$G$5:$G$1517,">=3") -> 237 | I12: =SUM(C12:E12) -> 336 | J12: =SUM(F12:H12) -> 307 | K12: =SUMPRODUCT(--((C12:E12=0)+(F12:H12=0)>0)) -> 0 | L12: =((IF(C12=0,0.0001,C12/$I12)-IF(F12=0,0.0001,F12/$J12))*LN(IF(C12=0,0.0001,C12/$I12)/IF(F12=0,0.0001,F12/$J12)))+((IF(D12=0,0.0001,D12/$I12)-IF(G12=0,0.0001,G12/$J12))*LN(IF(D12=0,0.0001,D12/$I12)/IF(G12=0,0.0001,G12/$J12)))+((IF(E12=0,0.0001,E12/$I12)-IF(H12=0,0.0001,H12/$J12))*LN(IF(E12=0,0.0001,E12/$I12)/IF(H12=0,0.0001,H12/$J12))) -> 0.010966776 | M12: =L12>0.2 -> FALSE | N12: 0.010967 | O12: =ABS(L12-N12) -> 2.2371569e-07
A13: all_accounts | B13: 0 | C13: =COUNTIFS('Test table'!$C$5:$C$1517,$B13,'Test table'!$G$5:$G$1517,">=0",'Test table'!$G$5:$G$1517,"<1") -> 14 | D13: =COUNTIFS('Test table'!$C$5:$C$1517,$B13,'Test table'!$G$5:$G$1517,">=1",'Test table'!$G$5:$G$1517,"<3") -> 68 | E13: =COUNTIFS('Test table'!$C$5:$C$1517,$B13,'Test table'!$G$5:$G$1517,">=3") -> 282 | F13: =COUNTIFS('Test table'!$C$5:$C$1517,0,'Test table'!$G$5:$G$1517,">=0",'Test table'!$G$5:$G$1517,"<1") -> 14 | G13: =COUNTIFS('Test table'!$C$5:$C$1517,0,'Test table'!$G$5:$G$1517,">=1",'Test table'!$G$5:$G$1517,"<3") -> 68 | H13: =COUNTIFS('Test table'!$C$5:$C$1517,0,'Test table'!$G$5:$G$1517,">=3") -> 282 | I13: =SUM(C13:E13) -> 364 | J13: =SUM(F13:H13) -> 364 | K13: =SUMPRODUCT(--((C13:E13=0)+(F13:H13=0)>0)) -> 0 | L13: =((IF(C13=0,0.0001,C13/$I13)-IF(F13=0,0.0001,F13/$J13))*LN(IF(C13=0,0.0001,C13/$I13)/IF(F13=0,0.0001,F13/$J13)))+((IF(D13=0,0.0001,D13/$I13)-IF(G13=0,0.0001,G13/$J13))*LN(IF(D13=0,0.0001,D13/$I13)/IF(G13=0,0.0001,G13/$J13)))+((IF(E13=0,0.0001,E13/$I13)-IF(H13=0,0.0001,H13/$J13))*LN(IF(E13=0,0.0001,E13/$I13)/IF(H13=0,0.0001,H13/$J13))) -> 0 | M13: =L13>0.2 -> FALSE | N13: 0 | O13: =ABS(L13-N13) -> 0
A14: all_accounts | B14: 1 | C14: =COUNTIFS('Test table'!$C$5:$C$1517,$B14,'Test table'!$G$5:$G$1517,">=0",'Test table'!$G$5:$G$1517,"<1") -> 5 | D14: =COUNTIFS('Test table'!$C$5:$C$1517,$B14,'Test table'!$G$5:$G$1517,">=1",'Test table'!$G$5:$G$1517,"<3") -> 66 | E14: =COUNTIFS('Test table'!$C$5:$C$1517,$B14,'Test table'!$G$5:$G$1517,">=3") -> 301 | F14: =COUNTIFS('Test table'!$C$5:$C$1517,0,'Test table'!$G$5:$G$1517,">=0",'Test table'!$G$5:$G$1517,"<1") -> 14 | G14: =COUNTIFS('Test table'!$C$5:$C$1517,0,'Test table'!$G$5:$G$1517,">=1",'Test table'!$G$5:$G$1517,"<3") -> 68 | H14: =COUNTIFS('Test table'!$C$5:$C$1517,0,'Test table'!$G$5:$G$1517,">=3") -> 282 | I14: =SUM(C14:E14) -> 372 | J14: =SUM(F14:H14) -> 364 | K14: =SUMPRODUCT(--((C14:E14=0)+(F14:H14=0)>0)) -> 0 | L14: =((IF(C14=0,0.0001,C14/$I14)-IF(F14=0,0.0001,F14/$J14))*LN(IF(C14=0,0.0001,C14/$I14)/IF(F14=0,0.0001,F14/$J14)))+((IF(D14=0,0.0001,D14/$I14)-IF(G14=0,0.0001,G14/$J14))*LN(IF(D14=0,0.0001,D14/$I14)/IF(G14=0,0.0001,G14/$J14)))+((IF(E14=0,0.0001,E14/$I14)-IF(H14=0,0.0001,H14/$J14))*LN(IF(E14=0,0.0001,E14/$I14)/IF(H14=0,0.0001,H14/$J14))) -> 0.028286146 | M14: =L14>0.2 -> FALSE | N14: 0.028286 | O14: =ABS(L14-N14) -> 1.4585323e-07
A15: all_accounts | B15: 2 | C15: =COUNTIFS('Test table'!$C$5:$C$1517,$B15,'Test table'!$G$5:$G$1517,">=0",'Test table'!$G$5:$G$1517,"<1") -> 11 | D15: =COUNTIFS('Test table'!$C$5:$C$1517,$B15,'Test table'!$G$5:$G$1517,">=1",'Test table'!$G$5:$G$1517,"<3") -> 61 | E15: =COUNTIFS('Test table'!$C$5:$C$1517,$B15,'Test table'!$G$5:$G$1517,">=3") -> 313 | F15: =COUNTIFS('Test table'!$C$5:$C$1517,0,'Test table'!$G$5:$G$1517,">=0",'Test table'!$G$5:$G$1517,"<1") -> 14 | G15: =COUNTIFS('Test table'!$C$5:$C$1517,0,'Test table'!$G$5:$G$1517,">=1",'Test table'!$G$5:$G$1517,"<3") -> 68 | H15: =COUNTIFS('Test table'!$C$5:$C$1517,0,'Test table'!$G$5:$G$1517,">=3") -> 282 | I15: =SUM(C15:E15) -> 385 | J15: =SUM(F15:H15) -> 364 | K15: =SUMPRODUCT(--((C15:E15=0)+(F15:H15=0)>0)) -> 0 | L15: =((IF(C15=0,0.0001,C15/$I15)-IF(F15=0,0.0001,F15/$J15))*LN(IF(C15=0,0.0001,C15/$I15)/IF(F15=0,0.0001,F15/$J15)))+((IF(D15=0,0.0001,D15/$I15)-IF(G15=0,0.0001,G15/$J15))*LN(IF(D15=0,0.0001,D15/$I15)/IF(G15=0,0.0001,G15/$J15)))+((IF(E15=0,0.0001,E15/$I15)-IF(H15=0,0.0001,H15/$J15))*LN(IF(E15=0,0.0001,E15/$I15)/IF(H15=0,0.0001,H15/$J15))) -> 0.009457789 | M15: =L15>0.2 -> FALSE | N15: 0.009458 | O15: =ABS(L15-N15) -> 2.1096131e-07
