Workbook

Sheet Read me
A1: ChangeWorks analyst workbook (P09-ART-05)
A3: What it is | B3: A formula-driven recomputation of the ChangeWorks scenario model over the published synthetic snapshot cw-20261026-20261026 (dataset hash 6bf7ebaad6bf75084c82c41de1031d6d585af730c8a22979ed7c77df2a38e3a9, code revision 29948f9, as-of 2026-10-05T00:00:00Z): 24 initiatives, 30 scenarios, 900 cost rows, 700 benefit rows, 36 monthly periods from 2026-01.
A4: The decision | B4: Which transformation initiative should be funded and how will success be established? The workbook shows each initiative's dated cash flow, NPV and both paybacks in the selected scenario, the four benefit classes kept apart and the attributable portfolio NPV beside the plain sum. Nothing here funds anything: a selected scenario is a proposal.
A5: Synthetic data | B5: Everything is synthetic (a seeded generator). Observed = what this one draw shows; constructed = what the generator built in on purpose (its designed relationships DR-01..DR-07 and injected defects INJ-01..INJ-12); every NPV is a plan estimate; no benefit to a real organisation is claimed.
A6: How to use it | B6: Open the .xlsx in any spreadsheet application; nothing needs installing to read the cached values. Controls!B3 switches the scenario; Controls!B4 overrides the period rate; Checks!B2 is TRUE when every figure agrees with the Python domain, the SQL ledger and the golden hand answer.
A7: Recalculation status | B7: openpyxl wrote formulas only; LibreOffice (headless) recalculated the delivered file. Microsoft Excel was NOT run: nothing here was opened or recalculated by Excel (docs/workbook.md).
A8: Sheets | B8: Controls, Checks, Portfolio, Initiatives, Cash flow, Golden case, Assumptions (read-this-first limits), data sheets (Benefits, Costs, Scenario inputs, Scenarios, Periods), Domain reference (pasted values), SQL results (pasted).
A9: Colour | B9: Blue = typed input or pasted value; black = formula.

Sheet Controls
A1: Controls
A2: Change B3 to any stored scenario: every sheet follows it. B4 overrides the period rate (blank = the scenario's own rate; the checks against the domain stand down while it is set). Blue cells are inputs.
A3: Scenario (switch) | B3: scn-025
A4: Period-rate override (blank = the scenario's rate)
A5: Period basis of the dataset | B5: monthly
A6: As-of (UTC) | B6: 46300
A7: First period starts | B7: 46023
A9: Selected scenario's declared rate and basis | B9: =INDEX(Scenarios!$D$4:$D$33,MATCH($B$3,Scenarios!$A$4:$A$33,0))&" "&INDEX(Scenarios!$C$4:$C$33,MATCH($B$3,Scenarios!$A$4:$A$33,0)) -> 0.08 annual
A10: Rate source | B10: =INDEX(Scenarios!$J$4:$J$33,MATCH($B$3,Scenarios!$A$4:$A$33,0)) -> conversion
A11: Effective period rate used | B11: =IF(LEN(B4)>0,B4,INDEX(Scenarios!$I$4:$I$33,MATCH($B$3,Scenarios!$A$4:$A$33,0))) -> 0.006434
A12: Horizon (periods) | B12: =INDEX(Scenarios!$F$4:$F$33,MATCH($B$3,Scenarios!$A$4:$A$33,0)) -> 36
A13: Matured periods at the as-of | B13: =SUM(Periods!D4:D39) -> 9
A15: All checks pass (Checks!B2) | B15: =Checks!B2 -> TRUE
A16: Attributable NPV of the selected scenario (Portfolio!B19) | B16: =Portfolio!B19 -> 1243149.1

Sheet Checks
A1: Checks: TRUE when every comparison with the Python domain, the SQL ledger and the golden hand answer holds
A2: All checks pass | B2: =AND(Portfolio!E4:E19,Initiatives!U4:U27,'Golden case'!E8,'Golden case'!E9,'Golden case'!E10,'Golden case'!E11,'Golden case'!E12,'Golden case'!E13,'Golden case'!E15,'Golden case'!E16,'Golden case'!E17,'Golden case'!E18,'Golden case'!E19,'Golden case'!E20,B5,B6,B7) -> TRUE
A4: check | B4: result
A5: Every benefit row has a class when its initiative is in the scenario and the row is inside the horizon, and none otherwise | B5: =SUMPRODUCT((Benefits!N4:N703=TRUE())*(Benefits!R4:R703=""))+SUMPRODUCT((Benefits!N4:N703=FALSE())*(Benefits!R4:R703<>""))=0 -> TRUE
A6: Every recurring cost row expands to end - start periods and every one-time row to exactly one (Costs!L) | B6: =SUMPRODUCT((Costs!C4:C903="one_time")*(Costs!L4:L903<>1))=0 -> TRUE
A7: The scenario switch names a stored scenario | B7: =COUNTIF(Scenarios!A4:A33,Controls!B3)=1 -> TRUE

Sheet Portfolio
A1: The portfolio ledger of the selected scenario: four benefit classes apart, the attributable totals beside the plain sums, checked against the domain and the SQL ledger
A2: Column B is a formula over the data sheets; C is the reference (pasted, `Domain reference`); D is the tolerance; E is TRUE when they agree (or when the rate override is in use: see Controls!B4).
A3: measure (USD unless hours) | B3: workbook (formula) | C3: reference (pasted) | D3: tolerance | E3: check
A4: initiatives in the scenario | B4: =SUM(Initiatives!B4:B27) -> 24 | C4: =INDEX(Scenarios!$H$4:$H$33,MATCH(Controls!$B$3,Scenarios!$A$4:$A$33,0)) -> 24 | D4: 0 | E4: =IF(LEN(Controls!$B$4)>0,TRUE(),ABS(B4-C4)<=D4) -> TRUE
A5: planned costs (inside the horizon, recurring rows expanded) | B5: =SUM('Cash flow'!E4:E867) -> 25914200 | C5: =INDEX('Domain reference'!$I$4:$I$33,MATCH(Controls!$B$3,'Domain reference'!$A$4:$A$33,0)) -> 25914200 | D5: 0.005 | E5: =IF(LEN(Controls!$B$4)>0,TRUE(),ABS(B5-C5)<=D5) -> TRUE
A6: cash benefits (enter the flow) | B6: =SUM('Cash flow'!F4:F867) -> 15288067 | C6: =INDEX('Domain reference'!$J$4:$J$33,MATCH(Controls!$B$3,'Domain reference'!$A$4:$A$33,0)) -> 15288067 | D6: 0.005 | E6: =IF(LEN(Controls!$B$4)>0,TRUE(),ABS(B6-C6)<=D6) -> TRUE
A7: revenue (enters the flow) | B7: =SUM('Cash flow'!G4:G867) -> 6074000.1 | C7: =INDEX('Domain reference'!$K$4:$K$33,MATCH(Controls!$B$3,'Domain reference'!$A$4:$A$33,0)) -> 6074000.1 | D7: 0.005 | E7: =IF(LEN(Controls!$B$4)>0,TRUE(),ABS(B7-C7)<=D7) -> TRUE
A8: avoided cost realised (cash_realisation and evidence) | B8: =SUM('Cash flow'!H4:H867) -> 5516433.3 | C8: =INDEX('Domain reference'!$L$4:$L$33,MATCH(Controls!$B$3,'Domain reference'!$A$4:$A$33,0)) -> 5516433.3 | D8: 0.005 | E8: =IF(LEN(Controls!$B$4)>0,TRUE(),ABS(B8-C8)<=D8) -> TRUE
A9: capacity converted to money (a conversion rate with staffing evidence) | B9: =SUM('Cash flow'!I4:I867) -> 1774010.6 | C9: =INDEX('Domain reference'!$M$4:$M$33,MATCH(Controls!$B$3,'Domain reference'!$A$4:$A$33,0)) -> 1774010.6 | D9: 0.005 | E9: =IF(LEN(Controls!$B$4)>0,TRUE(),ABS(B9-C9)<=D9) -> TRUE
A10: avoided cost beside the cash flow (never in it) | B10: =SUMIFS(Benefits!S4:S703,Benefits!R4:R703,"avoided_cost_beside") -> 4025383.5 | C10: =INDEX('Domain reference'!$N$4:$N$33,MATCH(Controls!$B$3,'Domain reference'!$A$4:$A$33,0)) -> 4025383.5 | D10: 0.005 | E10: =IF(LEN(Controls!$B$4)>0,TRUE(),ABS(B10-C10)<=D10) -> TRUE
A11: capacity hours not converted (hours, never added to dollars) | B11: =SUMIFS(Benefits!P4:P703,Benefits!R4:R703,"capacity_hours") -> 145045.62 | C11: =INDEX('Domain reference'!$O$4:$O$33,MATCH(Controls!$B$3,'Domain reference'!$A$4:$A$33,0)) -> 145045.62 | D11: 0.005 | E11: =IF(LEN(Controls!$B$4)>0,TRUE(),ABS(B11-C11)<=D11) -> TRUE
A12: planned benefits: the plain sum of the money claims | B12: =SUM(B6:B9)+B10 -> 32677895 | C12: =INDEX('Domain reference'!$E$4:$E$33,MATCH(Controls!$B$3,'Domain reference'!$A$4:$A$33,0)) -> 32677895 | D12: 0.005 | E12: =IF(LEN(Controls!$B$4)>0,TRUE(),ABS(B12-C12)<=D12) -> TRUE
A13: double-counted amount (the residual): claims beyond the largest of a shared key | B13: =SUM(Benefits!X4:X703) -> 207146.32 | C13: =INDEX('Domain reference'!$F$4:$F$33,MATCH(Controls!$B$3,'Domain reference'!$A$4:$A$33,0)) -> 207146.32 | D13: 0.005 | E13: =IF(LEN(Controls!$B$4)>0,TRUE(),ABS(B13-C13)<=D13) -> TRUE
A14: attributable benefits | B14: =B12-B13 -> 32470748 | C14: =INDEX('Domain reference'!$P$4:$P$33,MATCH(Controls!$B$3,'Domain reference'!$A$4:$A$33,0)) -> 32470748 | D14: 0.005 | E14: =IF(LEN(Controls!$B$4)>0,TRUE(),ABS(B14-C14)<=D14) -> TRUE
A15: capacity hours planned (every capacity row, converted or not) | B15: =SUMIFS(Benefits!P4:P703,Benefits!E4:E703,"capacity",Benefits!N4:N703,TRUE()) -> 194875.92 | C15: =INDEX('Domain reference'!$G$4:$G$33,MATCH(Controls!$B$3,'Domain reference'!$A$4:$A$33,0)) -> 194875.92 | D15: 0.005 | E15: =IF(LEN(Controls!$B$4)>0,TRUE(),ABS(B15-C15)<=D15) -> TRUE
A16: hours residual (shared capacity counted twice) | B16: =SUM(Benefits!AC4:AC703) -> 5974.8 | C16: =INDEX('Domain reference'!$H$4:$H$33,MATCH(Controls!$B$3,'Domain reference'!$A$4:$A$33,0)) -> 5974.8 | D16: 0.005 | E16: =IF(LEN(Controls!$B$4)>0,TRUE(),ABS(B16-C16)<=D16) -> TRUE
A17: NPV, plain sum of the initiative NPVs | B17: =SUM(Initiatives!G4:G27) -> 1438382.3 | C17: =INDEX('Domain reference'!$B$4:$B$33,MATCH(Controls!$B$3,'Domain reference'!$A$4:$A$33,0)) -> 1438382.2 | D17: 0.005 | E17: =IF(LEN(Controls!$B$4)>0,TRUE(),ABS(B17-C17)<=D17) -> TRUE
A18: present value of the claims counted twice (double_counted_pv) | B18: =SUM(Benefits!Y4:Y703) -> 195233.2 | C18: =INDEX('Domain reference'!$C$4:$C$33,MATCH(Controls!$B$3,'Domain reference'!$A$4:$A$33,0)) -> 195233.2 | D18: 0.005 | E18: =IF(LEN(Controls!$B$4)>0,TRUE(),ABS(B18-C18)<=D18) -> TRUE
A19: NPV, attributable (the headline) | B19: =B17-B18 -> 1243149.1 | C19: =INDEX('Domain reference'!$D$4:$D$33,MATCH(Controls!$B$3,'Domain reference'!$A$4:$A$33,0)) -> 1243149.1 | D19: 0.005 | E19: =IF(LEN(Controls!$B$4)>0,TRUE(),ABS(B19-C19)<=D19) -> TRUE
A20: initiatives that never pay back (simple) | B20: =SUMPRODUCT((Initiatives!B4:B27=1)*(Initiatives!K4:K27<>"")) -> 6

Sheet Initiatives
A1: Each initiative in the selected scenario: costs, benefits entering, NPV, both paybacks by the last crossing, checked against the domain
A2: A payback is the first period after the last negative cumulative; never negative = NO_INVESTMENT; ending negative = NOT_RECOVERED; no rows at all = NO_FLOWS (R9-12). Checks compare with `Domain reference` for the same scenario.
A3: initiative_id | B3: member | C3: has_flows | D3: planned_costs | E3: benefits_entering | F3: net_total | G3: npv | H3: negatives | I3: last_negative_plus_1 | J3: simple_payback | K3: simple_reason | L3: simple_interpolated | M3: negatives_discounted | N3: last_negative_discounted_plus_1 | O3: discounted_payback | P3: discounted_reason | Q3: discounted_interpolated | R3: domain npv | S3: domain simple | T3: domain discounted | U3: check
A4: init-001 | B4: =IF(COUNTIF('Scenario inputs'!$A$4:$A$213,Controls!$B$3&"|"&A4)>0,1,0) -> 1 | C4: =IF(B4=1,OR(SUMPRODUCT((Costs!$B$4:$B$903=A4)*(Costs!$D$4:$D$903="planned")*(Costs!$J$4:$J$903<Controls!$B$12)*(Costs!$K$4:$K$903>Costs!$J$4:$J$903))>0,SUMPRODUCT((Benefits!$B$4:$B$703=A4)*(Benefits!$T$4:$T$703=1))>0),FALSE()) -> TRUE | D4: =SUMIFS('Cash flow'!$E$4:$E$867,'Cash flow'!$A$4:$A$867,A4) -> 1163100 | E4: =SUMIFS('Cash flow'!$J$4:$J$867,'Cash flow'!$A$4:$A$867,A4) -> 1830605.5 | F4: =SUMIFS('Cash flow'!$K$4:$K$867,'Cash flow'!$A$4:$A$867,A4) -> 667505.47 | G4: =IF(C4,SUMIFS('Cash flow'!$N$4:$N$867,'Cash flow'!$A$4:$A$867,A4),"") -> 578533.26 | H4: =COUNTIFS('Cash flow'!$A$4:$A$867,A4,'Cash flow'!$P$4:$P$867,1) -> 10 | I4: =SUMPRODUCT(MAX(('Cash flow'!$A$4:$A$867=A4)*('Cash flow'!$P$4:$P$867=1)*('Cash flow'!$B$4:$B$867+1))) -> 10 | J4: =IF(OR(NOT(C4),H4=0,I4=Controls!$B$12),"",I4) -> 10 | K4: =IF(NOT(C4),"NO_FLOWS",IF(H4=0,"NO_INVESTMENT",IF(I4=Controls!$B$12,"NOT_RECOVERED",""))) | L4: =IF(J4="","",(J4-1)+(-SUMIFS('Cash flow'!$L$4:$L$867,'Cash flow'!$A$4:$A$867,A4,'Cash flow'!$B$4:$B$867,J4-1))/(SUMIFS('Cash flow'!$L$4:$L$867,'Cash flow'!$A$4:$A$867,A4,'Cash flow'!$B$4:$B$867,J4)-SUMIFS('Cash flow'!$L$4:$L$867,'Cash flow'!$A$4:$A$867,A4,'Cash flow'!$B$4:$B$867,J4-1))) -> 9.2751283 | M4: =COUNTIFS('Cash flow'!$A$4:$A$867,A4,'Cash flow'!$Q$4:$Q$867,1) -> 10 | N4: =SUMPRODUCT(MAX(('Cash flow'!$A$4:$A$867=A4)*('Cash flow'!$Q$4:$Q$867=1)*('Cash flow'!$B$4:$B$867+1))) -> 10 | O4: =IF(OR(NOT(C4),M4=0,N4=Controls!$B$12),"",N4) -> 10 | P4: =IF(NOT(C4),"NO_FLOWS",IF(M4=0,"NO_INVESTMENT",IF(N4=Controls!$B$12,"NOT_RECOVERED",""))) | Q4: =IF(O4="","",(O4-1)+(-SUMIFS('Cash flow'!$O$4:$O$867,'Cash flow'!$A$4:$A$867,A4,'Cash flow'!$B$4:$B$867,O4-1))/(SUMIFS('Cash flow'!$O$4:$O$867,'Cash flow'!$A$4:$A$867,A4,'Cash flow'!$B$4:$B$867,O4)-SUMIFS('Cash flow'!$O$4:$O$867,'Cash flow'!$A$4:$A$867,A4,'Cash flow'!$B$4:$B$867,O4-1))) -> 9.4880978 | R4: =IFERROR(INDEX('Domain reference'!$C$40:$C$249,MATCH(Controls!$B$3&"|"&A4,'Domain reference'!$A$40:$A$249,0)),"") -> 578533.26 | S4: =IFERROR(INDEX('Domain reference'!$D$40:$D$249,MATCH(Controls!$B$3&"|"&A4,'Domain reference'!$A$40:$A$249,0)),"") -> 10 | T4: =IFERROR(INDEX('Domain reference'!$E$40:$E$249,MATCH(Controls!$B$3&"|"&A4,'Domain reference'!$A$40:$A$249,0)),"") -> 10 | U4: =IF(LEN(Controls!$B$4)>0,TRUE(),IF(B4=0,AND(R4="",E4=0),AND(ABS(N(G4)-N(R4))<0.005,ISNUMBER(G4)=ISNUMBER(R4),IF(S4=-1,J4="",J4=S4),IF(T4=-1,O4="",O4=T4)))) -> TRUE
A5: init-002 | B5: =IF(COUNTIF('Scenario inputs'!$A$4:$A$213,Controls!$B$3&"|"&A5)>0,1,0) -> 1 | C5: =IF(B5=1,OR(SUMPRODUCT((Costs!$B$4:$B$903=A5)*(Costs!$D$4:$D$903="planned")*(Costs!$J$4:$J$903<Controls!$B$12)*(Costs!$K$4:$K$903>Costs!$J$4:$J$903))>0,SUMPRODUCT((Benefits!$B$4:$B$703=A5)*(Benefits!$T$4:$T$703=1))>0),FALSE()) -> TRUE | D5: =SUMIFS('Cash flow'!$E$4:$E$867,'Cash flow'!$A$4:$A$867,A5) -> 830750 | E5: =SUMIFS('Cash flow'!$J$4:$J$867,'Cash flow'!$A$4:$A$867,A5) -> 1308595.1 | F5: =SUMIFS('Cash flow'!$K$4:$K$867,'Cash flow'!$A$4:$A$867,A5) -> 477845.09 | G5: =IF(C5,SUMIFS('Cash flow'!$N$4:$N$867,'Cash flow'!$A$4:$A$867,A5),"") -> 413388.43 | H5: =COUNTIFS('Cash flow'!$A$4:$A$867,A5,'Cash flow'!$P$4:$P$867,1) -> 10 | I5: =SUMPRODUCT(MAX(('Cash flow'!$A$4:$A$867=A5)*('Cash flow'!$P$4:$P$867=1)*('Cash flow'!$B$4:$B$867+1))) -> 10 | J5: =IF(OR(NOT(C5),H5=0,I5=Controls!$B$12),"",I5) -> 10 | K5: =IF(NOT(C5),"NO_FLOWS",IF(H5=0,"NO_INVESTMENT",IF(I5=Controls!$B$12,"NOT_RECOVERED",""))) | L5: =IF(J5="","",(J5-1)+(-SUMIFS('Cash flow'!$L$4:$L$867,'Cash flow'!$A$4:$A$867,A5,'Cash flow'!$B$4:$B$867,J5-1))/(SUMIFS('Cash flow'!$L$4:$L$867,'Cash flow'!$A$4:$A$867,A5,'Cash flow'!$B$4:$B$867,J5)-SUMIFS('Cash flow'!$L$4:$L$867,'Cash flow'!$A$4:$A$867,A5,'Cash flow'!$B$4:$B$867,J5-1))) -> 9.9761475 | M5: =COUNTIFS('Cash flow'!$A$4:$A$867,A5,'Cash flow'!$Q$4:$Q$867,1) -> 11 | N5: =SUMPRODUCT(MAX(('Cash flow'!$A$4:$A$867=A5)*('Cash flow'!$Q$4:$Q$867=1)*('Cash flow'!$B$4:$B$867+1))) -> 11 | O5: =IF(OR(NOT(C5),M5=0,N5=Controls!$B$12),"",N5) -> 11 | P5: =IF(NOT(C5),"NO_FLOWS",IF(M5=0,"NO_INVESTMENT",IF(N5=Controls!$B$12,"NOT_RECOVERED",""))) | Q5: =IF(O5="","",(O5-1)+(-SUMIFS('Cash flow'!$O$4:$O$867,'Cash flow'!$A$4:$A$867,A5,'Cash flow'!$B$4:$B$867,O5-1))/(SUMIFS('Cash flow'!$O$4:$O$867,'Cash flow'!$A$4:$A$867,A5,'Cash flow'!$B$4:$B$867,O5)-SUMIFS('Cash flow'!$O$4:$O$867,'Cash flow'!$A$4:$A$867,A5,'Cash flow'!$B$4:$B$867,O5-1))) -> 10.181277 | R5: =IFERROR(INDEX('Domain reference'!$C$40:$C$249,MATCH(Controls!$B$3&"|"&A5,'Domain reference'!$A$40:$A$249,0)),"") -> 413388.43 | S5: =IFERROR(INDEX('Domain reference'!$D$40:$D$249,MATCH(Controls!$B$3&"|"&A5,'Domain reference'!$A$40:$A$249,0)),"") -> 10 | T5: =IFERROR(INDEX('Domain reference'!$E$40:$E$249,MATCH(Controls!$B$3&"|"&A5,'Domain reference'!$A$40:$A$249,0)),"") -> 11 | U5: =IF(LEN(Controls!$B$4)>0,TRUE(),IF(B5=0,AND(R5="",E5=0),AND(ABS(N(G5)-N(R5))<0.005,ISNUMBER(G5)=ISNUMBER(R5),IF(S5=-1,J5="",J5=S5),IF(T5=-1,O5="",O5=T5)))) -> TRUE
A6: init-003 | B6: =IF(COUNTIF('Scenario inputs'!$A$4:$A$213,Controls!$B$3&"|"&A6)>0,1,0) -> 1 | C6: =IF(B6=1,OR(SUMPRODUCT((Costs!$B$4:$B$903=A6)*(Costs!$D$4:$D$903="planned")*(Costs!$J$4:$J$903<Controls!$B$12)*(Costs!$K$4:$K$903>Costs!$J$4:$J$903))>0,SUMPRODUCT((Benefits!$B$4:$B$703=A6)*(Benefits!$T$4:$T$703=1))>0),FALSE()) -> TRUE | D6: =SUMIFS('Cash flow'!$E$4:$E$867,'Cash flow'!$A$4:$A$867,A6) -> 652800 | E6: =SUMIFS('Cash flow'!$J$4:$J$867,'Cash flow'!$A$4:$A$867,A6) -> 1075421.3 | F6: =SUMIFS('Cash flow'!$K$4:$K$867,'Cash flow'!$A$4:$A$867,A6) -> 422621.27 | G6: =IF(C6,SUMIFS('Cash flow'!$N$4:$N$867,'Cash flow'!$A$4:$A$867,A6),"") -> 363049.68 | H6: =COUNTIFS('Cash flow'!$A$4:$A$867,A6,'Cash flow'!$P$4:$P$867,1) -> 12 | I6: =SUMPRODUCT(MAX(('Cash flow'!$A$4:$A$867=A6)*('Cash flow'!$P$4:$P$867=1)*('Cash flow'!$B$4:$B$867+1))) -> 12 | J6: =IF(OR(NOT(C6),H6=0,I6=Controls!$B$12),"",I6) -> 12 | K6: =IF(NOT(C6),"NO_FLOWS",IF(H6=0,"NO_INVESTMENT",IF(I6=Controls!$B$12,"NOT_RECOVERED",""))) | L6: =IF(J6="","",(J6-1)+(-SUMIFS('Cash flow'!$L$4:$L$867,'Cash flow'!$A$4:$A$867,A6,'Cash flow'!$B$4:$B$867,J6-1))/(SUMIFS('Cash flow'!$L$4:$L$867,'Cash flow'!$A$4:$A$867,A6,'Cash flow'!$B$4:$B$867,J6)-SUMIFS('Cash flow'!$L$4:$L$867,'Cash flow'!$A$4:$A$867,A6,'Cash flow'!$B$4:$B$867,J6-1))) -> 11.151724 | M6: =COUNTIFS('Cash flow'!$A$4:$A$867,A6,'Cash flow'!$Q$4:$Q$867,1) -> 12 | N6: =SUMPRODUCT(MAX(('Cash flow'!$A$4:$A$867=A6)*('Cash flow'!$Q$4:$Q$867=1)*('Cash flow'!$B$4:$B$867+1))) -> 12 | O6: =IF(OR(NOT(C6),M6=0,N6=Controls!$B$12),"",N6) -> 12 | P6: =IF(NOT(C6),"NO_FLOWS",IF(M6=0,"NO_INVESTMENT",IF(N6=Controls!$B$12,"NOT_RECOVERED",""))) | Q6: =IF(O6="","",(O6-1)+(-SUMIFS('Cash flow'!$O$4:$O$867,'Cash flow'!$A$4:$A$867,A6,'Cash flow'!$B$4:$B$867,O6-1))/(SUMIFS('Cash flow'!$O$4:$O$867,'Cash flow'!$A$4:$A$867,A6,'Cash flow'!$B$4:$B$867,O6)-SUMIFS('Cash flow'!$O$4:$O$867,'Cash flow'!$A$4:$A$867,A6,'Cash flow'!$B$4:$B$867,O6-1))) -> 11.351814 | R6: =IFERROR(INDEX('Domain reference'!$C$40:$C$249,MATCH(Controls!$B$3&"|"&A6,'Domain reference'!$A$40:$A$249,0)),"") -> 363049.68 | S6: =IFERROR(INDEX('Domain reference'!$D$40:$D$249,MATCH(Controls!$B$3&"|"&A6,'Domain reference'!$A$40:$A$249,0)),"") -> 12 | T6: =IFERROR(INDEX('Domain reference'!$E$40:$E$249,MATCH(Controls!$B$3&"|"&A6,'Domain reference'!$A$40:$A$249,0)),"") -> 12 | U6: =IF(LEN(Controls!$B$4)>0,TRUE(),IF(B6=0,AND(R6="",E6=0),AND(ABS(N(G6)-N(R6))<0.005,ISNUMBER(G6)=ISNUMBER(R6),IF(S6=-1,J6="",J6=S6),IF(T6=-1,O6="",O6=T6)))) -> TRUE
A7: init-004 | B7: =IF(COUNTIF('Scenario inputs'!$A$4:$A$213,Controls!$B$3&"|"&A7)>0,1,0) -> 1 | C7: =IF(B7=1,OR(SUMPRODUCT((Costs!$B$4:$B$903=A7)*(Costs!$D$4:$D$903="planned")*(Costs!$J$4:$J$903<Controls!$B$12)*(Costs!$K$4:$K$903>Costs!$J$4:$J$903))>0,SUMPRODUCT((Benefits!$B$4:$B$703=A7)*(Benefits!$T$4:$T$703=1))>0),FALSE()) -> TRUE | D7: =SUMIFS('Cash flow'!$E$4:$E$867,'Cash flow'!$A$4:$A$867,A7) -> 1422150 | E7: =SUMIFS('Cash flow'!$J$4:$J$867,'Cash flow'!$A$4:$A$867,A7) -> 2058532.4 | F7: =SUMIFS('Cash flow'!$K$4:$K$867,'Cash flow'!$A$4:$A$867,A7) -> 636382.4 | G7: =IF(C7,SUMIFS('Cash flow'!$N$4:$N$867,'Cash flow'!$A$4:$A$867,A7),"") -> 523302.08 | H7: =COUNTIFS('Cash flow'!$A$4:$A$867,A7,'Cash flow'!$P$4:$P$867,1) -> 14 | I7: =SUMPRODUCT(MAX(('Cash flow'!$A$4:$A$867=A7)*('Cash flow'!$P$4:$P$867=1)*('Cash flow'!$B$4:$B$867+1))) -> 14 | J7: =IF(OR(NOT(C7),H7=0,I7=Controls!$B$12),"",I7) -> 14 | K7: =IF(NOT(C7),"NO_FLOWS",IF(H7=0,"NO_INVESTMENT",IF(I7=Controls!$B$12,"NOT_RECOVERED",""))) | L7: =IF(J7="","",(J7-1)+(-SUMIFS('Cash flow'!$L$4:$L$867,'Cash flow'!$A$4:$A$867,A7,'Cash flow'!$B$4:$B$867,J7-1))/(SUMIFS('Cash flow'!$L$4:$L$867,'Cash flow'!$A$4:$A$867,A7,'Cash flow'!$B$4:$B$867,J7)-SUMIFS('Cash flow'!$L$4:$L$867,'Cash flow'!$A$4:$A$867,A7,'Cash flow'!$B$4:$B$867,J7-1))) -> 13.099104 | M7: =COUNTIFS('Cash flow'!$A$4:$A$867,A7,'Cash flow'!$Q$4:$Q$867,1) -> 14 | N7: =SUMPRODUCT(MAX(('Cash flow'!$A$4:$A$867=A7)*('Cash flow'!$Q$4:$Q$867=1)*('Cash flow'!$B$4:$B$867+1))) -> 14 | O7: =IF(OR(NOT(C7),M7=0,N7=Controls!$B$12),"",N7) -> 14 | P7: =IF(NOT(C7),"NO_FLOWS",IF(M7=0,"NO_INVESTMENT",IF(N7=Controls!$B$12,"NOT_RECOVERED",""))) | Q7: =IF(O7="","",(O7-1)+(-SUMIFS('Cash flow'!$O$4:$O$867,'Cash flow'!$A$4:$A$867,A7,'Cash flow'!$B$4:$B$867,O7-1))/(SUMIFS('Cash flow'!$O$4:$O$867,'Cash flow'!$A$4:$A$867,A7,'Cash flow'!$B$4:$B$867,O7)-SUMIFS('Cash flow'!$O$4:$O$867,'Cash flow'!$A$4:$A$867,A7,'Cash flow'!$B$4:$B$867,O7-1))) -> 13.333038 | R7: =IFERROR(INDEX('Domain reference'!$C$40:$C$249,MATCH(Controls!$B$3&"|"&A7,'Domain reference'!$A$40:$A$249,0)),"") -> 523302.08 | S7: =IFERROR(INDEX('Domain reference'!$D$40:$D$249,MATCH(Controls!$B$3&"|"&A7,'Domain reference'!$A$40:$A$249,0)),"") -> 14 | T7: =IFERROR(INDEX('Domain reference'!$E$40:$E$249,MATCH(Controls!$B$3&"|"&A7,'Domain reference'!$A$40:$A$249,0)),"") -> 14 | U7: =IF(LEN(Controls!$B$4)>0,TRUE(),IF(B7=0,AND(R7="",E7=0),AND(ABS(N(G7)-N(R7))<0.005,ISNUMBER(G7)=ISNUMBER(R7),IF(S7=-1,J7="",J7=S7),IF(T7=-1,O7="",O7=T7)))) -> TRUE
A8: init-005 | B8: =IF(COUNTIF('Scenario inputs'!$A$4:$A$213,Controls!$B$3&"|"&A8)>0,1,0) -> 1 | C8: =IF(B8=1,OR(SUMPRODUCT((Costs!$B$4:$B$903=A8)*(Costs!$D$4:$D$903="planned")*(Costs!$J$4:$J$903<Controls!$B$12)*(Costs!$K$4:$K$903>Costs!$J$4:$J$903))>0,SUMPRODUCT((Benefits!$B$4:$B$703=A8)*(Benefits!$T$4:$T$703=1))>0),FALSE()) -> TRUE | D8: =SUMIFS('Cash flow'!$E$4:$E$867,'Cash flow'!$A$4:$A$867,A8) -> 907200 | E8: =SUMIFS('Cash flow'!$J$4:$J$867,'Cash flow'!$A$4:$A$867,A8) -> 1179266.8 | F8: =SUMIFS('Cash flow'!$K$4:$K$867,'Cash flow'!$A$4:$A$867,A8) -> 272066.75 | G8: =IF(C8,SUMIFS('Cash flow'!$N$4:$N$867,'Cash flow'!$A$4:$A$867,A8),"") -> 209002.21 | H8: =COUNTIFS('Cash flow'!$A$4:$A$867,A8,'Cash flow'!$P$4:$P$867,1) -> 19 | I8: =SUMPRODUCT(MAX(('Cash flow'!$A$4:$A$867=A8)*('Cash flow'!$P$4:$P$867=1)*('Cash flow'!$B$4:$B$867+1))) -> 19 | J8: =IF(OR(NOT(C8),H8=0,I8=Controls!$B$12),"",I8) -> 19 | K8: =IF(NOT(C8),"NO_FLOWS",IF(H8=0,"NO_INVESTMENT",IF(I8=Controls!$B$12,"NOT_RECOVERED",""))) | L8: =IF(J8="","",(J8-1)+(-SUMIFS('Cash flow'!$L$4:$L$867,'Cash flow'!$A$4:$A$867,A8,'Cash flow'!$B$4:$B$867,J8-1))/(SUMIFS('Cash flow'!$L$4:$L$867,'Cash flow'!$A$4:$A$867,A8,'Cash flow'!$B$4:$B$867,J8)-SUMIFS('Cash flow'!$L$4:$L$867,'Cash flow'!$A$4:$A$867,A8,'Cash flow'!$B$4:$B$867,J8-1))) -> 18.434749 | M8: =COUNTIFS('Cash flow'!$A$4:$A$867,A8,'Cash flow'!$Q$4:$Q$867,1) -> 19 | N8: =SUMPRODUCT(MAX(('Cash flow'!$A$4:$A$867=A8)*('Cash flow'!$Q$4:$Q$867=1)*('Cash flow'!$B$4:$B$867+1))) -> 19 | O8: =IF(OR(NOT(C8),M8=0,N8=Controls!$B$12),"",N8) -> 19 | P8: =IF(NOT(C8),"NO_FLOWS",IF(M8=0,"NO_INVESTMENT",IF(N8=Controls!$B$12,"NOT_RECOVERED",""))) | Q8: =IF(O8="","",(O8-1)+(-SUMIFS('Cash flow'!$O$4:$O$867,'Cash flow'!$A$4:$A$867,A8,'Cash flow'!$B$4:$B$867,O8-1))/(SUMIFS('Cash flow'!$O$4:$O$867,'Cash flow'!$A$4:$A$867,A8,'Cash flow'!$B$4:$B$867,O8)-SUMIFS('Cash flow'!$O$4:$O$867,'Cash flow'!$A$4:$A$867,A8,'Cash flow'!$B$4:$B$867,O8-1))) -> 18.74007 | R8: =IFERROR(INDEX('Domain reference'!$C$40:$C$249,MATCH(Controls!$B$3&"|"&A8,'Domain reference'!$A$40:$A$249,0)),"") -> 209002.21 | S8: =IFERROR(INDEX('Domain reference'!$D$40:$D$249,MATCH(Controls!$B$3&"|"&A8,'Domain reference'!$A$40:$A$249,0)),"") -> 19 | T8: =IFERROR(INDEX('Domain reference'!$E$40:$E$249,MATCH(Controls!$B$3&"|"&A8,'Domain reference'!$A$40:$A$249,0)),"") -> 19 | U8: =IF(LEN(Controls!$B$4)>0,TRUE(),IF(B8=0,AND(R8="",E8=0),AND(ABS(N(G8)-N(R8))<0.005,ISNUMBER(G8)=ISNUMBER(R8),IF(S8=-1,J8="",J8=S8),IF(T8=-1,O8="",O8=T8)))) -> TRUE
A9: init-006 | B9: =IF(COUNTIF('Scenario inputs'!$A$4:$A$213,Controls!$B$3&"|"&A9)>0,1,0) -> 1 | C9: =IF(B9=1,OR(SUMPRODUCT((Costs!$B$4:$B$903=A9)*(Costs!$D$4:$D$903="planned")*(Costs!$J$4:$J$903<Controls!$B$12)*(Costs!$K$4:$K$903>Costs!$J$4:$J$903))>0,SUMPRODUCT((Benefits!$B$4:$B$703=A9)*(Benefits!$T$4:$T$703=1))>0),FALSE()) -> TRUE | D9: =SUMIFS('Cash flow'!$E$4:$E$867,'Cash flow'!$A$4:$A$867,A9) -> 588850 | E9: =SUMIFS('Cash flow'!$J$4:$J$867,'Cash flow'!$A$4:$A$867,A9) -> 0 | F9: =SUMIFS('Cash flow'!$K$4:$K$867,'Cash flow'!$A$4:$A$867,A9) -> -588850 | G9: =IF(C9,SUMIFS('Cash flow'!$N$4:$N$867,'Cash flow'!$A$4:$A$867,A9),"") -> -535631.92 | H9: =COUNTIFS('Cash flow'!$A$4:$A$867,A9,'Cash flow'!$P$4:$P$867,1) -> 36 | I9: =SUMPRODUCT(MAX(('Cash flow'!$A$4:$A$867=A9)*('Cash flow'!$P$4:$P$867=1)*('Cash flow'!$B$4:$B$867+1))) -> 36 | J9: =IF(OR(NOT(C9),H9=0,I9=Controls!$B$12),"",I9) | K9: =IF(NOT(C9),"NO_FLOWS",IF(H9=0,"NO_INVESTMENT",IF(I9=Controls!$B$12,"NOT_RECOVERED",""))) -> NOT_RECOVERED | L9: =IF(J9="","",(J9-1)+(-SUMIFS('Cash flow'!$L$4:$L$867,'Cash flow'!$A$4:$A$867,A9,'Cash flow'!$B$4:$B$867,J9-1))/(SUMIFS('Cash flow'!$L$4:$L$867,'Cash flow'!$A$4:$A$867,A9,'Cash flow'!$B$4:$B$867,J9)-SUMIFS('Cash flow'!$L$4:$L$867,'Cash flow'!$A$4:$A$867,A9,'Cash flow'!$B$4:$B$867,J9-1))) | M9: =COUNTIFS('Cash flow'!$A$4:$A$867,A9,'Cash flow'!$Q$4:$Q$867,1) -> 36 | N9: =SUMPRODUCT(MAX(('Cash flow'!$A$4:$A$867=A9)*('Cash flow'!$Q$4:$Q$867=1)*('Cash flow'!$B$4:$B$867+1))) -> 36 | O9: =IF(OR(NOT(C9),M9=0,N9=Controls!$B$12),"",N9) | P9: =IF(NOT(C9),"NO_FLOWS",IF(M9=0,"NO_INVESTMENT",IF(N9=Controls!$B$12,"NOT_RECOVERED",""))) -> NOT_RECOVERED | Q9: =IF(O9="","",(O9-1)+(-SUMIFS('Cash flow'!$O$4:$O$867,'Cash flow'!$A$4:$A$867,A9,'Cash flow'!$B$4:$B$867,O9-1))/(SUMIFS('Cash flow'!$O$4:$O$867,'Cash flow'!$A$4:$A$867,A9,'Cash flow'!$B$4:$B$867,O9)-SUMIFS('Cash flow'!$O$4:$O$867,'Cash flow'!$A$4:$A$867,A9,'Cash flow'!$B$4:$B$867,O9-1))) | R9: =IFERROR(INDEX('Domain reference'!$C$40:$C$249,MATCH(Controls!$B$3&"|"&A9,'Domain reference'!$A$40:$A$249,0)),"") -> -535631.92 | S9: =IFERROR(INDEX('Domain reference'!$D$40:$D$249,MATCH(Controls!$B$3&"|"&A9,'Domain reference'!$A$40:$A$249,0)),"") -> -1 | T9: =IFERROR(INDEX('Domain reference'!$E$40:$E$249,MATCH(Controls!$B$3&"|"&A9,'Domain reference'!$A$40:$A$249,0)),"") -> -1 | U9: =IF(LEN(Controls!$B$4)>0,TRUE(),IF(B9=0,AND(R9="",E9=0),AND(ABS(N(G9)-N(R9))<0.005,ISNUMBER(G9)=ISNUMBER(R9),IF(S9=-1,J9="",J9=S9),IF(T9=-1,O9="",O9=T9)))) -> TRUE
A10: init-007 | B10: =IF(COUNTIF('Scenario inputs'!$A$4:$A$213,Controls!$B$3&"|"&A10)>0,1,0) -> 1 | C10: =IF(B10=1,OR(SUMPRODUCT((Costs!$B$4:$B$903=A10)*(Costs!$D$4:$D$903="planned")*(Costs!$J$4:$J$903<Controls!$B$12)*(Costs!$K$4:$K$903>Costs!$J$4:$J$903))>0,SUMPRODUCT((Benefits!$B$4:$B$703=A10)*(Benefits!$T$4:$T$703=1))>0),FALSE()) -> TRUE | D10: =SUMIFS('Cash flow'!$E$4:$E$867,'Cash flow'!$A$4:$A$867,A10) -> 1961550 | E10: =SUMIFS('Cash flow'!$J$4:$J$867,'Cash flow'!$A$4:$A$867,A10) -> 2489519.3 | F10: =SUMIFS('Cash flow'!$K$4:$K$867,'Cash flow'!$A$4:$A$867,A10) -> 527969.27 | G10: =IF(C10,SUMIFS('Cash flow'!$N$4:$N$867,'Cash flow'!$A$4:$A$867,A10),"") -> 415366 | H10: =COUNTIFS('Cash flow'!$A$4:$A$867,A10,'Cash flow'!$P$4:$P$867,1) -> 11 | I10: =SUMPRODUCT(MAX(('Cash flow'!$A$4:$A$867=A10)*('Cash flow'!$P$4:$P$867=1)*('Cash flow'!$B$4:$B$867+1))) -> 11 | J10: =IF(OR(NOT(C10),H10=0,I10=Controls!$B$12),"",I10) -> 11 | K10: =IF(NOT(C10),"NO_FLOWS",IF(H10=0,"NO_INVESTMENT",IF(I10=Controls!$B$12,"NOT_RECOVERED",""))) | L10: =IF(J10="","",(J10-1)+(-SUMIFS('Cash flow'!$L$4:$L$867,'Cash flow'!$A$4:$A$867,A10,'Cash flow'!$B$4:$B$867,J10-1))/(SUMIFS('Cash flow'!$L$4:$L$867,'Cash flow'!$A$4:$A$867,A10,'Cash flow'!$B$4:$B$867,J10)-SUMIFS('Cash flow'!$L$4:$L$867,'Cash flow'!$A$4:$A$867,A10,'Cash flow'!$B$4:$B$867,J10-1))) -> 10.255564 | M10: =COUNTIFS('Cash flow'!$A$4:$A$867,A10,'Cash flow'!$Q$4:$Q$867,1) -> 11 | N10: =SUMPRODUCT(MAX(('Cash flow'!$A$4:$A$867=A10)*('Cash flow'!$Q$4:$Q$867=1)*('Cash flow'!$B$4:$B$867+1))) -> 11 | O10: =IF(OR(NOT(C10),M10=0,N10=Controls!$B$12),"",N10) -> 11 | P10: =IF(NOT(C10),"NO_FLOWS",IF(M10=0,"NO_INVESTMENT",IF(N10=Controls!$B$12,"NOT_RECOVERED",""))) | Q10: =IF(O10="","",(O10-1)+(-SUMIFS('Cash flow'!$O$4:$O$867,'Cash flow'!$A$4:$A$867,A10,'Cash flow'!$B$4:$B$867,O10-1))/(SUMIFS('Cash flow'!$O$4:$O$867,'Cash flow'!$A$4:$A$867,A10,'Cash flow'!$B$4:$B$867,O10)-SUMIFS('Cash flow'!$O$4:$O$867,'Cash flow'!$A$4:$A$867,A10,'Cash flow'!$B$4:$B$867,O10-1))) -> 10.516712 | R10: =IFERROR(INDEX('Domain reference'!$C$40:$C$249,MATCH(Controls!$B$3&"|"&A10,'Domain reference'!$A$40:$A$249,0)),"") -> 415366 | S10: =IFERROR(INDEX('Domain reference'!$D$40:$D$249,MATCH(Controls!$B$3&"|"&A10,'Domain reference'!$A$40:$A$249,0)),"") -> 11 | T10: =IFERROR(INDEX('Domain reference'!$E$40:$E$249,MATCH(Controls!$B$3&"|"&A10,'Domain reference'!$A$40:$A$249,0)),"") -> 11 | U10: =IF(LEN(Controls!$B$4)>0,TRUE(),IF(B10=0,AND(R10="",E10=0),AND(ABS(N(G10)-N(R10))<0.005,ISNUMBER(G10)=ISNUMBER(R10),IF(S10=-1,J10="",J10=S10),IF(T10=-1,O10="",O10=T10)))) -> TRUE
A11: init-008 | B11: =IF(COUNTIF('Scenario inputs'!$A$4:$A$213,Controls!$B$3&"|"&A11)>0,1,0) -> 1 | C11: =IF(B11=1,OR(SUMPRODUCT((Costs!$B$4:$B$903=A11)*(Costs!$D$4:$D$903="planned")*(Costs!$J$4:$J$903<Controls!$B$12)*(Costs!$K$4:$K$903>Costs!$J$4:$J$903))>0,SUMPRODUCT((Benefits!$B$4:$B$703=A11)*(Benefits!$T$4:$T$703=1))>0),FALSE()) -> TRUE | D11: =SUMIFS('Cash flow'!$E$4:$E$867,'Cash flow'!$A$4:$A$867,A11) -> 1039700 | E11: =SUMIFS('Cash flow'!$J$4:$J$867,'Cash flow'!$A$4:$A$867,A11) -> 1158800 | F11: =SUMIFS('Cash flow'!$K$4:$K$867,'Cash flow'!$A$4:$A$867,A11) -> 119100 | G11: =IF(C11,SUMIFS('Cash flow'!$N$4:$N$867,'Cash flow'!$A$4:$A$867,A11),"") -> 65253.906 | H11: =COUNTIFS('Cash flow'!$A$4:$A$867,A11,'Cash flow'!$P$4:$P$867,1) -> 13 | I11: =SUMPRODUCT(MAX(('Cash flow'!$A$4:$A$867=A11)*('Cash flow'!$P$4:$P$867=1)*('Cash flow'!$B$4:$B$867+1))) -> 13 | J11: =IF(OR(NOT(C11),H11=0,I11=Controls!$B$12),"",I11) -> 13 | K11: =IF(NOT(C11),"NO_FLOWS",IF(H11=0,"NO_INVESTMENT",IF(I11=Controls!$B$12,"NOT_RECOVERED",""))) | L11: =IF(J11="","",(J11-1)+(-SUMIFS('Cash flow'!$L$4:$L$867,'Cash flow'!$A$4:$A$867,A11,'Cash flow'!$B$4:$B$867,J11-1))/(SUMIFS('Cash flow'!$L$4:$L$867,'Cash flow'!$A$4:$A$867,A11,'Cash flow'!$B$4:$B$867,J11)-SUMIFS('Cash flow'!$L$4:$L$867,'Cash flow'!$A$4:$A$867,A11,'Cash flow'!$B$4:$B$867,J11-1))) -> 12.387476 | M11: =COUNTIFS('Cash flow'!$A$4:$A$867,A11,'Cash flow'!$Q$4:$Q$867,1) -> 13 | N11: =SUMPRODUCT(MAX(('Cash flow'!$A$4:$A$867=A11)*('Cash flow'!$Q$4:$Q$867=1)*('Cash flow'!$B$4:$B$867+1))) -> 13 | O11: =IF(OR(NOT(C11),M11=0,N11=Controls!$B$12),"",N11) -> 13 | P11: =IF(NOT(C11),"NO_FLOWS",IF(M11=0,"NO_INVESTMENT",IF(N11=Controls!$B$12,"NOT_RECOVERED",""))) | Q11: =IF(O11="","",(O11-1)+(-SUMIFS('Cash flow'!$O$4:$O$867,'Cash flow'!$A$4:$A$867,A11,'Cash flow'!$B$4:$B$867,O11-1))/(SUMIFS('Cash flow'!$O$4:$O$867,'Cash flow'!$A$4:$A$867,A11,'Cash flow'!$B$4:$B$867,O11)-SUMIFS('Cash flow'!$O$4:$O$867,'Cash flow'!$A$4:$A$867,A11,'Cash flow'!$B$4:$B$867,O11-1))) -> 12.762514 | R11: =IFERROR(INDEX('Domain reference'!$C$40:$C$249,MATCH(Controls!$B$3&"|"&A11,'Domain reference'!$A$40:$A$249,0)),"") -> 65253.91 | S11: =IFERROR(INDEX('Domain reference'!$D$40:$D$249,MATCH(Controls!$B$3&"|"&A11,'Domain reference'!$A$40:$A$249,0)),"") -> 13 | T11: =IFERROR(INDEX('Domain reference'!$E$40:$E$249,MATCH(Controls!$B$3&"|"&A11,'Domain reference'!$A$40:$A$249,0)),"") -> 13 | U11: =IF(LEN(Controls!$B$4)>0,TRUE(),IF(B11=0,AND(R11="",E11=0),AND(ABS(N(G11)-N(R11))<0.005,ISNUMBER(G11)=ISNUMBER(R11),IF(S11=-1,J11="",J11=S11),IF(T11=-1,O11="",O11=T11)))) -> TRUE
A12: init-009 | B12: =IF(COUNTIF('Scenario inputs'!$A$4:$A$213,Controls!$B$3&"|"&A12)>0,1,0) -> 1 | C12: =IF(B12=1,OR(SUMPRODUCT((Costs!$B$4:$B$903=A12)*(Costs!$D$4:$D$903="planned")*(Costs!$J$4:$J$903<Controls!$B$12)*(Costs!$K$4:$K$903>Costs!$J$4:$J$903))>0,SUMPRODUCT((Benefits!$B$4:$B$703=A12)*(Benefits!$T$4:$T$703=1))>0),FALSE()) -> TRUE | D12: =SUMIFS('Cash flow'!$E$4:$E$867,'Cash flow'!$A$4:$A$867,A12) -> 775800 | E12: =SUMIFS('Cash flow'!$J$4:$J$867,'Cash flow'!$A$4:$A$867,A12) -> 0 | F12: =SUMIFS('Cash flow'!$K$4:$K$867,'Cash flow'!$A$4:$A$867,A12) -> -775800 | G12: =IF(C12,SUMIFS('Cash flow'!$N$4:$N$867,'Cash flow'!$A$4:$A$867,A12),"") -> -761535.73 | H12: =COUNTIFS('Cash flow'!$A$4:$A$867,A12,'Cash flow'!$P$4:$P$867,1) -> 36 | I12: =SUMPRODUCT(MAX(('Cash flow'!$A$4:$A$867=A12)*('Cash flow'!$P$4:$P$867=1)*('Cash flow'!$B$4:$B$867+1))) -> 36 | J12: =IF(OR(NOT(C12),H12=0,I12=Controls!$B$12),"",I12) | K12: =IF(NOT(C12),"NO_FLOWS",IF(H12=0,"NO_INVESTMENT",IF(I12=Controls!$B$12,"NOT_RECOVERED",""))) -> NOT_RECOVERED | L12: =IF(J12="","",(J12-1)+(-SUMIFS('Cash flow'!$L$4:$L$867,'Cash flow'!$A$4:$A$867,A12,'Cash flow'!$B$4:$B$867,J12-1))/(SUMIFS('Cash flow'!$L$4:$L$867,'Cash flow'!$A$4:$A$867,A12,'Cash flow'!$B$4:$B$867,J12)-SUMIFS('Cash flow'!$L$4:$L$867,'Cash flow'!$A$4:$A$867,A12,'Cash flow'!$B$4:$B$867,J12-1))) | M12: =COUNTIFS('Cash flow'!$A$4:$A$867,A12,'Cash flow'!$Q$4:$Q$867,1) -> 36 | N12: =SUMPRODUCT(MAX(('Cash flow'!$A$4:$A$867=A12)*('Cash flow'!$Q$4:$Q$867=1)*('Cash flow'!$B$4:$B$867+1))) -> 36 | O12: =IF(OR(NOT(C12),M12=0,N12=Controls!$B$12),"",N12) | P12: =IF(NOT(C12),"NO_FLOWS",IF(M12=0,"NO_INVESTMENT",IF(N12=Controls!$B$12,"NOT_RECOVERED",""))) -> NOT_RECOVERED | Q12: =IF(O12="","",(O12-1)+(-SUMIFS('Cash flow'!$O$4:$O$867,'Cash flow'!$A$4:$A$867,A12,'Cash flow'!$B$4:$B$867,O12-1))/(SUMIFS('Cash flow'!$O$4:$O$867,'Cash flow'!$A$4:$A$867,A12,'Cash flow'!$B$4:$B$867,O12)-SUMIFS('Cash flow'!$O$4:$O$867,'Cash flow'!$A$4:$A$867,A12,'Cash flow'!$B$4:$B$867,O12-1))) | R12: =IFERROR(INDEX('Domain reference'!$C$40:$C$249,MATCH(Controls!$B$3&"|"&A12,'Domain reference'!$A$40:$A$249,0)),"") -> -761535.73 | S12: =IFERROR(INDEX('Domain reference'!$D$40:$D$249,MATCH(Controls!$B$3&"|"&A12,'Domain reference'!$A$40:$A$249,0)),"") -> -1 | T12: =IFERROR(INDEX('Domain reference'!$E$40:$E$249,MATCH(Controls!$B$3&"|"&A12,'Domain reference'!$A$40:$A$249,0)),"") -> -1 | U12: =IF(LEN(Controls!$B$4)>0,TRUE(),IF(B12=0,AND(R12="",E12=0),AND(ABS(N(G12)-N(R12))<0.005,ISNUMBER(G12)=ISNUMBER(R12),IF(S12=-1,J12="",J12=S12),IF(T12=-1,O12="",O12=T12)))) -> TRUE
A13: init-010 | B13: =IF(COUNTIF('Scenario inputs'!$A$4:$A$213,Controls!$B$3&"|"&A13)>0,1,0) -> 1 | C13: =IF(B13=1,OR(SUMPRODUCT((Costs!$B$4:$B$903=A13)*(Costs!$D$4:$D$903="planned")*(Costs!$J$4:$J$903<Controls!$B$12)*(Costs!$K$4:$K$903>Costs!$J$4:$J$903))>0,SUMPRODUCT((Benefits!$B$4:$B$703=A13)*(Benefits!$T$4:$T$703=1))>0),FALSE()) -> TRUE | D13: =SUMIFS('Cash flow'!$E$4:$E$867,'Cash flow'!$A$4:$A$867,A13) -> 1571900 | E13: =SUMIFS('Cash flow'!$J$4:$J$867,'Cash flow'!$A$4:$A$867,A13) -> 2122033.2 | F13: =SUMIFS('Cash flow'!$K$4:$K$867,'Cash flow'!$A$4:$A$867,A13) -> 550133.17 | G13: =IF(C13,SUMIFS('Cash flow'!$N$4:$N$867,'Cash flow'!$A$4:$A$867,A13),"") -> 423409.74 | H13: =COUNTIFS('Cash flow'!$A$4:$A$867,A13,'Cash flow'!$P$4:$P$867,1) -> 18 | I13: =SUMPRODUCT(MAX(('Cash flow'!$A$4:$A$867=A13)*('Cash flow'!$P$4:$P$867=1)*('Cash flow'!$B$4:$B$867+1))) -> 18 | J13: =IF(OR(NOT(C13),H13=0,I13=Controls!$B$12),"",I13) -> 18 | K13: =IF(NOT(C13),"NO_FLOWS",IF(H13=0,"NO_INVESTMENT",IF(I13=Controls!$B$12,"NOT_RECOVERED",""))) | L13: =IF(J13="","",(J13-1)+(-SUMIFS('Cash flow'!$L$4:$L$867,'Cash flow'!$A$4:$A$867,A13,'Cash flow'!$B$4:$B$867,J13-1))/(SUMIFS('Cash flow'!$L$4:$L$867,'Cash flow'!$A$4:$A$867,A13,'Cash flow'!$B$4:$B$867,J13)-SUMIFS('Cash flow'!$L$4:$L$867,'Cash flow'!$A$4:$A$867,A13,'Cash flow'!$B$4:$B$867,J13-1))) -> 17.372425 | M13: =COUNTIFS('Cash flow'!$A$4:$A$867,A13,'Cash flow'!$Q$4:$Q$867,1) -> 18 | N13: =SUMPRODUCT(MAX(('Cash flow'!$A$4:$A$867=A13)*('Cash flow'!$Q$4:$Q$867=1)*('Cash flow'!$B$4:$B$867+1))) -> 18 | O13: =IF(OR(NOT(C13),M13=0,N13=Controls!$B$12),"",N13) -> 18 | P13: =IF(NOT(C13),"NO_FLOWS",IF(M13=0,"NO_INVESTMENT",IF(N13=Controls!$B$12,"NOT_RECOVERED",""))) | Q13: =IF(O13="","",(O13-1)+(-SUMIFS('Cash flow'!$O$4:$O$867,'Cash flow'!$A$4:$A$867,A13,'Cash flow'!$B$4:$B$867,O13-1))/(SUMIFS('Cash flow'!$O$4:$O$867,'Cash flow'!$A$4:$A$867,A13,'Cash flow'!$B$4:$B$867,O13)-SUMIFS('Cash flow'!$O$4:$O$867,'Cash flow'!$A$4:$A$867,A13,'Cash flow'!$B$4:$B$867,O13-1))) -> 17.697349 | R13: =IFERROR(INDEX('Domain reference'!$C$40:$C$249,MATCH(Controls!$B$3&"|"&A13,'Domain reference'!$A$40:$A$249,0)),"") -> 423409.74 | S13: =IFERROR(INDEX('Domain reference'!$D$40:$D$249,MATCH(Controls!$B$3&"|"&A13,'Domain reference'!$A$40:$A$249,0)),"") -> 18 | T13: =IFERROR(INDEX('Domain reference'!$E$40:$E$249,MATCH(Controls!$B$3&"|"&A13,'Domain reference'!$A$40:$A$249,0)),"") -> 18 | U13: =IF(LEN(Controls!$B$4)>0,TRUE(),IF(B13=0,AND(R13="",E13=0),AND(ABS(N(G13)-N(R13))<0.005,ISNUMBER(G13)=ISNUMBER(R13),IF(S13=-1,J13="",J13=S13),IF(T13=-1,O13="",O13=T13)))) -> TRUE
A14: init-011 | B14: =IF(COUNTIF('Scenario inputs'!$A$4:$A$213,Controls!$B$3&"|"&A14)>0,1,0) -> 1 | C14: =IF(B14=1,OR(SUMPRODUCT((Costs!$B$4:$B$903=A14)*(Costs!$D$4:$D$903="planned")*(Costs!$J$4:$J$903<Controls!$B$12)*(Costs!$K$4:$K$903>Costs!$J$4:$J$903))>0,SUMPRODUCT((Benefits!$B$4:$B$703=A14)*(Benefits!$T$4:$T$703=1))>0),FALSE()) -> TRUE | D14: =SUMIFS('Cash flow'!$E$4:$E$867,'Cash flow'!$A$4:$A$867,A14) -> 452900 | E14: =SUMIFS('Cash flow'!$J$4:$J$867,'Cash flow'!$A$4:$A$867,A14) -> 566000 | F14: =SUMIFS('Cash flow'!$K$4:$K$867,'Cash flow'!$A$4:$A$867,A14) -> 113100 | G14: =IF(C14,SUMIFS('Cash flow'!$N$4:$N$867,'Cash flow'!$A$4:$A$867,A14),"") -> 84012.759 | H14: =COUNTIFS('Cash flow'!$A$4:$A$867,A14,'Cash flow'!$P$4:$P$867,1) -> 21 | I14: =SUMPRODUCT(MAX(('Cash flow'!$A$4:$A$867=A14)*('Cash flow'!$P$4:$P$867=1)*('Cash flow'!$B$4:$B$867+1))) -> 21 | J14: =IF(OR(NOT(C14),H14=0,I14=Controls!$B$12),"",I14) -> 21 | K14: =IF(NOT(C14),"NO_FLOWS",IF(H14=0,"NO_INVESTMENT",IF(I14=Controls!$B$12,"NOT_RECOVERED",""))) | L14: =IF(J14="","",(J14-1)+(-SUMIFS('Cash flow'!$L$4:$L$867,'Cash flow'!$A$4:$A$867,A14,'Cash flow'!$B$4:$B$867,J14-1))/(SUMIFS('Cash flow'!$L$4:$L$867,'Cash flow'!$A$4:$A$867,A14,'Cash flow'!$B$4:$B$867,J14)-SUMIFS('Cash flow'!$L$4:$L$867,'Cash flow'!$A$4:$A$867,A14,'Cash flow'!$B$4:$B$867,J14-1))) -> 20.564777 | M14: =COUNTIFS('Cash flow'!$A$4:$A$867,A14,'Cash flow'!$Q$4:$Q$867,1) -> 21 | N14: =SUMPRODUCT(MAX(('Cash flow'!$A$4:$A$867=A14)*('Cash flow'!$Q$4:$Q$867=1)*('Cash flow'!$B$4:$B$867+1))) -> 21 | O14: =IF(OR(NOT(C14),M14=0,N14=Controls!$B$12),"",N14) -> 21 | P14: =IF(NOT(C14),"NO_FLOWS",IF(M14=0,"NO_INVESTMENT",IF(N14=Controls!$B$12,"NOT_RECOVERED",""))) | Q14: =IF(O14="","",(O14-1)+(-SUMIFS('Cash flow'!$O$4:$O$867,'Cash flow'!$A$4:$A$867,A14,'Cash flow'!$B$4:$B$867,O14-1))/(SUMIFS('Cash flow'!$O$4:$O$867,'Cash flow'!$A$4:$A$867,A14,'Cash flow'!$B$4:$B$867,O14)-SUMIFS('Cash flow'!$O$4:$O$867,'Cash flow'!$A$4:$A$867,A14,'Cash flow'!$B$4:$B$867,O14-1))) -> 20.89204 | R14: =IFERROR(INDEX('Domain reference'!$C$40:$C$249,MATCH(Controls!$B$3&"|"&A14,'Domain reference'!$A$40:$A$249,0)),"") -> 84012.76 | S14: =IFERROR(INDEX('Domain reference'!$D$40:$D$249,MATCH(Controls!$B$3&"|"&A14,'Domain reference'!$A$40:$A$249,0)),"") -> 21 | T14: =IFERROR(INDEX('Domain reference'!$E$40:$E$249,MATCH(Controls!$B$3&"|"&A14,'Domain reference'!$A$40:$A$249,0)),"") -> 21 | U14: =IF(LEN(Controls!$B$4)>0,TRUE(),IF(B14=0,AND(R14="",E14=0),AND(ABS(N(G14)-N(R14))<0.005,ISNUMBER(G14)=ISNUMBER(R14),IF(S14=-1,J14="",J14=S14),IF(T14=-1,O14="",O14=T14)))) -> TRUE
A15: init-012 | B15: =IF(COUNTIF('Scenario inputs'!$A$4:$A$213,Controls!$B$3&"|"&A15)>0,1,0) -> 1 | C15: =IF(B15=1,OR(SUMPRODUCT((Costs!$B$4:$B$903=A15)*(Costs!$D$4:$D$903="planned")*(Costs!$J$4:$J$903<Controls!$B$12)*(Costs!$K$4:$K$903>Costs!$J$4:$J$903))>0,SUMPRODUCT((Benefits!$B$4:$B$703=A15)*(Benefits!$T$4:$T$703=1))>0),FALSE()) -> TRUE | D15: =SUMIFS('Cash flow'!$E$4:$E$867,'Cash flow'!$A$4:$A$867,A15) -> 970800 | E15: =SUMIFS('Cash flow'!$J$4:$J$867,'Cash flow'!$A$4:$A$867,A15) -> 1164800.1 | F15: =SUMIFS('Cash flow'!$K$4:$K$867,'Cash flow'!$A$4:$A$867,A15) -> 194000.08 | G15: =IF(C15,SUMIFS('Cash flow'!$N$4:$N$867,'Cash flow'!$A$4:$A$867,A15),"") -> 126524.02 | H15: =COUNTIFS('Cash flow'!$A$4:$A$867,A15,'Cash flow'!$P$4:$P$867,1) -> 27 | I15: =SUMPRODUCT(MAX(('Cash flow'!$A$4:$A$867=A15)*('Cash flow'!$P$4:$P$867=1)*('Cash flow'!$B$4:$B$867+1))) -> 27 | J15: =IF(OR(NOT(C15),H15=0,I15=Controls!$B$12),"",I15) -> 27 | K15: =IF(NOT(C15),"NO_FLOWS",IF(H15=0,"NO_INVESTMENT",IF(I15=Controls!$B$12,"NOT_RECOVERED",""))) | L15: =IF(J15="","",(J15-1)+(-SUMIFS('Cash flow'!$L$4:$L$867,'Cash flow'!$A$4:$A$867,A15,'Cash flow'!$B$4:$B$867,J15-1))/(SUMIFS('Cash flow'!$L$4:$L$867,'Cash flow'!$A$4:$A$867,A15,'Cash flow'!$B$4:$B$867,J15)-SUMIFS('Cash flow'!$L$4:$L$867,'Cash flow'!$A$4:$A$867,A15,'Cash flow'!$B$4:$B$867,J15-1))) -> 26.224256 | M15: =COUNTIFS('Cash flow'!$A$4:$A$867,A15,'Cash flow'!$Q$4:$Q$867,1) -> 27 | N15: =SUMPRODUCT(MAX(('Cash flow'!$A$4:$A$867=A15)*('Cash flow'!$Q$4:$Q$867=1)*('Cash flow'!$B$4:$B$867+1))) -> 27 | O15: =IF(OR(NOT(C15),M15=0,N15=Controls!$B$12),"",N15) -> 27 | P15: =IF(NOT(C15),"NO_FLOWS",IF(M15=0,"NO_INVESTMENT",IF(N15=Controls!$B$12,"NOT_RECOVERED",""))) | Q15: =IF(O15="","",(O15-1)+(-SUMIFS('Cash flow'!$O$4:$O$867,'Cash flow'!$A$4:$A$867,A15,'Cash flow'!$B$4:$B$867,O15-1))/(SUMIFS('Cash flow'!$O$4:$O$867,'Cash flow'!$A$4:$A$867,A15,'Cash flow'!$B$4:$B$867,O15)-SUMIFS('Cash flow'!$O$4:$O$867,'Cash flow'!$A$4:$A$867,A15,'Cash flow'!$B$4:$B$867,O15-1))) -> 26.616542 | R15: =IFERROR(INDEX('Domain reference'!$C$40:$C$249,MATCH(Controls!$B$3&"|"&A15,'Domain reference'!$A$40:$A$249,0)),"") -> 126524.02 | S15: =IFERROR(INDEX('Domain reference'!$D$40:$D$249,MATCH(Controls!$B$3&"|"&A15,'Domain reference'!$A$40:$A$249,0)),"") -> 27 | T15: =IFERROR(INDEX('Domain reference'!$E$40:$E$249,MATCH(Controls!$B$3&"|"&A15,'Domain reference'!$A$40:$A$249,0)),"") -> 27 | U15: =IF(LEN(Controls!$B$4)>0,TRUE(),IF(B15=0,AND(R15="",E15=0),AND(ABS(N(G15)-N(R15))<0.005,ISNUMBER(G15)=ISNUMBER(R15),IF(S15=-1,J15="",J15=S15),IF(T15=-1,O15="",O15=T15)))) -> TRUE
... A27: init-024 | B27: =IF(COUNTIF('Scenario inputs'!$A$4:$A$213,Controls!$B$3&"|"&A27)>0,1,0) -> 1 | C27: =IF(B27=1,OR(SUMPRODUCT((Costs!$B$4:$B$903=A27)*(Costs!$D$4:$D$903="planned")*(Costs!$J$4:$J$903<Controls!$B$12)*(Costs!$K$4:$K$903>Costs!$J$4:$J$903))>0,SUMPRODUCT((Benefits!$B$4:$B$703=A27)*(Benefits!$T$4:$T$703=1))>0),FALSE()) -> TRUE | D27: =SUMIFS('Cash flow'!$E$4:$E$867,'Cash flow'!$A$4:$A$867,A27) -> 1284900 | E27: =SUMIFS('Cash flow'!$J$4:$J$867,'Cash flow'!$A$4:$A$867,A27) -> 1606266.8 | F27: =SUMIFS('Cash flow'!$K$4:$K$867,'Cash flow'!$A$4:$A$867,A27) -> 321366.78 | G27: =IF(C27,SUMIFS('Cash flow'!$N$4:$N$867,'Cash flow'!$A$4:$A$867,A27),"") -> 230132.79 | H27: =COUNTIFS('Cash flow'!$A$4:$A$867,A27,'Cash flow'!$P$4:$P$867,1) -> 20 | I27: =SUMPRODUCT(MAX(('Cash flow'!$A$4:$A$867=A27)*('Cash flow'!$P$4:$P$867=1)*('Cash flow'!$B$4:$B$867+1))) -> 20 | J27: =IF(OR(NOT(C27),H27=0,I27=Controls!$B$12),"",I27) -> 20 | K27: =IF(NOT(C27),"NO_FLOWS",IF(H27=0,"NO_INVESTMENT",IF(I27=Controls!$B$12,"NOT_RECOVERED",""))) | L27: =IF(J27="","",(J27-1)+(-SUMIFS('Cash flow'!$L$4:$L$867,'Cash flow'!$A$4:$A$867,A27,'Cash flow'!$B$4:$B$867,J27-1))/(SUMIFS('Cash flow'!$L$4:$L$867,'Cash flow'!$A$4:$A$867,A27,'Cash flow'!$B$4:$B$867,J27)-SUMIFS('Cash flow'!$L$4:$L$867,'Cash flow'!$A$4:$A$867,A27,'Cash flow'!$B$4:$B$867,J27-1))) -> 19.740642 | M27: =COUNTIFS('Cash flow'!$A$4:$A$867,A27,'Cash flow'!$Q$4:$Q$867,1) -> 21 | N27: =SUMPRODUCT(MAX(('Cash flow'!$A$4:$A$867=A27)*('Cash flow'!$Q$4:$Q$867=1)*('Cash flow'!$B$4:$B$867+1))) -> 21 | O27: =IF(OR(NOT(C27),M27=0,N27=Controls!$B$12),"",N27) -> 21 | P27: =IF(NOT(C27),"NO_FLOWS",IF(M27=0,"NO_INVESTMENT",IF(N27=Controls!$B$12,"NOT_RECOVERED",""))) | Q27: =IF(O27="","",(O27-1)+(-SUMIFS('Cash flow'!$O$4:$O$867,'Cash flow'!$A$4:$A$867,A27,'Cash flow'!$B$4:$B$867,O27-1))/(SUMIFS('Cash flow'!$O$4:$O$867,'Cash flow'!$A$4:$A$867,A27,'Cash flow'!$B$4:$B$867,O27)-SUMIFS('Cash flow'!$O$4:$O$867,'Cash flow'!$A$4:$A$867,A27,'Cash flow'!$B$4:$B$867,O27-1))) -> 20.119448 | R27: =IFERROR(INDEX('Domain reference'!$C$40:$C$249,MATCH(Controls!$B$3&"|"&A27,'Domain reference'!$A$40:$A$249,0)),"") -> 230132.79 | S27: =IFERROR(INDEX('Domain reference'!$D$40:$D$249,MATCH(Controls!$B$3&"|"&A27,'Domain reference'!$A$40:$A$249,0)),"") -> 20 | T27: =IFERROR(INDEX('Domain reference'!$E$40:$E$249,MATCH(Controls!$B$3&"|"&A27,'Domain reference'!$A$40:$A$249,0)),"") -> 21 | U27: =IF(LEN(Controls!$B$4)>0,TRUE(),IF(B27=0,AND(R27="",E27=0),AND(ABS(N(G27)-N(R27))<0.005,ISNUMBER(G27)=ISNUMBER(R27),IF(S27=-1,J27="",J27=S27),IF(T27=-1,O27="",O27=T27)))) -> TRUE

Sheet Cash flow
A1: The dated cash flow of every initiative in the selected scenario (formulas only)
A2: Rows past the horizon or for initiatives outside the scenario are 0. costs = planned rows whose half-open range holds the period; the four classes enter the flow; capacity hours and the avoided cost beside never do.
A3: initiative_id | B3: period_index | C3: member | D3: active | E3: costs | F3: cash | G3: revenue | H3: avoided_cost_realised | I3: capacity_converted | J3: benefits | K3: net_cash_flow | L3: cumulative | M3: discount_factor | N3: discounted | O3: cumulative_discounted | P3: negative | Q3: negative_discounted
A4: init-001 | B4: 0 | C4: =IF(COUNTIF('Scenario inputs'!$A$4:$A$213,Controls!$B$3&"|"&A4)>0,1,0) -> 1 | D4: =IF(AND(C4=1,B4<Controls!$B$12),1,0) -> 1 | E4: =IF(D4=1,SUMPRODUCT((Costs!$B$4:$B$903=A4)*(Costs!$D$4:$D$903="planned")*(Costs!$J$4:$J$903<=B4)*(Costs!$K$4:$K$903>B4)*Costs!$E$4:$E$903),0) -> 783200 | F4: =IF(D4=1,SUMIFS(Benefits!$S$4:$S$703,Benefits!$B$4:$B$703,A4,Benefits!$F$4:$F$703,B4,Benefits!$R$4:$R$703,"cash"),0) -> 0 | G4: =IF(D4=1,SUMIFS(Benefits!$S$4:$S$703,Benefits!$B$4:$B$703,A4,Benefits!$F$4:$F$703,B4,Benefits!$R$4:$R$703,"revenue"),0) -> 0 | H4: =IF(D4=1,SUMIFS(Benefits!$S$4:$S$703,Benefits!$B$4:$B$703,A4,Benefits!$F$4:$F$703,B4,Benefits!$R$4:$R$703,"avoided_cost_realised"),0) -> 0 | I4: =IF(D4=1,SUMIFS(Benefits!$S$4:$S$703,Benefits!$B$4:$B$703,A4,Benefits!$F$4:$F$703,B4,Benefits!$R$4:$R$703,"capacity_converted"),0) -> 0 | J4: =SUM(F4:I4) -> 0 | K4: =J4-E4 -> -783200 | L4: =IF(D4=1,K4,0) -> -783200 | M4: =IF(D4=1,1/(1+Controls!$B$11)^B4,0) -> 1 | N4: =K4*M4 -> -783200 | O4: =IF(D4=1,N4,0) -> -783200 | P4: =IF(AND(D4=1,L4<0),1,0) -> 1 | Q4: =IF(AND(D4=1,O4<0),1,0) -> 1
A5: init-001 | B5: 1 | C5: =IF(COUNTIF('Scenario inputs'!$A$4:$A$213,Controls!$B$3&"|"&A5)>0,1,0) -> 1 | D5: =IF(AND(C5=1,B5<Controls!$B$12),1,0) -> 1 | E5: =IF(D5=1,SUMPRODUCT((Costs!$B$4:$B$903=A5)*(Costs!$D$4:$D$903="planned")*(Costs!$J$4:$J$903<=B5)*(Costs!$K$4:$K$903>B5)*Costs!$E$4:$E$903),0) -> 161800 | F5: =IF(D5=1,SUMIFS(Benefits!$S$4:$S$703,Benefits!$B$4:$B$703,A5,Benefits!$F$4:$F$703,B5,Benefits!$R$4:$R$703,"cash"),0) -> 0 | G5: =IF(D5=1,SUMIFS(Benefits!$S$4:$S$703,Benefits!$B$4:$B$703,A5,Benefits!$F$4:$F$703,B5,Benefits!$R$4:$R$703,"revenue"),0) -> 0 | H5: =IF(D5=1,SUMIFS(Benefits!$S$4:$S$703,Benefits!$B$4:$B$703,A5,Benefits!$F$4:$F$703,B5,Benefits!$R$4:$R$703,"avoided_cost_realised"),0) -> 2669.6215 | I5: =IF(D5=1,SUMIFS(Benefits!$S$4:$S$703,Benefits!$B$4:$B$703,A5,Benefits!$F$4:$F$703,B5,Benefits!$R$4:$R$703,"capacity_converted"),0) -> 1497.3339 | J5: =SUM(F5:I5) -> 4166.9554 | K5: =J5-E5 -> -157633.04 | L5: =IF(D5=1,L4+K5,0) -> -940833.04 | M5: =IF(D5=1,1/(1+Controls!$B$11)^B5,0) -> 0.99360713 | N5: =K5*M5 -> -156625.32 | O5: =IF(D5=1,O4+N5,0) -> -939825.32 | P5: =IF(AND(D5=1,L5<0),1,0) -> 1 | Q5: =IF(AND(D5=1,O5<0),1,0) -> 1
A6: init-001 | B6: 2 | C6: =IF(COUNTIF('Scenario inputs'!$A$4:$A$213,Controls!$B$3&"|"&A6)>0,1,0) -> 1 | D6: =IF(AND(C6=1,B6<Controls!$B$12),1,0) -> 1 | E6: =IF(D6=1,SUMPRODUCT((Costs!$B$4:$B$903=A6)*(Costs!$D$4:$D$903="planned")*(Costs!$J$4:$J$903<=B6)*(Costs!$K$4:$K$903>B6)*Costs!$E$4:$E$903),0) -> 18000 | F6: =IF(D6=1,SUMIFS(Benefits!$S$4:$S$703,Benefits!$B$4:$B$703,A6,Benefits!$F$4:$F$703,B6,Benefits!$R$4:$R$703,"cash"),0) -> 4005.3251 | G6: =IF(D6=1,SUMIFS(Benefits!$S$4:$S$703,Benefits!$B$4:$B$703,A6,Benefits!$F$4:$F$703,B6,Benefits!$R$4:$R$703,"revenue"),0) -> 0 | H6: =IF(D6=1,SUMIFS(Benefits!$S$4:$S$703,Benefits!$B$4:$B$703,A6,Benefits!$F$4:$F$703,B6,Benefits!$R$4:$R$703,"avoided_cost_realised"),0) -> 8008.9393 | I6: =IF(D6=1,SUMIFS(Benefits!$S$4:$S$703,Benefits!$B$4:$B$703,A6,Benefits!$F$4:$F$703,B6,Benefits!$R$4:$R$703,"capacity_converted"),0) -> 4492.0435 | J6: =SUM(F6:I6) -> 16506.308 | K6: =J6-E6 -> -1493.6922 | L6: =IF(D6=1,L5+K6,0) -> -942326.74 | M6: =IF(D6=1,1/(1+Controls!$B$11)^B6,0) -> 0.98725513 | N6: =K6*M6 -> -1474.6552 | O6: =IF(D6=1,O5+N6,0) -> -941299.97 | P6: =IF(AND(D6=1,L6<0),1,0) -> 1 | Q6: =IF(AND(D6=1,O6<0),1,0) -> 1
A7: init-001 | B7: 3 | C7: =IF(COUNTIF('Scenario inputs'!$A$4:$A$213,Controls!$B$3&"|"&A7)>0,1,0) -> 1 | D7: =IF(AND(C7=1,B7<Controls!$B$12),1,0) -> 1 | E7: =IF(D7=1,SUMPRODUCT((Costs!$B$4:$B$903=A7)*(Costs!$D$4:$D$903="planned")*(Costs!$J$4:$J$903<=B7)*(Costs!$K$4:$K$903>B7)*Costs!$E$4:$E$903),0) -> 18000 | F7: =IF(D7=1,SUMIFS(Benefits!$S$4:$S$703,Benefits!$B$4:$B$703,A7,Benefits!$F$4:$F$703,B7,Benefits!$R$4:$R$703,"cash"),0) -> 12016.087 | G7: =IF(D7=1,SUMIFS(Benefits!$S$4:$S$703,Benefits!$B$4:$B$703,A7,Benefits!$F$4:$F$703,B7,Benefits!$R$4:$R$703,"revenue"),0) -> 0 | H7: =IF(D7=1,SUMIFS(Benefits!$S$4:$S$703,Benefits!$B$4:$B$703,A7,Benefits!$F$4:$F$703,B7,Benefits!$R$4:$R$703,"avoided_cost_realised"),0) -> 16017.879 | I7: =IF(D7=1,SUMIFS(Benefits!$S$4:$S$703,Benefits!$B$4:$B$703,A7,Benefits!$F$4:$F$703,B7,Benefits!$R$4:$R$703,"capacity_converted"),0) -> 8984.087 | J7: =SUM(F7:I7) -> 37018.053 | K7: =J7-E7 -> 19018.053 | L7: =IF(D7=1,L6+K7,0) -> -923308.68 | M7: =IF(D7=1,1/(1+Controls!$B$11)^B7,0) -> 0.98094374 | N7: =K7*M7 -> 18655.64 | O7: =IF(D7=1,O6+N7,0) -> -922644.33 | P7: =IF(AND(D7=1,L7<0),1,0) -> 1 | Q7: =IF(AND(D7=1,O7<0),1,0) -> 1
A8: init-001 | B8: 4 | C8: =IF(COUNTIF('Scenario inputs'!$A$4:$A$213,Controls!$B$3&"|"&A8)>0,1,0) -> 1 | D8: =IF(AND(C8=1,B8<Controls!$B$12),1,0) -> 1 | E8: =IF(D8=1,SUMPRODUCT((Costs!$B$4:$B$903=A8)*(Costs!$D$4:$D$903="planned")*(Costs!$J$4:$J$903<=B8)*(Costs!$K$4:$K$903>B8)*Costs!$E$4:$E$903),0) -> 18000 | F8: =IF(D8=1,SUMIFS(Benefits!$S$4:$S$703,Benefits!$B$4:$B$703,A8,Benefits!$F$4:$F$703,B8,Benefits!$R$4:$R$703,"cash"),0) -> 24032.175 | G8: =IF(D8=1,SUMIFS(Benefits!$S$4:$S$703,Benefits!$B$4:$B$703,A8,Benefits!$F$4:$F$703,B8,Benefits!$R$4:$R$703,"revenue"),0) -> 0 | H8: =IF(D8=1,SUMIFS(Benefits!$S$4:$S$703,Benefits!$B$4:$B$703,A8,Benefits!$F$4:$F$703,B8,Benefits!$R$4:$R$703,"avoided_cost_realised"),0) -> 26696.439 | I8: =IF(D8=1,SUMIFS(Benefits!$S$4:$S$703,Benefits!$B$4:$B$703,A8,Benefits!$F$4:$F$703,B8,Benefits!$R$4:$R$703,"capacity_converted"),0) -> 14973.464 | J8: =SUM(F8:I8) -> 65702.078 | K8: =J8-E8 -> 47702.078 | L8: =IF(D8=1,L7+K8,0) -> -875606.61 | M8: =IF(D8=1,1/(1+Controls!$B$11)^B8,0) -> 0.9746727 | N8: =K8*M8 -> 46493.913 | O8: =IF(D8=1,O7+N8,0) -> -876150.42 | P8: =IF(AND(D8=1,L8<0),1,0) -> 1 | Q8: =IF(AND(D8=1,O8<0),1,0) -> 1
A9: init-001 | B9: 5 | C9: =IF(COUNTIF('Scenario inputs'!$A$4:$A$213,Controls!$B$3&"|"&A9)>0,1,0) -> 1 | D9: =IF(AND(C9=1,B9<Controls!$B$12),1,0) -> 1 | E9: =IF(D9=1,SUMPRODUCT((Costs!$B$4:$B$903=A9)*(Costs!$D$4:$D$903="planned")*(Costs!$J$4:$J$903<=B9)*(Costs!$K$4:$K$903>B9)*Costs!$E$4:$E$903),0) -> 18000 | F9: =IF(D9=1,SUMIFS(Benefits!$S$4:$S$703,Benefits!$B$4:$B$703,A9,Benefits!$F$4:$F$703,B9,Benefits!$R$4:$R$703,"cash"),0) -> 40053.587 | G9: =IF(D9=1,SUMIFS(Benefits!$S$4:$S$703,Benefits!$B$4:$B$703,A9,Benefits!$F$4:$F$703,B9,Benefits!$R$4:$R$703,"revenue"),0) -> 0 | H9: =IF(D9=1,SUMIFS(Benefits!$S$4:$S$703,Benefits!$B$4:$B$703,A9,Benefits!$F$4:$F$703,B9,Benefits!$R$4:$R$703,"avoided_cost_realised"),0) -> 40044.622 | I9: =IF(D9=1,SUMIFS(Benefits!$S$4:$S$703,Benefits!$B$4:$B$703,A9,Benefits!$F$4:$F$703,B9,Benefits!$R$4:$R$703,"capacity_converted"),0) -> 22460.176 | J9: =SUM(F9:I9) -> 102558.38 | K9: =J9-E9 -> 84558.385 | L9: =IF(D9=1,L8+K9,0) -> -791048.22 | M9: =IF(D9=1,1/(1+Controls!$B$11)^B9,0) -> 0.96844174 | N9: =K9*M9 -> 81889.869 | O9: =IF(D9=1,O8+N9,0) -> -794260.55 | P9: =IF(AND(D9=1,L9<0),1,0) -> 1 | Q9: =IF(AND(D9=1,O9<0),1,0) -> 1
A10: init-001 | B10: 6 | C10: =IF(COUNTIF('Scenario inputs'!$A$4:$A$213,Controls!$B$3&"|"&A10)>0,1,0) -> 1 | D10: =IF(AND(C10=1,B10<Controls!$B$12),1,0) -> 1 | E10: =IF(D10=1,SUMPRODUCT((Costs!$B$4:$B$903=A10)*(Costs!$D$4:$D$903="planned")*(Costs!$J$4:$J$903<=B10)*(Costs!$K$4:$K$903>B10)*Costs!$E$4:$E$903),0) -> 18000 | F10: =IF(D10=1,SUMIFS(Benefits!$S$4:$S$703,Benefits!$B$4:$B$703,A10,Benefits!$F$4:$F$703,B10,Benefits!$R$4:$R$703,"cash"),0) -> 60080.325 | G10: =IF(D10=1,SUMIFS(Benefits!$S$4:$S$703,Benefits!$B$4:$B$703,A10,Benefits!$F$4:$F$703,B10,Benefits!$R$4:$R$703,"revenue"),0) -> 0 | H10: =IF(D10=1,SUMIFS(Benefits!$S$4:$S$703,Benefits!$B$4:$B$703,A10,Benefits!$F$4:$F$703,B10,Benefits!$R$4:$R$703,"avoided_cost_realised"),0) -> 56062.5 | I10: =IF(D10=1,SUMIFS(Benefits!$S$4:$S$703,Benefits!$B$4:$B$703,A10,Benefits!$F$4:$F$703,B10,Benefits!$R$4:$R$703,"capacity_converted"),0) -> 31444.263 | J10: =SUM(F10:I10) -> 147587.09 | K10: =J10-E10 -> 129587.09 | L10: =IF(D10=1,L9+K10,0) -> -661461.13 | M10: =IF(D10=1,1/(1+Controls!$B$11)^B10,0) -> 0.96225062 | N10: =K10*M10 -> 124695.26 | O10: =IF(D10=1,O9+N10,0) -> -669565.29 | P10: =IF(AND(D10=1,L10<0),1,0) -> 1 | Q10: =IF(AND(D10=1,O10<0),1,0) -> 1
A11: init-001 | B11: 7 | C11: =IF(COUNTIF('Scenario inputs'!$A$4:$A$213,Controls!$B$3&"|"&A11)>0,1,0) -> 1 | D11: =IF(AND(C11=1,B11<Controls!$B$12),1,0) -> 1 | E11: =IF(D11=1,SUMPRODUCT((Costs!$B$4:$B$903=A11)*(Costs!$D$4:$D$903="planned")*(Costs!$J$4:$J$903<=B11)*(Costs!$K$4:$K$903>B11)*Costs!$E$4:$E$903),0) -> 18300 | F11: =IF(D11=1,SUMIFS(Benefits!$S$4:$S$703,Benefits!$B$4:$B$703,A11,Benefits!$F$4:$F$703,B11,Benefits!$R$4:$R$703,"cash"),0) -> 84112.5 | G11: =IF(D11=1,SUMIFS(Benefits!$S$4:$S$703,Benefits!$B$4:$B$703,A11,Benefits!$F$4:$F$703,B11,Benefits!$R$4:$R$703,"revenue"),0) -> 0 | H11: =IF(D11=1,SUMIFS(Benefits!$S$4:$S$703,Benefits!$B$4:$B$703,A11,Benefits!$F$4:$F$703,B11,Benefits!$R$4:$R$703,"avoided_cost_realised"),0) -> 74750 | I11: =IF(D11=1,SUMIFS(Benefits!$S$4:$S$703,Benefits!$B$4:$B$703,A11,Benefits!$F$4:$F$703,B11,Benefits!$R$4:$R$703,"capacity_converted"),0) -> 41925.683 | J11: =SUM(F11:I11) -> 200788.18 | K11: =J11-E11 -> 182488.18 | L11: =IF(D11=1,L10+K11,0) -> -478972.95 | M11: =IF(D11=1,1/(1+Controls!$B$11)^B11,0) -> 0.95609908 | N11: =K11*M11 -> 174476.78 | O11: =IF(D11=1,O10+N11,0) -> -495088.51 | P11: =IF(AND(D11=1,L11<0),1,0) -> 1 | Q11: =IF(AND(D11=1,O11<0),1,0) -> 1
A12: init-001 | B12: 8 | C12: =IF(COUNTIF('Scenario inputs'!$A$4:$A$213,Controls!$B$3&"|"&A12)>0,1,0) -> 1 | D12: =IF(AND(C12=1,B12<Controls!$B$12),1,0) -> 1 | E12: =IF(D12=1,SUMPRODUCT((Costs!$B$4:$B$903=A12)*(Costs!$D$4:$D$903="planned")*(Costs!$J$4:$J$903<=B12)*(Costs!$K$4:$K$903>B12)*Costs!$E$4:$E$903),0) -> 18300 | F12: =IF(D12=1,SUMIFS(Benefits!$S$4:$S$703,Benefits!$B$4:$B$703,A12,Benefits!$F$4:$F$703,B12,Benefits!$R$4:$R$703,"cash"),0) -> 112150 | G12: =IF(D12=1,SUMIFS(Benefits!$S$4:$S$703,Benefits!$B$4:$B$703,A12,Benefits!$F$4:$F$703,B12,Benefits!$R$4:$R$703,"revenue"),0) -> 0 | H12: =IF(D12=1,SUMIFS(Benefits!$S$4:$S$703,Benefits!$B$4:$B$703,A12,Benefits!$F$4:$F$703,B12,Benefits!$R$4:$R$703,"avoided_cost_realised"),0) -> 74750 | I12: =IF(D12=1,SUMIFS(Benefits!$S$4:$S$703,Benefits!$B$4:$B$703,A12,Benefits!$F$4:$F$703,B12,Benefits!$R$4:$R$703,"capacity_converted"),0) -> 41925.683 | J12: =SUM(F12:I12) -> 228825.68 | K12: =J12-E12 -> 210525.68 | L12: =IF(D12=1,L11+K12,0) -> -268447.27 | M12: =IF(D12=1,1/(1+Controls!$B$11)^B12,0) -> 0.94998686 | N12: =K12*M12 -> 199996.63 | O12: =IF(D12=1,O11+N12,0) -> -295091.88 | P12: =IF(AND(D12=1,L12<0),1,0) -> 1 | Q12: =IF(AND(D12=1,O12<0),1,0) -> 1
A13: init-001 | B13: 9 | C13: =IF(COUNTIF('Scenario inputs'!$A$4:$A$213,Controls!$B$3&"|"&A13)>0,1,0) -> 1 | D13: =IF(AND(C13=1,B13<Controls!$B$12),1,0) -> 1 | E13: =IF(D13=1,SUMPRODUCT((Costs!$B$4:$B$903=A13)*(Costs!$D$4:$D$903="planned")*(Costs!$J$4:$J$903<=B13)*(Costs!$K$4:$K$903>B13)*Costs!$E$4:$E$903),0) -> 18300 | F13: =IF(D13=1,SUMIFS(Benefits!$S$4:$S$703,Benefits!$B$4:$B$703,A13,Benefits!$F$4:$F$703,B13,Benefits!$R$4:$R$703,"cash"),0) -> 112150 | G13: =IF(D13=1,SUMIFS(Benefits!$S$4:$S$703,Benefits!$B$4:$B$703,A13,Benefits!$F$4:$F$703,B13,Benefits!$R$4:$R$703,"revenue"),0) -> 0 | H13: =IF(D13=1,SUMIFS(Benefits!$S$4:$S$703,Benefits!$B$4:$B$703,A13,Benefits!$F$4:$F$703,B13,Benefits!$R$4:$R$703,"avoided_cost_realised"),0) -> 74750 | I13: =IF(D13=1,SUMIFS(Benefits!$S$4:$S$703,Benefits!$B$4:$B$703,A13,Benefits!$F$4:$F$703,B13,Benefits!$R$4:$R$703,"capacity_converted"),0) -> 41925.683 | J13: =SUM(F13:I13) -> 228825.68 | K13: =J13-E13 -> 210525.68 | L13: =IF(D13=1,L12+K13,0) -> -57921.583 | M13: =IF(D13=1,1/(1+Controls!$B$11)^B13,0) -> 0.94391372 | N13: =K13*M13 -> 198718.08 | O13: =IF(D13=1,O12+N13,0) -> -96373.795 | P13: =IF(AND(D13=1,L13<0),1,0) -> 1 | Q13: =IF(AND(D13=1,O13<0),1,0) -> 1
A14: init-001 | B14: 10 | C14: =IF(COUNTIF('Scenario inputs'!$A$4:$A$213,Controls!$B$3&"|"&A14)>0,1,0) -> 1 | D14: =IF(AND(C14=1,B14<Controls!$B$12),1,0) -> 1 | E14: =IF(D14=1,SUMPRODUCT((Costs!$B$4:$B$903=A14)*(Costs!$D$4:$D$903="planned")*(Costs!$J$4:$J$903<=B14)*(Costs!$K$4:$K$903>B14)*Costs!$E$4:$E$903),0) -> 18300 | F14: =IF(D14=1,SUMIFS(Benefits!$S$4:$S$703,Benefits!$B$4:$B$703,A14,Benefits!$F$4:$F$703,B14,Benefits!$R$4:$R$703,"cash"),0) -> 112150 | G14: =IF(D14=1,SUMIFS(Benefits!$S$4:$S$703,Benefits!$B$4:$B$703,A14,Benefits!$F$4:$F$703,B14,Benefits!$R$4:$R$703,"revenue"),0) -> 0 | H14: =IF(D14=1,SUMIFS(Benefits!$S$4:$S$703,Benefits!$B$4:$B$703,A14,Benefits!$F$4:$F$703,B14,Benefits!$R$4:$R$703,"avoided_cost_realised"),0) -> 74750 | I14: =IF(D14=1,SUMIFS(Benefits!$S$4:$S$703,Benefits!$B$4:$B$703,A14,Benefits!$F$4:$F$703,B14,Benefits!$R$4:$R$703,"capacity_converted"),0) -> 41925.683 | J14: =SUM(F14:I14) -> 228825.68 | K14: =J14-E14 -> 210525.68 | L14: =IF(D14=1,L13+K14,0) -> 152604.1 | M14: =IF(D14=1,1/(1+Controls!$B$11)^B14,0) -> 0.93787941 | N14: =K14*M14 -> 197447.7 | O14: =IF(D14=1,O13+N14,0) -> 101073.91 | P14: =IF(AND(D14=1,L14<0),1,0) -> 0 | Q14: =IF(AND(D14=1,O14<0),1,0) -> 0
A15: init-001 | B15: 11 | C15: =IF(COUNTIF('Scenario inputs'!$A$4:$A$213,Controls!$B$3&"|"&A15)>0,1,0) -> 1 | D15: =IF(AND(C15=1,B15<Controls!$B$12),1,0) -> 1 | E15: =IF(D15=1,SUMPRODUCT((Costs!$B$4:$B$903=A15)*(Costs!$D$4:$D$903="planned")*(Costs!$J$4:$J$903<=B15)*(Costs!$K$4:$K$903>B15)*Costs!$E$4:$E$903),0) -> 18300 | F15: =IF(D15=1,SUMIFS(Benefits!$S$4:$S$703,Benefits!$B$4:$B$703,A15,Benefits!$F$4:$F$703,B15,Benefits!$R$4:$R$703,"cash"),0) -> 112150 | G15: =IF(D15=1,SUMIFS(Benefits!$S$4:$S$703,Benefits!$B$4:$B$703,A15,Benefits!$F$4:$F$703,B15,Benefits!$R$4:$R$703,"revenue"),0) -> 0 | H15: =IF(D15=1,SUMIFS(Benefits!$S$4:$S$703,Benefits!$B$4:$B$703,A15,Benefits!$F$4:$F$703,B15,Benefits!$R$4:$R$703,"avoided_cost_realised"),0) -> 74750 | I15: =IF(D15=1,SUMIFS(Benefits!$S$4:$S$703,Benefits!$B$4:$B$703,A15,Benefits!$F$4:$F$703,B15,Benefits!$R$4:$R$703,"capacity_converted"),0) -> 41925.683 | J15: =SUM(F15:I15) -> 228825.68 | K15: =J15-E15 -> 210525.68 | L15: =IF(D15=1,L14+K15,0) -> 363129.78 | M15: =IF(D15=1,1/(1+Controls!$B$11)^B15,0) -> 0.93188367 | N15: =K15*M15 -> 196185.45 | O15: =IF(D15=1,O14+N15,0) -> 297259.35 | P15: =IF(AND(D15=1,L15<0),1,0) -> 0 | Q15: =IF(AND(D15=1,O15<0),1,0) -> 0
A16: init-001 | B16: 12 | C16: =IF(COUNTIF('Scenario inputs'!$A$4:$A$213,Controls!$B$3&"|"&A16)>0,1,0) -> 1 | D16: =IF(AND(C16=1,B16<Controls!$B$12),1,0) -> 1 | E16: =IF(D16=1,SUMPRODUCT((Costs!$B$4:$B$903=A16)*(Costs!$D$4:$D$903="planned")*(Costs!$J$4:$J$903<=B16)*(Costs!$K$4:$K$903>B16)*Costs!$E$4:$E$903),0) -> 18300 | F16: =IF(D16=1,SUMIFS(Benefits!$S$4:$S$703,Benefits!$B$4:$B$703,A16,Benefits!$F$4:$F$703,B16,Benefits!$R$4:$R$703,"cash"),0) -> 112150 | G16: =IF(D16=1,SUMIFS(Benefits!$S$4:$S$703,Benefits!$B$4:$B$703,A16,Benefits!$F$4:$F$703,B16,Benefits!$R$4:$R$703,"revenue"),0) -> 0 | H16: =IF(D16=1,SUMIFS(Benefits!$S$4:$S$703,Benefits!$B$4:$B$703,A16,Benefits!$F$4:$F$703,B16,Benefits!$R$4:$R$703,"avoided_cost_realised"),0) -> 74750 | I16: =IF(D16=1,SUMIFS(Benefits!$S$4:$S$703,Benefits!$B$4:$B$703,A16,Benefits!$F$4:$F$703,B16,Benefits!$R$4:$R$703,"capacity_converted"),0) -> 41925.683 | J16: =SUM(F16:I16) -> 228825.68 | K16: =J16-E16 -> 210525.68 | L16: =IF(D16=1,L15+K16,0) -> 573655.47 | M16: =IF(D16=1,1/(1+Controls!$B$11)^B16,0) -> 0.92592626 | N16: =K16*M16 -> 194931.26 | O16: =IF(D16=1,O15+N16,0) -> 492190.61 | P16: =IF(AND(D16=1,L16<0),1,0) -> 0 | Q16: =IF(AND(D16=1,O16<0),1,0) -> 0
