Workbook

Sheet Read me
A1: ProductSignal analyst workbook (P06-ART-05)
A2: SYNTHETIC DATA: every account, user and event is generated (seed 20261026); nothing describes a real product, customer or measurement.
A4: What it is | B4: A formula-driven workbook over the published synthetic snapshot of ProductSignal (600 accounts, 554 experiment assignments in two versions of one onboarding experiment). It recomputes the experiment read of any of the five logged analysis runs with live formulas: conversions, absolute and relative lift, Wilson and Newcombe intervals, the chi-square sample-ratio statistic, exposure, the guardrail, revenue per assigned account and the conclusive rule.
A5: The decision it supports | B5: Should an onboarding change ship, stop, or receive more investigation? Metrics shows, for the selected run, what the evidence was at that cutoff, and the check column compares every figure with the Python domain's value for the same run.
A6: How to read it without installing anything | B6: Open the .xlsx in any spreadsheet application, or read docs/workbook.md (it lists every sheet and the checked values). The delivered file already carries values calculated by LibreOffice for run an-004 (the final run of v1).
A7: How to use the switch | B7: Cutoff!B3 takes an-001, an-002, an-003, an-004 or an-005 (a list): the four v1 runs (an-001, an-002, an-003 are interim, an-004 is the final run at planned_end) and v2's one run (an-005). Every figure on Metrics follows it, including which assignments existed (the cutoff rule D-08).
A8: The sample ratio comes first | B8: When the sample-ratio verdict is MISMATCH (v2, an-005) every outcome row of Metrics shows the word withheld, as the site does: no lift of v2 is shown or decided on. The domain's figures are not pasted for those rows.
A9: Observed, constructed, hypothetical | B9: Everything here is OBSERVED in one draw of a synthetic world. The generator built the treatment effect (a designed +8.00 percentage points), a designed sample-ratio mismatch in v2 and an injected instrumentation gap (INJ-10) that reaches the published v1 lift: published +9.50, drawn +11.50, +9.96 excluding the 11 gap accounts. Four generator choices were made after looking at earlier drafts (docs/executive-memo.md). Nothing is a benefit to a real product. The v1 result is conclusive by a hair: the lower bound of the Newcombe interval is +0.000812.
A10: Inputs (blue) and formulas (black) | B10: Blue cells are typed inputs: the accounts, the assignments with their signup, activation, error and exposure instants (epoch seconds), the subscriptions, the runs and the plans. Black cells are formulas.
A11: What the formulas do NOT do | B11: They do not canonicalise the event log (received by the cutoff, deduplicated, identity forward only, bots and internal accounts excluded) or take the plan's sha256: the instants of the first signup, the activation and the first error inside the guardrail window are typed from the independent Python side. A signup whose earliest event arrives late while a later one arrives earlier would be read differently; none exists in this snapshot at the five runs (limit W-02, checked at build time).
A12: Provenance | B12: Dataset hash 12672f9c39402517083bbbbe9164cbefe3435361dff086eb0d9e16e60f9b66f8 (generator, seed 20261026, dataset ps-20261026-20261026), contract v1, code revision fdf911a. Built by artifacts/build_workbook.py with openpyxl 3.1.5.
A13: Recalculation status | B13: openpyxl wrote formulas only; LibreOffice (headless) recalculated the delivered file. Microsoft Excel was NOT run: nothing here was opened or recalculated by Excel (docs/workbook.md).

Sheet Cutoff
A1: The cutoff switch
A2: Type an-001 .. an-005 in B3 (a list). Every figure on Metrics and every flag column of Assignments follows it.
A3: selected run | B3: an-004
A10: selected cutoff (epoch seconds, UTC) | B10: =INDEX(Runs!$D$5:$D$9,B11) -> 1785628800
A11: selected position in Runs | B11: =MATCH($B$3,Runs!$A$5:$A$9,0) -> 4
A12: selected experiment version | B12: =INDEX(Runs!$B$5:$B$9,B11) -> xv-001
A13: selected planned_end (epoch) | B13: =INDEX(Plans!$B$5:$B$6,MATCH($B$12,Plans!$A$5:$A$6,0)) -> 1785628800 | C13: as-of epoch (2026-10-05T00:00:00Z), used by Accounts | D13: 1791158400
A14: selected run is interim (cutoff before planned_end) | B14: =B10<B13 -> FALSE
A16: activation window (seconds) | B16: =INDEX(Plans!$K$5:$K$6,MATCH($B$12,Plans!$A$5:$A$6,0))*86400 -> 604800
A17: guardrail window (seconds) | B17: =INDEX(Plans!$L$5:$L$6,MATCH($B$12,Plans!$A$5:$A$6,0))*86400 -> 604800
A18: z of the plan | B18: =INDEX(Plans!$G$5:$G$6,MATCH($B$12,Plans!$A$5:$A$6,0)) -> 1.959964
A19: alpha (1 - confidence) | B19: =1-INDEX(Plans!$H$5:$H$6,MATCH($B$12,Plans!$A$5:$A$6,0)) -> 0.05
A20: allocation control | B20: =INDEX(Plans!$E$5:$E$6,MATCH($B$12,Plans!$A$5:$A$6,0)) -> 0.5
A21: allocation treatment | B21: =INDEX(Plans!$F$5:$F$6,MATCH($B$12,Plans!$A$5:$A$6,0)) -> 0.5
A22: SRM p threshold | B22: =INDEX(Plans!$I$5:$I$6,MATCH($B$12,Plans!$A$5:$A$6,0)) -> 0.001
A23: SRM minimum expected cell | B23: =INDEX(Plans!$J$5:$J$6,MATCH($B$12,Plans!$A$5:$A$6,0)) -> 5
A24: revenue window from (epoch) | B24: =INDEX(Plans!$M$5:$M$6,MATCH($B$12,Plans!$A$5:$A$6,0)) -> 1775433600
A25: revenue window to (epoch) | B25: =INDEX(Plans!$N$5:$N$6,MATCH($B$12,Plans!$A$5:$A$6,0)) -> 1785628800
A26: plan frozen before the first logged run | B26: =INDEX(Plans!$C$5:$C$6,MATCH($B$12,Plans!$A$5:$A$6,0))<=INDEX(Plans!$D$5:$D$6,MATCH($B$12,Plans!$A$5:$A$6,0)) -> TRUE
A27: plan hash valid (typed) | B27: =INDEX(Plans!$P$5:$P$6,MATCH($B$12,Plans!$A$5:$A$6,0)) -> TRUE

Sheet Metrics
A1: Experiment read for the selected run (live formulas)
A2: Run: Cutoff!B3. Control, treatment and a combined/difference column. 'check' is TRUE when every figure of the row equals the Python domain's value for the same run within the tolerance (pasted on 'Domain reference'; for a sample-ratio MISMATCH the reference is the word withheld).
A3: selected run | B3: =Cutoff!B3 -> an-004 | D3: all checks TRUE | E3: =AND(I6:I44) -> TRUE
A4: outcomes withheld (sample ratio is a MISMATCH) | B4: =F12="MISMATCH" -> FALSE
A5: metric id | B5: metric | C5: unit | D5: control | E5: treatment | F5: combined / difference | G5: definition | H5: tolerance | I5: check
A6: assigned_accounts | B6: assigned accounts | C6: accounts | D6: =SUMIFS(Assignments!$L$2:$L$555,Assignments!$D$2:$D$555,"control") -> 200 | E6: =SUMIFS(Assignments!$L$2:$L$555,Assignments!$D$2:$D$555,"treatment") -> 200 | F6: =$D$6+$E$6 -> 400 | G6: Assignments of the selected version with assigned_at <= the cutoff (D-08): the first assignment of each account is its assignment. | H6: 0 | I6: =AND(IF(ISNUMBER(INDEX('Domain reference'!$B$5:$P$5,MATCH(Cutoff!$B$3&"|control",'Domain reference'!$B$4:$P$4,0))),IF(ISNUMBER(D6),ABS(D6-INDEX('Domain reference'!$B$5:$P$5,MATCH(Cutoff!$B$3&"|control",'Domain reference'!$B$4:$P$4,0)))<=$H6+0.0000000001,FALSE()),IF(ISBLANK(INDEX('Domain reference'!$B$5:$P$5,MATCH(Cutoff!$B$3&"|control",'Domain reference'!$B$4:$P$4,0))),D6="",D6=INDEX('Domain reference'!$B$5:$P$5,MATCH(Cutoff!$B$3&"|control",'Domain reference'!$B$4:$P$4,0)))),IF(ISNUMBER(INDEX('Domain reference'!$B$5:$P$5,MATCH(Cutoff!$B$3&"|treatment",'Domain reference'!$B$4:$P$4,0))),IF(ISNUMBER(E6),ABS(E6-INDEX('Domain reference'!$B$5:$P$5,MATCH(Cutoff!$B$3&"|treatment",'Domain reference'!$B$4:$P$4,0)))<=$H6+0.0000000001,FALSE()),IF(ISBLANK(INDEX('Domain reference'!$B$5:$P$5,MATCH(Cutoff!$B$3&"|treatment",'Domain reference'!$B$4:$P$4,0))),E6="",E6=INDEX('Domain reference'!$B$5:$P$5,MATCH(Cutoff!$B$3&"|treatment",'Domain reference'!$B$4:$P$4,0)))),IF(ISNUMBER(INDEX('Domain reference'!$B$5:$P$5,MATCH(Cutoff!$B$3&"|combined",'Domain reference'!$B$4:$P$4,0))),IF(ISNUMBER(F6),ABS(F6-INDEX('Domain reference'!$B$5:$P$5,MATCH(Cutoff!$B$3&"|combined",'Domain reference'!$B$4:$P$4,0)))<=$H6+0.0000000001,FALSE()),IF(ISBLANK(INDEX('Domain reference'!$B$5:$P$5,MATCH(Cutoff!$B$3&"|combined",'Domain reference'!$B$4:$P$4,0))),F6="",F6=INDEX('Domain reference'!$B$5:$P$5,MATCH(Cutoff!$B$3&"|combined",'Domain reference'!$B$4:$P$4,0))))) -> TRUE
A7: mature_accounts | B7: mature assigned accounts | C7: accounts | D7: =COUNTIFS(Assignments!$D$2:$D$555,"control",Assignments!$N$2:$N$555,1) -> 200 | E7: =COUNTIFS(Assignments!$D$2:$D$555,"treatment",Assignments!$N$2:$N$555,1) -> 200 | F7: =$D$7+$E$7 -> 400 | G7: Assigned accounts whose signup (the earliest signup event received by the cutoff) + 7 x 24 h <= the cutoff. | H7: 0 | I7: =AND(IF(ISNUMBER(INDEX('Domain reference'!$B$6:$P$6,MATCH(Cutoff!$B$3&"|control",'Domain reference'!$B$4:$P$4,0))),IF(ISNUMBER(D7),ABS(D7-INDEX('Domain reference'!$B$6:$P$6,MATCH(Cutoff!$B$3&"|control",'Domain reference'!$B$4:$P$4,0)))<=$H7+0.0000000001,FALSE()),IF(ISBLANK(INDEX('Domain reference'!$B$6:$P$6,MATCH(Cutoff!$B$3&"|control",'Domain reference'!$B$4:$P$4,0))),D7="",D7=INDEX('Domain reference'!$B$6:$P$6,MATCH(Cutoff!$B$3&"|control",'Domain reference'!$B$4:$P$4,0)))),IF(ISNUMBER(INDEX('Domain reference'!$B$6:$P$6,MATCH(Cutoff!$B$3&"|treatment",'Domain reference'!$B$4:$P$4,0))),IF(ISNUMBER(E7),ABS(E7-INDEX('Domain reference'!$B$6:$P$6,MATCH(Cutoff!$B$3&"|treatment",'Domain reference'!$B$4:$P$4,0)))<=$H7+0.0000000001,FALSE()),IF(ISBLANK(INDEX('Domain reference'!$B$6:$P$6,MATCH(Cutoff!$B$3&"|treatment",'Domain reference'!$B$4:$P$4,0))),E7="",E7=INDEX('Domain reference'!$B$6:$P$6,MATCH(Cutoff!$B$3&"|treatment",'Domain reference'!$B$4:$P$4,0)))),IF(ISNUMBER(INDEX('Domain reference'!$B$6:$P$6,MATCH(Cutoff!$B$3&"|combined",'Domain reference'!$B$4:$P$4,0))),IF(ISNUMBER(F7),ABS(F7-INDEX('Domain reference'!$B$6:$P$6,MATCH(Cutoff!$B$3&"|combined",'Domain reference'!$B$4:$P$4,0)))<=$H7+0.0000000001,FALSE()),IF(ISBLANK(INDEX('Domain reference'!$B$6:$P$6,MATCH(Cutoff!$B$3&"|combined",'Domain reference'!$B$4:$P$4,0))),F7="",F7=INDEX('Domain reference'!$B$6:$P$6,MATCH(Cutoff!$B$3&"|combined",'Domain reference'!$B$4:$P$4,0))))) -> TRUE
A8: immature_or_unobserved | B8: assigned, not yet mature | C8: accounts | D8: =$D$6-$D$7 -> 0 | E8: =$E$6-$E$7 -> 0 | F8: =$F$6-$F$7 -> 0 | G8: Assigned minus mature: counted apart and in no rate. | H8: 0 | I8: =AND(IF(ISNUMBER(INDEX('Domain reference'!$B$7:$P$7,MATCH(Cutoff!$B$3&"|control",'Domain reference'!$B$4:$P$4,0))),IF(ISNUMBER(D8),ABS(D8-INDEX('Domain reference'!$B$7:$P$7,MATCH(Cutoff!$B$3&"|control",'Domain reference'!$B$4:$P$4,0)))<=$H8+0.0000000001,FALSE()),IF(ISBLANK(INDEX('Domain reference'!$B$7:$P$7,MATCH(Cutoff!$B$3&"|control",'Domain reference'!$B$4:$P$4,0))),D8="",D8=INDEX('Domain reference'!$B$7:$P$7,MATCH(Cutoff!$B$3&"|control",'Domain reference'!$B$4:$P$4,0)))),IF(ISNUMBER(INDEX('Domain reference'!$B$7:$P$7,MATCH(Cutoff!$B$3&"|treatment",'Domain reference'!$B$4:$P$4,0))),IF(ISNUMBER(E8),ABS(E8-INDEX('Domain reference'!$B$7:$P$7,MATCH(Cutoff!$B$3&"|treatment",'Domain reference'!$B$4:$P$4,0)))<=$H8+0.0000000001,FALSE()),IF(ISBLANK(INDEX('Domain reference'!$B$7:$P$7,MATCH(Cutoff!$B$3&"|treatment",'Domain reference'!$B$4:$P$4,0))),E8="",E8=INDEX('Domain reference'!$B$7:$P$7,MATCH(Cutoff!$B$3&"|treatment",'Domain reference'!$B$4:$P$4,0)))),IF(ISNUMBER(INDEX('Domain reference'!$B$7:$P$7,MATCH(Cutoff!$B$3&"|combined",'Domain reference'!$B$4:$P$4,0))),IF(ISNUMBER(F8),ABS(F8-INDEX('Domain reference'!$B$7:$P$7,MATCH(Cutoff!$B$3&"|combined",'Domain reference'!$B$4:$P$4,0)))<=$H8+0.0000000001,FALSE()),IF(ISBLANK(INDEX('Domain reference'!$B$7:$P$7,MATCH(Cutoff!$B$3&"|combined",'Domain reference'!$B$4:$P$4,0))),F8="",F8=INDEX('Domain reference'!$B$7:$P$7,MATCH(Cutoff!$B$3&"|combined",'Domain reference'!$B$4:$P$4,0))))) -> TRUE
A9: srm_expected | B9: expected assignments under the allocation | C9: accounts | D9: =$F$6*Cutoff!$B$20 -> 200 | E9: =$F$6*Cutoff!$B$21 -> 200 | G9: Total assigned x the plan's allocation of the arm. | H9: 5e-07 | I9: =AND(IF(ISNUMBER(INDEX('Domain reference'!$B$8:$P$8,MATCH(Cutoff!$B$3&"|control",'Domain reference'!$B$4:$P$4,0))),IF(ISNUMBER(D9),ABS(D9-INDEX('Domain reference'!$B$8:$P$8,MATCH(Cutoff!$B$3&"|control",'Domain reference'!$B$4:$P$4,0)))<=$H9+0.0000000001,FALSE()),IF(ISBLANK(INDEX('Domain reference'!$B$8:$P$8,MATCH(Cutoff!$B$3&"|control",'Domain reference'!$B$4:$P$4,0))),D9="",D9=INDEX('Domain reference'!$B$8:$P$8,MATCH(Cutoff!$B$3&"|control",'Domain reference'!$B$4:$P$4,0)))),IF(ISNUMBER(INDEX('Domain reference'!$B$8:$P$8,MATCH(Cutoff!$B$3&"|treatment",'Domain reference'!$B$4:$P$4,0))),IF(ISNUMBER(E9),ABS(E9-INDEX('Domain reference'!$B$8:$P$8,MATCH(Cutoff!$B$3&"|treatment",'Domain reference'!$B$4:$P$4,0)))<=$H9+0.0000000001,FALSE()),IF(ISBLANK(INDEX('Domain reference'!$B$8:$P$8,MATCH(Cutoff!$B$3&"|treatment",'Domain reference'!$B$4:$P$4,0))),E9="",E9=INDEX('Domain reference'!$B$8:$P$8,MATCH(Cutoff!$B$3&"|treatment",'Domain reference'!$B$4:$P$4,0))))) -> TRUE
A10: srm_statistic | B10: sample-ratio chi-square statistic | C10: chi-square, df 1 | F10: =IF($F$6=0,"",($D$6-$D$9)^2/$D$9+($E$6-$E$9)^2/$E$9) -> 0 | G10: Sum of (observed - expected)^2 / expected over the two arms. | H10: 5e-07 | I10: =AND(IF(ISNUMBER(INDEX('Domain reference'!$B$9:$P$9,MATCH(Cutoff!$B$3&"|combined",'Domain reference'!$B$4:$P$4,0))),IF(ISNUMBER(F10),ABS(F10-INDEX('Domain reference'!$B$9:$P$9,MATCH(Cutoff!$B$3&"|combined",'Domain reference'!$B$4:$P$4,0)))<=$H10+0.0000000001,FALSE()),IF(ISBLANK(INDEX('Domain reference'!$B$9:$P$9,MATCH(Cutoff!$B$3&"|combined",'Domain reference'!$B$4:$P$4,0))),F10="",F10=INDEX('Domain reference'!$B$9:$P$9,MATCH(Cutoff!$B$3&"|combined",'Domain reference'!$B$4:$P$4,0))))) -> TRUE
A11: srm_p_value | B11: sample-ratio p-value | C11: probability | F11: =IF($F$10="","",CHIDIST($F$10,1)) -> 1 | G11: CHIDIST(statistic, 1); the domain publishes it to six decimals. | H11: 5e-07 | I11: =AND(IF(ISNUMBER(INDEX('Domain reference'!$B$10:$P$10,MATCH(Cutoff!$B$3&"|combined",'Domain reference'!$B$4:$P$4,0))),IF(ISNUMBER(F11),ABS(F11-INDEX('Domain reference'!$B$10:$P$10,MATCH(Cutoff!$B$3&"|combined",'Domain reference'!$B$4:$P$4,0)))<=$H11+0.0000000001,FALSE()),IF(ISBLANK(INDEX('Domain reference'!$B$10:$P$10,MATCH(Cutoff!$B$3&"|combined",'Domain reference'!$B$4:$P$4,0))),F11="",F11=INDEX('Domain reference'!$B$10:$P$10,MATCH(Cutoff!$B$3&"|combined",'Domain reference'!$B$4:$P$4,0))))) -> TRUE
A12: srm_verdict | B12: sample-ratio verdict | C12: text | F12: =IF($F$6=0,"INSUFFICIENT",IF(MIN($D$9,$E$9)<Cutoff!$B$23,"INSUFFICIENT",IF($F$11<Cutoff!$B$22,"MISMATCH","OK"))) -> OK | G12: INSUFFICIENT when an expected cell is below the plan's minimum, MISMATCH when p is below the plan's threshold, else OK. | H12: 0 | I12: =AND(IF(ISNUMBER(INDEX('Domain reference'!$B$11:$P$11,MATCH(Cutoff!$B$3&"|combined",'Domain reference'!$B$4:$P$4,0))),IF(ISNUMBER(F12),ABS(F12-INDEX('Domain reference'!$B$11:$P$11,MATCH(Cutoff!$B$3&"|combined",'Domain reference'!$B$4:$P$4,0)))<=$H12+0.0000000001,FALSE()),IF(ISBLANK(INDEX('Domain reference'!$B$11:$P$11,MATCH(Cutoff!$B$3&"|combined",'Domain reference'!$B$4:$P$4,0))),F12="",F12=INDEX('Domain reference'!$B$11:$P$11,MATCH(Cutoff!$B$3&"|combined",'Domain reference'!$B$4:$P$4,0))))) -> TRUE
A13: exposure_rate | B13: exposure rate | C13: share | D13: =IF($D$7=0,"",COUNTIFS(Assignments!$D$2:$D$555,"control",Assignments!$N$2:$N$555,1,Assignments!$P$2:$P$555,1)/$D$7) -> 0.875 | E13: =IF($E$7=0,"",COUNTIFS(Assignments!$D$2:$D$555,"treatment",Assignments!$N$2:$N$555,1,Assignments!$P$2:$P$555,1)/$E$7) -> 0.87 | G13: Mature assigned accounts with an exposure by the cutoff / mature assigned accounts (reported beside intention to treat, never a denominator). | H13: 5e-07 | I13: =AND(IF(ISNUMBER(INDEX('Domain reference'!$B$12:$P$12,MATCH(Cutoff!$B$3&"|control",'Domain reference'!$B$4:$P$4,0))),IF(ISNUMBER(D13),ABS(D13-INDEX('Domain reference'!$B$12:$P$12,MATCH(Cutoff!$B$3&"|control",'Domain reference'!$B$4:$P$4,0)))<=$H13+0.0000000001,FALSE()),IF(ISBLANK(INDEX('Domain reference'!$B$12:$P$12,MATCH(Cutoff!$B$3&"|control",'Domain reference'!$B$4:$P$4,0))),D13="",D13=INDEX('Domain reference'!$B$12:$P$12,MATCH(Cutoff!$B$3&"|control",'Domain reference'!$B$4:$P$4,0)))),IF(ISNUMBER(INDEX('Domain reference'!$B$12:$P$12,MATCH(Cutoff!$B$3&"|treatment",'Domain reference'!$B$4:$P$4,0))),IF(ISNUMBER(E13),ABS(E13-INDEX('Domain reference'!$B$12:$P$12,MATCH(Cutoff!$B$3&"|treatment",'Domain reference'!$B$4:$P$4,0)))<=$H13+0.0000000001,FALSE()),IF(ISBLANK(INDEX('Domain reference'!$B$12:$P$12,MATCH(Cutoff!$B$3&"|treatment",'Domain reference'!$B$4:$P$4,0))),E13="",E13=INDEX('Domain reference'!$B$12:$P$12,MATCH(Cutoff!$B$3&"|treatment",'Domain reference'!$B$4:$P$4,0))))) -> TRUE
A14: activated_accounts | B14: activated within 7 days | C14: accounts | D14: =IF($B$4,"withheld",COUNTIFS(Assignments!$D$2:$D$555,"control",Assignments!$O$2:$O$555,1)) -> 63 | E14: =IF($B$4,"withheld",COUNTIFS(Assignments!$D$2:$D$555,"treatment",Assignments!$O$2:$O$555,1)) -> 82 | G14: Mature accounts with an activation at or after max(signup, assigned_at) and before signup + 7 x 24 h, received by the cutoff (D-10). | H14: 0 | I14: =AND(IF(ISNUMBER(INDEX('Domain reference'!$B$13:$P$13,MATCH(Cutoff!$B$3&"|control",'Domain reference'!$B$4:$P$4,0))),IF(ISNUMBER(D14),ABS(D14-INDEX('Domain reference'!$B$13:$P$13,MATCH(Cutoff!$B$3&"|control",'Domain reference'!$B$4:$P$4,0)))<=$H14+0.0000000001,FALSE()),IF(ISBLANK(INDEX('Domain reference'!$B$13:$P$13,MATCH(Cutoff!$B$3&"|control",'Domain reference'!$B$4:$P$4,0))),D14="",D14=INDEX('Domain reference'!$B$13:$P$13,MATCH(Cutoff!$B$3&"|control",'Domain reference'!$B$4:$P$4,0)))),IF(ISNUMBER(INDEX('Domain reference'!$B$13:$P$13,MATCH(Cutoff!$B$3&"|treatment",'Domain reference'!$B$4:$P$4,0))),IF(ISNUMBER(E14),ABS(E14-INDEX('Domain reference'!$B$13:$P$13,MATCH(Cutoff!$B$3&"|treatment",'Domain reference'!$B$4:$P$4,0)))<=$H14+0.0000000001,FALSE()),IF(ISBLANK(INDEX('Domain reference'!$B$13:$P$13,MATCH(Cutoff!$B$3&"|treatment",'Domain reference'!$B$4:$P$4,0))),E14="",E14=INDEX('Domain reference'!$B$13:$P$13,MATCH(Cutoff!$B$3&"|treatment",'Domain reference'!$B$4:$P$4,0))))) -> TRUE
A15: conversion_rate | B15: activation conversion (intention to treat) | C15: share | D15: =IF($B$4,"withheld",IF($D$7=0,"",$D$14/$D$7)) -> 0.315 | E15: =IF($B$4,"withheld",IF($E$7=0,"",$E$14/$E$7)) -> 0.41 | G15: Activated / mature assigned accounts, six decimals in the domain. | H15: 5e-07 | I15: =AND(IF(ISNUMBER(INDEX('Domain reference'!$B$14:$P$14,MATCH(Cutoff!$B$3&"|control",'Domain reference'!$B$4:$P$4,0))),IF(ISNUMBER(D15),ABS(D15-INDEX('Domain reference'!$B$14:$P$14,MATCH(Cutoff!$B$3&"|control",'Domain reference'!$B$4:$P$4,0)))<=$H15+0.0000000001,FALSE()),IF(ISBLANK(INDEX('Domain reference'!$B$14:$P$14,MATCH(Cutoff!$B$3&"|control",'Domain reference'!$B$4:$P$4,0))),D15="",D15=INDEX('Domain reference'!$B$14:$P$14,MATCH(Cutoff!$B$3&"|control",'Domain reference'!$B$4:$P$4,0)))),IF(ISNUMBER(INDEX('Domain reference'!$B$14:$P$14,MATCH(Cutoff!$B$3&"|treatment",'Domain reference'!$B$4:$P$4,0))),IF(ISNUMBER(E15),ABS(E15-INDEX('Domain reference'!$B$14:$P$14,MATCH(Cutoff!$B$3&"|treatment",'Domain reference'!$B$4:$P$4,0)))<=$H15+0.0000000001,FALSE()),IF(ISBLANK(INDEX('Domain reference'!$B$14:$P$14,MATCH(Cutoff!$B$3&"|treatment",'Domain reference'!$B$4:$P$4,0))),E15="",E15=INDEX('Domain reference'!$B$14:$P$14,MATCH(Cutoff!$B$3&"|treatment",'Domain reference'!$B$4:$P$4,0))))) -> TRUE
A16: wilson_low | B16: Wilson 95% low | C16: share | D16: =IF($B$4,"withheld",IF($D$7=0,"",(($D$14/$D$7)+Cutoff!$B$18^2/(2*$D$7)-Cutoff!$B$18*SQRT(($D$14/$D$7)*(1-($D$14/$D$7))/$D$7+Cutoff!$B$18^2/(4*$D$7^2)))/(1+Cutoff!$B$18^2/$D$7))) -> 0.25462321 | E16: =IF($B$4,"withheld",IF($E$7=0,"",(($E$14/$E$7)+Cutoff!$B$18^2/(2*$E$7)-Cutoff!$B$18*SQRT(($E$14/$E$7)*(1-($E$14/$E$7))/$E$7+Cutoff!$B$18^2/(4*$E$7^2)))/(1+Cutoff!$B$18^2/$E$7))) -> 0.34415675 | G16: Wilson score interval of the arm's conversion at the plan's z. | H16: 5e-07 | I16: =AND(IF(ISNUMBER(INDEX('Domain reference'!$B$15:$P$15,MATCH(Cutoff!$B$3&"|control",'Domain reference'!$B$4:$P$4,0))),IF(ISNUMBER(D16),ABS(D16-INDEX('Domain reference'!$B$15:$P$15,MATCH(Cutoff!$B$3&"|control",'Domain reference'!$B$4:$P$4,0)))<=$H16+0.0000000001,FALSE()),IF(ISBLANK(INDEX('Domain reference'!$B$15:$P$15,MATCH(Cutoff!$B$3&"|control",'Domain reference'!$B$4:$P$4,0))),D16="",D16=INDEX('Domain reference'!$B$15:$P$15,MATCH(Cutoff!$B$3&"|control",'Domain reference'!$B$4:$P$4,0)))),IF(ISNUMBER(INDEX('Domain reference'!$B$15:$P$15,MATCH(Cutoff!$B$3&"|treatment",'Domain reference'!$B$4:$P$4,0))),IF(ISNUMBER(E16),ABS(E16-INDEX('Domain reference'!$B$15:$P$15,MATCH(Cutoff!$B$3&"|treatment",'Domain reference'!$B$4:$P$4,0)))<=$H16+0.0000000001,FALSE()),IF(ISBLANK(INDEX('Domain reference'!$B$15:$P$15,MATCH(Cutoff!$B$3&"|treatment",'Domain reference'!$B$4:$P$4,0))),E16="",E16=INDEX('Domain reference'!$B$15:$P$15,MATCH(Cutoff!$B$3&"|treatment",'Domain reference'!$B$4:$P$4,0))))) -> TRUE
A17: wilson_high | B17: Wilson 95% high | C17: share | D17: =IF($B$4,"withheld",IF($D$7=0,"",(($D$14/$D$7)+Cutoff!$B$18^2/(2*$D$7)+Cutoff!$B$18*SQRT(($D$14/$D$7)*(1-($D$14/$D$7))/$D$7+Cutoff!$B$18^2/(4*$D$7^2)))/(1+Cutoff!$B$18^2/$D$7))) -> 0.38234956 | E17: =IF($B$4,"withheld",IF($E$7=0,"",(($E$14/$E$7)+Cutoff!$B$18^2/(2*$E$7)+Cutoff!$B$18*SQRT(($E$14/$E$7)*(1-($E$14/$E$7))/$E$7+Cutoff!$B$18^2/(4*$E$7^2)))/(1+Cutoff!$B$18^2/$E$7))) -> 0.47923541 | G17: As above. | H17: 5e-07 | I17: =AND(IF(ISNUMBER(INDEX('Domain reference'!$B$16:$P$16,MATCH(Cutoff!$B$3&"|control",'Domain reference'!$B$4:$P$4,0))),IF(ISNUMBER(D17),ABS(D17-INDEX('Domain reference'!$B$16:$P$16,MATCH(Cutoff!$B$3&"|control",'Domain reference'!$B$4:$P$4,0)))<=$H17+0.0000000001,FALSE()),IF(ISBLANK(INDEX('Domain reference'!$B$16:$P$16,MATCH(Cutoff!$B$3&"|control",'Domain reference'!$B$4:$P$4,0))),D17="",D17=INDEX('Domain reference'!$B$16:$P$16,MATCH(Cutoff!$B$3&"|control",'Domain reference'!$B$4:$P$4,0)))),IF(ISNUMBER(INDEX('Domain reference'!$B$16:$P$16,MATCH(Cutoff!$B$3&"|treatment",'Domain reference'!$B$4:$P$4,0))),IF(ISNUMBER(E17),ABS(E17-INDEX('Domain reference'!$B$16:$P$16,MATCH(Cutoff!$B$3&"|treatment",'Domain reference'!$B$4:$P$4,0)))<=$H17+0.0000000001,FALSE()),IF(ISBLANK(INDEX('Domain reference'!$B$16:$P$16,MATCH(Cutoff!$B$3&"|treatment",'Domain reference'!$B$4:$P$4,0))),E17="",E17=INDEX('Domain reference'!$B$16:$P$16,MATCH(Cutoff!$B$3&"|treatment",'Domain reference'!$B$4:$P$4,0))))) -> TRUE
A18: absolute_lift_pp | B18: absolute lift (treatment - control) | C18: percentage points | F18: =IF($B$4,"withheld",IF(OR($D$7=0,$E$7=0),"",($E$15-$D$15)*100)) -> 9.5 | G18: (treatment conversion - control conversion) x 100. | H18: 0.005 | I18: =AND(IF(ISNUMBER(INDEX('Domain reference'!$B$17:$P$17,MATCH(Cutoff!$B$3&"|combined",'Domain reference'!$B$4:$P$4,0))),IF(ISNUMBER(F18),ABS(F18-INDEX('Domain reference'!$B$17:$P$17,MATCH(Cutoff!$B$3&"|combined",'Domain reference'!$B$4:$P$4,0)))<=$H18+0.0000000001,FALSE()),IF(ISBLANK(INDEX('Domain reference'!$B$17:$P$17,MATCH(Cutoff!$B$3&"|combined",'Domain reference'!$B$4:$P$4,0))),F18="",F18=INDEX('Domain reference'!$B$17:$P$17,MATCH(Cutoff!$B$3&"|combined",'Domain reference'!$B$4:$P$4,0))))) -> TRUE
A19: relative_lift | B19: relative lift | C19: ratio | F19: =IF($B$4,"withheld",IF(OR($D$7=0,$E$7=0),"",IF($D$15=0,"",($E$15-$D$15)/$D$15))) -> 0.3015873 | G19: Absolute lift / control conversion; blank when the control conversion is 0. | H19: 5e-07 | I19: =AND(IF(ISNUMBER(INDEX('Domain reference'!$B$18:$P$18,MATCH(Cutoff!$B$3&"|combined",'Domain reference'!$B$4:$P$4,0))),IF(ISNUMBER(F19),ABS(F19-INDEX('Domain reference'!$B$18:$P$18,MATCH(Cutoff!$B$3&"|combined",'Domain reference'!$B$4:$P$4,0)))<=$H19+0.0000000001,FALSE()),IF(ISBLANK(INDEX('Domain reference'!$B$18:$P$18,MATCH(Cutoff!$B$3&"|combined",'Domain reference'!$B$4:$P$4,0))),F19="",F19=INDEX('Domain reference'!$B$18:$P$18,MATCH(Cutoff!$B$3&"|combined",'Domain reference'!$B$4:$P$4,0))))) -> TRUE
A20: newcombe_low | B20: Newcombe 95% low (difference) | C20: share difference | F20: =IF($B$4,"withheld",IF(OR($D$7=0,$E$7=0),"",($E$15-$D$15)-SQRT(($E$15-$E$16)^2+($D$17-$D$15)^2))) -> 0.00081243618 | G20: Newcombe hybrid score interval of treatment minus control from the two Wilson intervals. | H20: 5e-07 | I20: =AND(IF(ISNUMBER(INDEX('Domain reference'!$B$19:$P$19,MATCH(Cutoff!$B$3&"|combined",'Domain reference'!$B$4:$P$4,0))),IF(ISNUMBER(F20),ABS(F20-INDEX('Domain reference'!$B$19:$P$19,MATCH(Cutoff!$B$3&"|combined",'Domain reference'!$B$4:$P$4,0)))<=$H20+0.0000000001,FALSE()),IF(ISBLANK(INDEX('Domain reference'!$B$19:$P$19,MATCH(Cutoff!$B$3&"|combined",'Domain reference'!$B$4:$P$4,0))),F20="",F20=INDEX('Domain reference'!$B$19:$P$19,MATCH(Cutoff!$B$3&"|combined",'Domain reference'!$B$4:$P$4,0))))) -> TRUE
A21: newcombe_high | B21: Newcombe 95% high (difference) | C21: share difference | F21: =IF($B$4,"withheld",IF(OR($D$7=0,$E$7=0),"",($E$15-$D$15)+SQRT(($E$17-$E$15)^2+($D$15-$D$16)^2))) -> 0.18686348 | G21: As above. | H21: 5e-07 | I21: =AND(IF(ISNUMBER(INDEX('Domain reference'!$B$20:$P$20,MATCH(Cutoff!$B$3&"|combined",'Domain reference'!$B$4:$P$4,0))),IF(ISNUMBER(F21),ABS(F21-INDEX('Domain reference'!$B$20:$P$20,MATCH(Cutoff!$B$3&"|combined",'Domain reference'!$B$4:$P$4,0)))<=$H21+0.0000000001,FALSE()),IF(ISBLANK(INDEX('Domain reference'!$B$20:$P$20,MATCH(Cutoff!$B$3&"|combined",'Domain reference'!$B$4:$P$4,0))),F21="",F21=INDEX('Domain reference'!$B$20:$P$20,MATCH(Cutoff!$B$3&"|combined",'Domain reference'!$B$4:$P$4,0))))) -> TRUE
A22: interval_includes_zero | B22: interval includes 0 | C22: TRUE/FALSE | F22: =IF($B$4,"withheld",IF($F$20="",TRUE(),AND($F$20<=0,$F$21>=0))) -> FALSE | G22: low <= 0 <= high. | H22: 0 | I22: =AND(IF(ISNUMBER(INDEX('Domain reference'!$B$21:$P$21,MATCH(Cutoff!$B$3&"|combined",'Domain reference'!$B$4:$P$4,0))),IF(ISNUMBER(F22),ABS(F22-INDEX('Domain reference'!$B$21:$P$21,MATCH(Cutoff!$B$3&"|combined",'Domain reference'!$B$4:$P$4,0)))<=$H22+0.0000000001,FALSE()),IF(ISBLANK(INDEX('Domain reference'!$B$21:$P$21,MATCH(Cutoff!$B$3&"|combined",'Domain reference'!$B$4:$P$4,0))),F22="",F22=INDEX('Domain reference'!$B$21:$P$21,MATCH(Cutoff!$B$3&"|combined",'Domain reference'!$B$4:$P$4,0))))) -> TRUE
A23: interim | B23: interim run (cutoff before planned_end) | C23: TRUE/FALSE | F23: =Cutoff!$B$14 -> FALSE | G23: The cutoff is before the plan's planned_end; an interim run cannot support a ship decision. | H23: 0 | I23: =AND(IF(ISNUMBER(INDEX('Domain reference'!$B$22:$P$22,MATCH(Cutoff!$B$3&"|combined",'Domain reference'!$B$4:$P$4,0))),IF(ISNUMBER(F23),ABS(F23-INDEX('Domain reference'!$B$22:$P$22,MATCH(Cutoff!$B$3&"|combined",'Domain reference'!$B$4:$P$4,0)))<=$H23+0.0000000001,FALSE()),IF(ISBLANK(INDEX('Domain reference'!$B$22:$P$22,MATCH(Cutoff!$B$3&"|combined",'Domain reference'!$B$4:$P$4,0))),F23="",F23=INDEX('Domain reference'!$B$22:$P$22,MATCH(Cutoff!$B$3&"|combined",'Domain reference'!$B$4:$P$4,0))))) -> TRUE
A24: plan_frozen | B24: plan frozen before the first run | C24: TRUE/FALSE | F24: =Cutoff!$B$26 -> TRUE | G24: The plan's frozen_at is at or before the creation of the version's first logged run (typed from the plan and the run log). | H24: 0 | I24: =AND(IF(ISNUMBER(INDEX('Domain reference'!$B$23:$P$23,MATCH(Cutoff!$B$3&"|combined",'Domain reference'!$B$4:$P$4,0))),IF(ISNUMBER(F24),ABS(F24-INDEX('Domain reference'!$B$23:$P$23,MATCH(Cutoff!$B$3&"|combined",'Domain reference'!$B$4:$P$4,0)))<=$H24+0.0000000001,FALSE()),IF(ISBLANK(INDEX('Domain reference'!$B$23:$P$23,MATCH(Cutoff!$B$3&"|combined",'Domain reference'!$B$4:$P$4,0))),F24="",F24=INDEX('Domain reference'!$B$23:$P$23,MATCH(Cutoff!$B$3&"|combined",'Domain reference'!$B$4:$P$4,0))))) -> TRUE
A25: plan_hash_valid | B25: plan hash valid | C25: TRUE/FALSE | F25: =Cutoff!$B$27 -> TRUE | G25: config_hash is the sha256 of the key-sorted compact plan (typed: a spreadsheet cannot take a sha256; the domain and SQL do). | H25: 0 | I25: =AND(IF(ISNUMBER(INDEX('Domain reference'!$B$24:$P$24,MATCH(Cutoff!$B$3&"|combined",'Domain reference'!$B$4:$P$4,0))),IF(ISNUMBER(F25),ABS(F25-INDEX('Domain reference'!$B$24:$P$24,MATCH(Cutoff!$B$3&"|combined",'Domain reference'!$B$4:$P$4,0)))<=$H25+0.0000000001,FALSE()),IF(ISBLANK(INDEX('Domain reference'!$B$24:$P$24,MATCH(Cutoff!$B$3&"|combined",'Domain reference'!$B$4:$P$4,0))),F25="",F25=INDEX('Domain reference'!$B$24:$P$24,MATCH(Cutoff!$B$3&"|combined",'Domain reference'!$B$4:$P$4,0))))) -> TRUE
A26: conclusive | B26: conclusive (D-10) | C26: TRUE/FALSE | F26: =IF($B$4,"withheld",AND(NOT($F$22),NOT($F$23),$F$25,$F$24,$F$12="OK")) -> TRUE | G26: The interval excludes 0 AND a final run AND a valid plan hash AND a plan frozen before the first run AND a sample-ratio verdict of OK. | H26: 0 | I26: =AND(IF(ISNUMBER(INDEX('Domain reference'!$B$25:$P$25,MATCH(Cutoff!$B$3&"|combined",'Domain reference'!$B$4:$P$4,0))),IF(ISNUMBER(F26),ABS(F26-INDEX('Domain reference'!$B$25:$P$25,MATCH(Cutoff!$B$3&"|combined",'Domain reference'!$B$4:$P$4,0)))<=$H26+0.0000000001,FALSE()),IF(ISBLANK(INDEX('Domain reference'!$B$25:$P$25,MATCH(Cutoff!$B$3&"|combined",'Domain reference'!$B$4:$P$4,0))),F26="",F26=INDEX('Domain reference'!$B$25:$P$25,MATCH(Cutoff!$B$3&"|combined",'Domain reference'!$B$4:$P$4,0))))) -> TRUE
A27: guardrail_eligible | B27: guardrail: eligible accounts | C27: accounts | D27: =IF($B$4,"withheld",COUNTIFS(Assignments!$D$2:$D$555,"control",Assignments!$Q$2:$Q$555,1)) -> 200 | E27: =IF($B$4,"withheld",COUNTIFS(Assignments!$D$2:$D$555,"treatment",Assignments!$Q$2:$Q$555,1)) -> 200 | G27: Mature accounts whose 7 x 24 h guardrail window is complete at the cutoff (D-10). | H27: 0 | I27: =AND(IF(ISNUMBER(INDEX('Domain reference'!$B$26:$P$26,MATCH(Cutoff!$B$3&"|control",'Domain reference'!$B$4:$P$4,0))),IF(ISNUMBER(D27),ABS(D27-INDEX('Domain reference'!$B$26:$P$26,MATCH(Cutoff!$B$3&"|control",'Domain reference'!$B$4:$P$4,0)))<=$H27+0.0000000001,FALSE()),IF(ISBLANK(INDEX('Domain reference'!$B$26:$P$26,MATCH(Cutoff!$B$3&"|control",'Domain reference'!$B$4:$P$4,0))),D27="",D27=INDEX('Domain reference'!$B$26:$P$26,MATCH(Cutoff!$B$3&"|control",'Domain reference'!$B$4:$P$4,0)))),IF(ISNUMBER(INDEX('Domain reference'!$B$26:$P$26,MATCH(Cutoff!$B$3&"|treatment",'Domain reference'!$B$4:$P$4,0))),IF(ISNUMBER(E27),ABS(E27-INDEX('Domain reference'!$B$26:$P$26,MATCH(Cutoff!$B$3&"|treatment",'Domain reference'!$B$4:$P$4,0)))<=$H27+0.0000000001,FALSE()),IF(ISBLANK(INDEX('Domain reference'!$B$26:$P$26,MATCH(Cutoff!$B$3&"|treatment",'Domain reference'!$B$4:$P$4,0))),E27="",E27=INDEX('Domain reference'!$B$26:$P$26,MATCH(Cutoff!$B$3&"|treatment",'Domain reference'!$B$4:$P$4,0))))) -> TRUE
A28: guardrail_errors | B28: guardrail: accounts with a product_error | C28: accounts | D28: =IF($B$4,"withheld",COUNTIFS(Assignments!$D$2:$D$555,"control",Assignments!$R$2:$R$555,1)) -> 31 | E28: =IF($B$4,"withheld",COUNTIFS(Assignments!$D$2:$D$555,"treatment",Assignments!$R$2:$R$555,1)) -> 30 | G28: An analysed product_error in [assigned_at, assigned_at + 7 x 24 h), received by the cutoff. | H28: 0 | I28: =AND(IF(ISNUMBER(INDEX('Domain reference'!$B$27:$P$27,MATCH(Cutoff!$B$3&"|control",'Domain reference'!$B$4:$P$4,0))),IF(ISNUMBER(D28),ABS(D28-INDEX('Domain reference'!$B$27:$P$27,MATCH(Cutoff!$B$3&"|control",'Domain reference'!$B$4:$P$4,0)))<=$H28+0.0000000001,FALSE()),IF(ISBLANK(INDEX('Domain reference'!$B$27:$P$27,MATCH(Cutoff!$B$3&"|control",'Domain reference'!$B$4:$P$4,0))),D28="",D28=INDEX('Domain reference'!$B$27:$P$27,MATCH(Cutoff!$B$3&"|control",'Domain reference'!$B$4:$P$4,0)))),IF(ISNUMBER(INDEX('Domain reference'!$B$27:$P$27,MATCH(Cutoff!$B$3&"|treatment",'Domain reference'!$B$4:$P$4,0))),IF(ISNUMBER(E28),ABS(E28-INDEX('Domain reference'!$B$27:$P$27,MATCH(Cutoff!$B$3&"|treatment",'Domain reference'!$B$4:$P$4,0)))<=$H28+0.0000000001,FALSE()),IF(ISBLANK(INDEX('Domain reference'!$B$27:$P$27,MATCH(Cutoff!$B$3&"|treatment",'Domain reference'!$B$4:$P$4,0))),E28="",E28=INDEX('Domain reference'!$B$27:$P$27,MATCH(Cutoff!$B$3&"|treatment",'Domain reference'!$B$4:$P$4,0))))) -> TRUE
A29: guardrail_error_rate | B29: guardrail: error rate | C29: share | D29: =IF($B$4,"withheld",IF($D$27=0,"",$D$28/$D$27)) -> 0.155 | E29: =IF($B$4,"withheld",IF($E$27=0,"",$E$28/$E$27)) -> 0.15 | G29: Errors / eligible. | H29: 5e-07 | I29: =AND(IF(ISNUMBER(INDEX('Domain reference'!$B$28:$P$28,MATCH(Cutoff!$B$3&"|control",'Domain reference'!$B$4:$P$4,0))),IF(ISNUMBER(D29),ABS(D29-INDEX('Domain reference'!$B$28:$P$28,MATCH(Cutoff!$B$3&"|control",'Domain reference'!$B$4:$P$4,0)))<=$H29+0.0000000001,FALSE()),IF(ISBLANK(INDEX('Domain reference'!$B$28:$P$28,MATCH(Cutoff!$B$3&"|control",'Domain reference'!$B$4:$P$4,0))),D29="",D29=INDEX('Domain reference'!$B$28:$P$28,MATCH(Cutoff!$B$3&"|control",'Domain reference'!$B$4:$P$4,0)))),IF(ISNUMBER(INDEX('Domain reference'!$B$28:$P$28,MATCH(Cutoff!$B$3&"|treatment",'Domain reference'!$B$4:$P$4,0))),IF(ISNUMBER(E29),ABS(E29-INDEX('Domain reference'!$B$28:$P$28,MATCH(Cutoff!$B$3&"|treatment",'Domain reference'!$B$4:$P$4,0)))<=$H29+0.0000000001,FALSE()),IF(ISBLANK(INDEX('Domain reference'!$B$28:$P$28,MATCH(Cutoff!$B$3&"|treatment",'Domain reference'!$B$4:$P$4,0))),E29="",E29=INDEX('Domain reference'!$B$28:$P$28,MATCH(Cutoff!$B$3&"|treatment",'Domain reference'!$B$4:$P$4,0))))) -> TRUE
A30: guardrail_wilson_low | B30: guardrail: Wilson 95% low | C30: share | D30: =IF($B$4,"withheld",IF($D$27=0,"",(($D$28/$D$27)+Cutoff!$B$18^2/(2*$D$27)-Cutoff!$B$18*SQRT(($D$28/$D$27)*(1-($D$28/$D$27))/$D$27+Cutoff!$B$18^2/(4*$D$27^2)))/(1+Cutoff!$B$18^2/$D$27))) -> 0.11139637 | E30: =IF($B$4,"withheld",IF($E$27=0,"",(($E$28/$E$27)+Cutoff!$B$18^2/(2*$E$27)-Cutoff!$B$18*SQRT(($E$28/$E$27)*(1-($E$28/$E$27))/$E$27+Cutoff!$B$18^2/(4*$E$27^2)))/(1+Cutoff!$B$18^2/$E$27))) -> 0.10713594 | G30: Wilson interval of the error rate (intermediate for the Newcombe interval). | H30: 5e-07 | I30: =AND(IF(ISNUMBER(INDEX('Domain reference'!$B$29:$P$29,MATCH(Cutoff!$B$3&"|control",'Domain reference'!$B$4:$P$4,0))),IF(ISNUMBER(D30),ABS(D30-INDEX('Domain reference'!$B$29:$P$29,MATCH(Cutoff!$B$3&"|control",'Domain reference'!$B$4:$P$4,0)))<=$H30+0.0000000001,FALSE()),IF(ISBLANK(INDEX('Domain reference'!$B$29:$P$29,MATCH(Cutoff!$B$3&"|control",'Domain reference'!$B$4:$P$4,0))),D30="",D30=INDEX('Domain reference'!$B$29:$P$29,MATCH(Cutoff!$B$3&"|control",'Domain reference'!$B$4:$P$4,0)))),IF(ISNUMBER(INDEX('Domain reference'!$B$29:$P$29,MATCH(Cutoff!$B$3&"|treatment",'Domain reference'!$B$4:$P$4,0))),IF(ISNUMBER(E30),ABS(E30-INDEX('Domain reference'!$B$29:$P$29,MATCH(Cutoff!$B$3&"|treatment",'Domain reference'!$B$4:$P$4,0)))<=$H30+0.0000000001,FALSE()),IF(ISBLANK(INDEX('Domain reference'!$B$29:$P$29,MATCH(Cutoff!$B$3&"|treatment",'Domain reference'!$B$4:$P$4,0))),E30="",E30=INDEX('Domain reference'!$B$29:$P$29,MATCH(Cutoff!$B$3&"|treatment",'Domain reference'!$B$4:$P$4,0))))) -> TRUE
A31: guardrail_wilson_high | B31: guardrail: Wilson 95% high | C31: share | D31: =IF($B$4,"withheld",IF($D$27=0,"",(($D$28/$D$27)+Cutoff!$B$18^2/(2*$D$27)+Cutoff!$B$18*SQRT(($D$28/$D$27)*(1-($D$28/$D$27))/$D$27+Cutoff!$B$18^2/(4*$D$27^2)))/(1+Cutoff!$B$18^2/$D$27))) -> 0.21160691 | E31: =IF($B$4,"withheld",IF($E$27=0,"",(($E$28/$E$27)+Cutoff!$B$18^2/(2*$E$27)+Cutoff!$B$18*SQRT(($E$28/$E$27)*(1-($E$28/$E$27))/$E$27+Cutoff!$B$18^2/(4*$E$27^2)))/(1+Cutoff!$B$18^2/$E$27))) -> 0.20605579 | G31: As above. | H31: 5e-07 | I31: =AND(IF(ISNUMBER(INDEX('Domain reference'!$B$30:$P$30,MATCH(Cutoff!$B$3&"|control",'Domain reference'!$B$4:$P$4,0))),IF(ISNUMBER(D31),ABS(D31-INDEX('Domain reference'!$B$30:$P$30,MATCH(Cutoff!$B$3&"|control",'Domain reference'!$B$4:$P$4,0)))<=$H31+0.0000000001,FALSE()),IF(ISBLANK(INDEX('Domain reference'!$B$30:$P$30,MATCH(Cutoff!$B$3&"|control",'Domain reference'!$B$4:$P$4,0))),D31="",D31=INDEX('Domain reference'!$B$30:$P$30,MATCH(Cutoff!$B$3&"|control",'Domain reference'!$B$4:$P$4,0)))),IF(ISNUMBER(INDEX('Domain reference'!$B$30:$P$30,MATCH(Cutoff!$B$3&"|treatment",'Domain reference'!$B$4:$P$4,0))),IF(ISNUMBER(E31),ABS(E31-INDEX('Domain reference'!$B$30:$P$30,MATCH(Cutoff!$B$3&"|treatment",'Domain reference'!$B$4:$P$4,0)))<=$H31+0.0000000001,FALSE()),IF(ISBLANK(INDEX('Domain reference'!$B$30:$P$30,MATCH(Cutoff!$B$3&"|treatment",'Domain reference'!$B$4:$P$4,0))),E31="",E31=INDEX('Domain reference'!$B$30:$P$30,MATCH(Cutoff!$B$3&"|treatment",'Domain reference'!$B$4:$P$4,0))))) -> TRUE
A32: guardrail_difference_pp | B32: guardrail: error-rate difference (treatment - control) | C32: percentage points | F32: =IF($B$4,"withheld",IF(OR($D$27=0,$E$27=0),"",($E$29-$D$29)*100)) -> -0.5 | G32: (treatment rate - control rate) x 100. | H32: 0.005 | I32: =AND(IF(ISNUMBER(INDEX('Domain reference'!$B$31:$P$31,MATCH(Cutoff!$B$3&"|combined",'Domain reference'!$B$4:$P$4,0))),IF(ISNUMBER(F32),ABS(F32-INDEX('Domain reference'!$B$31:$P$31,MATCH(Cutoff!$B$3&"|combined",'Domain reference'!$B$4:$P$4,0)))<=$H32+0.0000000001,FALSE()),IF(ISBLANK(INDEX('Domain reference'!$B$31:$P$31,MATCH(Cutoff!$B$3&"|combined",'Domain reference'!$B$4:$P$4,0))),F32="",F32=INDEX('Domain reference'!$B$31:$P$31,MATCH(Cutoff!$B$3&"|combined",'Domain reference'!$B$4:$P$4,0))))) -> TRUE
A33: guardrail_newcombe_low | B33: guardrail: Newcombe 95% low | C33: share difference | F33: =IF($B$4,"withheld",IF(OR($D$27=0,$E$27=0),"",($E$29-$D$29)-SQRT(($E$29-$E$30)^2+($D$31-$D$29)^2))) -> -0.076004717 | G33: Newcombe interval of the error-rate difference. | H33: 5e-07 | I33: =AND(IF(ISNUMBER(INDEX('Domain reference'!$B$32:$P$32,MATCH(Cutoff!$B$3&"|combined",'Domain reference'!$B$4:$P$4,0))),IF(ISNUMBER(F33),ABS(F33-INDEX('Domain reference'!$B$32:$P$32,MATCH(Cutoff!$B$3&"|combined",'Domain reference'!$B$4:$P$4,0)))<=$H33+0.0000000001,FALSE()),IF(ISBLANK(INDEX('Domain reference'!$B$32:$P$32,MATCH(Cutoff!$B$3&"|combined",'Domain reference'!$B$4:$P$4,0))),F33="",F33=INDEX('Domain reference'!$B$32:$P$32,MATCH(Cutoff!$B$3&"|combined",'Domain reference'!$B$4:$P$4,0))))) -> TRUE
A34: guardrail_newcombe_high | B34: guardrail: Newcombe 95% high | C34: share difference | F34: =IF($B$4,"withheld",IF(OR($D$27=0,$E$27=0),"",($E$29-$D$29)+SQRT(($E$31-$E$29)^2+($D$29-$D$30)^2))) -> 0.066017805 | G34: As above. | H34: 5e-07 | I34: =AND(IF(ISNUMBER(INDEX('Domain reference'!$B$33:$P$33,MATCH(Cutoff!$B$3&"|combined",'Domain reference'!$B$4:$P$4,0))),IF(ISNUMBER(F34),ABS(F34-INDEX('Domain reference'!$B$33:$P$33,MATCH(Cutoff!$B$3&"|combined",'Domain reference'!$B$4:$P$4,0)))<=$H34+0.0000000001,FALSE()),IF(ISBLANK(INDEX('Domain reference'!$B$33:$P$33,MATCH(Cutoff!$B$3&"|combined",'Domain reference'!$B$4:$P$4,0))),F34="",F34=INDEX('Domain reference'!$B$33:$P$33,MATCH(Cutoff!$B$3&"|combined",'Domain reference'!$B$4:$P$4,0))))) -> TRUE
A35: guardrail_verdict | B35: guardrail verdict (C09) | C35: text | F35: =IF($B$4,"withheld",IF(OR($D$27=0,$E$27=0),"INSUFFICIENT",IF($F$33>0,"HARMFUL","OK"))) -> OK | G35: HARMFUL when the whole interval is above 0, INSUFFICIENT when an arm has no eligible account, else OK. | H35: 0 | I35: =AND(IF(ISNUMBER(INDEX('Domain reference'!$B$34:$P$34,MATCH(Cutoff!$B$3&"|combined",'Domain reference'!$B$4:$P$4,0))),IF(ISNUMBER(F35),ABS(F35-INDEX('Domain reference'!$B$34:$P$34,MATCH(Cutoff!$B$3&"|combined",'Domain reference'!$B$4:$P$4,0)))<=$H35+0.0000000001,FALSE()),IF(ISBLANK(INDEX('Domain reference'!$B$34:$P$34,MATCH(Cutoff!$B$3&"|combined",'Domain reference'!$B$4:$P$4,0))),F35="",F35=INDEX('Domain reference'!$B$34:$P$34,MATCH(Cutoff!$B$3&"|combined",'Domain reference'!$B$4:$P$4,0))))) -> TRUE
A36: revenue_total | B36: revenue (USD) | C36: USD | D36: =IF($B$4,"withheld",SUMIFS(Assignments!$S$2:$S$555,Assignments!$D$2:$D$555,"control")) -> 19566 | E36: =IF($B$4,"withheld",SUMIFS(Assignments!$S$2:$S$555,Assignments!$D$2:$D$555,"treatment")) -> 26190 | G36: Subscriptions active or ended, starts_at inside the plan's revenue window and <= the cutoff, of the mature assigned accounts. | H36: 0.005 | I36: =AND(IF(ISNUMBER(INDEX('Domain reference'!$B$35:$P$35,MATCH(Cutoff!$B$3&"|control",'Domain reference'!$B$4:$P$4,0))),IF(ISNUMBER(D36),ABS(D36-INDEX('Domain reference'!$B$35:$P$35,MATCH(Cutoff!$B$3&"|control",'Domain reference'!$B$4:$P$4,0)))<=$H36+0.0000000001,FALSE()),IF(ISBLANK(INDEX('Domain reference'!$B$35:$P$35,MATCH(Cutoff!$B$3&"|control",'Domain reference'!$B$4:$P$4,0))),D36="",D36=INDEX('Domain reference'!$B$35:$P$35,MATCH(Cutoff!$B$3&"|control",'Domain reference'!$B$4:$P$4,0)))),IF(ISNUMBER(INDEX('Domain reference'!$B$35:$P$35,MATCH(Cutoff!$B$3&"|treatment",'Domain reference'!$B$4:$P$4,0))),IF(ISNUMBER(E36),ABS(E36-INDEX('Domain reference'!$B$35:$P$35,MATCH(Cutoff!$B$3&"|treatment",'Domain reference'!$B$4:$P$4,0)))<=$H36+0.0000000001,FALSE()),IF(ISBLANK(INDEX('Domain reference'!$B$35:$P$35,MATCH(Cutoff!$B$3&"|treatment",'Domain reference'!$B$4:$P$4,0))),E36="",E36=INDEX('Domain reference'!$B$35:$P$35,MATCH(Cutoff!$B$3&"|treatment",'Domain reference'!$B$4:$P$4,0))))) -> TRUE
A37: revenue_per_assigned_account | B37: revenue per assigned account (USD) | C37: USD per account | D37: =IF($B$4,"withheld",IF($D$7=0,"",$D$36/$D$7)) -> 97.83 | E37: =IF($B$4,"withheld",IF($E$7=0,"",$E$36/$E$7)) -> 130.95 | G37: Revenue / mature assigned accounts, zeros included. | H37: 0.005 | I37: =AND(IF(ISNUMBER(INDEX('Domain reference'!$B$36:$P$36,MATCH(Cutoff!$B$3&"|control",'Domain reference'!$B$4:$P$4,0))),IF(ISNUMBER(D37),ABS(D37-INDEX('Domain reference'!$B$36:$P$36,MATCH(Cutoff!$B$3&"|control",'Domain reference'!$B$4:$P$4,0)))<=$H37+0.0000000001,FALSE()),IF(ISBLANK(INDEX('Domain reference'!$B$36:$P$36,MATCH(Cutoff!$B$3&"|control",'Domain reference'!$B$4:$P$4,0))),D37="",D37=INDEX('Domain reference'!$B$36:$P$36,MATCH(Cutoff!$B$3&"|control",'Domain reference'!$B$4:$P$4,0)))),IF(ISNUMBER(INDEX('Domain reference'!$B$36:$P$36,MATCH(Cutoff!$B$3&"|treatment",'Domain reference'!$B$4:$P$4,0))),IF(ISNUMBER(E37),ABS(E37-INDEX('Domain reference'!$B$36:$P$36,MATCH(Cutoff!$B$3&"|treatment",'Domain reference'!$B$4:$P$4,0)))<=$H37+0.0000000001,FALSE()),IF(ISBLANK(INDEX('Domain reference'!$B$36:$P$36,MATCH(Cutoff!$B$3&"|treatment",'Domain reference'!$B$4:$P$4,0))),E37="",E37=INDEX('Domain reference'!$B$36:$P$36,MATCH(Cutoff!$B$3&"|treatment",'Domain reference'!$B$4:$P$4,0))))) -> TRUE
A38: revenue_variance | B38: revenue: sample variance | C38: USD squared | D38: =IF($B$4,"withheld",IF($D$7<2,"",SUMPRODUCT((Assignments!$D$2:$D$555="control")*(Assignments!$N$2:$N$555=1)*(Assignments!$S$2:$S$555-$D$37)^2)/($D$7-1))) -> 77628.916 | E38: =IF($B$4,"withheld",IF($E$7<2,"",SUMPRODUCT((Assignments!$D$2:$D$555="treatment")*(Assignments!$N$2:$N$555=1)*(Assignments!$S$2:$S$555-$E$37)^2)/($E$7-1))) -> 100694.06 | G38: Sum of squared deviations of the account-level revenue / (n - 1). | H38: 0.005 | I38: =AND(IF(ISNUMBER(INDEX('Domain reference'!$B$37:$P$37,MATCH(Cutoff!$B$3&"|control",'Domain reference'!$B$4:$P$4,0))),IF(ISNUMBER(D38),ABS(D38-INDEX('Domain reference'!$B$37:$P$37,MATCH(Cutoff!$B$3&"|control",'Domain reference'!$B$4:$P$4,0)))<=$H38+0.0000000001,FALSE()),IF(ISBLANK(INDEX('Domain reference'!$B$37:$P$37,MATCH(Cutoff!$B$3&"|control",'Domain reference'!$B$4:$P$4,0))),D38="",D38=INDEX('Domain reference'!$B$37:$P$37,MATCH(Cutoff!$B$3&"|control",'Domain reference'!$B$4:$P$4,0)))),IF(ISNUMBER(INDEX('Domain reference'!$B$37:$P$37,MATCH(Cutoff!$B$3&"|treatment",'Domain reference'!$B$4:$P$4,0))),IF(ISNUMBER(E38),ABS(E38-INDEX('Domain reference'!$B$37:$P$37,MATCH(Cutoff!$B$3&"|treatment",'Domain reference'!$B$4:$P$4,0)))<=$H38+0.0000000001,FALSE()),IF(ISBLANK(INDEX('Domain reference'!$B$37:$P$37,MATCH(Cutoff!$B$3&"|treatment",'Domain reference'!$B$4:$P$4,0))),E38="",E38=INDEX('Domain reference'!$B$37:$P$37,MATCH(Cutoff!$B$3&"|treatment",'Domain reference'!$B$4:$P$4,0))))) -> TRUE
A39: revenue_t_low | B39: revenue: t interval low | C39: USD | D39: =IF($B$4,"withheld",IF($D$7<2,"",$D$37-TINV(Cutoff!$B$19,$D$7-1)*SQRT($D$38/$D$7))) -> 58.979725 | E39: =IF($B$4,"withheld",IF($E$7<2,"",$E$37-TINV(Cutoff!$B$19,$E$7-1)*SQRT($E$38/$E$7))) -> 86.702956 | G39: mean - t(0.975, n - 1) x sqrt(variance / n). | H39: 0.005 | I39: =AND(IF(ISNUMBER(INDEX('Domain reference'!$B$38:$P$38,MATCH(Cutoff!$B$3&"|control",'Domain reference'!$B$4:$P$4,0))),IF(ISNUMBER(D39),ABS(D39-INDEX('Domain reference'!$B$38:$P$38,MATCH(Cutoff!$B$3&"|control",'Domain reference'!$B$4:$P$4,0)))<=$H39+0.0000000001,FALSE()),IF(ISBLANK(INDEX('Domain reference'!$B$38:$P$38,MATCH(Cutoff!$B$3&"|control",'Domain reference'!$B$4:$P$4,0))),D39="",D39=INDEX('Domain reference'!$B$38:$P$38,MATCH(Cutoff!$B$3&"|control",'Domain reference'!$B$4:$P$4,0)))),IF(ISNUMBER(INDEX('Domain reference'!$B$38:$P$38,MATCH(Cutoff!$B$3&"|treatment",'Domain reference'!$B$4:$P$4,0))),IF(ISNUMBER(E39),ABS(E39-INDEX('Domain reference'!$B$38:$P$38,MATCH(Cutoff!$B$3&"|treatment",'Domain reference'!$B$4:$P$4,0)))<=$H39+0.0000000001,FALSE()),IF(ISBLANK(INDEX('Domain reference'!$B$38:$P$38,MATCH(Cutoff!$B$3&"|treatment",'Domain reference'!$B$4:$P$4,0))),E39="",E39=INDEX('Domain reference'!$B$38:$P$38,MATCH(Cutoff!$B$3&"|treatment",'Domain reference'!$B$4:$P$4,0))))) -> TRUE
A40: revenue_t_high | B40: revenue: t interval high | C40: USD | D40: =IF($B$4,"withheld",IF($D$7<2,"",$D$37+TINV(Cutoff!$B$19,$D$7-1)*SQRT($D$38/$D$7))) -> 136.68028 | E40: =IF($B$4,"withheld",IF($E$7<2,"",$E$37+TINV(Cutoff!$B$19,$E$7-1)*SQRT($E$38/$E$7))) -> 175.19704 | G40: mean + t(0.975, n - 1) x sqrt(variance / n). | H40: 0.005 | I40: =AND(IF(ISNUMBER(INDEX('Domain reference'!$B$39:$P$39,MATCH(Cutoff!$B$3&"|control",'Domain reference'!$B$4:$P$4,0))),IF(ISNUMBER(D40),ABS(D40-INDEX('Domain reference'!$B$39:$P$39,MATCH(Cutoff!$B$3&"|control",'Domain reference'!$B$4:$P$4,0)))<=$H40+0.0000000001,FALSE()),IF(ISBLANK(INDEX('Domain reference'!$B$39:$P$39,MATCH(Cutoff!$B$3&"|control",'Domain reference'!$B$4:$P$4,0))),D40="",D40=INDEX('Domain reference'!$B$39:$P$39,MATCH(Cutoff!$B$3&"|control",'Domain reference'!$B$4:$P$4,0)))),IF(ISNUMBER(INDEX('Domain reference'!$B$39:$P$39,MATCH(Cutoff!$B$3&"|treatment",'Domain reference'!$B$4:$P$4,0))),IF(ISNUMBER(E40),ABS(E40-INDEX('Domain reference'!$B$39:$P$39,MATCH(Cutoff!$B$3&"|treatment",'Domain reference'!$B$4:$P$4,0)))<=$H40+0.0000000001,FALSE()),IF(ISBLANK(INDEX('Domain reference'!$B$39:$P$39,MATCH(Cutoff!$B$3&"|treatment",'Domain reference'!$B$4:$P$4,0))),E40="",E40=INDEX('Domain reference'!$B$39:$P$39,MATCH(Cutoff!$B$3&"|treatment",'Domain reference'!$B$4:$P$4,0))))) -> TRUE
...

Sheet Domain reference
A1: PASTED VALUES from the Python domain (run_pipeline, guardrail_review, revenue_difference), not formulas
A2: One column per run and scope: the domain's figure over web/public/data, exact decimals as numbers. Metrics reads these only for its check column. Blank = the domain publishes no such figure; the word withheld = an outcome of a run whose sample ratio is a MISMATCH.
A4: metric | B4: an-001|control | C4: an-001|treatment | D4: an-001|combined | E4: an-002|control | F4: an-002|treatment | G4: an-002|combined | H4: an-003|control | I4: an-003|treatment | J4: an-003|combined | K4: an-004|control | L4: an-004|treatment | M4: an-004|combined | N4: an-005|control | O4: an-005|treatment | P4: an-005|combined
A5: assigned_accounts | B5: 77 | C5: 78 | D5: 155 | E5: 127 | F5: 126 | G5: 253 | H5: 177 | I5: 176 | J5: 353 | K5: 200 | L5: 200 | M5: 400 | N5: 62 | O5: 92 | P5: 154
A6: mature_accounts | B6: 65 | C6: 64 | D6: 129 | E6: 114 | F6: 115 | G6: 229 | H6: 164 | I6: 164 | J6: 328 | K6: 200 | L6: 200 | M6: 400 | N6: 56 | O6: 87 | P6: 143
A7: immature_or_unobserved | B7: 12 | C7: 14 | D7: 26 | E7: 13 | F7: 11 | G7: 24 | H7: 13 | I7: 12 | J7: 25 | K7: 0 | L7: 0 | M7: 0 | N7: 6 | O7: 5 | P7: 11
A8: srm_expected | B8: 77.5 | C8: 77.5 | E8: 126.5 | F8: 126.5 | H8: 176.5 | I8: 176.5 | K8: 200 | L8: 200 | N8: 92.4 | O8: 61.6
A9: srm_statistic | D9: 0.006452 | G9: 0.003953 | J9: 0.002833 | M9: 0 | P9: 25.004329
A10: srm_p_value | D10: 0.935981 | G10: 0.94987 | J10: 0.957553 | M10: 1 | P10: 1e-06
A11: srm_verdict | D11: OK | G11: OK | J11: OK | M11: OK | P11: MISMATCH
A12: exposure_rate | B12: 0.892308 | C12: 0.8125 | E12: 0.877193 | F12: 0.86087 | H12: 0.890244 | I12: 0.871951 | K12: 0.875 | L12: 0.87 | N12: 0.928571 | O12: 0.873563
A13: activated_accounts | B13: 18 | C13: 25 | E13: 34 | F13: 48 | H13: 53 | I13: 68 | K13: 63 | L13: 82 | N13: withheld | O13: withheld
A14: conversion_rate | B14: 0.276923 | C14: 0.390625 | E14: 0.298246 | F14: 0.417391 | H14: 0.323171 | I14: 0.414634 | K14: 0.315 | L14: 0.41 | N14: withheld | O14: withheld
A15: wilson_low | B15: 0.182936 | C15: 0.280556 | E15: 0.221961 | F15: 0.331362 | H15: 0.256348 | I15: 0.34203 | K15: 0.254623 | L15: 0.344157 | N15: withheld | O15: withheld
A16: wilson_high | B16: 0.395806 | C16: 0.513081 | E16: 0.387684 | F16: 0.508761 | H16: 0.398088 | I16: 0.491146 | K16: 0.38235 | L16: 0.479235 | N16: withheld | O16: withheld
A17: absolute_lift_pp | D17: 11.37 | G17: 11.91 | J17: 9.15 | M17: 9.5 | P17: withheld
A18: relative_lift | D18: 0.41059 | G18: 0.399488 | J18: 0.283019 | M18: 0.301587 | P18: withheld
A19: newcombe_low | D19: -0.048312 | G19: -0.004952 | J19: -0.012863 | M19: 0.000812 | P19: withheld
A20: newcombe_high | D20: 0.268068 | G20: 0.238174 | J20: 0.193048 | M20: 0.186863 | P20: withheld
A21: interval_includes_zero | D21: =TRUE() -> TRUE | G21: =TRUE() -> TRUE | J21: =TRUE() -> TRUE | M21: =FALSE() -> FALSE | P21: withheld
A22: interim | D22: =TRUE() -> TRUE | G22: =TRUE() -> TRUE | J22: =TRUE() -> TRUE | M22: =FALSE() -> FALSE | P22: =FALSE() -> FALSE
A23: plan_frozen | D23: =TRUE() -> TRUE | G23: =TRUE() -> TRUE | J23: =TRUE() -> TRUE | M23: =TRUE() -> TRUE | P23: =TRUE() -> TRUE
A24: plan_hash_valid | D24: =TRUE() -> TRUE | G24: =TRUE() -> TRUE | J24: =TRUE() -> TRUE | M24: =TRUE() -> TRUE | P24: =TRUE() -> TRUE
A25: conclusive | D25: =FALSE() -> FALSE | G25: =FALSE() -> FALSE | J25: =FALSE() -> FALSE | M25: =TRUE() -> TRUE | P25: withheld
A26: guardrail_eligible | B26: 65 | C26: 64 | E26: 114 | F26: 115 | H26: 164 | I26: 164 | K26: 200 | L26: 200 | N26: withheld | O26: withheld
A27: guardrail_errors | B27: 12 | C27: 12 | E27: 19 | F27: 19 | H27: 27 | I27: 26 | K27: 31 | L27: 30 | N27: withheld | O27: withheld
A28: guardrail_error_rate | B28: 0.184615 | C28: 0.1875 | E28: 0.166667 | F28: 0.165217 | H28: 0.164634 | I28: 0.158537 | K28: 0.155 | L28: 0.15 | N28: withheld | O28: withheld
A29: guardrail_wilson_low | B29: 0.108889 | C29: 0.110646 | E29: 0.109374 | F29: 0.108398 | H29: 0.115683 | I29: 0.110546 | K29: 0.111396 | L29: 0.107136 | N29: withheld | O29: withheld
A30: guardrail_wilson_high | B30: 0.29554 | C30: 0.299744 | E30: 0.245692 | F30: 0.24368 | H30: 0.228937 | I30: 0.222158 | K30: 0.211607 | L30: 0.206056 | N30: withheld | O30: withheld
A31: guardrail_difference_pp | D31: 0.29 | G31: -0.14 | J31: -0.61 | M31: -0.5 | P31: withheld
A32: guardrail_newcombe_low | D32: -0.132063 | G32: -0.098781 | J32: -0.086334 | M32: -0.076005 | P32: withheld
A33: guardrail_newcombe_high | D33: 0.138285 | G33: 0.095704 | J33: 0.074176 | M33: 0.066018 | P33: withheld
A34: guardrail_verdict | D34: OK | G34: OK | J34: OK | M34: OK | P34: withheld
A35: revenue_total | B35: 5322 | C35: 5481 | E35: 11271 | F35: 11364 | H35: 17559 | I35: 20262 | K35: 19566 | L35: 26190 | N35: withheld | O35: withheld
A36: revenue_per_assigned_account | B36: 81.88 | C36: 85.64 | E36: 98.87 | F36: 98.82 | H36: 107.07 | I36: 123.55 | K36: 97.83 | L36: 130.95 | N36: withheld | O36: withheld
A37: revenue_variance | B37: 58724.64 | C37: 56433.12 | E37: 79308.38 | F37: 73426.31 | H37: 87941.11 | I37: 93820.11 | K37: 77628.92 | L37: 100694.06 | N37: withheld | O37: withheld
A38: revenue_t_low | B38: 21.83 | C38: 26.3 | E38: 46.61 | F38: 48.76 | H38: 61.34 | I38: 76.32 | K38: 58.98 | L38: 86.7 | N38: withheld | O38: withheld
A39: revenue_t_high | B39: 141.92 | C39: 144.98 | E39: 151.12 | F39: 148.87 | H39: 152.79 | I39: 170.78 | K39: 136.68 | L39: 175.2 | N39: withheld | O39: withheld
A40: revenue_difference | D40: 3.76 | G40: -0.05 | J40: 16.48 | M40: 33.12 | P40: withheld
A41: welch_df | D41: 126 | G41: 226 | J41: 325 | M41: 391 | P41: withheld
...

Sheet Golden case
A1: The known answer, with formulas (P06-GOLD-01)
A2: 20 of 100 control and 30 of 100 treatment mature assigned accounts activate: 0.200000 and 0.300000, +10.00 pp, relative lift 0.500000, Newcombe [-0.020249, 0.216734] includes 0, not conclusive; the sample ratio 100/100 against 0.50/0.50 gives chi-square 0. Blue = typed inputs, black = formulas, column C = tests/fixtures/golden/expected.json.
A3: input | B3: value
A4: control mature assigned accounts | B4: 100
A5: control activated | B5: 20
A6: treatment mature assigned accounts | B6: 100
A7: treatment activated | B7: 30
A8: z | B8: 1.959964
A9: allocation control | B9: 0.5
A10: allocation treatment | B10: 0.5
A11: control assigned | B11: 100
A12: treatment assigned | B12: 100
A15: figure | B15: formula | C15: expected.json | D15: check
A16: control conversion | B16: =B5/B4 -> 0.2 | C16: 0.2 | D16: =IF(ISNUMBER(B16),ABS(B16-C16)<=0.0000005+0.0000000001,B16=C16) -> TRUE
A17: treatment conversion | B17: =B7/B6 -> 0.3 | C17: 0.3 | D17: =IF(ISNUMBER(B17),ABS(B17-C17)<=0.0000005+0.0000000001,B17=C17) -> TRUE
A18: control Wilson low | B18: =(B5/B4+$B$8^2/(2*B4)-$B$8*SQRT((B5/B4)*(1-B5/B4)/B4+$B$8^2/(4*B4^2)))/(1+$B$8^2/B4) -> 0.13336693 | C18: 0.133367 | D18: =IF(ISNUMBER(B18),ABS(B18-C18)<=0.0000005+0.0000000001,B18=C18) -> TRUE
A19: control Wilson high | B19: =(B5/B4+$B$8^2/(2*B4)+$B$8*SQRT((B5/B4)*(1-B5/B4)/B4+$B$8^2/(4*B4^2)))/(1+$B$8^2/B4) -> 0.28882917 | C19: 0.288829 | D19: =IF(ISNUMBER(B19),ABS(B19-C19)<=0.0000005+0.0000000001,B19=C19) -> TRUE
A20: treatment Wilson low | B20: =(B7/B6+$B$8^2/(2*B6)-$B$8*SQRT((B7/B6)*(1-B7/B6)/B6+$B$8^2/(4*B6^2)))/(1+$B$8^2/B6) -> 0.21894885 | C20: 0.218949 | D20: =IF(ISNUMBER(B20),ABS(B20-C20)<=0.0000005+0.0000000001,B20=C20) -> TRUE
A21: treatment Wilson high | B21: =(B7/B6+$B$8^2/(2*B6)+$B$8*SQRT((B7/B6)*(1-B7/B6)/B6+$B$8^2/(4*B6^2)))/(1+$B$8^2/B6) -> 0.39584855 | C21: 0.395849 | D21: =IF(ISNUMBER(B21),ABS(B21-C21)<=0.0000005+0.0000000001,B21=C21) -> TRUE
A22: absolute lift (percentage points) | B22: =(B17-B16)*100 -> 10 | C22: 10 | D22: =IF(ISNUMBER(B22),ABS(B22-C22)<=0.0000005+0.0000000001,B22=C22) -> TRUE
A23: relative lift | B23: =(B17-B16)/B16 -> 0.5 | C23: 0.5 | D23: =IF(ISNUMBER(B23),ABS(B23-C23)<=0.0000005+0.0000000001,B23=C23) -> TRUE
A24: Newcombe low | B24: =(B17-B16)-SQRT((B17-B20)^2+(B19-B16)^2) -> -0.020249363 | C24: -0.020249 | D24: =IF(ISNUMBER(B24),ABS(B24-C24)<=0.0000005+0.0000000001,B24=C24) -> TRUE
A25: Newcombe high | B25: =(B17-B16)+SQRT((B21-B17)^2+(B16-B18)^2) -> 0.21673435 | C25: 0.216734 | D25: =IF(ISNUMBER(B25),ABS(B25-C25)<=0.0000005+0.0000000001,B25=C25) -> TRUE
A26: interval includes 0 | B26: =AND(B24<=0,B25>=0) -> TRUE | C26: =TRUE() -> TRUE | D26: =B26=C26 -> TRUE
A27: sample-ratio chi-square | B27: =(B11-(B11+B12)*B9)^2/((B11+B12)*B9)+(B12-(B11+B12)*B10)^2/((B11+B12)*B10) -> 0 | C27: 0 | D27: =IF(ISNUMBER(B27),ABS(B27-C27)<=0.0000005+0.0000000001,B27=C27) -> TRUE
A28: sample-ratio p-value | B28: =CHIDIST(B27,1) -> 1 | C28: 1 | D28: =IF(ISNUMBER(B28),ABS(B28-C28)<=0.0000005+0.0000000001,B28=C28) -> TRUE
A30: all golden checks TRUE | B30: =AND(D16:D28) -> TRUE

Sheet Plan x segment
A1: Seven-day activation by plan and segment at the as-of (live formulas over Accounts)
A2: Internal accounts excluded. Mature = signup + 7 x 24 h <= 2026-10-05T00:00:00Z; the rate has the mature accounts as denominator. Equals investigation 01 (docs/sql-analysis.md); observed, not experimental.
A4: plan | B4: segment | C4: accounts | D4: signed up | E4: mature | F4: activated | G4: activation rate | H4: immature (signed up, not mature)
A5: business | B5: enterprise | C5: =COUNTIFS(Accounts!$E$2:$E$601,0,Accounts!$B$2:$B$601,A5,Accounts!$C$2:$C$601,B5) -> 51 | D5: =COUNTIFS(Accounts!$E$2:$E$601,0,Accounts!$B$2:$B$601,A5,Accounts!$C$2:$C$601,B5,Accounts!$F$2:$F$601,"<1E+15") -> 51 | E5: =COUNTIFS(Accounts!$E$2:$E$601,0,Accounts!$B$2:$B$601,A5,Accounts!$C$2:$C$601,B5,Accounts!$H$2:$H$601,1) -> 50 | F5: =COUNTIFS(Accounts!$E$2:$E$601,0,Accounts!$B$2:$B$601,A5,Accounts!$C$2:$C$601,B5,Accounts!$I$2:$I$601,1) -> 31 | G5: =IF(E5=0,"",F5/E5) -> 0.62 | H5: =D5-E5 -> 1
A6: business | B6: mid | C6: =COUNTIFS(Accounts!$E$2:$E$601,0,Accounts!$B$2:$B$601,A6,Accounts!$C$2:$C$601,B6) -> 27 | D6: =COUNTIFS(Accounts!$E$2:$E$601,0,Accounts!$B$2:$B$601,A6,Accounts!$C$2:$C$601,B6,Accounts!$F$2:$F$601,"<1E+15") -> 27 | E6: =COUNTIFS(Accounts!$E$2:$E$601,0,Accounts!$B$2:$B$601,A6,Accounts!$C$2:$C$601,B6,Accounts!$H$2:$H$601,1) -> 26 | F6: =COUNTIFS(Accounts!$E$2:$E$601,0,Accounts!$B$2:$B$601,A6,Accounts!$C$2:$C$601,B6,Accounts!$I$2:$I$601,1) -> 16 | G6: =IF(E6=0,"",F6/E6) -> 0.61538462 | H6: =D6-E6 -> 1
A7: business | B7: smb | C7: =COUNTIFS(Accounts!$E$2:$E$601,0,Accounts!$B$2:$B$601,A7,Accounts!$C$2:$C$601,B7) -> 9 | D7: =COUNTIFS(Accounts!$E$2:$E$601,0,Accounts!$B$2:$B$601,A7,Accounts!$C$2:$C$601,B7,Accounts!$F$2:$F$601,"<1E+15") -> 9 | E7: =COUNTIFS(Accounts!$E$2:$E$601,0,Accounts!$B$2:$B$601,A7,Accounts!$C$2:$C$601,B7,Accounts!$H$2:$H$601,1) -> 9 | F7: =COUNTIFS(Accounts!$E$2:$E$601,0,Accounts!$B$2:$B$601,A7,Accounts!$C$2:$C$601,B7,Accounts!$I$2:$I$601,1) -> 4 | G7: =IF(E7=0,"",F7/E7) -> 0.44444444 | H7: =D7-E7 -> 0
A8: business | B8: ALL | C8: =COUNTIFS(Accounts!$E$2:$E$601,0,Accounts!$B$2:$B$601,A8) -> 87 | D8: =COUNTIFS(Accounts!$E$2:$E$601,0,Accounts!$B$2:$B$601,A8,Accounts!$F$2:$F$601,"<1E+15") -> 87 | E8: =COUNTIFS(Accounts!$E$2:$E$601,0,Accounts!$B$2:$B$601,A8,Accounts!$H$2:$H$601,1) -> 85 | F8: =COUNTIFS(Accounts!$E$2:$E$601,0,Accounts!$B$2:$B$601,A8,Accounts!$I$2:$I$601,1) -> 51 | G8: =IF(E8=0,"",F8/E8) -> 0.6 | H8: =D8-E8 -> 2
A9: free | B9: enterprise | C9: =COUNTIFS(Accounts!$E$2:$E$601,0,Accounts!$B$2:$B$601,A9,Accounts!$C$2:$C$601,B9) -> 13 | D9: =COUNTIFS(Accounts!$E$2:$E$601,0,Accounts!$B$2:$B$601,A9,Accounts!$C$2:$C$601,B9,Accounts!$F$2:$F$601,"<1E+15") -> 13 | E9: =COUNTIFS(Accounts!$E$2:$E$601,0,Accounts!$B$2:$B$601,A9,Accounts!$C$2:$C$601,B9,Accounts!$H$2:$H$601,1) -> 13 | F9: =COUNTIFS(Accounts!$E$2:$E$601,0,Accounts!$B$2:$B$601,A9,Accounts!$C$2:$C$601,B9,Accounts!$I$2:$I$601,1) -> 7 | G9: =IF(E9=0,"",F9/E9) -> 0.53846154 | H9: =D9-E9 -> 0
A10: free | B10: mid | C10: =COUNTIFS(Accounts!$E$2:$E$601,0,Accounts!$B$2:$B$601,A10,Accounts!$C$2:$C$601,B10) -> 52 | D10: =COUNTIFS(Accounts!$E$2:$E$601,0,Accounts!$B$2:$B$601,A10,Accounts!$C$2:$C$601,B10,Accounts!$F$2:$F$601,"<1E+15") -> 52 | E10: =COUNTIFS(Accounts!$E$2:$E$601,0,Accounts!$B$2:$B$601,A10,Accounts!$C$2:$C$601,B10,Accounts!$H$2:$H$601,1) -> 51 | F10: =COUNTIFS(Accounts!$E$2:$E$601,0,Accounts!$B$2:$B$601,A10,Accounts!$C$2:$C$601,B10,Accounts!$I$2:$I$601,1) -> 19 | G10: =IF(E10=0,"",F10/E10) -> 0.37254902 | H10: =D10-E10 -> 1
A11: free | B11: smb | C11: =COUNTIFS(Accounts!$E$2:$E$601,0,Accounts!$B$2:$B$601,A11,Accounts!$C$2:$C$601,B11) -> 191 | D11: =COUNTIFS(Accounts!$E$2:$E$601,0,Accounts!$B$2:$B$601,A11,Accounts!$C$2:$C$601,B11,Accounts!$F$2:$F$601,"<1E+15") -> 191 | E11: =COUNTIFS(Accounts!$E$2:$E$601,0,Accounts!$B$2:$B$601,A11,Accounts!$C$2:$C$601,B11,Accounts!$H$2:$H$601,1) -> 185 | F11: =COUNTIFS(Accounts!$E$2:$E$601,0,Accounts!$B$2:$B$601,A11,Accounts!$C$2:$C$601,B11,Accounts!$I$2:$I$601,1) -> 53 | G11: =IF(E11=0,"",F11/E11) -> 0.28648649 | H11: =D11-E11 -> 6
A12: free | B12: ALL | C12: =COUNTIFS(Accounts!$E$2:$E$601,0,Accounts!$B$2:$B$601,A12) -> 256 | D12: =COUNTIFS(Accounts!$E$2:$E$601,0,Accounts!$B$2:$B$601,A12,Accounts!$F$2:$F$601,"<1E+15") -> 256 | E12: =COUNTIFS(Accounts!$E$2:$E$601,0,Accounts!$B$2:$B$601,A12,Accounts!$H$2:$H$601,1) -> 249 | F12: =COUNTIFS(Accounts!$E$2:$E$601,0,Accounts!$B$2:$B$601,A12,Accounts!$I$2:$I$601,1) -> 79 | G12: =IF(E12=0,"",F12/E12) -> 0.31726908 | H12: =D12-E12 -> 7
