Workbook

Sheet Read me
A1: Pipeline Observatory analyst workbook (P08-ART-05)
A3: What it is | B3: A formula-driven recomputation of the Pipeline Observatory headline measures over the published synthetic snapshot po-20261026-20261026 (dataset hash 0a90687778634365c402c5431661b56625de20785e28d9b2388d36c0cad19aab, code revision ed7eb5a, as-of 2026-10-05T00:00:00Z): 6 sources, 1,311 batches, 1,343 hourly runs, 25 incidents, 15 backfill requests, 1,361 fetches.
A4: The decision | B4: Is this dataset safe, complete and fresh enough to publish? Publish decision applies the printed rule of the site: a blocked latest gate or a source past its freshness target means do not publish; a silent source means publish with a stated exception.
A5: Synthetic data and scope | B5: Everything is synthetic (a seeded generator). Every figure carries a scope: COMPLETE world (published in full), 2,000-row SAMPLE (raw rows), or RECORDED (the generator's statement). Observed = what this one draw shows; constructed = the designed relationships and injected defects; no real-world benefit is claimed.
A6: How to use it | B6: Open the .xlsx in any spreadsheet application. Controls!B3 changes how many cadences make a source silent; Controls!B5 switches the scope of the Selected rates; Checks!B2 is TRUE when every figure agrees with the Python domain, the manifest's record and the golden hand answer. Nothing needs installing to read the cached values.
A7: Recalculation status | B7: openpyxl wrote formulas only; LibreOffice (headless) recalculated the delivered file. Microsoft Excel was NOT run: nothing here was opened or recalculated by Excel (docs/workbook.md).
A8: Sheets | B8: Controls, Checks, Publish decision, Source health, Sample scope, Golden case, Assumptions (read-this-first limits), data sheets (Sources, Batches, Checkpoints, Runs, Incidents, Backfills, Retries, Fetch log), Domain reference (pasted values), SQL results (pasted).
A9: Colour | B9: Blue = typed input or pasted value; black = formula.

Sheet Controls
A1: Controls
A2: Change B3 (cadences) or B5 (scope): Source health and Publish decision follow. Blue cells are inputs.
A3: A source is silent above this many declared cadences (display rule, D-08) | B3: 2
A4: As-of (UTC) | B4: 46300
A5: Scope of the Selected rates (complete world | sample) | B5: complete world
A7: All checks pass (Checks!B2) | B7: =Checks!B2 -> TRUE
A8: Publish verdict (Publish decision!B10) | B8: ='Publish decision'!B10 -> PUBLISH WITH A STATED EXCEPTION: 1 source is silent while the jobs stay green, the first is src-refunds

Sheet Checks
A1: Checks: TRUE when every comparison with the Python domain, the manifest's record and the golden hand answer holds
A2: All checks pass | B2: =AND(B5:B15) -> TRUE
A4: check | B4: result
A5: Every source row of Source health agrees with the domain / the manifest's record (counts, rates, ingestion age, freshness, completeness) | B5: =COUNTIF('Source health'!T4:T9,TRUE())=ROWS('Source health'!T4:T9) -> TRUE
A6: Run funnel: runs | reached the gate | allowed | blocked at the gate | failed before it equal the domain's gate results | B6: =AND('Publish decision'!B14='Domain reference'!A13,'Publish decision'!B15='Domain reference'!B13,'Publish decision'!B16='Domain reference'!C13,'Publish decision'!B17='Domain reference'!D13,'Publish decision'!B18='Domain reference'!E13) -> TRUE
A7: Task success and attempt success equal the domain | B7: =AND(ROUND('Publish decision'!B30-'Domain reference'!F13,6)=0,ROUND('Publish decision'!B31-'Domain reference'!G13,6)=0) -> TRUE
A8: Failed runs by kind equal the manifest's by_type (freshness, relationships, residual, ingest, transform, gate_infra) | B8: =AND('Publish decision'!B22=5,'Publish decision'!B23=4,'Publish decision'!B24=1,'Publish decision'!B25=3,'Publish decision'!B26=9,'Publish decision'!B27=3) -> TRUE
A9: Incidents and mean recovery minutes equal the domain | B9: =AND('Publish decision'!B34='Domain reference'!A17,ROUND('Publish decision'!B35-'Domain reference'!B17,4)=0) -> TRUE
A10: Backfill coverage (requested, verified, coverage) equals the domain | B10: =AND('Publish decision'!B38='Domain reference'!C17,'Publish decision'!B39='Domain reference'!D17,ROUND('Publish decision'!B40-'Domain reference'!E17,6)=0,'Publish decision'!B41=4) -> TRUE
A11: Retry-after: every rate-limited fetch was retried no sooner than its hint | B11: =AND('Publish decision'!B44='Domain reference'!G17,'Publish decision'!B45='Domain reference'!H17,'Publish decision'!B44='Publish decision'!B45) -> TRUE
A12: Publication pointer equals the domain's current publication | B12: ='Publish decision'!B6='Domain reference'!I17 -> TRUE
A13: Publish verdict at the default controls is the stated exception for the one silent source | B13: =IF(AND(Controls!B3=2,Controls!B4=46300),LEFT('Publish decision'!B10,31)="PUBLISH WITH A STATED EXCEPTION",TRUE()) -> TRUE
A14: Golden case: every formula figure equals the hand answer | B14: =COUNTIF('Golden case'!D16:D34,TRUE())=ROWS('Golden case'!D16:D34) -> TRUE
A15: Sample scope: the sample's accepted count exceeds the world's for the same batches and the duplicate count falls short (the scope warning holds) | B15: =AND('Sample scope'!K10>0,'Sample scope'!L10<0) -> TRUE

Sheet Publish decision
A1: Is this dataset safe, complete and fresh enough to publish? The printed rule of the site, as formulas
A2: Rule: a blocked latest gate or a source past its declared freshness target means DO NOT PUBLISH; a silent source (freshness above Controls!B3 declared cadences) means PUBLISH WITH A STATED EXCEPTION. Scope: complete world except freshness (recorded).
A3: Latest run | B3: =INDEX(Runs!$A$4:$A$1346,ROWS(Runs!$A$4:$A$1346)) -> run-1343
A4: Latest run: status | B4: =INDEX(Runs!$C$4:$C$1346,ROWS(Runs!$C$4:$C$1346)) -> success
A5: Latest run: gate decision | B5: =INDEX(Runs!$P$4:$P$1346,ROWS(Runs!$P$4:$P$1346)) -> allowed
A6: Publication pointer (publication of the latest published run) | B6: =LOOKUP(2,1/(Runs!$J$4:$J$1346=TRUE()),Runs!$K$4:$K$1346) -> pub-1343
A7: Sources past their declared freshness target | B7: ='Source health'!P10 -> 0
A8: Silent sources | B8: ='Source health'!Q10 -> 1
A9: First silent source | B9: =IFERROR(INDEX('Source health'!A4:A9,MATCH(TRUE(),'Source health'!Q4:Q9,0)),"none") -> src-refunds
A10: Verdict | B10: =IF(B5<>"allowed","DO NOT PUBLISH: the latest gate did not allow the run",IF(B7>0,"DO NOT PUBLISH: a source is past its declared freshness target",IF(B8>0,"PUBLISH WITH A STATED EXCEPTION: "&B8&IF(B8=1," source is"," sources are")&" silent while the jobs stay green, the first is "&B9,"PUBLISH"))) -> PUBLISH WITH A STATED EXCEPTION: 1 source is silent while the jobs stay green, the first is src-refunds
A13: Run funnel (D-09 R8-07)
A14: runs | B14: =COUNTA(Runs!$A$4:$A$1346) -> 1343
A15: reached the gate | B15: =COUNTIF(Runs!$P$4:$P$1346,"allowed")+COUNTIF(Runs!$P$4:$P$1346,"blocked") -> 1328
A16: allowed | B16: =COUNTIF(Runs!$P$4:$P$1346,"allowed") -> 1318
A17: blocked at the gate | B17: =COUNTIF(Runs!$Q$4:$Q$1346,"blocked_at_gate") -> 10
A18: failed before the gate | B18: =COUNTIF(Runs!$Q$4:$Q$1346,"failed_before_gate") -> 15
A19: published | B19: =COUNTIF(Runs!$J$4:$J$1346,TRUE()) -> 1318
A21: Failed runs by kind | C21: mean recovery minutes
A22: freshness | B22: =COUNTIF(Runs!$R$4:$R$1346,A22) -> 5 | C22: =ROUND(AVERAGEIFS(Incidents!$E$4:$E$28,Incidents!$G$4:$G$28,A22)/60,4) -> 66.78
A23: relationships | B23: =COUNTIF(Runs!$R$4:$R$1346,A23) -> 4 | C23: =ROUND(AVERAGEIFS(Incidents!$E$4:$E$28,Incidents!$G$4:$G$28,A23)/60,4) -> 64.1
A24: residual | B24: =COUNTIF(Runs!$R$4:$R$1346,A24) -> 1 | C24: =ROUND(AVERAGEIFS(Incidents!$E$4:$E$28,Incidents!$G$4:$G$28,A24)/60,4) -> 63.1
A25: ingest | B25: =COUNTIF(Runs!$R$4:$R$1346,A25) -> 3 | C25: =ROUND(AVERAGEIFS(Incidents!$E$4:$E$28,Incidents!$G$4:$G$28,A25)/60,4) -> 65.2778
A26: transform | B26: =COUNTIF(Runs!$R$4:$R$1346,A26) -> 9 | C26: =ROUND(AVERAGEIFS(Incidents!$E$4:$E$28,Incidents!$G$4:$G$28,A26)/60,4) -> 55.3611
A27: gate_infra | B27: =COUNTIF(Runs!$R$4:$R$1346,A27) -> 3 | C27: =ROUND(AVERAGEIFS(Incidents!$E$4:$E$28,Incidents!$G$4:$G$28,A27)/60,4) -> 56.5278
A29: Tasks against attempts
A30: task success rate | B30: =ROUND(SUM(Runs!$M$4:$M$1346)/SUM(Runs!$L$4:$L$1346),6) -> 0.995311
A31: attempt success rate | B31: =ROUND(SUM(Runs!$O$4:$O$1346)/SUM(Runs!$N$4:$N$1346),6) -> 0.971622
A33: Incidents and recovery
A34: incidents | B34: =COUNTA(Incidents!$A$4:$A$28) -> 25
A35: mean recovery minutes (verified recovery minus detection) | B35: =ROUND(AVERAGE(Incidents!$E$4:$E$28)/60,4) -> 60.6827
A37: Backfill coverage (accepted requests only)
A38: requested partitions | B38: =COUNTIF(Backfills!$C$4:$C$22,"accepted") -> 15
A39: verified partitions | B39: =COUNTIFS(Backfills!$C$4:$C$22,"accepted",Backfills!$E$4:$E$22,TRUE()) -> 11
A40: coverage | B40: =ROUND(B39/B38,6) -> 0.733333
A41: refused partitions (beside, never inside) | B41: =COUNTIF(Backfills!$C$4:$C$22,"refused") -> 4
A43: Retry-after
A44: rate-limited fetches | B44: =COUNTIF('Fetch log'!$D$4:$D$1364,"rate_limited") -> 49
A45: retries honouring the hint | B45: =COUNTIF(Retries!$H$4:$H$52,TRUE()) -> 49
A46: refetch rows | loop rows | B46: =COUNTIF('Fetch log'!$D$4:$D$1364,"refetch")&" | "&COUNTIF('Fetch log'!$D$4:$D$1364,"cursor_loop") -> 48 | 1

Sheet Source health
A1: Source health at the as-of: counts and rates (complete world), ingestion age, freshness (recorded), flags
A2: Controls!B3 = the number of declared cadences that make a source silent; Controls!B5 = the scope of the Selected rates. Check = the row agrees with the domain / the manifest's record (Domain reference).
A3: source_id | B3: cadence_seconds | C3: target_seconds | D3: committed_batches | E3: received | F3: accepted_unique | G3: duplicate | H3: quarantined | I3: deleted | J3: rejection_rate | K3: duplicate_rate | L3: selected_rejection_rate | M3: selected_duplicate_rate | N3: ingestion_age_seconds | O3: freshness_seconds | P3: over_target | Q3: silent | R3: expected_records | S3: completeness | T3: check
A4: src-inventory | B4: =INDEX(Sources!$C$4:$C$9,MATCH(A4,Sources!$A$4:$A$9,0)) -> 86400 | C4: =INDEX(Sources!$D$4:$D$9,MATCH(A4,Sources!$A$4:$A$9,0)) -> 259200 | D4: =COUNTIFS(Batches!$B$4:$B$1314,A4,Batches!$C$4:$C$1314,"committed") -> 61 | E4: =SUMIFS(Batches!$G$4:$G$1314,Batches!$B$4:$B$1314,$A4,Batches!$C$4:$C$1314,"committed") -> 1723 | F4: =SUMIFS(Batches!$H$4:$H$1314,Batches!$B$4:$B$1314,$A4,Batches!$C$4:$C$1314,"committed") -> 1630 | G4: =SUMIFS(Batches!$I$4:$I$1314,Batches!$B$4:$B$1314,$A4,Batches!$C$4:$C$1314,"committed") -> 72 | H4: =SUMIFS(Batches!$J$4:$J$1314,Batches!$B$4:$B$1314,$A4,Batches!$C$4:$C$1314,"committed") -> 21 | I4: =SUMIFS(Batches!$K$4:$K$1314,Batches!$B$4:$B$1314,$A4,Batches!$C$4:$C$1314,"committed") -> 0 | J4: =ROUND(H4/E4,6) -> 0.012188 | K4: =ROUND(G4/E4,6) -> 0.041788 | L4: =IF(Controls!$B$5="sample",'Sample scope'!G4,J4) -> 0.012188 | M4: =IF(Controls!$B$5="sample",'Sample scope'!H4,K4) -> 0.041788 | N4: =ROUND((Controls!$B$4-_xlfn.MAXIFS(Checkpoints!$C$4:$C$1305,Checkpoints!$B$4:$B$1305,A4))*86400,0) -> 67674 | O4: =ROUND((Controls!$B$4-INDEX(Sources!$G$4:$G$9,MATCH(A4,Sources!$A$4:$A$9,0)))*86400,0) -> 79203 | P4: =O4>C4 -> FALSE | Q4: =O4>Controls!$B$3*B4 -> FALSE | R4: =INDEX(Sources!$F$4:$F$9,MATCH(A4,Sources!$A$4:$A$9,0)) -> 1645 | S4: =ROUND(F4/R4,6) -> 0.990881 | T4: =AND(E4='Domain reference'!B4,F4='Domain reference'!C4,G4='Domain reference'!D4,H4='Domain reference'!E4,ROUND(J4-'Domain reference'!F4,6)=0,ROUND(K4-'Domain reference'!G4,6)=0,N4='Domain reference'!H4,O4='Domain reference'!I4,ROUND(S4-'Domain reference'!J4,6)=0) -> TRUE
A5: src-orders | B5: =INDEX(Sources!$C$4:$C$9,MATCH(A5,Sources!$A$4:$A$9,0)) -> 14400 | C5: =INDEX(Sources!$D$4:$D$9,MATCH(A5,Sources!$A$4:$A$9,0)) -> 19800 | D5: =COUNTIFS(Batches!$B$4:$B$1314,A5,Batches!$C$4:$C$1314,"committed") -> 335 | E5: =SUMIFS(Batches!$G$4:$G$1314,Batches!$B$4:$B$1314,$A5,Batches!$C$4:$C$1314,"committed") -> 16815 | F5: =SUMIFS(Batches!$H$4:$H$1314,Batches!$B$4:$B$1314,$A5,Batches!$C$4:$C$1314,"committed") -> 16066 | G5: =SUMIFS(Batches!$I$4:$I$1314,Batches!$B$4:$B$1314,$A5,Batches!$C$4:$C$1314,"committed") -> 502 | H5: =SUMIFS(Batches!$J$4:$J$1314,Batches!$B$4:$B$1314,$A5,Batches!$C$4:$C$1314,"committed") -> 181 | I5: =SUMIFS(Batches!$K$4:$K$1314,Batches!$B$4:$B$1314,$A5,Batches!$C$4:$C$1314,"committed") -> 66 | J5: =ROUND(H5/E5,6) -> 0.010764 | K5: =ROUND(G5/E5,6) -> 0.029854 | L5: =IF(Controls!$B$5="sample",'Sample scope'!G5,J5) -> 0.010764 | M5: =IF(Controls!$B$5="sample",'Sample scope'!H5,K5) -> 0.029854 | N5: =ROUND((Controls!$B$4-_xlfn.MAXIFS(Checkpoints!$C$4:$C$1305,Checkpoints!$B$4:$B$1305,A5))*86400,0) -> 13887 | O5: =ROUND((Controls!$B$4-INDEX(Sources!$G$4:$G$9,MATCH(A5,Sources!$A$4:$A$9,0)))*86400,0) -> 14514 | P5: =O5>C5 -> FALSE | Q5: =O5>Controls!$B$3*B5 -> FALSE | R5: =INDEX(Sources!$F$4:$F$9,MATCH(A5,Sources!$A$4:$A$9,0)) -> 16176 | S5: =ROUND(F5/R5,6) -> 0.9932 | T5: =AND(E5='Domain reference'!B5,F5='Domain reference'!C5,G5='Domain reference'!D5,H5='Domain reference'!E5,ROUND(J5-'Domain reference'!F5,6)=0,ROUND(K5-'Domain reference'!G5,6)=0,N5='Domain reference'!H5,O5='Domain reference'!I5,ROUND(S5-'Domain reference'!J5,6)=0) -> TRUE
A6: src-payments | B6: =INDEX(Sources!$C$4:$C$9,MATCH(A6,Sources!$A$4:$A$9,0)) -> 14400 | C6: =INDEX(Sources!$D$4:$D$9,MATCH(A6,Sources!$A$4:$A$9,0)) -> 21600 | D6: =COUNTIFS(Batches!$B$4:$B$1314,A6,Batches!$C$4:$C$1314,"committed") -> 336 | E6: =SUMIFS(Batches!$G$4:$G$1314,Batches!$B$4:$B$1314,$A6,Batches!$C$4:$C$1314,"committed") -> 10805 | F6: =SUMIFS(Batches!$H$4:$H$1314,Batches!$B$4:$B$1314,$A6,Batches!$C$4:$C$1314,"committed") -> 10125 | G6: =SUMIFS(Batches!$I$4:$I$1314,Batches!$B$4:$B$1314,$A6,Batches!$C$4:$C$1314,"committed") -> 522 | H6: =SUMIFS(Batches!$J$4:$J$1314,Batches!$B$4:$B$1314,$A6,Batches!$C$4:$C$1314,"committed") -> 123 | I6: =SUMIFS(Batches!$K$4:$K$1314,Batches!$B$4:$B$1314,$A6,Batches!$C$4:$C$1314,"committed") -> 35 | J6: =ROUND(H6/E6,6) -> 0.011384 | K6: =ROUND(G6/E6,6) -> 0.048311 | L6: =IF(Controls!$B$5="sample",'Sample scope'!G6,J6) -> 0.011384 | M6: =IF(Controls!$B$5="sample",'Sample scope'!H6,K6) -> 0.048311 | N6: =ROUND((Controls!$B$4-_xlfn.MAXIFS(Checkpoints!$C$4:$C$1305,Checkpoints!$B$4:$B$1305,A6))*86400,0) -> 6638 | O6: =ROUND((Controls!$B$4-INDEX(Sources!$G$4:$G$9,MATCH(A6,Sources!$A$4:$A$9,0)))*86400,0) -> 7766 | P6: =O6>C6 -> FALSE | Q6: =O6>Controls!$B$3*B6 -> FALSE | R6: =INDEX(Sources!$F$4:$F$9,MATCH(A6,Sources!$A$4:$A$9,0)) -> 10207 | S6: =ROUND(F6/R6,6) -> 0.991966 | T6: =AND(E6='Domain reference'!B6,F6='Domain reference'!C6,G6='Domain reference'!D6,H6='Domain reference'!E6,ROUND(J6-'Domain reference'!F6,6)=0,ROUND(K6-'Domain reference'!G6,6)=0,N6='Domain reference'!H6,O6='Domain reference'!I6,ROUND(S6-'Domain reference'!J6,6)=0) -> TRUE
A7: src-refunds | B7: =INDEX(Sources!$C$4:$C$9,MATCH(A7,Sources!$A$4:$A$9,0)) -> 21600 | C7: =INDEX(Sources!$D$4:$D$9,MATCH(A7,Sources!$A$4:$A$9,0)) -> 604800 | D7: =COUNTIFS(Batches!$B$4:$B$1314,A7,Batches!$C$4:$C$1314,"committed") -> 228 | E7: =SUMIFS(Batches!$G$4:$G$1314,Batches!$B$4:$B$1314,$A7,Batches!$C$4:$C$1314,"committed") -> 4295 | F7: =SUMIFS(Batches!$H$4:$H$1314,Batches!$B$4:$B$1314,$A7,Batches!$C$4:$C$1314,"committed") -> 3785 | G7: =SUMIFS(Batches!$I$4:$I$1314,Batches!$B$4:$B$1314,$A7,Batches!$C$4:$C$1314,"committed") -> 468 | H7: =SUMIFS(Batches!$J$4:$J$1314,Batches!$B$4:$B$1314,$A7,Batches!$C$4:$C$1314,"committed") -> 42 | I7: =SUMIFS(Batches!$K$4:$K$1314,Batches!$B$4:$B$1314,$A7,Batches!$C$4:$C$1314,"committed") -> 0 | J7: =ROUND(H7/E7,6) -> 0.009779 | K7: =ROUND(G7/E7,6) -> 0.108964 | L7: =IF(Controls!$B$5="sample",'Sample scope'!G7,J7) -> 0.009779 | M7: =IF(Controls!$B$5="sample",'Sample scope'!H7,K7) -> 0.108964 | N7: =ROUND((Controls!$B$4-_xlfn.MAXIFS(Checkpoints!$C$4:$C$1305,Checkpoints!$B$4:$B$1305,A7))*86400,0) -> 17363 | O7: =ROUND((Controls!$B$4-INDEX(Sources!$G$4:$G$9,MATCH(A7,Sources!$A$4:$A$9,0)))*86400,0) -> 262378 | P7: =O7>C7 -> FALSE | Q7: =O7>Controls!$B$3*B7 -> TRUE | R7: =INDEX(Sources!$F$4:$F$9,MATCH(A7,Sources!$A$4:$A$9,0)) -> 4003 | S7: =ROUND(F7/R7,6) -> 0.945541 | T7: =AND(E7='Domain reference'!B7,F7='Domain reference'!C7,G7='Domain reference'!D7,H7='Domain reference'!E7,ROUND(J7-'Domain reference'!F7,6)=0,ROUND(K7-'Domain reference'!G7,6)=0,N7='Domain reference'!H7,O7='Domain reference'!I7,ROUND(S7-'Domain reference'!J7,6)=0) -> TRUE
A8: src-shipments | B8: =INDEX(Sources!$C$4:$C$9,MATCH(A8,Sources!$A$4:$A$9,0)) -> 21600 | C8: =INDEX(Sources!$D$4:$D$9,MATCH(A8,Sources!$A$4:$A$9,0)) -> 259200 | D8: =COUNTIFS(Batches!$B$4:$B$1314,A8,Batches!$C$4:$C$1314,"committed") -> 226 | E8: =SUMIFS(Batches!$G$4:$G$1314,Batches!$B$4:$B$1314,$A8,Batches!$C$4:$C$1314,"committed") -> 4410 | F8: =SUMIFS(Batches!$H$4:$H$1314,Batches!$B$4:$B$1314,$A8,Batches!$C$4:$C$1314,"committed") -> 3985 | G8: =SUMIFS(Batches!$I$4:$I$1314,Batches!$B$4:$B$1314,$A8,Batches!$C$4:$C$1314,"committed") -> 368 | H8: =SUMIFS(Batches!$J$4:$J$1314,Batches!$B$4:$B$1314,$A8,Batches!$C$4:$C$1314,"committed") -> 35 | I8: =SUMIFS(Batches!$K$4:$K$1314,Batches!$B$4:$B$1314,$A8,Batches!$C$4:$C$1314,"committed") -> 22 | J8: =ROUND(H8/E8,6) -> 0.007937 | K8: =ROUND(G8/E8,6) -> 0.083447 | L8: =IF(Controls!$B$5="sample",'Sample scope'!G8,J8) -> 0.007937 | M8: =IF(Controls!$B$5="sample",'Sample scope'!H8,K8) -> 0.083447 | N8: =ROUND((Controls!$B$4-_xlfn.MAXIFS(Checkpoints!$C$4:$C$1305,Checkpoints!$B$4:$B$1305,A8))*86400,0) -> 9931 | O8: =ROUND((Controls!$B$4-INDEX(Sources!$G$4:$G$9,MATCH(A8,Sources!$A$4:$A$9,0)))*86400,0) -> 11789 | P8: =O8>C8 -> FALSE | Q8: =O8>Controls!$B$3*B8 -> FALSE | R8: =INDEX(Sources!$F$4:$F$9,MATCH(A8,Sources!$A$4:$A$9,0)) -> 4004 | S8: =ROUND(F8/R8,6) -> 0.995255 | T8: =AND(E8='Domain reference'!B8,F8='Domain reference'!C8,G8='Domain reference'!D8,H8='Domain reference'!E8,ROUND(J8-'Domain reference'!F8,6)=0,ROUND(K8-'Domain reference'!G8,6)=0,N8='Domain reference'!H8,O8='Domain reference'!I8,ROUND(S8-'Domain reference'!J8,6)=0) -> TRUE
A9: src-web-events | B9: =INDEX(Sources!$C$4:$C$9,MATCH(A9,Sources!$A$4:$A$9,0)) -> 43200 | C9: =INDEX(Sources!$D$4:$D$9,MATCH(A9,Sources!$A$4:$A$9,0)) -> 216000 | D9: =COUNTIFS(Batches!$B$4:$B$1314,A9,Batches!$C$4:$C$1314,"committed") -> 116 | E9: =SUMIFS(Batches!$G$4:$G$1314,Batches!$B$4:$B$1314,$A9,Batches!$C$4:$C$1314,"committed") -> 1853 | F9: =SUMIFS(Batches!$H$4:$H$1314,Batches!$B$4:$B$1314,$A9,Batches!$C$4:$C$1314,"committed") -> 1657 | G9: =SUMIFS(Batches!$I$4:$I$1314,Batches!$B$4:$B$1314,$A9,Batches!$C$4:$C$1314,"committed") -> 169 | H9: =SUMIFS(Batches!$J$4:$J$1314,Batches!$B$4:$B$1314,$A9,Batches!$C$4:$C$1314,"committed") -> 27 | I9: =SUMIFS(Batches!$K$4:$K$1314,Batches!$B$4:$B$1314,$A9,Batches!$C$4:$C$1314,"committed") -> 0 | J9: =ROUND(H9/E9,6) -> 0.014571 | K9: =ROUND(G9/E9,6) -> 0.091203 | L9: =IF(Controls!$B$5="sample",'Sample scope'!G9,J9) -> 0.014571 | M9: =IF(Controls!$B$5="sample",'Sample scope'!H9,K9) -> 0.091203 | N9: =ROUND((Controls!$B$4-_xlfn.MAXIFS(Checkpoints!$C$4:$C$1305,Checkpoints!$B$4:$B$1305,A9))*86400,0) -> 20724 | O9: =ROUND((Controls!$B$4-INDEX(Sources!$G$4:$G$9,MATCH(A9,Sources!$A$4:$A$9,0)))*86400,0) -> 21398 | P9: =O9>C9 -> FALSE | Q9: =O9>Controls!$B$3*B9 -> FALSE | R9: =INDEX(Sources!$F$4:$F$9,MATCH(A9,Sources!$A$4:$A$9,0)) -> 1678 | S9: =ROUND(F9/R9,6) -> 0.987485 | T9: =AND(E9='Domain reference'!B9,F9='Domain reference'!C9,G9='Domain reference'!D9,H9='Domain reference'!E9,ROUND(J9-'Domain reference'!F9,6)=0,ROUND(K9-'Domain reference'!G9,6)=0,N9='Domain reference'!H9,O9='Domain reference'!I9,ROUND(S9-'Domain reference'!J9,6)=0) -> TRUE
A10: all sources | D10: =SUM(D4:D9) -> 1302 | E10: =SUM(E4:E9) -> 39901 | F10: =SUM(F4:F9) -> 37248 | G10: =SUM(G4:G9) -> 2101 | H10: =SUM(H4:H9) -> 429 | I10: =SUM(I4:I9) -> 123 | J10: =ROUND(H10/E10,6) -> 0.010752 | K10: =ROUND(G10/E10,6) -> 0.052655 | P10: =COUNTIF(P4:P9,TRUE()) -> 0 | Q10: =COUNTIF(Q4:Q9,TRUE()) -> 1 | T10: =AND(T4:T9) -> TRUE

Sheet Sample scope
A1: The same rows under two scopes: the 2,000-row sample classified from the loaded rows only, and the complete world's classification of the SAME sampled batches
A2: The sample overstates accepted and understates duplicates because a key whose first copy sits in an unsampled batch looks new. Typed from the independent Python side (python_side.classify_sample) and the batch summaries.
A3: source_id | B3: sample_received | C3: sample_accepted | D3: sample_quarantined | E3: sample_duplicate | F3: sample_deleted | G3: sample_rejection_rate | H3: sample_duplicate_rate | I3: world_accepted (same batches) | J3: world_duplicate (same batches) | K3: accepted_delta | L3: duplicate_delta
A4: src-inventory | B4: 86 | C4: 83 | D4: 3 | E4: 0 | F4: 0 | G4: =ROUND(D4/B4,6) -> 0.034884 | H4: =ROUND(E4/B4,6) -> 0 | I4: 81 | J4: 2 | K4: =C4-I4 -> 2 | L4: =E4-J4 -> -2
A5: src-orders | B5: 983 | C5: 967 | D5: 11 | E5: 4 | F5: 1 | G5: =ROUND(D5/B5,6) -> 0.01119 | H5: =ROUND(E5/B5,6) -> 0.004069 | I5: 948 | J5: 23 | K5: =C5-I5 -> 19 | L5: =E5-J5 -> -19
A6: src-payments | B6: 367 | C6: 356 | D6: 11 | E6: 0 | F6: 0 | G6: =ROUND(D6/B6,6) -> 0.029973 | H6: =ROUND(E6/B6,6) -> 0 | I6: 346 | J6: 10 | K6: =C6-I6 -> 10 | L6: =E6-J6 -> -10
A7: src-refunds | B7: 152 | C7: 131 | D7: 2 | E7: 19 | F7: 0 | G7: =ROUND(D7/B7,6) -> 0.013158 | H7: =ROUND(E7/B7,6) -> 0.125 | I7: 124 | J7: 26 | K7: =C7-I7 -> 7 | L7: =E7-J7 -> -7
A8: src-shipments | B8: 193 | C8: 191 | D8: 2 | E8: 0 | F8: 0 | G8: =ROUND(D8/B8,6) -> 0.010363 | H8: =ROUND(E8/B8,6) -> 0 | I8: 182 | J8: 9 | K8: =C8-I8 -> 9 | L8: =E8-J8 -> -9
A9: src-web-events | B9: 97 | C9: 94 | D9: 3 | E9: 0 | F9: 0 | G9: =ROUND(D9/B9,6) -> 0.030928 | H9: =ROUND(E9/B9,6) -> 0 | I9: 88 | J9: 6 | K9: =C9-I9 -> 6 | L9: =E9-J9 -> -6
A10: all sources | B10: =SUM(B4:B9) -> 1878 | C10: =SUM(C4:C9) -> 1822 | D10: =SUM(D4:D9) -> 32 | E10: =SUM(E4:E9) -> 23 | F10: =SUM(F4:F9) -> 1 | G10: =ROUND(D10/B10,6) -> 0.017039 | H10: =ROUND(E10/B10,6) -> 0.012247 | I10: =SUM(I4:I9) -> 1769 | J10: =SUM(J4:J9) -> 76 | K10: =SUM(K4:K9) -> 53 | L10: =SUM(L4:L9) -> -53
A12: Selected scope (Controls!B5) headline duplicate rate | B12: =IF(Controls!$B$5="sample",H10,'Source health'!K10) -> 0.052655

Sheet Golden case
A1: Golden known answer (P08-GOLD-01, tests/fixtures/golden): ten rows by formula
A2: Typed inputs are blue; the class of each row, every count, rate, instant difference and the residual are formulas. Check = equals the hand answer of CALCULATION.md.
A3: source_key | B3: quantity | C3: unit_price | D3: amount | E3: event_ts (serial) | F3: class (formula)
A4: ORD-1001 | B4: 2 | C4: 12.5 | D4: 25 | E4: 46299.333 | F4: =IF(COUNTIFS(A$3:A3,A4,F$3:F3,"accepted")>0,"duplicate",IF(B4<0,"quarantined","accepted")) -> accepted
A5: ORD-1002 | B5: 1 | C5: 40 | D5: 40 | E5: 46299.347 | F5: =IF(COUNTIFS(A$3:A4,A5,F$3:F4,"accepted")>0,"duplicate",IF(B5<0,"quarantined","accepted")) -> accepted
A6: ORD-1003 | B6: 3 | C6: 9.99 | D6: 29.97 | E6: 46299.361 | F6: =IF(COUNTIFS(A$3:A5,A6,F$3:F5,"accepted")>0,"duplicate",IF(B6<0,"quarantined","accepted")) -> accepted
A7: ORD-1004 | B7: 5 | C7: 4 | D7: 20 | E7: 46299.375 | F7: =IF(COUNTIFS(A$3:A6,A7,F$3:F6,"accepted")>0,"duplicate",IF(B7<0,"quarantined","accepted")) -> accepted
A8: ORD-1005 | B8: 1 | C8: 100 | D8: 100 | E8: 46299.382 | F8: =IF(COUNTIFS(A$3:A7,A8,F$3:F7,"accepted")>0,"duplicate",IF(B8<0,"quarantined","accepted")) -> accepted
A9: ORD-1003 | B9: 3 | C9: 9.99 | D9: 29.97 | E9: 46299.361 | F9: =IF(COUNTIFS(A$3:A8,A9,F$3:F8,"accepted")>0,"duplicate",IF(B9<0,"quarantined","accepted")) -> duplicate
A10: ORD-1006 | B10: 4 | C10: 7.25 | D10: 29 | E10: 46299.389 | F10: =IF(COUNTIFS(A$3:A9,A10,F$3:F9,"accepted")>0,"duplicate",IF(B10<0,"quarantined","accepted")) -> accepted
A11: ORD-1009 | B11: -3 | C11: 10 | D11: -30 | E11: 46299.392 | F11: =IF(COUNTIFS(A$3:A10,A11,F$3:F10,"accepted")>0,"duplicate",IF(B11<0,"quarantined","accepted")) -> quarantined
A12: ORD-1007 | B12: 2 | C12: 15.5 | D12: 31 | E12: 46299.396 | F12: =IF(COUNTIFS(A$3:A11,A12,F$3:F11,"accepted")>0,"duplicate",IF(B12<0,"quarantined","accepted")) -> accepted
A13: ORD-1008 | B13: 6 | C13: 2.5 | D13: 15 | E13: 46299.385 | F13: =IF(COUNTIFS(A$3:A12,A13,F$3:F12,"accepted")>0,"duplicate",IF(B13<0,"quarantined","accepted")) -> accepted
A15: figure | B15: formula result | C15: hand answer (typed) | D15: check
A16: received | B16: =COUNTA(A4:A13) -> 10 | C16: 10 | D16: =ROUND(B16-C16,6)=0 -> TRUE
A17: accepted unique | B17: =COUNTIF(F4:F13,"accepted") -> 8 | C17: 8 | D17: =ROUND(B17-C17,6)=0 -> TRUE
A18: duplicate | B18: =COUNTIF(F4:F13,"duplicate") -> 1 | C18: 1 | D18: =ROUND(B18-C18,6)=0 -> TRUE
A19: quarantined | B19: =COUNTIF(F4:F13,"quarantined") -> 1 | C19: 1 | D19: =ROUND(B19-C19,6)=0 -> TRUE
A20: rejection rate | B20: =ROUND(B19/B16,6) -> 0.1 | C20: 0.1 | D20: =ROUND(B20-C20,6)=0 -> TRUE
A21: duplicate rate | B21: =ROUND(B18/B16,6) -> 0.1 | C21: 0.1 | D21: =ROUND(B21-C21,6)=0 -> TRUE
A22: freshness seconds (as-of minus the latest accepted event) | B22: =ROUND((Controls!$B$4-_xlfn.MAXIFS(E4:E13,F4:F13,"accepted"))*86400,0) -> 52200 | C22: 52200 | D22: =ROUND(B22-C22,6)=0 -> TRUE
A23: ingestion age seconds (as-of minus the last committed batch, b-002 at 12:05) | B23: =ROUND((Controls!$B$4-46299.5034722222)*86400,0) -> 42900 | C23: 42900 | D23: =ROUND(B23-C23,6)=0 -> TRUE
A24: completeness (accepted / 9 expected) | B24: =ROUND(B17/9,6) -> 0.888889 | C24: 0.888889 | D24: =ROUND(B24-C24,6)=0 -> TRUE
A25: run-001 task success (4 tasks, 4 successful) | B25: =ROUND(4/4,6) -> 1 | C25: 1 | D25: =ROUND(B25-C25,6)=0 -> TRUE
A26: run-001 attempt success (5 attempts: transform twice; 4 successful) | B26: =ROUND(4/(1+2+1+1),6) -> 0.8 | C26: 0.8 | D26: =ROUND(B26-C26,6)=0 -> TRUE
A27: source total (every received row) | B27: =ROUND(SUM(D4:D13),2) -> 289.94 | C27: 289.94 | D27: =ROUND(B27-C27,6)=0 -> TRUE
A28: published total (accepted rows) | B28: =ROUND(SUMIF(F4:F13,"accepted",D4:D13),2) -> 289.97 | C28: 289.97 | D28: =ROUND(B28-C28,6)=0 -> TRUE
A29: quarantined amount (exclusion) | B29: =ROUND(SUMIF(F4:F13,"quarantined",D4:D13),2) -> -30 | C29: -30 | D29: =ROUND(B29-C29,6)=0 -> TRUE
A30: duplicate amount (exclusion) | B30: =ROUND(SUMIF(F4:F13,"duplicate",D4:D13),2) -> 29.97 | C30: 29.97 | D30: =ROUND(B30-C30,6)=0 -> TRUE
A31: residual = source - published - exclusions | B31: =ROUND(B27-B28-(B29+B30),2) -> 0 | C31: 0 | D31: =ROUND(B31-C31,6)=0 -> TRUE
A32: recovery minutes (verified 20:15 minus detected 12:20) | B32: =ROUND(ROUND((46299.84375-46299.5138888889)*86400,0)/60,4) -> 475 | C32: 475 | D32: =ROUND(B32-C32,6)=0 -> TRUE
A33: backfill coverage (2 of 3 partitions) | B33: =ROUND(2/3,6) -> 0.666667 | C33: 0.666667 | D33: =ROUND(B33-C33,6)=0 -> TRUE
A34: processing rate (8 accepted / 12 s) | B34: =ROUND(B17/12,6) -> 0.666667 | C34: 0.666667 | D34: =ROUND(B34-C34,6)=0 -> TRUE

Sheet Assumptions
A1: Assumptions and limits
A3: id | B3: statement
A4: A-01 | B4: Gate (D-P8-08): a run reached the gate when it has quality results; allowed iff at least one critical result exists and none failed, else blocked; a run that never reached the gate has no decision (not_reached). 'Blocked' in the domain's pointer_history counts those 15 runs too; the funnel keeps them apart (D-09 R8-07).
A5: A-02 | B5: Failure kind: a failed run that reached the gate is named for its failed critical check (freshness_within_target = freshness, relationships_intact = relationships, reconciliation_residual_zero = residual); otherwise for the task that failed last (ingest, transform; quality_gate = gate_infra).
A6: A-03 | B6: Rates divide by received (committed batches only; the schema-quarantined batch and the aborted batches count for nothing). A zero denominator is null, never 0. Deleted rows are beside accepted, duplicate and quarantined, not inside a rate's numerator.
A7: A-04 | B7: Ingestion age = as-of minus the latest checkpoint of a committed batch; freshness = as-of minus the latest ACCEPTED event, which is RECORDED by the generator (the files hold a 2,000-row sample of the raw rows). Silent = freshness above Controls!B3 declared cadences (a display rule, not a contract rule).
A8: A-05 | B8: Task success = successful terminal tasks / terminal tasks (the status of a task's last attempt); attempt success = successful attempts / attempts. An attempt is not a task.
A9: A-06 | B9: Recovery minutes = (verified recovery - detection) / 60, the verified recovery being the publication of the first later run that succeeded, was allowed and reconciled (D-P8-06); the recovery publication instants are typed from the published files.
A10: A-07 | B10: Backfill coverage = verified / requested partitions of the ACCEPTED requests; the 4 partitions of the 2 requests refused for overlap are shown beside it (D-09 R8-11).
A11: W-01 | B11: Observed, constructed and hypothetical results are kept apart: every figure is observed in one draw of a generated world; the designed relationships (DR-01..DR-05) and the twelve injected defects are constructed; no benefit to a real organisation is claimed.
A12: W-02 | B12: TYPED, not replayed by formulas: the per-batch counts (the generator's domain run over 40,191 raw rows), the gate and task counts of each run, the recorded latest accepted event of each source, the recovery publication instants and the sample's own classification (python_side.py). Each is compared with the Python domain, the manifest or the SQL after recalculation.
A13: W-03 | B13: Recalculation: openpyxl writes formulas only; the delivered file was recalculated by LibreOffice headless and carries its cached values; Excel was NOT run. fullCalcOnLoad is set so Excel recalculates on open. Functions used: SUMIFS, COUNTIFS, COUNTIF, MAXIFS, AVERAGEIFS, INDEX, MATCH, LOOKUP, ROUND, IF, AND, IFERROR (MAXIFS needs Excel 2019 or later).
A14: W-04 | B14: The switches change what the Selected columns and the verdict show; the check cell does not depend on the scope switch, and its verdict check applies at the default controls.
A15: W-05 | B15: The workbook has no macros, no external links and no credentials.

Sheet Sources
A1: Source contracts (6) and the RECORDED latest accepted event of each
A2: latest_accepted_event is RECORDED by the generator (manifest stats.freshness_at_as_of): the published raw rows are a sample and cannot show it. expected_records = the declared expectation over 56 partitions (complete world).
A3: source_id | B3: expected_frequency | C3: cadence_seconds | D3: freshness_target_seconds | E3: schema_version | F3: expected_records | G3: latest_accepted_event (recorded, serial) | H3: sample_rows_in_the_files
A4: src-inventory | B4: daily | C4: 86400 | D4: 259200 | E4: 1 | F4: 1645 | G4: 46299.083 | H4: 86
A5: src-orders | B5: every 4 hours | C5: 14400 | D5: 19800 | E5: 1 | F5: 16176 | G5: 46299.832 | H5: 1054
A6: src-payments | B6: every 4 hours | C6: 14400 | D6: 21600 | E6: 2 | F6: 10207 | G6: 46299.91 | H6: 418
A7: src-refunds | B7: every 6 hours | C7: 21600 | D7: 604800 | E7: 1 | F7: 4003 | G7: 46296.963 | H7: 152
A8: src-shipments | B8: every 6 hours | C8: 21600 | D8: 259200 | E8: 1 | F8: 4004 | G8: 46299.864 | H8: 193
A9: src-web-events | B9: every 12 hours | C9: 43200 | D9: 216000 | E9: 1 | F9: 1678 | G9: 46299.752 | H9: 97

Sheet Batches
A1: Ingestion batches (1,311): the per-batch counts the generator's domain run computed over ALL raw rows (COMPLETE world)
A2: received counts committed batches only; the schema-quarantined batch (status quarantined) and the aborted batches count for nothing.
A3: batch_id | B3: source_id | C3: status | D3: kind | E3: started_at (serial) | F3: written_rows | G3: received | H3: accepted_unique | I3: duplicate | J3: quarantined | K3: deleted | L3: sampled
A4: b-0001 | B4: src-refunds | C4: committed | D4: live | E4: 46244.046 | F4: 1 | G4: 1 | H4: 1 | I4: 0 | J4: 0 | K4: 0 | L4: =FALSE() -> FALSE
A5: b-0002 | B5: src-payments | C5: committed | D5: live | E5: 46244.088 | F5: 4 | G5: 4 | H5: 4 | I5: 0 | J5: 0 | K5: 0 | L5: =FALSE() -> FALSE
A6: b-0003 | B6: src-shipments | C6: committed | D6: live | E6: 46244.13 | F6: 2 | G6: 2 | H6: 2 | I6: 0 | J6: 0 | K6: 0 | L6: =FALSE() -> FALSE
A7: b-0004 | B7: src-orders | C7: committed | D7: live | E7: 46244.17 | F7: 15 | G7: 15 | H7: 15 | I7: 0 | J7: 0 | K7: 0 | L7: =FALSE() -> FALSE
A8: b-0005 | B8: src-inventory | C8: committed | D8: live | E8: 46244.213 | F8: 2 | G8: 2 | H8: 2 | I8: 0 | J8: 0 | K8: 0 | L8: =TRUE() -> TRUE
A9: b-0006 | B9: src-payments | C9: committed | D9: live | E9: 46244.253 | F9: 12 | G9: 12 | H9: 9 | I9: 3 | J9: 0 | K9: 0 | L9: =FALSE() -> FALSE
A10: b-0007 | B10: src-web-events | C10: committed | D10: live | E10: 46244.256 | F10: 1 | G10: 1 | H10: 1 | I10: 0 | J10: 0 | K10: 0 | L10: =FALSE() -> FALSE
A11: b-0008 | B11: src-refunds | C11: committed | D11: live | E11: 46244.297 | F11: 7 | G11: 7 | H11: 7 | I11: 0 | J11: 0 | K11: 0 | L11: =FALSE() -> FALSE
A12: b-0009 | B12: src-orders | C12: committed | D12: live | E12: 46244.336 | F12: 33 | G12: 33 | H12: 29 | I12: 3 | J12: 1 | K12: 0 | L12: =FALSE() -> FALSE
A13: b-0010 | B13: src-shipments | C13: committed | D13: live | E13: 46244.38 | F13: 14 | G13: 14 | H13: 14 | I13: 0 | J13: 0 | K13: 0 | L13: =FALSE() -> FALSE
A14: b-0011 | B14: src-payments | C14: committed | D14: live | E14: 46244.42 | F14: 36 | G14: 36 | H14: 33 | I14: 3 | J14: 0 | K14: 0 | L14: =FALSE() -> FALSE
A15: b-0012 | B15: src-orders | C15: committed | D15: live | E15: 46244.502 | F15: 74 | G15: 74 | H15: 72 | I15: 1 | J15: 1 | K15: 0 | L15: =FALSE() -> FALSE
A16: b-0013 | B16: src-refunds | C16: committed | D16: live | E16: 46244.547 | F16: 30 | G16: 30 | H16: 27 | I16: 3 | J16: 0 | K16: 0 | L16: =FALSE() -> FALSE
A17: b-0014 | B17: src-payments | C17: committed | D17: live | E17: 46244.587 | F17: 52 | G17: 52 | H17: 50 | I17: 2 | J17: 0 | K17: 0 | L17: =FALSE() -> FALSE
A18: b-0015 | B18: src-shipments | C18: committed | D18: live | E18: 46244.631 | F18: 34 | G18: 34 | H18: 31 | I18: 3 | J18: 0 | K18: 0 | L18: =FALSE() -> FALSE
A19: b-0016 | B19: src-orders | C19: committed | D19: live | E19: 46244.669 | F19: 74 | G19: 74 | H19: 72 | I19: 2 | J19: 0 | K19: 0 | L19: =FALSE() -> FALSE
A20: b-0017 | B20: src-payments | C20: committed | D20: live | E20: 46244.753 | F20: 48 | G20: 48 | H20: 47 | I20: 1 | J20: 0 | K20: 0 | L20: =FALSE() -> FALSE
... A63: b-0060 | B63: src-payments | C63: committed | D63: live | E63: 46246.588 | F63: 48 | G63: 48 | H63: 48 | I63: 0 | J63: 0 | K63: 0 | L63: =FALSE() -> FALSE
A64: b-0061 | B64: src-shipments | C64: committed | D64: live | E64: 46246.631 | F64: 27 | G64: 27 | H64: 25 | I64: 2 | J64: 0 | K64: 0 | L64: =TRUE() -> TRUE
A65: b-0062 | B65: src-orders | C65: committed | D65: live | E65: 46246.669 | F65: 85 | G65: 85 | H65: 84 | I65: 1 | J65: 0 | K65: 0 | L65: =FALSE() -> FALSE
A66: b-0063 | B66: src-payments | C66: committed | D66: live | E66: 46246.754 | F66: 48 | G66: 48 | H66: 43 | I66: 3 | J66: 2 | K66: 0 | L66: =FALSE() -> FALSE
A67: b-0064 | B67: src-web-events | C67: committed | D67: live | E67: 46246.757 | F67: 25 | G67: 25 | H67: 21 | I67: 3 | J67: 1 | K67: 0 | L67: =FALSE() -> FALSE
A68: b-0065 | B68: src-refunds | C68: committed | D68: live | E68: 46246.796 | F68: 26 | G68: 26 | H68: 24 | I68: 2 | J68: 0 | K68: 0 | L68: =FALSE() -> FALSE
A69: b-0066 | B69: src-orders | C69: committed | D69: live | E69: 46246.836 | F69: 75 | G69: 75 | H69: 71 | I69: 3 | J69: 1 | K69: 0 | L69: =FALSE() -> FALSE
A70: b-0067 | B70: src-shipments | C70: committed | D70: live | E70: 46246.88 | F70: 24 | G70: 24 | H70: 23 | I70: 1 | J70: 0 | K70: 0 | L70: =FALSE() -> FALSE
A71: b-0068 | B71: src-payments | C71: committed | D71: live | E71: 46246.921 | F71: 39 | G71: 39 | H71: 36 | I71: 3 | J71: 0 | K71: 0 | L71: =FALSE() -> FALSE
A72: b-0069 | B72: src-orders | C72: committed | D72: live | E72: 46247.004 | F72: 42 | G72: 42 | H72: 41 | I72: 1 | J72: 0 | K72: 0 | L72: =FALSE() -> FALSE
A73: b-0070 | B73: src-refunds | C73: committed | D73: live | E73: 46247.046 | F73: 17 | G73: 17 | H73: 15 | I73: 2 | J73: 0 | K73: 0 | L73: =FALSE() -> FALSE
A74: b-0071 | B74: src-payments | C74: committed | D74: live | E74: 46247.086 | F74: 14 | G74: 14 | H74: 13 | I74: 0 | J74: 1 | K74: 0 | L74: =FALSE() -> FALSE
A75: b-0072 | B75: src-shipments | C75: committed | D75: live | E75: 46247.13 | F75: 10 | G75: 10 | H75: 10 | I75: 0 | J75: 0 | K75: 0 | L75: =TRUE() -> TRUE
A76: b-0073 | B76: src-orders | C76: committed | D76: live | E76: 46247.17 | F76: 15 | G76: 15 | H76: 13 | I76: 2 | J76: 0 | K76: 0 | L76: =FALSE() -> FALSE
A77: b-0074 | B77: src-inventory | C77: committed | D77: live | E77: 46247.214 | F77: 36 | G77: 36 | H77: 34 | I77: 2 | J77: 0 | K77: 0 | L77: =FALSE() -> FALSE
A78: b-0075 | B78: src-payments | C78: committed | D78: live | E78: 46247.253 | F78: 10 | G78: 10 | H78: 8 | I78: 2 | J78: 0 | K78: 0 | L78: =FALSE() -> FALSE
A79: b-0076 | B79: src-web-events | C79: committed | D79: live | E79: 46247.256 | F79: 8 | G79: 8 | H79: 7 | I79: 1 | J79: 0 | K79: 0 | L79: =FALSE() -> FALSE
A80: b-0077 | B80: src-refunds | C80: committed | D80: live | E80: 46247.296 | F80: 9 | G80: 9 | H80: 6 | I80: 3 | J80: 0 | K80: 0 | L80: =FALSE() -> FALSE
A81: b-0078 | B81: src-orders | C81: committed | D81: live | E81: 46247.336 | F81: 33 | G81: 33 | H81: 30 | I81: 2 | J81: 1 | K81: 0 | L81: =FALSE() -> FALSE
A82: b-0079 | B82: src-shipments | C82: committed | D82: live | E82: 46247.38 | F82: 15 | G82: 15 | H82: 14 | I82: 1 | J82: 0 | K82: 0 | L82: =FALSE() -> FALSE
...

Sheet Checkpoints
A1: Checkpoints (1,302): one per committed batch, committed with its rows in one transaction
A2: The last successful ingestion of a source is its latest committed_at.
A3: batch_id | B3: source_id | C3: committed_at (serial) | D3: version_number
A4: b-0005 | B4: src-inventory | C4: 46244.217 | D4: 1
A5: b-0028 | B5: src-inventory | C5: 46245.218 | D5: 2
A6: b-0051 | B6: src-inventory | C6: 46246.217 | D6: 3
A7: b-0074 | B7: src-inventory | C7: 46247.218 | D7: 4
A8: b-0097 | B8: src-inventory | C8: 46248.218 | D8: 5
A9: b-0120 | B9: src-inventory | C9: 46249.22 | D9: 6
A10: b-0143 | B10: src-inventory | C10: 46250.22 | D10: 7
A11: b-0167 | B11: src-inventory | C11: 46251.218 | D11: 8
A12: b-0190 | B12: src-inventory | C12: 46252.219 | D12: 9
A13: b-0213 | B13: src-inventory | C13: 46253.216 | D13: 10
A14: b-0237 | B14: src-inventory | C14: 46254.218 | D14: 11
A15: b-0260 | B15: src-inventory | C15: 46255.216 | D15: 12
... A1305: b-1307 | B1305: src-web-events | C1305: 46299.76 | D1305: 116

Sheet Runs
A1: Pipeline runs (1,343): typed gate and task counts, the stage and failure kind by formula (COMPLETE world)
A2: gate_decision: not_reached when the run has no check result; allowed when a critical result exists and none failed; else blocked (D-P8-08). failure_kind: the failed critical check, or the task that failed last.
A3: run_id | B3: started_at (serial) | C3: status | D3: duration_seconds | E3: checks | F3: critical_checks | G3: critical_failed | H3: failed_task | I3: first_failed_critical | J3: published | K3: publication_id | L3: tasks_terminal | M3: tasks_successful | N3: attempts | O3: attempts_successful | P3: gate_decision | Q3: stage | R3: failure_kind
A4: run-0001 | B4: 46244.052 | C4: success | D4: 934 | E4: 7 | F4: 6 | G4: 0 | J4: =TRUE() -> TRUE | K4: pub-0001 | L4: 4 | M4: 4 | N4: 4 | O4: 4 | P4: =IF(E4=0,"not_reached",IF(AND(F4>0,G4=0),"allowed","blocked")) -> allowed | Q4: =IF(C4="success","published",IF(E4>0,"blocked_at_gate","failed_before_gate")) -> published | R4: =IF(C4="success","",IF(E4>0,IF(I4="freshness_within_target","freshness",IF(I4="relationships_intact","relationships",IF(I4="reconciliation_residual_zero","residual",I4))),IF(H4="quality_gate","gate_infra",H4)))
A5: run-0002 | B5: 46244.094 | C5: success | D5: 864 | E5: 7 | F5: 6 | G5: 0 | J5: =TRUE() -> TRUE | K5: pub-0002 | L5: 4 | M5: 4 | N5: 4 | O5: 4 | P5: =IF(E5=0,"not_reached",IF(AND(F5>0,G5=0),"allowed","blocked")) -> allowed | Q5: =IF(C5="success","published",IF(E5>0,"blocked_at_gate","failed_before_gate")) -> published | R5: =IF(C5="success","",IF(E5>0,IF(I5="freshness_within_target","freshness",IF(I5="relationships_intact","relationships",IF(I5="reconciliation_residual_zero","residual",I5))),IF(H5="quality_gate","gate_infra",H5)))
A6: run-0003 | B6: 46244.135 | C6: success | D6: 829 | E6: 7 | F6: 6 | G6: 0 | J6: =TRUE() -> TRUE | K6: pub-0003 | L6: 4 | M6: 4 | N6: 4 | O6: 4 | P6: =IF(E6=0,"not_reached",IF(AND(F6>0,G6=0),"allowed","blocked")) -> allowed | Q6: =IF(C6="success","published",IF(E6>0,"blocked_at_gate","failed_before_gate")) -> published | R6: =IF(C6="success","",IF(E6>0,IF(I6="freshness_within_target","freshness",IF(I6="relationships_intact","relationships",IF(I6="reconciliation_residual_zero","residual",I6))),IF(H6="quality_gate","gate_infra",H6)))
A7: run-0004 | B7: 46244.177 | C7: success | D7: 765 | E7: 7 | F7: 6 | G7: 0 | J7: =TRUE() -> TRUE | K7: pub-0004 | L7: 4 | M7: 4 | N7: 4 | O7: 4 | P7: =IF(E7=0,"not_reached",IF(AND(F7>0,G7=0),"allowed","blocked")) -> allowed | Q7: =IF(C7="success","published",IF(E7>0,"blocked_at_gate","failed_before_gate")) -> published | R7: =IF(C7="success","",IF(E7>0,IF(I7="freshness_within_target","freshness",IF(I7="relationships_intact","relationships",IF(I7="reconciliation_residual_zero","residual",I7))),IF(H7="quality_gate","gate_infra",H7)))
A8: run-0005 | B8: 46244.219 | C8: success | D8: 819 | E8: 7 | F8: 6 | G8: 0 | J8: =TRUE() -> TRUE | K8: pub-0005 | L8: 4 | M8: 4 | N8: 4 | O8: 4 | P8: =IF(E8=0,"not_reached",IF(AND(F8>0,G8=0),"allowed","blocked")) -> allowed | Q8: =IF(C8="success","published",IF(E8>0,"blocked_at_gate","failed_before_gate")) -> published | R8: =IF(C8="success","",IF(E8>0,IF(I8="freshness_within_target","freshness",IF(I8="relationships_intact","relationships",IF(I8="reconciliation_residual_zero","residual",I8))),IF(H8="quality_gate","gate_infra",H8)))
A9: run-0006 | B9: 46244.26 | C9: success | D9: 938 | E9: 7 | F9: 6 | G9: 0 | J9: =TRUE() -> TRUE | K9: pub-0006 | L9: 4 | M9: 4 | N9: 4 | O9: 4 | P9: =IF(E9=0,"not_reached",IF(AND(F9>0,G9=0),"allowed","blocked")) -> allowed | Q9: =IF(C9="success","published",IF(E9>0,"blocked_at_gate","failed_before_gate")) -> published | R9: =IF(C9="success","",IF(E9>0,IF(I9="freshness_within_target","freshness",IF(I9="relationships_intact","relationships",IF(I9="reconciliation_residual_zero","residual",I9))),IF(H9="quality_gate","gate_infra",H9)))
A10: run-0007 | B10: 46244.302 | C10: success | D10: 894 | E10: 7 | F10: 6 | G10: 0 | J10: =TRUE() -> TRUE | K10: pub-0007 | L10: 4 | M10: 4 | N10: 4 | O10: 4 | P10: =IF(E10=0,"not_reached",IF(AND(F10>0,G10=0),"allowed","blocked")) -> allowed | Q10: =IF(C10="success","published",IF(E10>0,"blocked_at_gate","failed_before_gate")) -> published | R10: =IF(C10="success","",IF(E10>0,IF(I10="freshness_within_target","freshness",IF(I10="relationships_intact","relationships",IF(I10="reconciliation_residual_zero","residual",I10))),IF(H10="quality_gate","gate_infra",H10)))
A11: run-0008 | B11: 46244.344 | C11: success | D11: 753 | E11: 7 | F11: 6 | G11: 0 | J11: =TRUE() -> TRUE | K11: pub-0008 | L11: 4 | M11: 4 | N11: 4 | O11: 4 | P11: =IF(E11=0,"not_reached",IF(AND(F11>0,G11=0),"allowed","blocked")) -> allowed | Q11: =IF(C11="success","published",IF(E11>0,"blocked_at_gate","failed_before_gate")) -> published | R11: =IF(C11="success","",IF(E11>0,IF(I11="freshness_within_target","freshness",IF(I11="relationships_intact","relationships",IF(I11="reconciliation_residual_zero","residual",I11))),IF(H11="quality_gate","gate_infra",H11)))
A12: run-0009 | B12: 46244.385 | C12: success | D12: 697 | E12: 7 | F12: 6 | G12: 0 | J12: =TRUE() -> TRUE | K12: pub-0009 | L12: 4 | M12: 4 | N12: 4 | O12: 4 | P12: =IF(E12=0,"not_reached",IF(AND(F12>0,G12=0),"allowed","blocked")) -> allowed | Q12: =IF(C12="success","published",IF(E12>0,"blocked_at_gate","failed_before_gate")) -> published | R12: =IF(C12="success","",IF(E12>0,IF(I12="freshness_within_target","freshness",IF(I12="relationships_intact","relationships",IF(I12="reconciliation_residual_zero","residual",I12))),IF(H12="quality_gate","gate_infra",H12)))
A13: run-0010 | B13: 46244.427 | C13: success | D13: 786 | E13: 7 | F13: 6 | G13: 0 | J13: =TRUE() -> TRUE | K13: pub-0010 | L13: 4 | M13: 4 | N13: 4 | O13: 4 | P13: =IF(E13=0,"not_reached",IF(AND(F13>0,G13=0),"allowed","blocked")) -> allowed | Q13: =IF(C13="success","published",IF(E13>0,"blocked_at_gate","failed_before_gate")) -> published | R13: =IF(C13="success","",IF(E13>0,IF(I13="freshness_within_target","freshness",IF(I13="relationships_intact","relationships",IF(I13="reconciliation_residual_zero","residual",I13))),IF(H13="quality_gate","gate_infra",H13)))
A14: run-0011 | B14: 46244.469 | C14: success | D14: 959 | E14: 7 | F14: 6 | G14: 0 | J14: =TRUE() -> TRUE | K14: pub-0011 | L14: 4 | M14: 4 | N14: 4 | O14: 4 | P14: =IF(E14=0,"not_reached",IF(AND(F14>0,G14=0),"allowed","blocked")) -> allowed | Q14: =IF(C14="success","published",IF(E14>0,"blocked_at_gate","failed_before_gate")) -> published | R14: =IF(C14="success","",IF(E14>0,IF(I14="freshness_within_target","freshness",IF(I14="relationships_intact","relationships",IF(I14="reconciliation_residual_zero","residual",I14))),IF(H14="quality_gate","gate_infra",H14)))
A15: run-0012 | B15: 46244.51 | C15: success | D15: 675 | E15: 7 | F15: 6 | G15: 0 | J15: =TRUE() -> TRUE | K15: pub-0012 | L15: 4 | M15: 4 | N15: 4 | O15: 4 | P15: =IF(E15=0,"not_reached",IF(AND(F15>0,G15=0),"allowed","blocked")) -> allowed | Q15: =IF(C15="success","published",IF(E15>0,"blocked_at_gate","failed_before_gate")) -> published | R15: =IF(C15="success","",IF(E15>0,IF(I15="freshness_within_target","freshness",IF(I15="relationships_intact","relationships",IF(I15="reconciliation_residual_zero","residual",I15))),IF(H15="quality_gate","gate_infra",H15)))
... A181: run-0178 | B181: 46251.427 | C181: success | D181: 721 | E181: 7 | F181: 6 | G181: 0 | J181: =TRUE() -> TRUE | K181: pub-0178 | L181: 4 | M181: 4 | N181: 4 | O181: 4 | P181: =IF(E181=0,"not_reached",IF(AND(F181>0,G181=0),"allowed","blocked")) -> allowed | Q181: =IF(C181="success","published",IF(E181>0,"blocked_at_gate","failed_before_gate")) -> published | R181: =IF(C181="success","",IF(E181>0,IF(I181="freshness_within_target","freshness",IF(I181="relationships_intact","relationships",IF(I181="reconciliation_residual_zero","residual",I181))),IF(H181="quality_gate","gate_infra",H181)))
A182: run-0179 | B182: 46251.469 | C182: failed | D182: 428 | E182: 0 | F182: 0 | G182: 0 | H182: ingest | J182: =FALSE() -> FALSE | L182: 1 | M182: 0 | N182: 3 | O182: 0 | P182: =IF(E182=0,"not_reached",IF(AND(F182>0,G182=0),"allowed","blocked")) -> not_reached | Q182: =IF(C182="success","published",IF(E182>0,"blocked_at_gate","failed_before_gate")) -> failed_before_gate | R182: =IF(C182="success","",IF(E182>0,IF(I182="freshness_within_target","freshness",IF(I182="relationships_intact","relationships",IF(I182="reconciliation_residual_zero","residual",I182))),IF(H182="quality_gate","gate_infra",H182))) -> ingest
A183: run-0180 | B183: 46251.51 | C183: success | D183: 874 | E183: 7 | F183: 6 | G183: 0 | J183: =TRUE() -> TRUE | K183: pub-0180 | L183: 4 | M183: 4 | N183: 4 | O183: 4 | P183: =IF(E183=0,"not_reached",IF(AND(F183>0,G183=0),"allowed","blocked")) -> allowed | Q183: =IF(C183="success","published",IF(E183>0,"blocked_at_gate","failed_before_gate")) -> published | R183: =IF(C183="success","",IF(E183>0,IF(I183="freshness_within_target","freshness",IF(I183="relationships_intact","relationships",IF(I183="reconciliation_residual_zero","residual",I183))),IF(H183="quality_gate","gate_infra",H183)))
A184: run-0181 | B184: 46251.552 | C184: success | D184: 694 | E184: 7 | F184: 6 | G184: 0 | J184: =TRUE() -> TRUE | K184: pub-0181 | L184: 4 | M184: 4 | N184: 4 | O184: 4 | P184: =IF(E184=0,"not_reached",IF(AND(F184>0,G184=0),"allowed","blocked")) -> allowed | Q184: =IF(C184="success","published",IF(E184>0,"blocked_at_gate","failed_before_gate")) -> published | R184: =IF(C184="success","",IF(E184>0,IF(I184="freshness_within_target","freshness",IF(I184="relationships_intact","relationships",IF(I184="reconciliation_residual_zero","residual",I184))),IF(H184="quality_gate","gate_infra",H184)))
A185: run-0182 | B185: 46251.594 | C185: success | D185: 686 | E185: 7 | F185: 6 | G185: 0 | J185: =TRUE() -> TRUE | K185: pub-0182 | L185: 4 | M185: 4 | N185: 4 | O185: 4 | P185: =IF(E185=0,"not_reached",IF(AND(F185>0,G185=0),"allowed","blocked")) -> allowed | Q185: =IF(C185="success","published",IF(E185>0,"blocked_at_gate","failed_before_gate")) -> published | R185: =IF(C185="success","",IF(E185>0,IF(I185="freshness_within_target","freshness",IF(I185="relationships_intact","relationships",IF(I185="reconciliation_residual_zero","residual",I185))),IF(H185="quality_gate","gate_infra",H185)))
A186: run-0183 | B186: 46251.635 | C186: success | D186: 1072 | E186: 7 | F186: 6 | G186: 0 | J186: =TRUE() -> TRUE | K186: pub-0183 | L186: 4 | M186: 4 | N186: 5 | O186: 4 | P186: =IF(E186=0,"not_reached",IF(AND(F186>0,G186=0),"allowed","blocked")) -> allowed | Q186: =IF(C186="success","published",IF(E186>0,"blocked_at_gate","failed_before_gate")) -> published | R186: =IF(C186="success","",IF(E186>0,IF(I186="freshness_within_target","freshness",IF(I186="relationships_intact","relationships",IF(I186="reconciliation_residual_zero","residual",I186))),IF(H186="quality_gate","gate_infra",H186)))
A187: run-0184 | B187: 46251.677 | C187: success | D187: 844 | E187: 7 | F187: 6 | G187: 0 | J187: =TRUE() -> TRUE | K187: pub-0184 | L187: 4 | M187: 4 | N187: 4 | O187: 4 | P187: =IF(E187=0,"not_reached",IF(AND(F187>0,G187=0),"allowed","blocked")) -> allowed | Q187: =IF(C187="success","published",IF(E187>0,"blocked_at_gate","failed_before_gate")) -> published | R187: =IF(C187="success","",IF(E187>0,IF(I187="freshness_within_target","freshness",IF(I187="relationships_intact","relationships",IF(I187="reconciliation_residual_zero","residual",I187))),IF(H187="quality_gate","gate_infra",H187)))
A188: run-0185 | B188: 46251.719 | C188: failed | D188: 941 | E188: 0 | F188: 0 | G188: 0 | H188: transform | J188: =FALSE() -> FALSE | L188: 2 | M188: 1 | N188: 4 | O188: 1 | P188: =IF(E188=0,"not_reached",IF(AND(F188>0,G188=0),"allowed","blocked")) -> not_reached | Q188: =IF(C188="success","published",IF(E188>0,"blocked_at_gate","failed_before_gate")) -> failed_before_gate | R188: =IF(C188="success","",IF(E188>0,IF(I188="freshness_within_target","freshness",IF(I188="relationships_intact","relationships",IF(I188="reconciliation_residual_zero","residual",I188))),IF(H188="quality_gate","gate_infra",H188))) -> transform
A189: run-0186 | B189: 46251.76 | C189: success | D189: 902 | E189: 7 | F189: 6 | G189: 0 | J189: =TRUE() -> TRUE | K189: pub-0186 | L189: 4 | M189: 4 | N189: 4 | O189: 4 | P189: =IF(E189=0,"not_reached",IF(AND(F189>0,G189=0),"allowed","blocked")) -> allowed | Q189: =IF(C189="success","published",IF(E189>0,"blocked_at_gate","failed_before_gate")) -> published | R189: =IF(C189="success","",IF(E189>0,IF(I189="freshness_within_target","freshness",IF(I189="relationships_intact","relationships",IF(I189="reconciliation_residual_zero","residual",I189))),IF(H189="quality_gate","gate_infra",H189)))
A190: run-0187 | B190: 46251.802 | C190: success | D190: 757 | E190: 7 | F190: 6 | G190: 0 | J190: =TRUE() -> TRUE | K190: pub-0187 | L190: 4 | M190: 4 | N190: 4 | O190: 4 | P190: =IF(E190=0,"not_reached",IF(AND(F190>0,G190=0),"allowed","blocked")) -> allowed | Q190: =IF(C190="success","published",IF(E190>0,"blocked_at_gate","failed_before_gate")) -> published | R190: =IF(C190="success","",IF(E190>0,IF(I190="freshness_within_target","freshness",IF(I190="relationships_intact","relationships",IF(I190="reconciliation_residual_zero","residual",I190))),IF(H190="quality_gate","gate_infra",H190)))
A191: run-0188 | B191: 46251.844 | C191: success | D191: 769 | E191: 7 | F191: 6 | G191: 0 | J191: =TRUE() -> TRUE | K191: pub-0188 | L191: 4 | M191: 4 | N191: 4 | O191: 4 | P191: =IF(E191=0,"not_reached",IF(AND(F191>0,G191=0),"allowed","blocked")) -> allowed | Q191: =IF(C191="success","published",IF(E191>0,"blocked_at_gate","failed_before_gate")) -> published | R191: =IF(C191="success","",IF(E191>0,IF(I191="freshness_within_target","freshness",IF(I191="relationships_intact","relationships",IF(I191="reconciliation_residual_zero","residual",I191))),IF(H191="quality_gate","gate_infra",H191)))
A192: run-0189 | B192: 46251.885 | C192: success | D192: 899 | E192: 7 | F192: 6 | G192: 0 | J192: =TRUE() -> TRUE | K192: pub-0189 | L192: 4 | M192: 4 | N192: 5 | O192: 4 | P192: =IF(E192=0,"not_reached",IF(AND(F192>0,G192=0),"allowed","blocked")) -> allowed | Q192: =IF(C192="success","published",IF(E192>0,"blocked_at_gate","failed_before_gate")) -> published | R192: =IF(C192="success","",IF(E192>0,IF(I192="freshness_within_target","freshness",IF(I192="relationships_intact","relationships",IF(I192="reconciliation_residual_zero","residual",I192))),IF(H192="quality_gate","gate_infra",H192)))
A193: run-0190 | B193: 46251.927 | C193: success | D193: 766 | E193: 7 | F193: 6 | G193: 0 | J193: =TRUE() -> TRUE | K193: pub-0190 | L193: 4 | M193: 4 | N193: 4 | O193: 4 | P193: =IF(E193=0,"not_reached",IF(AND(F193>0,G193=0),"allowed","blocked")) -> allowed | Q193: =IF(C193="success","published",IF(E193>0,"blocked_at_gate","failed_before_gate")) -> published | R193: =IF(C193="success","",IF(E193>0,IF(I193="freshness_within_target","freshness",IF(I193="relationships_intact","relationships",IF(I193="reconciliation_residual_zero","residual",I193))),IF(H193="quality_gate","gate_infra",H193)))
A194: run-0191 | B194: 46251.969 | C194: success | D194: 864 | E194: 7 | F194: 6 | G194: 0 | J194: =TRUE() -> TRUE | K194: pub-0191 | L194: 4 | M194: 4 | N194: 4 | O194: 4 | P194: =IF(E194=0,"not_reached",IF(AND(F194>0,G194=0),"allowed","blocked")) -> allowed | Q194: =IF(C194="success","published",IF(E194>0,"blocked_at_gate","failed_before_gate")) -> published | R194: =IF(C194="success","",IF(E194>0,IF(I194="freshness_within_target","freshness",IF(I194="relationships_intact","relationships",IF(I194="reconciliation_residual_zero","residual",I194))),IF(H194="quality_gate","gate_infra",H194)))
A195: run-0192 | B195: 46252.01 | C195: success | D195: 777 | E195: 7 | F195: 6 | G195: 0 | J195: =TRUE() -> TRUE | K195: pub-0192 | L195: 4 | M195: 4 | N195: 4 | O195: 4 | P195: =IF(E195=0,"not_reached",IF(AND(F195>0,G195=0),"allowed","blocked")) -> allowed | Q195: =IF(C195="success","published",IF(E195>0,"blocked_at_gate","failed_before_gate")) -> published | R195: =IF(C195="success","",IF(E195>0,IF(I195="freshness_within_target","freshness",IF(I195="relationships_intact","relationships",IF(I195="reconciliation_residual_zero","residual",I195))),IF(H195="quality_gate","gate_infra",H195)))
A196: run-0193 | B196: 46252.052 | C196: success | D196: 763 | E196: 7 | F196: 6 | G196: 0 | J196: =TRUE() -> TRUE | K196: pub-0193 | L196: 4 | M196: 4 | N196: 4 | O196: 4 | P196: =IF(E196=0,"not_reached",IF(AND(F196>0,G196=0),"allowed","blocked")) -> allowed | Q196: =IF(C196="success","published",IF(E196>0,"blocked_at_gate","failed_before_gate")) -> published | R196: =IF(C196="success","",IF(E196>0,IF(I196="freshness_within_target","freshness",IF(I196="relationships_intact","relationships",IF(I196="reconciliation_residual_zero","residual",I196))),IF(H196="quality_gate","gate_infra",H196)))
A197: run-0194 | B197: 46252.094 | C197: success | D197: 763 | E197: 7 | F197: 6 | G197: 0 | J197: =TRUE() -> TRUE | K197: pub-0194 | L197: 4 | M197: 4 | N197: 4 | O197: 4 | P197: =IF(E197=0,"not_reached",IF(AND(F197>0,G197=0),"allowed","blocked")) -> allowed | Q197: =IF(C197="success","published",IF(E197>0,"blocked_at_gate","failed_before_gate")) -> published | R197: =IF(C197="success","",IF(E197>0,IF(I197="freshness_within_target","freshness",IF(I197="relationships_intact","relationships",IF(I197="reconciliation_residual_zero","residual",I197))),IF(H197="quality_gate","gate_infra",H197)))
A198: run-0195 | B198: 46252.135 | C198: success | D198: 936 | E198: 7 | F198: 6 | G198: 0 | J198: =TRUE() -> TRUE | K198: pub-0195 | L198: 4 | M198: 4 | N198: 4 | O198: 4 | P198: =IF(E198=0,"not_reached",IF(AND(F198>0,G198=0),"allowed","blocked")) -> allowed | Q198: =IF(C198="success","published",IF(E198>0,"blocked_at_gate","failed_before_gate")) -> published | R198: =IF(C198="success","",IF(E198>0,IF(I198="freshness_within_target","freshness",IF(I198="relationships_intact","relationships",IF(I198="reconciliation_residual_zero","residual",I198))),IF(H198="quality_gate","gate_infra",H198)))
A199: run-0196 | B199: 46252.177 | C199: success | D199: 929 | E199: 7 | F199: 6 | G199: 0 | J199: =TRUE() -> TRUE | K199: pub-0196 | L199: 4 | M199: 4 | N199: 4 | O199: 4 | P199: =IF(E199=0,"not_reached",IF(AND(F199>0,G199=0),"allowed","blocked")) -> allowed | Q199: =IF(C199="success","published",IF(E199>0,"blocked_at_gate","failed_before_gate")) -> published | R199: =IF(C199="success","",IF(E199>0,IF(I199="freshness_within_target","freshness",IF(I199="relationships_intact","relationships",IF(I199="reconciliation_residual_zero","residual",I199))),IF(H199="quality_gate","gate_infra",H199)))
A200: run-0197 | B200: 46252.219 | C200: success | D200: 793 | E200: 7 | F200: 6 | G200: 0 | J200: =TRUE() -> TRUE | K200: pub-0197 | L200: 4 | M200: 4 | N200: 4 | O200: 4 | P200: =IF(E200=0,"not_reached",IF(AND(F200>0,G200=0),"allowed","blocked")) -> allowed | Q200: =IF(C200="success","published",IF(E200>0,"blocked_at_gate","failed_before_gate")) -> published | R200: =IF(C200="success","",IF(E200>0,IF(I200="freshness_within_target","freshness",IF(I200="relationships_intact","relationships",IF(I200="reconciliation_residual_zero","residual",I200))),IF(H200="quality_gate","gate_infra",H200)))
... A208: run-0205 | B208: 46252.552 | C208: success | D208: 947 | E208: 7 | F208: 6 | G208: 0 | J208: =TRUE() -> TRUE | K208: pub-0205 | L208: 4 | M208: 4 | N208: 4 | O208: 4 | P208: =IF(E208=0,"not_reached",IF(AND(F208>0,G208=0),"allowed","blocked")) -> allowed | Q208: =IF(C208="success","published",IF(E208>0,"blocked_at_gate","failed_before_gate")) -> published | R208: =IF(C208="success","",IF(E208>0,IF(I208="freshness_within_target","freshness",IF(I208="relationships_intact","relationships",IF(I208="reconciliation_residual_zero","residual",I208))),IF(H208="quality_gate","gate_infra",H208)))
A209: run-0206 | B209: 46252.594 | C209: failed | D209: 1065 | E209: 0 | F209: 0 | G209: 0 | H209: quality_gate | J209: =FALSE() -> FALSE | L209: 3 | M209: 2 | N209: 5 | O209: 2 | P209: =IF(E209=0,"not_reached",IF(AND(F209>0,G209=0),"allowed","blocked")) -> not_reached | Q209: =IF(C209="success","published",IF(E209>0,"blocked_at_gate","failed_before_gate")) -> failed_before_gate | R209: =IF(C209="success","",IF(E209>0,IF(I209="freshness_within_target","freshness",IF(I209="relationships_intact","relationships",IF(I209="reconciliation_residual_zero","residual",I209))),IF(H209="quality_gate","gate_infra",H209))) -> gate_infra
A210: run-0207 | B210: 46252.635 | C210: success | D210: 852 | E210: 7 | F210: 6 | G210: 0 | J210: =TRUE() -> TRUE | K210: pub-0207 | L210: 4 | M210: 4 | N210: 4 | O210: 4 | P210: =IF(E210=0,"not_reached",IF(AND(F210>0,G210=0),"allowed","blocked")) -> allowed | Q210: =IF(C210="success","published",IF(E210>0,"blocked_at_gate","failed_before_gate")) -> published | R210: =IF(C210="success","",IF(E210>0,IF(I210="freshness_within_target","freshness",IF(I210="relationships_intact","relationships",IF(I210="reconciliation_residual_zero","residual",I210))),IF(H210="quality_gate","gate_infra",H210)))
